Workbook

Sheet L30CZ
B2: ='L30CZ-1'!$O$2 -> Ult Load, N | C2: ='L30CZ-1'!$P$2 -> Ult Stress, MPa | D2: ='L30CZ-1'!$Q$2 -> Failure Strain, % | E2: ='L30CZ-1'!$R$2 -> Ez, MPa | F2: ='L30CZ-1'!$S$2 -> νxz | G2: ='L30CZ-3'!$S$2 -> νyz | U2: 0.8 | V2: 504 | W2: =U2*V2 -> 403.2 | X2: =(E$3-W2)/E$3 -> 0.10363915
A3: average | B3: =AVERAGE(B6:B8) -> 113877.33 | C3: =AVERAGE(C6:C8) -> 68.386665 | D3: =AVERAGE(D6:D8) -> 0.16324467 | E3: =AVERAGE(E6:E8) -> 449.81884 | F3: =AVERAGE(F6:F8) -> 0.011068737 | G3: =AVERAGE(G6:G8) -> 0.037569689 | S3: =SUM(S4:S13) -> 1355 | T3: =AVERAGE('L30CZ-1'!C2,'L30CZ-2'!C2,'L30CZ-3'!C2) -> 1665.7286 | U3: =S3/T3 -> 0.81345783 | V3: 504 | W3: =U3*V3 -> 409.98275 | X3: =(E$3-W3)/E$3 -> 0.088560312
A4: sr. dev. | B4: =STDEV(B6:B8) -> 1121.7314 | C4: =STDEV(C6:C8) -> 0.55834511 | D4: =STDEV(D6:D8) -> 0.036379927 | E4: =STDEV(E6:E8) -> 30.013888 | F4: =STDEV(F6:F8) -> 0.0048835688 | Q4: =5*37.6 -> 188 | R4: 2 | S4: =Q4*R4 -> 376
A5: CV | B5: =B4/B3 -> 0.0098503483 | C5: =C4/C3 -> 0.008164532 | D5: =D4/D3 -> 0.22285522 | E5: =E4/E3 -> 0.06672439 | F5: =F4/F3 -> 0.44120379 | Q5: =5*38.4 -> 192 | R5: 2 | S5: =Q5*R5 -> 384
A6: 1 | B6: ='L30CZ-1'!$O$3 -> 114702 | C6: ='L30CZ-1'!$P$3 -> 68.702777 | D6: ='L30CZ-1'!$Q$3 -> 0.174986 | E6: ='L30CZ-1'!$R$3 -> 445.68897 | F6: ='L30CZ-1'!$S$3 -> 0.0076155327 | Q6: =3*38 -> 114 | R6: 2 | S6: =Q6*R6 -> 228
A7: 2 | B7: ='L30CZ-2'!$O$3 -> 114330 | C7: ='L30CZ-2'!$P$3 -> 68.715234 | D7: ='L30CZ-2'!$Q$3 -> 0.192304 | E7: ='L30CZ-2'!$R$3 -> 422.08375 | F7: ='L30CZ-2'!$S$3 -> 0.014521942 | Q7: =17.5*2 -> 35 | R7: 2 | S7: =Q7*R7 -> 70
A8: 3 | B8: ='L30CZ-3'!$O$3 -> 112600 | C8: ='L30CZ-3'!$P$3 -> 67.741983 | D8: ='L30CZ-3'!$Q$3 -> 0.122444 | E8: ='L30CZ-3'!$R$3 -> 481.68381 | G8: ='L30CZ-3'!$S$3 -> 0.037569689 | Q8: 31 | R8: 2 | S8: =Q8*R8 -> 62
Q9: 9.5 | R9: 2 | S9: =Q9*R9 -> 19
Q10: 36 | R10: 1 | S10: =Q10*R10 -> 36
Q11: 40 | R11: 1 | S11: =Q11*R11 -> 40
Q12: =8*5 -> 40 | R12: 2 | S12: =Q12*R12 -> 80
Q13: 30 | R13: 2 | S13: =Q13*R13 -> 60
S15: =S3/2 -> 677.5

Sheet L30CZ-1
A1: w | B1: t | Q1: =MATCH(Q3,Q5:Q1048576,0)-1 -> 680
A2: 40.85 | B2: 40.87 | C2: =A2*B2 -> 1669.5395 | O2: Ult Load, N | P2: Ult Stress, MPa | Q2: Failure Strain, % | R2: Ez, MPa | S2: νxz
A3: E0 | F3: E1 | J3: Analog | O3: =MAX(O5:O1048576) -> 114702 | P3: =MAX(P5:P1048576) -> 68.702777 | Q3: =INDEX(Q5:Q1048576,MATCH(P3,P5:P1048576,0)) -> 0.174986 | R3: =INDEX(LINEST(P150:P300,Q150:Q300),1) -> 445.68897 | S3: =INDEX(LINEST(B20:B130,Q20:Q130),1) -> 0.0076155327
A4: Index [1] | B4: ?L/L0 [1] | C4: ?L [mm] | D4: L1 [mm] | E4: L0 [mm] | F4: ?L/L0 [1] | G4: ?L [mm] | H4: L1 [mm] | I4: L0 [mm] | J4: Time_1 | K4: Time_0 | L4: Dev1/ai0 | M4: Dev1/ai1 | N4: Force_[N] | O4: =N4 -> Force_[N] | P4: stress | Q4: lo str
A5: 0 | B5: 0 | C5: 0 | D5: 29.8462 | E5: 29.8462 | F5: 0 | G5: 0 | H5: 7.29698 | I5: 7.29698 | J5: 0 | K5: 0.004 | L5: -0.0058 | M5: -0.0064 | N5: -72.7033 | O5: =-N5 -> 72.7033 | P5: =-N5/A$2/B$2 -> 0.043546918 | Q5: =-F5 -> 0
A6: 1 | B6: -3.75739e-05 | C6: -0.00112144 | D6: 29.845 | E6: 29.8462 | F6: 2.57913e-05 | G6: 0.000188199 | H6: 7.29716 | I6: 7.29698 | J6: 0.498 | K6: 0.499 | L6: -0.0045 | M6: -0.0003 | N6: -40.3907 | O6: =-N6 -> 40.3907 | P6: =-N6/A$2/B$2 -> 0.024192719 | Q6: =-F6 -> -2.57913e-05
A7: 2 | B7: -5.85157e-05 | C7: -0.00174647 | D7: 29.8444 | E7: 29.8462 | F7: 5.63078e-06 | G7: 4.10876e-05 | H7: 7.29702 | I7: 7.29698 | J7: 0.686 | K7: 0.687 | L7: -0.0019 | M7: -0.0064 | N7: 24.2344 | O7: =-N7 -> -24.2344 | P7: =-N7/A$2/B$2 -> -0.014515619 | Q7: =-F7 -> -5.63078e-06
A8: 3 | B8: -3.28538e-05 | C8: -0.000980559 | D8: 29.8452 | E8: 29.8462 | F8: -2.15256e-05 | G8: -0.000157071 | H8: 7.29682 | I8: 7.29698 | J8: 1.185 | K8: 1.186 | L8: -0.0051 | M8: -0.0038 | N8: -56.547 | O8: =-N8 -> 56.547 | P8: =-N8/A$2/B$2 -> 0.033869819 | Q8: =-F8 -> 2.15256e-05
A9: 4 | B9: -1.92671e-05 | C9: -0.00057505 | D9: 29.8456 | E9: 29.8462 | F9: 5.74039e-05 | G9: 0.000418875 | H9: 7.29739 | I9: 7.29698 | J9: 1.559 | K9: 1.559 | L9: -0.0042 | M9: -0.0045 | N9: -32.3126 | O9: =-N9 -> 32.3126 | P9: =-N9/A$2/B$2 -> 0.019354199 | Q9: =-F9 -> -5.74039e-05
A10: 5 | B10: -2.49925e-05 | C10: -0.00074593 | D10: 29.8454 | E10: 29.8462 | F10: 3.21206e-05 | G10: 0.000234383 | H10: 7.29721 | I10: 7.29698 | J10: 1.684 | K10: 1.684 | L10: -0.0071 | M10: -0.0035 | N10: -105.016 | O10: =-N10 -> 105.016 | P10: =-N10/A$2/B$2 -> 0.062901177 | Q10: =-F10 -> -3.21206e-05
A11: 6 | B11: -2.8063e-05 | C11: -0.000837574 | D11: 29.8453 | E11: 29.8462 | F11: -3.94577e-07 | G11: -2.87922e-06 | H11: 7.29697 | I11: 7.29698 | J11: 2.935 | K11: 2.935 | L11: -0.0045 | M11: 0.0126 | N11: -40.3907 | O11: =-N11 -> 40.3907 | P11: =-N11/A$2/B$2 -> 0.024192719 | Q11: =-F11 -> 3.94577e-07
A12: 7 | B12: -7.56208e-05 | C12: -0.00225699 | D12: 29.8439 | E12: 29.8462 | F12: -1.1405e-05 | G12: -8.32218e-05 | H12: 7.29689 | I12: 7.29698 | J12: 6.801 | K12: 6.801 | L12: -0.0067 | M12: -0.0706 | N12: -96.9377 | O12: =-N12 -> 96.9377 | P12: =-N12/A$2/B$2 -> 0.058062538 | Q12: =-F12 -> 1.1405e-05
A13: 8 | B13: -2.45492e-05 | C13: -0.000732701 | D13: 29.8454 | E13: 29.8462 | F13: 3.1532e-06 | G13: 2.30088e-05 | H13: 7.297 | I13: 7.29698 | J13: 6.926 | K13: 6.926 | L13: -0.0064 | M13: -0.0767 | N13: -88.8595 | O13: =-N13 -> 88.8595 | P13: =-N13/A$2/B$2 -> 0.053223958 | Q13: =-F13 -> -3.1532e-06
A14: 9 | B14: -3.6333e-05 | C14: -0.0010844 | D14: 29.8451 | E14: 29.8462 | F14: -2.04951e-05 | G14: -0.000149552 | H14: 7.29683 | I14: 7.29698 | J14: 7.175 | K14: 7.175 | L14: -0.0074 | M14: -0.0857 | N14: -113.094 | O14: =-N14 -> 113.094 | P14: =-N14/A$2/B$2 -> 0.067739637 | Q14: =-F14 -> 2.04951e-05
A15: 10 | B15: -2.63106e-05 | C15: -0.000785271 | D15: 29.8454 | E15: 29.8462 | F15: -5.25505e-06 | G15: -3.8346e-05 | H15: 7.29694 | I15: 7.29698 | J15: 7.737 | K15: 7.737 | L15: -0.0067 | M15: -0.0989 | N15: -96.9377 | O15: =-N15 -> 96.9377 | P15: =-N15/A$2/B$2 -> 0.058062538 | Q15: =-F15 -> 5.25505e-06
A16: 11 | B16: -4.76078e-05 | C16: -0.00142091 | D16: 29.8447 | E16: 29.8462 | F16: -2.18974e-05 | G16: -0.000159785 | H16: 7.29682 | I16: 7.29698 | J16: 9.796 | K16: 9.796 | L16: -0.0125 | M16: -0.1695 | N16: -242.344 | O16: =-N16 -> 242.344 | P16: =-N16/A$2/B$2 -> 0.14515619 | Q16: =-F16 -> 2.18974e-05
... A804: 799 | B804: -0.00177188 | C804: -0.0528837 | D804: 29.7933 | E804: 29.8462 | F804: -0.11906 | G804: -0.868777 | H804: 6.4282 | I804: 7.29698 | J804: 176.279 | K804: 176.28 | L804: -4.1804 | M804: -5.7071 | N804: -104709 | O804: =-N804 -> 104709 | P804: =-N804/A$2/B$2 -> 62.717294 | Q804: =-F804 -> 0.11906
A805: 800 | B805: -0.00183097 | C805: -0.0546474 | D805: 29.7915 | E805: 29.8462 | J805: 177.03 | K805: 177.031 | L805: -4.1771 | M805: -5.7303 | N805: -104628 | O805: =-N805 -> 104628
A806: 801 | B806: -0.00190262 | C806: -0.0567858 | D806: 29.7894 | E806: 29.8462 | J806: 178.277 | K806: 178.277 | L806: -4.1752 | M806: -5.7722 | N806: -104580 | O806: =-N806 -> 104580
A807: 802 | B807: -0.00191631 | C807: -0.0571946 | D807: 29.789 | E807: 29.8462 | J807: 178.401 | K807: 178.402 | L807: -4.1768 | M807: -5.7773 | N807: -104620 | O807: =-N807 -> 104620
A808: 803 | B808: -0.00196142 | C808: -0.058541 | D808: 29.7876 | E808: 29.8462 | J808: 178.964 | K808: 178.965 | L808: -4.1749 | M808: -5.7928 | N808: -104572 | O808: =-N808 -> 104572
A809: 804 | B809: -0.00200171 | C809: -0.0597432 | D809: 29.7864 | E809: 29.8462 | J809: 179.277 | K809: 179.278 | L809: -4.173 | M809: -5.8076 | N809: -104523 | O809: =-N809 -> 104523
A810: 805 | B810: -0.00204076 | C810: -0.0609089 | D810: 29.7852 | E810: 29.8462 | J810: 179.839 | K810: 179.839 | L810: -4.1755 | M810: -5.8247 | N810: -104588 | O810: =-N810 -> 104588
A811: 806 | B811: -0.00207521 | C811: -0.0619369 | D811: 29.7842 | E811: 29.8462 | J811: 180.273 | K811: 180.273 | L811: -4.1749 | M811: -5.8398 | N811: -104572 | O811: =-N811 -> 104572
A812: 807 | B812: -0.00217411 | C812: -0.0648889 | D812: 29.7813 | E812: 29.8462 | J812: 181.522 | K812: 181.522 | L812: -4.18 | M812: -5.8811 | N812: -104701 | O812: =-N812 -> 104701
A813: 808 | B813: -0.0022106 | C813: -0.0659778 | D813: 29.7802 | E813: 29.8462 | J813: 182.021 | K813: 182.021 | L813: -4.181 | M813: -5.9008 | N813: -104725 | O813: =-N813 -> 104725
A814: 809 | B814: -0.00225078 | C814: -0.0671772 | D814: 29.779 | E814: 29.8462 | J814: 182.457 | K814: 182.457 | L814: -4.1829 | M814: -5.9137 | N814: -104774 | O814: =-N814 -> 104774
A815: 810 | B815: -0.00227262 | C815: -0.0678291 | D815: 29.7783 | E815: 29.8462 | J815: 182.771 | K815: 182.771 | L815: -4.18 | M815: -5.923 | N815: -104701 | O815: =-N815 -> 104701
A816: 811 | B816: -0.00230266 | C816: -0.0687256 | D816: 29.7774 | E816: 29.8462 | J816: 183.27 | K816: 183.27 | L816: -4.1862 | M816: -5.9391 | N816: -104855 | O816: =-N816 -> 104855
... A822: 817 | B822: -0.00247755 | C822: -0.0739454 | D822: 29.7722 | E822: 29.8462 | J822: 185.203 | K822: 185.203 | L822: -4.1933 | M822: -6.0042 | N822: -105032 | O822: =-N822 -> 105032

Sheet L30CZ-2
A1: w | B1: t | Q1: =MATCH(Q3,Q5:Q1048576,0)-1 -> 780
A2: 40.82 | B2: 40.76 | C2: =A2*B2 -> 1663.8232 | O2: Ult Load, N | P2: Ult Stress, MPa | Q2: Failure Strain, % | R2: Ez, MPa | S2: νxz
A3: E0 | F3: E1 | J3: Analog | O3: =MAX(O5:O1048576) -> 114330 | P3: =MAX(P5:P1048576) -> 68.715234 | Q3: =INDEX(Q5:Q1048576,MATCH(P3,P5:P1048576,0)) -> 0.192304 | R3: =INDEX(LINEST(P150:P340,Q150:Q340),1) -> 422.08375 | S3: =INDEX(LINEST(F70:F130,Q70:Q130),1) -> 0.014521942
A4: Index [1] | B4: ?L/L0 [1] | C4: ?L [mm] | D4: L1 [mm] | E4: L0 [mm] | F4: ?L/L0 [1] | G4: ?L [mm] | H4: L1 [mm] | I4: L0 [mm] | J4: Time_1 | K4: Time_0 | L4: Dev1/ai0 | M4: Dev1/ai1 | N4: Force_[N] | O4: =N4 -> Force_[N] | P4: stress | Q4: lo str | R4: lostr
A5: 0 | B5: 0 | C5: 0 | D5: 12.6219 | E5: 12.6219 | F5: 0 | G5: 0 | H5: 28.7114 | I5: 28.7114 | J5: 0 | K5: 0.005 | L5: -0.0035 | M5: -0.0032 | N5: -16.1563 | O5: =-N5 -> 16.1563 | P5: =-N5/A$2/B$2 -> 0.0097103466 | Q5: =-B5 -> 0 | R5: =-B5 -> 0
A6: 1 | B6: -1.19796e-05 | C6: -0.000151205 | D6: 12.6217 | E6: 12.6219 | F6: -2.66589e-05 | G6: -0.000765413 | H6: 28.7106 | I6: 28.7114 | J6: 0.689 | K6: 0.69 | L6: -0.0029 | M6: -0.0045 | N6: 0 | O6: =-N6 -> 0 | P6: =-N6/A$2/B$2 -> 0 | Q6: =-B6 -> 1.19796e-05 | R6: =-B6 -> 1.19796e-05
A7: 2 | B7: 1.93284e-05 | C7: 0.000243961 | D7: 12.6221 | E7: 12.6219 | F7: -5.60307e-06 | G7: -0.000160872 | H7: 28.7113 | I7: 28.7114 | J7: 0.814 | K7: 0.815 | L7: -0.0048 | M7: -0.0048 | N7: -48.4688 | O7: =-N7 -> 48.4688 | P7: =-N7/A$2/B$2 -> 0.02913098 | Q7: =-B7 -> -1.93284e-05 | R7: =-B7 -> -1.93284e-05
A8: 3 | B8: -3.20069e-06 | C8: -4.03987e-05 | D8: 12.6218 | E8: 12.6219 | F8: -5.13125e-05 | G8: -0.00147325 | H8: 28.7099 | I8: 28.7114 | J8: 3.81 | K8: 3.81 | L8: -0.0058 | M8: -0.0203 | N8: -72.7033 | O8: =-N8 -> 72.7033 | P8: =-N8/A$2/B$2 -> 0.04369653 | Q8: =-B8 -> 3.20069e-06 | R8: =-B8 -> 3.20069e-06
A9: 4 | B9: 5.59785e-06 | C9: 7.06553e-05 | D9: 12.6219 | E9: 12.6219 | F9: -4.31505e-05 | G9: -0.00123891 | H9: 28.7102 | I9: 28.7114 | J9: 3.996 | K9: 3.997 | L9: -0.0055 | M9: -0.0251 | N9: -64.6251 | O9: =-N9 -> 64.6251 | P9: =-N9/A$2/B$2 -> 0.038841326 | Q9: =-B9 -> -5.59785e-06 | R9: =-B9 -> -5.59785e-06
A10: 5 | B10: 1.61967e-05 | C10: 0.000204432 | D10: 12.6221 | E10: 12.6219 | F10: -3.92783e-05 | G10: -0.00112774 | H10: 28.7103 | I10: 28.7114 | J10: 4.123 | K10: 4.124 | L10: -0.0045 | M10: -0.0332 | N10: -40.3907 | O10: =-N10 -> 40.3907 | P10: =-N10/A$2/B$2 -> 0.024275837 | Q10: =-B10 -> -1.61967e-05 | R10: =-B10 -> -1.61967e-05
A11: 6 | B11: 2.61263e-06 | C11: 3.29763e-05 | D11: 12.6219 | E11: 12.6219 | F11: -2.20325e-05 | G11: -0.000632584 | H11: 28.7108 | I11: 28.7114 | J11: 4.433 | K11: 4.433 | L11: -0.0048 | M11: -0.0406 | N11: -48.4688 | O11: =-N11 -> 48.4688 | P11: =-N11/A$2/B$2 -> 0.02913098 | Q11: =-B11 -> -2.61263e-06 | R11: =-B11 -> -2.61263e-06
A12: 7 | B12: 2.00433e-05 | C12: 0.000252984 | D12: 12.6221 | E12: 12.6219 | F12: -3.7785e-05 | G12: -0.00108486 | H12: 28.7103 | I12: 28.7114 | J12: 5.372 | K12: 5.372 | L12: -0.0077 | M12: -0.0722 | N12: -121.172 | O12: =-N12 -> 121.172 | P12: =-N12/A$2/B$2 -> 0.072827449 | Q12: =-B12 -> -2.00433e-05 | R12: =-B12 -> -2.00433e-05
A13: 8 | B13: -2.35776e-05 | C13: -0.000297594 | D13: 12.6216 | E13: 12.6219 | F13: -3.48326e-05 | G13: -0.00100009 | H13: 28.7104 | I13: 28.7114 | J13: 5.746 | K13: 5.746 | L13: -0.0058 | M13: -0.0867 | N13: -72.7033 | O13: =-N13 -> 72.7033 | P13: =-N13/A$2/B$2 -> 0.04369653 | Q13: =-B13 -> 2.35776e-05 | R13: =-B13 -> 2.35776e-05
A14: 9 | B14: 1.13666e-05 | C14: 0.000143468 | D14: 12.622 | E14: 12.6219 | F14: -3.55671e-05 | G14: -0.00102118 | H14: 28.7104 | I14: 28.7114 | J14: 7.742 | K14: 7.742 | L14: -0.0103 | M14: -0.1492 | N14: -185.797 | O14: =-N14 -> 185.797 | P14: =-N14/A$2/B$2 -> 0.11166872 | Q14: =-B14 -> -1.13666e-05 | R14: =-B14 -> -1.13666e-05
A15: 10 | B15: 4.97877e-05 | C15: 0.000628415 | D15: 12.6225 | E15: 12.6219 | F15: -4.37037e-05 | G15: -0.0012548 | H15: 28.7102 | I15: 28.7114 | J15: 8.179 | K15: 8.179 | L15: -0.0145 | M15: -0.1637 | N15: -290.813 | O15: =-N15 -> 290.813 | P15: =-N15/A$2/B$2 -> 0.174786 | Q15: =-B15 -> -4.97877e-05 | R15: =-B15 -> -4.97877e-05
A16: 11 | B16: 3.66873e-05 | C16: 0.000463062 | D16: 12.6223 | E16: 12.6219 | F16: -6.21847e-05 | G16: -0.00178541 | H16: 28.7096 | I16: 28.7114 | J16: 8.614 | K16: 8.614 | L16: -0.0113 | M16: -0.1776 | N16: -210.032 | O16: =-N16 -> 210.032 | P16: =-N16/A$2/B$2 -> 0.12623457 | Q16: =-B16 -> -3.66873e-05 | R16: =-B16 -> -3.66873e-05
... A256: 251 | B256: -0.041525 | C256: -0.524123 | D256: 12.0978 | E256: 12.6219 | F256: 0.000228526 | G256: 0.00656129 | H256: 28.718 | I256: 28.7114 | J256: 56.852 | K256: 56.852 | L256: -1.3678 | M256: -1.7813 | N256: -34210.9 | O256: =-N256 -> 34210.9 | P256: =-N256/A$2/B$2 -> 20.56162 | Q256: =-B256 -> 0.041525 | R256: =-B256 -> 0.041525
A257: 252 | B257: -0.0416698 | C257: -0.525951 | D257: 12.0959 | E257: 12.6219 | F257: 0.000223724 | G257: 0.00642343 | H257: 28.7178 | I257: 28.7114 | J257: 56.974 | K257: 56.975 | L257: -1.3729 | M257: -1.7877 | N257: -34340.2 | O257: =-N257 -> 34340.2 | P257: =-N257/A$2/B$2 -> 20.639332 | Q257: =-B257 -> 0.0416698
A258: 253 | B258: -0.0418787 | C258: -0.528588 | D258: 12.0933 | E258: 12.6219 | F258: 0.000229825 | G258: 0.00659859 | H258: 28.718 | I258: 28.7114 | J258: 57.162 | K258: 57.162 | L258: -1.3781 | M258: -1.7922 | N258: -34469.4 | O258: =-N258 -> 34469.4 | P258: =-N258/A$2/B$2 -> 20.716985 | Q258: =-B258 -> 0.0418787
A259: 254 | B259: -0.0420338 | C259: -0.530545 | D259: 12.0913 | E259: 12.6219 | F259: 0.000249111 | G259: 0.00715233 | H259: 28.7186 | I259: 28.7114 | J259: 57.286 | K259: 57.287 | L259: -1.3865 | M259: -1.798 | N259: -34679.5 | O259: =-N259 -> 34679.5 | P259: =-N259/A$2/B$2 -> 20.84326 | Q259: =-B259 -> 0.0420338
A260: 255 | B260: -0.0422746 | C260: -0.533584 | D260: 12.0883 | E260: 12.6219 | F260: 0.00025684 | G260: 0.00737423 | H260: 28.7188 | I260: 28.7114 | J260: 57.476 | K260: 57.476 | L260: -1.3894 | M260: -1.8022 | N260: -34752.2 | O260: =-N260 -> 34752.2 | P260: =-N260/A$2/B$2 -> 20.886955 | Q260: =-B260 -> 0.0422746
A261: 256 | B261: -0.0424315 | C261: -0.535565 | D261: 12.0863 | E261: 12.6219 | F261: 0.000255858 | G261: 0.00734606 | H261: 28.7188 | I261: 28.7114 | J261: 57.599 | K261: 57.6 | L261: -1.3932 | M261: -1.8125 | N261: -34849.1 | O261: =-N261 -> 34849.1 | P261: =-N261/A$2/B$2 -> 20.945194 | Q261: =-B261 -> 0.0424315
A262: 257 | B262: -0.0428129 | C262: -0.540379 | D262: 12.0815 | E262: 12.6219 | F262: 0.000269068 | G262: 0.00772534 | H262: 28.7191 | I262: 28.7114 | J262: 57.91 | K262: 57.911 | L262: -1.4074 | M262: -1.8215 | N262: -35204.6 | O262: =-N262 -> 35204.6 | P262: =-N262/A$2/B$2 -> 21.158859 | Q262: =-B262 -> 0.0428129
A263: 258 | B263: -0.0430597 | C263: -0.543495 | D263: 12.0784 | E263: 12.6219 | F263: 0.000254608 | G263: 0.00731015 | H263: 28.7187 | I263: 28.7114 | J263: 58.099 | K263: 58.099 | L263: -1.4126 | M263: -1.8299 | N263: -35333.8 | O263: =-N263 -> 35333.8 | P263: =-N263/A$2/B$2 -> 21.236511 | Q263: =-B263 -> 0.0430597
A264: 259 | B264: -0.0433046 | C264: -0.546585 | D264: 12.0753 | E264: 12.6219 | F264: 0.000255492 | G264: 0.00733553 | H264: 28.7187 | I264: 28.7114 | J264: 58.286 | K264: 58.286 | L264: -1.4203 | M264: -1.8293 | N264: -35527.7 | O264: =-N264 -> 35527.7 | P264: =-N264/A$2/B$2 -> 21.35305 | Q264: =-B264 -> 0.0433046
A265: 260 | B265: -0.0434672 | C265: -0.548638 | D265: 12.0732 | E265: 12.6219 | F265: 0.000255024 | G265: 0.00732211 | H265: 28.7187 | I265: 28.7114 | J265: 58.409 | K265: 58.41 | L265: -1.4238 | M265: -1.8322 | N265: -35616.5 | O265: =-N265 -> 35616.5 | P265: =-N265/A$2/B$2 -> 21.406421 | Q265: =-B265 -> 0.0434672
A266: 261 | B266: -0.0437182 | C266: -0.551806 | D266: 12.0701 | E266: 12.6219 | F266: 0.000250246 | G266: 0.00718492 | H266: 28.7186 | I266: 28.7114 | J266: 58.597 | K266: 58.598 | L266: -1.4271 | M266: -1.8428 | N266: -35697.3 | O266: =-N266 -> 35697.3 | P266: =-N266/A$2/B$2 -> 21.454984 | Q266: =-B266 -> 0.0437182
A267: 262 | B267: -0.0439579 | C267: -0.554831 | D267: 12.067 | E267: 12.6219 | F267: 0.000256272 | G267: 0.00735793 | H267: 28.7188 | I267: 28.7114 | J267: 58.785 | K267: 58.785 | L267: -1.4345 | M267: -1.8447 | N267: -35883.1 | O267: =-N267 -> 35883.1 | P267: =-N267/A$2/B$2 -> 21.566654 | Q267: =-B267 -> 0.0439579
A268: 263 | B268: -0.0441688 | C268: -0.557493 | D268: 12.0644 | E268: 12.6219 | F268: 0.000264098 | G268: 0.00758262 | H268: 28.719 | I268: 28.7114 | J268: 58.972 | K268: 58.972 | L268: -1.4448 | M268: -1.8522 | N268: -36141.6 | O268: =-N268 -> 36141.6 | P268: =-N268/A$2/B$2 -> 21.72202 | Q268: =-B268 -> 0.0441688
... A841: 836 | B841: -0.239607 | C841: -3.02429 | D841: 9.59758 | E841: 12.6219 | F841: -0.00349631 | G841: -0.100384 | H841: 28.611 | I841: 28.7114 | J841: 184.273 | K841: 184.273 | L841: -4.4446 | M841: -6.0242 | N841: -111333 | O841: =-N841 -> 111333 | P841: =-N841/A$2/B$2 -> 66.913961 | Q841: =-B841 -> 0.239607
A842: 837 | F842: -0.00351441 | G842: -0.100904 | H842: 28.6105 | I842: 28.7114 | J842: 184.647 | K842: 184.647 | L842: -4.4411 | M842: -6.0352 | N842: -111244 | O842: =-N842 -> 111244 | P842: =-N842/A$2/B$2 -> 66.860469
A843: 838 | F843: -0.0035785 | G843: -0.102744 | H843: 28.6087 | I843: 28.7114 | J843: 185.019 | K843: 185.019 | L843: -4.4372 | M843: -6.0442 | N843: -111148 | O843: =-N843 -> 111148 | P843: =-N843/A$2/B$2 -> 66.802771
A844: 839 | F844: -0.00359071 | G844: -0.103094 | H844: 28.6083 | I844: 28.7114 | J844: 185.519 | K844: 185.519 | L844: -4.4321 | M844: -6.0613 | N844: -111018 | O844: =-N844 -> 111018 | P844: =-N844/A$2/B$2 -> 66.724638
A845: 840 | F845: -0.00361071 | G845: -0.103669 | H845: 28.6077 | I845: 28.7114 | J845: 185.648 | K845: 185.648 | L845: -4.4289 | M845: -6.0696 | N845: -110938 | O845: =-N845 -> 110938 | P845: =-N845/A$2/B$2 -> 66.676556
A846: 841 | F846: -0.00360844 | G846: -0.103603 | H846: 28.6078 | I846: 28.7114 | J846: 186.081 | K846: 186.081 | L846: -4.4282 | M846: -6.078 | N846: -110921 | O846: =-N846 -> 110921 | P846: =-N846/A$2/B$2 -> 66.666338
A847: 842 | F847: -0.00363385 | G847: -0.104333 | H847: 28.6071 | I847: 28.7114 | J847: 186.455 | K847: 186.455 | L847: -4.4247 | M847: -6.0925 | N847: -110832 | O847: =-N847 -> 110832 | P847: =-N847/A$2/B$2 -> 66.612847
A848: 843 | F848: -0.0036784 | G848: -0.105612 | H848: 28.6058 | I848: 28.7114 | J848: 186.704 | K848: 186.704 | L848: -4.4198 | M848: -6.108 | N848: -110711 | O848: =-N848 -> 110711 | P848: =-N848/A$2/B$2 -> 66.540123
A849: 844 | F849: -0.00368042 | G849: -0.10567 | H849: 28.6057 | I849: 28.7114 | J849: 187.016 | K849: 187.017 | L849: -4.4192 | M849: -6.1119 | N849: -110695 | O849: =-N849 -> 110695 | P849: =-N849/A$2/B$2 -> 66.530506
A850: 845 | F850: -0.00370295 | G850: -0.106317 | H850: 28.6051 | I850: 28.7114 | J850: 187.208 | K850: 187.208 | L850: -4.4173 | M850: -6.1222 | N850: -110647 | O850: =-N850 -> 110647 | P850: =-N850/A$2/B$2 -> 66.501657
A851: 846 | F851: -0.00376757 | G851: -0.108172 | H851: 28.6032 | I851: 28.7114 | J851: 187.766 | K851: 187.766 | L851: -4.4063 | M851: -6.1383 | N851: -110372 | O851: =-N851 -> 110372 | P851: =-N851/A$2/B$2 -> 66.336375
...

Sheet L30CZ-3
A1: w | B1: t | Q1: =MATCH(Q3,Q5:Q1048576,0)-1 -> 673
A2: 40.82 | B2: 40.76 | C2: =A2*B2 -> 1663.8232 | O2: Ult Load, N | P2: Ult Stress, MPa | Q2: Failure Strain, % | R2: Ez, MPa | S2: νyz
A3: E1 | F3: E0 | J3: Analog | O3: =MAX(O5:O1048576) -> 112600 | P3: =MAX(P5:P1048576) -> 67.741983 | Q3: =INDEX(Q5:Q1048576,MATCH(P3,P5:P1048576,0)) -> 0.122444 | R3: =INDEX(LINEST(P5:P336,Q5:Q336),1) -> 481.68381 | S3: =INDEX(LINEST(B5:B336,Q5:Q336),1) -> 0.037569689
A4: Index [1] | B4: ?L/L0 [1] | C4: ?L [mm] | D4: L1 [mm] | E4: L0 [mm] | F4: ?L/L0 [1] | G4: ?L [mm] | H4: L1 [mm] | I4: L0 [mm] | J4: Time_1 | K4: Time_0 | L4: Dev1/ai0 | M4: Dev1/ai1 | N4: Force_[N] | O4: =N4 -> Force_[N] | P4: stress | Q4: lostr
A5: 0 | B5: 0 | C5: 0 | D5: 22.6276 | E5: 22.6276 | F5: 0 | G5: 0 | H5: 8.00425 | I5: 8.00425 | J5: 0 | K5: 0.004 | L5: -0.0032 | M5: -0.0177 | N5: -48.4784 | O5: =-N5 -> 48.4784 | P5: =-N5/40.83/40.71 -> 0.02916539 | Q5: =-F5 -> 0
A6: 1 | B6: 6.44271e-06 | C6: 0.000145783 | D6: 22.6277 | E6: 22.6276 | F6: -3.40406e-05 | G6: -0.00027247 | H6: 8.00398 | I6: 8.00425 | J6: 0.361 | K6: 0.362 | L6: -0.0051 | M6: -0.0077 | N6: -96.9569 | O6: =-N6 -> 96.9569 | P6: =-N6/40.83/40.71 -> 0.058330841 | Q6: =-F6 -> 3.40406e-05
A7: 2 | B7: -9.19562e-06 | C7: -0.000208075 | D7: 22.6274 | E7: 22.6276 | F7: 3.90127e-06 | G7: 3.12267e-05 | H7: 8.00428 | I7: 8.00425 | J7: 1.858 | K7: 1.858 | L7: -0.0051 | M7: -0.0225 | N7: -96.9569 | O7: =-N7 -> 96.9569 | P7: =-N7/40.83/40.71 -> 0.058330841 | Q7: =-F7 -> -3.90127e-06
A8: 3 | B8: -9.23206e-06 | C8: -0.000208899 | D8: 22.6274 | E8: 22.6276 | F8: 2.60719e-06 | G8: 2.08686e-05 | H8: 8.00427 | I8: 8.00425 | J8: 2.045 | K8: 2.045 | L8: -0.0045 | M8: 0.0055 | N8: -80.7974 | O8: =-N8 -> 80.7974 | P8: =-N8/40.83/40.71 -> 0.048609024 | Q8: =-F8 -> -2.60719e-06
A9: 4 | B9: 6.3146e-07 | C9: 1.42884e-05 | D9: 22.6276 | E9: 22.6276 | F9: 2.30929e-05 | G9: 0.000184841 | H9: 8.00443 | I9: 8.00425 | J9: 2.172 | K9: 2.172 | L9: -0.0067 | M9: -0.0074 | N9: -137.355 | O9: =-N9 -> 137.355 | P9: =-N9/40.83/40.71 -> 0.082634992 | Q9: =-F9 -> -2.30929e-05
A10: 5 | B10: 8.59777e-06 | C10: 0.000194547 | D10: 22.6278 | E10: 22.6276 | F10: 1.37512e-05 | G10: 0.000110068 | H10: 8.00436 | I10: 8.00425 | J10: 2.546 | K10: 2.546 | L10: -0.0019 | M10: -0.0132 | N10: -16.1595 | O10: =-N10 -> 16.1595 | P10: =-N10/40.83/40.71 -> 0.0097218169 | Q10: =-F10 -> -1.37512e-05
A11: 6 | B11: 1.50712e-06 | C11: 3.41026e-05 | D11: 22.6276 | E11: 22.6276 | F11: 1.14952e-05 | G11: 9.20102e-05 | H11: 8.00434 | I11: 8.00425 | J11: 3.108 | K11: 3.108 | L11: -0.0048 | M11: -0.0251 | N11: -88.8771 | O11: =-N11 -> 88.8771 | P11: =-N11/40.83/40.71 -> 0.053469903 | Q11: =-F11 -> -1.14952e-05
A12: 7 | B12: -3.95292e-06 | C12: -8.9445e-05 | D12: 22.6275 | E12: 22.6276 | F12: -1.66563e-05 | G12: -0.000133321 | H12: 8.00412 | I12: 8.00425 | J12: 4.167 | K12: 4.167 | L12: -0.0074 | M12: -0.0287 | N12: -153.515 | O12: =-N12 -> 153.515 | P12: =-N12/40.83/40.71 -> 0.09235711 | Q12: =-F12 -> 1.66563e-05
A13: 8 | B13: -1.94367e-06 | C13: -4.39806e-05 | D13: 22.6275 | E13: 22.6276 | F13: -2.35151e-05 | G13: -0.000188221 | H13: 8.00406 | I13: 8.00425 | J13: 4.293 | K13: 4.293 | L13: -0.0055 | M13: -0.0183 | N13: -105.037 | O13: =-N13 -> 105.037 | P13: =-N13/40.83/40.71 -> 0.06319196 | Q13: =-F13 -> 2.35151e-05
A14: 9 | B14: -9.89466e-06 | C14: -0.000223892 | D14: 22.6274 | E14: 22.6276 | F14: -3.13584e-05 | G14: -0.000251001 | H14: 8.004 | I14: 8.00425 | J14: 4.668 | K14: 4.668 | L14: -0.0058 | M14: -0.0254 | N14: -113.116 | O14: =-N14 -> 113.116 | P14: =-N14/40.83/40.71 -> 0.068052417 | Q14: =-F14 -> 3.13584e-05
A15: 10 | B15: -6.90887e-07 | C15: -1.56331e-05 | D15: 22.6276 | E15: 22.6276 | F15: -1.28885e-05 | G15: -0.000103163 | H15: 8.00415 | I15: 8.00425 | J15: 4.792 | K15: 4.792 | L15: -0.0042 | M15: -0.0258 | N15: -72.7177 | O15: =-N15 -> 72.7177 | P15: =-N15/40.83/40.71 -> 0.043748146 | Q15: =-F15 -> 1.28885e-05
A16: 11 | B16: -2.22442e-05 | C16: -0.000503333 | D16: 22.6271 | E16: 22.6276 | F16: -1.7616e-05 | G16: -0.000141003 | H16: 8.00411 | I16: 8.00425 | J16: 5.041 | K16: 5.041 | L16: -0.0106 | M16: -0.0113 | N16: -234.312 | O16: =-N16 -> 234.312 | P16: =-N16/40.83/40.71 -> 0.14096589 | Q16: =-F16 -> 1.7616e-05
... A784: 779 | B784: 0.0459869 | C784: 1.04057 | D784: 23.6682 | E784: 22.6276 | F784: -0.150131 | G784: -1.20169 | H784: 6.80256 | I784: 8.00425 | J784: 198.356 | K784: 198.356 | L784: -4.1214 | M784: -4.0518 | N784: -103292 | O784: =-N784 -> 103292 | P784: =-N784/40.83/40.71 -> 62.14214 | Q784: =-F784 -> 0.150131
A785: 780 | F785: -0.150223 | G785: -1.20242 | H785: 6.80183 | I785: 8.00425 | J785: 198.733 | K785: 198.733 | L785: -4.1108 | M785: -4.0321 | N785: -103025 | O785: =-N785 -> 103025 | P785: =-N785/40.83/40.71 -> 61.981508 | Q785: =-F785 -> 0.150223
A786: 781 | F786: -0.150274 | G786: -1.20283 | H786: 6.80142 | I786: 8.00425 | J786: 198.916 | K786: 198.916 | L786: -4.1053 | M786: -4.0421 | N786: -102888 | O786: =-N786 -> 102888 | P786: =-N786/40.83/40.71 -> 61.899087 | Q786: =-F786 -> 0.150274
A787: 782 | B787: 0.0472725 | C787: 1.06966 | D787: 23.6973 | E787: 22.6276 | F787: -0.150414 | G787: -1.20395 | H787: 6.8003 | I787: 8.00425 | J787: 199.103 | K787: 199.103 | L787: -4.1053 | M787: -4.0492 | N787: -102888 | O787: =-N787 -> 102888 | P787: =-N787/40.83/40.71 -> 61.899087 | Q787: =-F787 -> 0.150414
A788: 783 | B788: 0.0479193 | C788: 1.0843 | D788: 23.7119 | E788: 22.6276 | F788: -0.150446 | G788: -1.20421 | H788: 6.80004 | I788: 8.00425 | J788: 199.415 | K788: 199.415 | L788: -4.0995 | M788: -4.0366 | N788: -102742 | O788: =-N788 -> 102742 | P788: =-N788/40.83/40.71 -> 61.811251 | Q788: =-F788 -> 0.150446
A789: 784 | F789: -0.150523 | G789: -1.20482 | H789: 6.79943 | I789: 8.00425 | J789: 199.603 | K789: 199.603 | L789: -4.0937 | M789: -4.0405 | N789: -102597 | O789: =-N789 -> 102597 | P789: =-N789/40.83/40.71 -> 61.724017 | Q789: =-F789 -> 0.150523
A790: 785 | F790: -0.15062 | G790: -1.2056 | H790: 6.79865 | I790: 8.00425 | J790: 199.727 | K790: 199.727 | L790: -4.093 | M790: -4.0221 | N790: -102581 | O790: =-N790 -> 102581 | P790: =-N790/40.83/40.71 -> 61.714391 | Q790: =-F790 -> 0.15062
A791: 786 | B791: 0.0489125 | C791: 1.10677 | D791: 23.7344 | E791: 22.6276 | F791: -0.150719 | G791: -1.20639 | H791: 6.79786 | I791: 8.00425 | J791: 199.977 | K791: 199.977 | L791: -4.0905 | M791: -4.0076 | N791: -102516 | O791: =-N791 -> 102516 | P791: =-N791/40.83/40.71 -> 61.675286 | Q791: =-F791 -> 0.150719
A792: 787 | F792: -0.150835 | G792: -1.20732 | H792: 6.79693 | I792: 8.00425 | J792: 200.167 | K792: 200.167 | L792: -4.0753 | M792: -4.0279 | N792: -102136 | O792: =-N792 -> 102136 | P792: =-N792/40.83/40.71 -> 61.446672 | Q792: =-F792 -> 0.150835
A793: 788 | F793: -0.151047 | G793: -1.20902 | H793: 6.79523 | I793: 8.00425 | J793: 200.725 | K793: 200.725 | L793: -4.0759 | M793: -3.9902 | N793: -102152 | O793: =-N793 -> 102152 | P793: =-N793/40.83/40.71 -> 61.456297 | Q793: =-F793 -> 0.151047
A794: 789 | B794: 0.0512633 | C794: 1.15997 | D794: 23.7876 | E794: 22.6276 | F794: -0.151285 | G794: -1.21092 | H794: 6.79333 | I794: 8.00425 | J794: 201.29 | K794: 201.29 | L794: -4.0666 | M794: -3.9806 | N794: -101918 | O794: =-N794 -> 101918 | P794: =-N794/40.83/40.71 -> 61.315519 | Q794: =-F794 -> 0.151285
A795: 790 | B795: 0.0518307 | C795: 1.1728 | D795: 23.8004 | E795: 22.6276 | F795: -0.15143 | G795: -1.21208 | H795: 6.79217 | I795: 8.00425 | J795: 201.599 | K795: 201.599 | L795: -4.0672 | M795: -4.0125 | N795: -101934 | O795: =-N795 -> 101934 | P795: =-N795/40.83/40.71 -> 61.325145 | Q795: =-F795 -> 0.15143
A796: 791 | B796: 0.0531128 | C796: 1.20181 | D796: 23.8294 | E796: 22.6276 | F796: -0.151833 | G796: -1.21531 | H796: 6.78894 | I796: 8.00425 | J796: 202.352 | K796: 202.352 | L796: -4.0527 | M796: -3.9941 | N796: -101571 | O796: =-N796 -> 101571 | P796: =-N796/40.83/40.71 -> 61.106758 | Q796: =-F796 -> 0.151833
A797: 792 | B797: 0.0535926 | C797: 1.21267 | D797: 23.8403 | E797: 22.6276 | F797: -0.151945 | G797: -1.21621 | H797: 6.78804 | I797: 8.00425 | J797: 202.599 | K797: 202.6 | L797: -4.0498 | M797: -3.987 | N797: -101498 | O797: =-N797 -> 101498 | P797: =-N797/40.83/40.71 -> 61.06284 | Q797: =-F797 -> 0.151945
A798: 793 | B798: 0.0539684 | C798: 1.22118 | D798: 23.8488 | E798: 22.6276 | F798: -0.152063 | G798: -1.21715 | H798: 6.7871 | I798: 8.00425 | J798: 202.847 | K798: 202.847 | L798: -4.0434 | M798: -3.9631 | N798: -101336 | O798: =-N798 -> 101336 | P798: =-N798/40.83/40.71 -> 60.965379 | Q798: =-F798 -> 0.152063
A799: 794 | B799: 0.0543413 | C799: 1.22961 | D799: 23.8572 | E799: 22.6276 | F799: -0.152115 | G799: -1.21757 | H799: 6.78668 | I799: 8.00425 | J799: 203.036 | K799: 203.036 | L799: -4.0408 | M799: -3.9683 | N799: -101272 | O799: =-N799 -> 101272 | P799: =-N799/40.83/40.71 -> 60.926875 | Q799: =-F799 -> 0.152115
A800: 795 | F800: -0.152244 | G800: -1.2186 | H800: 6.78565 | I800: 8.00425 | J800: 203.222 | K800: 203.222 | L800: -4.0389 | M800: -3.9957 | N800: -101223 | O800: =-N800 -> 101223 | P800: =-N800/40.83/40.71 -> 60.897396 | Q800: =-F800 -> 0.152244
A801: 796 | B801: 0.0548746 | C801: 1.24168 | D801: 23.8693 | E801: 22.6276 | F801: -0.152283 | G801: -1.21891 | H801: 6.78534 | I801: 8.00425 | J801: 203.346 | K801: 203.347 | L801: -4.0389 | M801: -3.9831 | N801: -101223 | O801: =-N801 -> 101223 | P801: =-N801/40.83/40.71 -> 60.897396 | Q801: =-F801 -> 0.152283
A802: 797 | F802: -0.152359 | G802: -1.21952 | H802: 6.78473 | I802: 8.00425 | J802: 203.535 | K802: 203.535 | L802: -4.0386 | M802: -3.9847 | N802: -101215 | O802: =-N802 -> 101215 | P802: =-N802/40.83/40.71 -> 60.892583 | Q802: =-F802 -> 0.152359
A803: 798 | B803: 0.0563625 | C803: 1.27535 | D803: 23.9029 | E803: 22.6276 | F803: -0.152647 | G803: -1.22183 | H803: 6.78242 | I803: 8.00425 | J803: 204.159 | K803: 204.159 | L803: -4.0276 | M803: -3.9329 | N803: -100940 | O803: =-N803 -> 100940 | P803: =-N803/40.83/40.71 -> 60.727139 | Q803: =-F803 -> 0.152647
A804: 799 | B804: 0.0570449 | C804: 1.29079 | D804: 23.9184 | E804: 22.6276 | F804: -0.152867 | G804: -1.22358 | H804: 6.78067 | I804: 8.00425 | J804: 204.532 | K804: 204.532 | L804: -4.0247 | M804: -3.9657 | N804: -100868 | O804: =-N804 -> 100868 | P804: =-N804/40.83/40.71 -> 60.683822 | Q804: =-F804 -> 0.152867
A805: 800 | F805: -0.153163 | G805: -1.22596 | H805: 6.77829 | I805: 8.00425 | J805: 205.094 | K805: 205.095 | L805: -4.0183 | M805: -3.9432 | N805: -100706 | O805: =-N805 -> 100706 | P805: =-N805/40.83/40.71 -> 60.58636 | Q805: =-F805 -> 0.153163
A806: 801 | B806: 0.0584952 | C806: 1.32361 | D806: 23.9512 | E806: 22.6276 | F806: -0.153298 | G806: -1.22703 | H806: 6.77722 | I806: 8.00425 | J806: 205.345 | K806: 205.345 | L806: -4.0118 | M806: -3.9403 | N806: -100545 | O806: =-N806 -> 100545 | P806: =-N806/40.83/40.71 -> 60.4895 | Q806: =-F806 -> 0.153298
A807: 802 | F807: -0.153854 | G807: -1.23149 | H807: 6.77276 | I807: 8.00425 | J807: 206.217 | K807: 206.217 | L807: -4.0099 | M807: -3.908 | N807: -100496 | O807: =-N807 -> 100496 | P807: =-N807/40.83/40.71 -> 60.460021 | Q807: =-F807 -> 0.153854
...
