Workbook

Sheet L30NTX
B2: ='L30NTX-1'!$F$9 -> Ult Load, N | C2: ='L30NTX-1'!$G$9 -> Ult Stress, MPa | D2: ='L30NTX-1'!$E$9 -> Failure Strain, % | E2: ='L30NTX-1'!$J$9 -> Ex, MPa | F2: ='L30NTX-1'!$K$9 -> νyx | G2: ='L30NTX-1_DIC'!P2 -> νzx
A3: average | B3: =AVERAGE(B6:B8) -> 17703.549 | C3: =AVERAGE(C6:C8) -> 100.23575 | D3: =AVERAGE(D6:D8) -> 0.01196 | E3: =AVERAGE(E6:E8) -> 13552.196 | F3: =AVERAGE(F6:F8) -> 0.67720321 | G3: =AVERAGE(G6:G8) -> 0.2279824 | Q3: =AVERAGE('L30NTX-1'!B5,'L30NTX-2'!B5,'L30NTX-3'!B5) -> 7.8166667
A4: sr. dev. | B4: =STDEV(B6:B8) -> 743.90322 | C4: =STDEV(C6:C8) -> 5.8442816 | D4: =STDEV(D6:D8) -> 0.0012317467 | E4: =STDEV(E6:E8) -> 763.71667 | F4: =STDEV(F6:F8) -> 0.094808877 | G4: =STDEV(G6:G8) -> 0.078855194 | Q4: =AVERAGE('L30NTX-1'!B6,'L30NTX-2'!B6,'L30NTX-3'!B6) -> 22.61
A5: CV | B5: =B4/B3 -> 0.042020006 | C5: =C4/C3 -> 0.058305359 | D5: =D4/D3 -> 0.10298886 | E5: =E4/E3 -> 0.05635372 | F5: =F4/F3 -> 0.14000063 | G5: =G4/G3 -> 0.34588281
A6: 1 | B6: ='L30NTX-1'!F10 -> 17100.752 | C6: ='L30NTX-1'!G10 -> 94.20531 | D6: ='L30NTX-1'!E10 -> 0.01118 | E6: ='L30NTX-1'!J10 -> 12670.346 | F6: ='L30NTX-1'!K10 -> 0.70403589 | G6: ='L30NTX-1_DIC'!P3 -> 0.17222336
A7: 2 | B7: ='L30NTX-2'!F10 -> 18534.918 | C7: ='L30NTX-2'!G10 -> 105.87413 | D7: ='L30NTX-2'!E10 -> 0.01338 | E7: ='L30NTX-2'!J10 -> 13997.456 | F7: ='L30NTX-2'!K10 -> 0.75570384
A8: 3 | B8: ='L30NTX-3'!F10 -> 17474.977 | C8: ='L30NTX-3'!G10 -> 100.62782 | D8: ='L30NTX-3'!E10 -> 0.01132 | E8: ='L30NTX-3'!J10 -> 13988.787 | F8: ='L30NTX-3'!K10 -> 0.5718699 | G8: ='L30NTX-3_DIC'!P3 -> 0.28374145

Sheet L30NTX-1
A1: General : End date | B1: 5/28/2025
A2: General : Specimen number (included) | B2: 1
A3: Maximum Load : Maximum Load | B3: 17100.752 | C3: N
A4: Specimen choice input : Fiber direction | B4: <None>
A5: Specimen properties : Thickness | B5: 7.92 | C5: mm
A6: Specimen properties : Width | B6: 22.92 | C6: mm
A7: Specimen properties : Length | B7: 200 | C7: mm
A8: Modulus (Chord 0,05 % - 0,25 %) : Modulus (Chord 0,05 % - 0,25 %) | B8: 9320.4458 | C8: MPa | E8: =MATCH(G10,G13:G1048576,0)-1 -> 2048
A9: Strain : Tensile strain (Extension) gauge length | B9: 25 | C9: mm | E9: Failure Strain, % | F9: Ult Load, N | G9: Ult Stress, MPa | J9: Ex, MPa | K9: νyx
E10: =INDEX(C13:C1048576,MATCH(G10,G13:G1048576,0)) -> 0.01118 | F10: =MAX(F13:F1048576) -> 17100.752 | G10: =MAX(G13:G1048576) -> 94.20531 | J10: =INDEX(LINEST(G13:G500,E13:E500),1) -> 12670.346 | K10: =INDEX(LINEST(I110:I500,E110:E500),1) -> 0.70403589
A11: Time | B11: Extension | C11: Strain 1 | D11: Tensile extension | E11: Tensile strain (Strain 1) | F11: Load | G11: Tensile stress | H11: Transverse deformation | I11: Transverse strain
A12: (s) | B12: (mm) | C12: (mm/mm) | D12: (mm) | E12: (mm/mm) | F12: (N) | G12: (MPa) | H12: (mm) | I12: (mm/mm)
A13: 0 | B13: 0 | C13: -1e-05 | D13: 1e-05 | E13: =C13 -> -1e-05 | F13: 73.18764 | G13: 0.40318 | H13: 2e-05 | I13: 0
A14: 0.1 | B14: 0.00098 | C14: 0 | D14: 0.00017 | E14: =C14 -> 0 | F14: 87.82813 | G14: 0.48383 | H14: 0.00011 | I14: 0
A15: 0.2 | B15: 0.00341 | C15: 0 | D15: 0.00061 | E15: =C15 -> 0 | F15: 126.63761 | G15: 0.69763 | H15: 0.0004 | I15: 2e-05
A16: 0.3 | B16: 0.00808 | C16: 3e-05 | D16: 0.0015 | E16: =C16 -> 3e-05 | F16: 201.96187 | G16: 1.11258 | H16: 0.00094 | I16: 4e-05
A17: 0.4 | B17: 0.01105 | C17: 4e-05 | D17: 0.00205 | E17: =C17 -> 4e-05 | F17: 246.89682 | G17: 1.36012 | H17: 0.00127 | I17: 6e-05
A18: 0.5 | B18: 0.0148 | C18: 6e-05 | D18: 0.00274 | E18: =C18 -> 6e-05 | F18: 303.50549 | G18: 1.67196 | H18: 0.00169 | I18: 7e-05
A19: 0.6 | B19: 0.01795 | C19: 7e-05 | D19: 0.0033 | E19: =C19 -> 7e-05 | F19: 348.71271 | G19: 1.921 | H19: 0.00204 | I19: 9e-05
A20: 0.7 | B20: 0.02126 | C20: 9e-05 | D20: 0.00385 | E20: =C20 -> 9e-05 | F20: 394.44803 | G20: 2.17295 | H20: 0.00239 | I20: 0.0001
A21: 0.8 | B21: 0.02478 | C21: 0.00011 | D21: 0.00444 | E21: =C21 -> 0.00011 | F21: 443.44617 | G21: 2.44287 | H21: 0.00276 | I21: 0.00012
A22: 0.9 | B22: 0.02778 | C22: 0.00012 | D22: 0.00493 | E22: =C22 -> 0.00012 | F22: 482.35324 | G22: 2.65721 | H22: 0.00305 | I22: 0.00013
A23: 1 | B23: 0.03176 | C23: 0.00013 | D23: 0.00559 | E23: =C23 -> 0.00013 | F23: 536.45319 | G23: 2.95524 | H23: 0.00346 | I23: 0.00015
A24: 1.1 | B24: 0.03442 | C24: 0.00015 | D24: 0.00602 | E24: =C24 -> 0.00015 | F24: 569.1651 | G24: 3.13544 | H24: 0.00369 | I24: 0.00016
... A2080: 204.857 | B2080: 6.82724 | C2080: 0.05739 | D2080: 1.47523 | E2080: =C2080 -> 0.05739 | F2080: 9870.8008 | G2080: 54.37667 | H2080: 0.07837 | I2080: 0.00342

Sheet L30NTX-1_DIC
P2: νzx
A3: E0 | F3: E1 | J3: Analog | P3: =-INDEX(LINEST(F5:F100,B5:B100),1) -> 0.17222336
A4: Index [1] | B4: ?L/L0 [1] | C4: ?L [mm] | D4: L1 [mm] | E4: L0 [mm] | F4: ?L/L0 [1] | G4: ?L [mm] | H4: L1 [mm] | I4: L0 [mm] | J4: Time_1 | K4: Time_0 | L4: Dev1/ai0 | M4: Dev1/ai1 | N4: Force_[N] | O4: stress
A5: 0 | B5: 0 | C5: 0 | D5: 31.2471 | E5: 31.2471 | F5: 0 | G5: 0 | H5: 4.87922 | I5: 4.87922 | J5: 0 | K5: 0.004 | L5: 0.012 | M5: -0.0029 | N5: 79.0979 | O5: =N5/22.92/7.92 -> 0.43573772
A6: 1 | B6: 6.29588e-06 | C6: 0.000196728 | D6: 31.2473 | E6: 31.2471 | F6: -6.47247e-06 | G6: -3.15806e-05 | H6: 4.87918 | I6: 4.87922 | J6: 1.744 | K6: 1.745 | L6: 0.0136 | M6: -0.0009 | N6: 87.173 | O6: =N6/22.92/7.92 -> 0.48022216
A7: 2 | B7: 1.07068e-05 | C7: 0.000334555 | D7: 31.2474 | E7: 31.2471 | F7: -4.13695e-05 | G7: -0.000201851 | H7: 4.87901 | I7: 4.87922 | J7: 5.987 | K7: 5.988 | L7: 0.0113 | M7: -0.0258 | N7: 75.8678 | O7: =N7/22.92/7.92 -> 0.41794362
A8: 3 | B8: 2.1605e-05 | C8: 0.000675093 | D8: 31.2478 | E8: 31.2471 | F8: -2.02044e-05 | G8: -9.85815e-05 | H8: 4.87912 | I8: 4.87922 | J8: 6.111 | K8: 6.112 | L8: 0.0065 | M8: -0.0158 | N8: 51.6424 | O8: =N8/22.92/7.92 -> 0.28448975
A9: 4 | B9: 6.01909e-05 | C9: 0.00188079 | D9: 31.249 | E9: 31.2471 | F9: -5.98046e-05 | G9: -0.000291799 | H9: 4.87892 | I9: 4.87922 | J9: 9.419 | K9: 9.419 | L9: 0.0168 | M9: 0.0078 | N9: 103.323 | O9: =N9/22.92/7.92 -> 0.56918994
A10: 5 | B10: 9.06937e-05 | C10: 0.00283391 | D10: 31.2499 | E10: 31.2471 | F10: -2.78521e-05 | G10: -0.000135896 | H10: 4.87908 | I10: 4.87922 | J10: 9.544 | K10: 9.545 | L10: 0.0261 | M10: 0.001 | N10: 150.159 | O10: =N10/22.92/7.92 -> 0.82720199
A11: 6 | B11: 0.000104823 | C11: 0.00327541 | D11: 31.2504 | E11: 31.2471 | F11: -4.6132e-05 | G11: -0.000225088 | H11: 4.87899 | I11: 4.87922 | J11: 9.671 | K11: 9.671 | L11: 0.0326 | M11: 0.0181 | N11: 182.46 | O11: =N11/22.92/7.92 -> 1.0051431
A12: 7 | B12: 0.00012975 | C12: 0.00405432 | D12: 31.2512 | E12: 31.2471 | F12: -9.36929e-05 | G12: -0.000457148 | H12: 4.87876 | I12: 4.87922 | J12: 9.799 | K12: 9.799 | L12: 0.0493 | M12: 0.041 | N12: 266.441 | O12: =N12/22.92/7.92 -> 1.467781
A13: 8 | B13: 0.000145643 | C13: 0.00455091 | D13: 31.2516 | E13: 31.2471 | F13: -6.87453e-05 | G13: -0.000335423 | H13: 4.87888 | I13: 4.87922 | J13: 9.917 | K13: 9.918 | L13: 0.0709 | M13: 0.0484 | N13: 374.648 | O13: =N13/22.92/7.92 -> 2.0638761
A14: 9 | B14: 0.000206597 | C14: 0.00645557 | D14: 31.2535 | E14: 31.2471 | F14: -1.45451e-05 | G14: -7.09689e-05 | H14: 4.87915 | I14: 4.87922 | J14: 10.17 | K14: 10.17 | L14: 0.0893 | M14: 0.0561 | N14: 466.705 | O14: =N14/22.92/7.92 -> 2.5710034
A15: 10 | B15: 0.00021767 | C15: 0.00680156 | D15: 31.2539 | E15: 31.2471 | F15: -0.000151318 | G15: -0.000738312 | H15: 4.87848 | I15: 4.87922 | J15: 10.355 | K15: 10.355 | L15: 0.098 | M15: 0.0658 | N15: 510.31 | O15: =N15/22.92/7.92 -> 2.8112164
A16: 11 | B16: 0.000248513 | C16: 0.00776531 | D16: 31.2549 | E16: 31.2471 | F16: -0.000116684 | G16: -0.000569327 | H16: 4.87865 | I16: 4.87922 | J16: 10.48 | K16: 10.481 | L16: 0.1202 | M16: 0.0851 | N16: 621.747 | O16: =N16/22.92/7.92 -> 3.4251051
... A100: 95 | B100: 0.00246919 | C100: 0.077155 | D100: 31.3242 | E100: 31.2471 | F100: -0.000451408 | G100: -0.00220252 | H100: 4.87701 | I100: 4.87922 | J100: 61.462 | K100: 61.462 | L100: 1.0165 | M100: 0.9904 | N100: 5113.14 | O100: =N100/22.92/7.92 -> 28.167473
A101: 96 | H101: 4.87707 | I101: 4.87922 | J101: 62.147 | K101: 62.148 | L101: 1.0297 | M101: 0.9923 | N101: 5179.36 | O101: =N101/22.92/7.92 -> 28.532269
A102: 97 | H102: 4.87699 | I102: 4.87922 | J102: 63.147 | K102: 63.148 | L102: 1.0417 | M102: 1.0239 | N102: 5239.11 | O102: =N102/22.92/7.92 -> 28.861422
A103: 98 | H103: 4.87705 | I103: 4.87922 | J103: 63.77 | K103: 63.77 | L103: 1.0478 | M103: 1.0081 | N103: 5269.8 | O103: =N103/22.92/7.92 -> 29.030488
A104: 99 | H104: 4.87702 | I104: 4.87922 | J104: 64.709 | K104: 64.709 | L104: 1.0594 | M104: 1.0301 | N104: 5327.94 | O104: =N104/22.92/7.92 -> 29.350772
A105: 100 | H105: 4.87706 | I105: 4.87922 | J105: 65.331 | K105: 65.331 | L105: 1.0597 | M105: 1.0339 | N105: 5329.56 | O105: =N105/22.92/7.92 -> 29.359696
A106: 101 | H106: 4.87682 | I106: 4.87922 | J106: 65.518 | K106: 65.518 | L106: 1.071 | M106: 1.0375 | N106: 5386.08 | O106: =N106/22.92/7.92 -> 29.671056
A107: 102 | H107: 4.87721 | I107: 4.87922 | J107: 67.014 | K107: 67.015 | L107: 1.0855 | M107: 1.0678 | N107: 5458.76 | O107: =N107/22.92/7.92 -> 30.071439
A108: 103 | H108: 4.87708 | I108: 4.87922 | J108: 67.638 | K108: 67.638 | L108: 1.0952 | M108: 1.0771 | N108: 5507.21 | O108: =N108/22.92/7.92 -> 30.338342
A109: 104 | H109: 4.87705 | I109: 4.87922 | J109: 68.326 | K109: 68.327 | L109: 1.1045 | M109: 1.0742 | N109: 5554.05 | O109: =N109/22.92/7.92 -> 30.596376
A110: 105 | H110: 4.877 | I110: 4.87922 | J110: 69.263 | K110: 69.263 | L110: 1.1255 | M110: 1.09 | N110: 5659.02 | O110: =N110/22.92/7.92 -> 31.174639
A111: 106 | H111: 4.87715 | I111: 4.87922 | J111: 69.949 | K111: 69.949 | L111: 1.1264 | M111: 1.0816 | N111: 5663.87 | O111: =N111/22.92/7.92 -> 31.201357
A112: 107 | H112: 4.87687 | I112: 4.87922 | J112: 70.758 | K112: 70.758 | L112: 1.1429 | M112: 1.1016 | N112: 5746.23 | O112: =N112/22.92/7.92 -> 31.655065
... A431: 426 | H431: 4.87814 | I431: 4.87922 | J431: 317.738 | K431: 317.738 | L431: -0.0022 | M431: -0.0074 | N431: 8.0366 | O431: =N431/22.92/7.92 -> 0.044272348

Sheet L30NTX-2
A1: General : End date | B1: 5/28/2025
A2: General : Specimen number (included) | B2: 2
A3: Maximum Load : Maximum Load | B3: 18534.918 | C3: N
A4: Specimen choice input : Fiber direction | B4: <None>
A5: Specimen properties : Thickness | B5: 7.76 | C5: mm
A6: Specimen properties : Width | B6: 22.56 | C6: mm
A7: Specimen properties : Length | B7: 200 | C7: mm
A8: Modulus (Chord 0,05 % - 0,25 %) : Modulus (Chord 0,05 % - 0,25 %) | B8: 13217.266 | C8: MPa | E8: =MATCH(G10,G13:G1048576,0)-1 -> 2011
A9: Strain : Tensile strain (Extension) gauge length | B9: 25 | C9: mm | E9: Failure Strain, % | F9: Ult Load, N | G9: Ult Stress, MPa | J9: Ex, MPa | K9: νyx
E10: =INDEX(C13:C1048576,MATCH(G10,G13:G1048576,0)) -> 0.01338 | F10: =MAX(F13:F1048576) -> 18534.918 | G10: =MAX(G13:G1048576) -> 105.87413 | J10: =INDEX(LINEST(G13:G390,E13:E390),1) -> 13997.456 | K10: =INDEX(LINEST(I70:I390,E70:E390),1) -> 0.75570384
A11: Time | B11: Extension | C11: Strain 1 | D11: Tensile extension | E11: Tensile strain (Strain 1) | F11: Load | G11: Tensile stress | H11: Transverse deformation | I11: Transverse strain
A12: (s) | B12: (mm) | C12: (mm/mm) | D12: (mm) | E12: (mm/mm) | F12: (N) | G12: (MPa) | H12: (mm) | I12: (mm/mm)
A13: 0 | B13: 0 | C13: 0 | D13: 0 | E13: 0 | F13: 75.01897 | G13: 0.42852 | H13: 1e-05 | I13: 0
A14: 0.1 | B14: 0.00069 | C14: 0 | D14: 8e-05 | E14: 0 | F14: 85.4989 | G14: 0.48838 | H14: 5e-05 | I14: 0
A15: 0.2 | B15: 0.00266 | C15: 1e-05 | D15: 0.00037 | E15: 1e-05 | F15: 118.59949 | G15: 0.67746 | H15: 0.00018 | I15: 1e-05
A16: 0.3 | B16: 0.00753 | C16: 4e-05 | D16: 0.00111 | E16: 4e-05 | F16: 200.36716 | G16: 1.14453 | H16: 0.00052 | I16: 2e-05
A17: 0.4 | B17: 0.01057 | C17: 6e-05 | D17: 0.00157 | E17: 6e-05 | F17: 249.1105 | G17: 1.42296 | H17: 0.00074 | I17: 3e-05
A18: 0.5 | B18: 0.01441 | C18: 9e-05 | D18: 0.00213 | E18: 9e-05 | F18: 310.50031 | G18: 1.77362 | H18: 0.00102 | I18: 5e-05
A19: 0.6 | B19: 0.01738 | C19: 0.0001 | D19: 0.00256 | E19: 0.0001 | F19: 356.30725 | G19: 2.03528 | H19: 0.00125 | I19: 6e-05
A20: 0.7 | B20: 0.02094 | C20: 0.00012 | D20: 0.00306 | E20: 0.00012 | F20: 410.25876 | G20: 2.34346 | H20: 0.00151 | I20: 7e-05
A21: 0.8 | B21: 0.02423 | C21: 0.00014 | D21: 0.00351 | E21: 0.00014 | F21: 458.43939 | G21: 2.61867 | H21: 0.00172 | I21: 8e-05
A22: 0.9 | B22: 0.0274 | C22: 0.00016 | D22: 0.00391 | E22: 0.00016 | F22: 502.11301 | G22: 2.86814 | H22: 0.00195 | I22: 9e-05
A23: 1 | B23: 0.03132 | C23: 0.00018 | D23: 0.00443 | E23: 0.00018 | F23: 557.79846 | G23: 3.18623 | H23: 0.0022 | I23: 0.0001
A24: 1.1 | B24: 0.03395 | C24: 0.00019 | D24: 0.00476 | E24: 0.00019 | F24: 591.41162 | G24: 3.37823 | H24: 0.00238 | I24: 0.00011
... A2044: 201.308 | B2044: 6.7081 | C2044: 0.01038 | D2044: 0.25947 | E2044: 0.01038 | F2044: 10694.405 | G2044: 61.08799 | H2044: -0.25031 | I2044: -0.0111

Sheet L30NTX-2_DIC
P2: νzx
A3: E0 | F3: E1 | J3: Analog | P3: =-INDEX(LINEST(F5:F169,B5:B169),1) -> 0.0048266937
A4: Index [1] | B4: ?L/L0 [1] | C4: ?L [mm] | D4: L1 [mm] | E4: L0 [mm] | F4: ?L/L0 [1] | G4: ?L [mm] | H4: L1 [mm] | I4: L0 [mm] | J4: Time_1 | K4: Time_0 | L4: Dev1/ai0 | M4: Dev1/ai1 | N4: Force_[N] | O4: stress
A5: 0 | B5: 0 | C5: 0 | D5: 30.6033 | E5: 30.6033 | F5: 0 | G5: 0 | H5: 4.86648 | I5: 4.86648 | J5: 0 | K5: 0.003 | L5: 0.0171 | M5: 0.0087 | N5: 104.938 | O5: =N5/22.56/7.76 -> 0.59942102
A6: 1 | B6: 1.5032e-05 | C6: 0.000460029 | D6: 30.6037 | E6: 30.6033 | F6: -2.31698e-05 | G6: -0.000112755 | H6: 4.86637 | I6: 4.86648 | J6: 4.781 | K6: 4.781 | L6: 0.0058 | M6: 0.0055 | N6: 48.4123 | O6: =N6/22.56/7.76 -> 0.27653805
A7: 2 | B7: -2.24193e-05 | C7: -0.000686104 | D7: 30.6026 | E7: 30.6033 | F7: -1.40576e-05 | G7: -6.84112e-05 | H7: 4.86642 | I7: 4.86648 | J7: 5.654 | K7: 5.654 | L7: 0.0126 | M7: -0.009 | N7: 82.3279 | O7: =N7/22.56/7.76 -> 0.47026886
A8: 3 | B8: 1.76536e-06 | C8: 5.40258e-05 | D8: 30.6033 | E8: 30.6033 | F8: 7.56595e-05 | G8: 0.000368196 | H8: 4.86685 | I8: 4.86648 | J8: 5.842 | K8: 5.842 | L8: 0.0091 | M8: -0.0045 | N8: 64.5626 | O8: =N8/22.56/7.76 -> 0.3687909
A9: 4 | B9: 6.84094e-06 | C9: 0.000209355 | D9: 30.6035 | E9: 30.6033 | F9: 2.23661e-06 | G9: 1.08844e-05 | H9: 4.8665 | I9: 4.86648 | J9: 6.657 | K9: 6.657 | L9: 0.0071 | M9: -0.0071 | N9: 54.8724 | O9: =N9/22.56/7.76 -> 0.31343908
A10: 5 | B10: -7.78771e-06 | C10: -0.000238329 | D10: 30.603 | E10: 30.6033 | F10: -4.30696e-05 | G10: -0.000209598 | H10: 4.86627 | I10: 4.86648 | J10: 10.712 | K10: 10.712 | L10: 0.0094 | M10: -0.0122 | N10: 66.1776 | O10: =N10/22.56/7.76 -> 0.37801601
A11: 6 | B11: 5.22355e-06 | C11: 0.000159858 | D11: 30.6034 | E11: 30.6033 | F11: 3.10774e-05 | G11: 0.000151238 | H11: 4.86664 | I11: 4.86648 | J11: 10.834 | K11: 10.835 | L11: 0.0087 | M11: -0.0084 | N11: 62.9476 | O11: =N11/22.56/7.76 -> 0.35956579
A12: 7 | B12: 2.45649e-05 | C12: 0.000751767 | D12: 30.604 | E12: 30.6033 | F12: 7.05822e-05 | G12: 0.000343487 | H12: 4.86683 | I12: 4.86648 | J12: 12.894 | K12: 12.894 | L12: 0.0339 | M12: 0.0136 | N12: 188.92 | O12: =N12/22.56/7.76 -> 1.0791383
A13: 8 | B13: 3.45787e-05 | C13: 0.00105822 | D13: 30.6043 | E13: 30.6033 | F13: -8.11367e-05 | G13: -0.000394851 | H13: 4.86609 | I13: 4.86648 | J13: 13.019 | K13: 13.019 | L13: 0.0509 | M13: 0.0358 | N13: 274.516 | O13: =N13/22.56/7.76 -> 1.5680751
A14: 9 | B14: 9.42791e-05 | C14: 0.00288525 | D14: 30.6061 | E14: 30.6033 | F14: -4.58405e-05 | G14: -0.000223082 | H14: 4.86626 | I14: 4.86648 | J14: 13.204 | K14: 13.204 | L14: 0.049 | M14: 0.0342 | N14: 264.826 | O14: =N14/22.56/7.76 -> 1.5127244
A15: 10 | B15: 0.000112083 | C15: 0.00343009 | D15: 30.6067 | E15: 30.6033 | F15: -0.000146733 | G15: -0.000714076 | H15: 4.86577 | I15: 4.86648 | J15: 13.333 | K15: 13.333 | L15: 0.0796 | M15: 0.0539 | N15: 418.254 | O15: =N15/22.56/7.76 -> 2.3891273
A16: 11 | B16: 0.000118693 | C16: 0.0036324 | D16: 30.6069 | E16: 30.6033 | F16: -1.23249e-06 | G16: -5.99791e-06 | H16: 4.86648 | I16: 4.86648 | J16: 13.517 | K16: 13.517 | L16: 0.0909 | M16: 0.0622 | N16: 474.78 | O16: =N16/22.56/7.76 -> 2.712012
... A398: 393 | B398: 0.00137339 | C398: 0.0420302 | D398: 30.6453 | E398: 30.6033 | F398: 2.10021e-05 | G398: 0.000102207 | H398: 4.86659 | I398: 4.86648 | J398: 214.88 | K398: 214.88 | L398: 0.0016 | M398: 0.0126 | N398: 27.4169 | O398: =N398/22.56/7.76 -> 0.15660929

Sheet L30NTX-3
A1: General : End date | B1: 5/28/2025
A2: General : Specimen number (included) | B2: 3
A3: Maximum Load : Maximum Load | B3: 17474.977 | C3: N
A4: Specimen choice input : Fiber direction | B4: <None>
A5: Specimen properties : Thickness | B5: 7.77 | C5: mm
A6: Specimen properties : Width | B6: 22.35 | C6: mm
A7: Specimen properties : Length | B7: 200 | C7: mm
A8: Modulus (Chord 0,05 % - 0,25 %) : Modulus (Chord 0,05 % - 0,25 %) | B8: 13240.622 | C8: MPa | E8: =MATCH(G10,G13:G1048576,0)-1 -> 1979
A9: Strain : Tensile strain (Extension) gauge length | B9: 25 | C9: mm | E9: Failure Strain, % | F9: Ult Load, N | G9: Ult Stress, MPa | J9: Ex, MPa | K9: νyx
E10: =INDEX(C13:C1048576,MATCH(G10,G13:G1048576,0)) -> 0.01132 | F10: =MAX(F13:F1048576) -> 17474.977 | G10: =MAX(G13:G1048576) -> 100.62782 | J10: =INDEX(LINEST(G13:G450,E13:E450),1) -> 13988.787 | K10: =INDEX(LINEST(I190:I390,E190:E390),1) -> 0.5718699
A11: Time | B11: Extension | C11: Strain 1 | D11: Tensile extension | E11: Tensile strain (Strain 1) | F11: Load | G11: Tensile stress | H11: Transverse deformation | I11: Transverse strain
A12: (s) | B12: (mm) | C12: (mm/mm) | D12: (mm) | E12: (mm/mm) | F12: (N) | G12: (MPa) | H12: (mm) | I12: (mm/mm)
A13: 0 | B13: 0 | C13: 0 | D13: 4e-05 | E13: 0 | F13: 3.88929 | G13: 0.0224 | H13: 0.00014 | I13: 1e-05
A14: 0.1 | B14: 0.00071 | C14: 1e-05 | D14: 0.00013 | E14: 1e-05 | F14: 14.33158 | G14: 0.08253 | H14: 0.00018 | I14: 1e-05
A15: 0.2 | B15: 0.00274 | C15: 2e-05 | D15: 0.0004 | E15: 2e-05 | F15: 47.4024 | G15: 0.27296 | H15: 0.00031 | I15: 1e-05
A16: 0.3 | B16: 0.00758 | C16: 4e-05 | D16: 0.00108 | E16: 4e-05 | F16: 125.95709 | G16: 0.72531 | H16: 0.00064 | I16: 3e-05
A17: 0.4 | B17: 0.01062 | C17: 6e-05 | D17: 0.00151 | E17: 6e-05 | F17: 173.17604 | G17: 0.99722 | H17: 0.00083 | I17: 4e-05
A18: 0.5 | B18: 0.01444 | C18: 8e-05 | D18: 0.00203 | E18: 8e-05 | F18: 232.33945 | G18: 1.3379 | H18: 0.0011 | I18: 5e-05
A19: 0.6 | B19: 0.01743 | C19: 0.0001 | D19: 0.00243 | E19: 0.0001 | F19: 276.61087 | G19: 1.59283 | H19: 0.00129 | I19: 6e-05
A20: 0.7 | B20: 0.02097 | C20: 0.00012 | D20: 0.00292 | E20: 0.00012 | F20: 328.33585 | G20: 1.89069 | H20: 0.00154 | I20: 7e-05
A21: 0.8 | B21: 0.02428 | C21: 0.00013 | D21: 0.00335 | E21: 0.00013 | F21: 375.21219 | G21: 2.16062 | H21: 0.00175 | I21: 8e-05
A22: 0.9 | B22: 0.02744 | C22: 0.00015 | D22: 0.00374 | E22: 0.00015 | F22: 417.77313 | G22: 2.4057 | H22: 0.00195 | I22: 9e-05
A23: 1 | B23: 0.03135 | C23: 0.00017 | D23: 0.00422 | E23: 0.00017 | F23: 471.59232 | G23: 2.71561 | H23: 0.00218 | I23: 0.0001
A24: 1.1 | B24: 0.034 | C24: 0.00018 | D24: 0.00453 | E24: 0.00018 | F24: 504.40173 | G24: 2.90454 | H24: 0.00233 | I24: 0.0001
... A2014: 198.253 | B2014: 6.60623 | C2014: -0.01229 | D2014: -0.30725 | E2014: -0.01229 | F2014: 9980.4502 | G2014: 57.47137 | H2014: -0.10789 | I2014: -0.00483

Sheet L30NTX-3_DIC
P2: νzx
A3: E0 | F3: E1 | J3: Analog | P3: =INDEX(LINEST(F5:F169,B5:B169),1) -> 0.28374145
A4: Index [1] | B4: ?L/L0 [1] | C4: ?L [mm] | D4: L1 [mm] | E4: L0 [mm] | F4: ?L/L0 [1] | G4: ?L [mm] | H4: L1 [mm] | I4: L0 [mm] | J4: Time_1 | K4: Time_0 | L4: Dev1/ai0 | M4: Dev1/ai1 | N4: Force_[N]
A5: 0 | B5: 0 | C5: 0 | D5: 28.7547 | E5: 28.7547 | F5: 0 | G5: 0 | H5: 4.61444 | I5: 4.61444 | J5: 0 | K5: 0.004 | L5: -0.0022 | M5: -0.01 | N5: 8.0366
A6: 1 | B6: 2.1993e-05 | C6: 0.000632403 | D6: 28.7554 | E6: 28.7547 | F6: 6.8848e-05 | G6: 0.000317695 | H6: 4.61476 | I6: 4.61444 | J6: 1.517 | K6: 1.517 | L6: -0.0048 | M6: -0.0113 | N6: -4.8836
A7: 2 | B7: -3.4624e-05 | C7: -0.000995603 | D7: 28.7537 | E7: 28.7547 | F7: -0.000139866 | G7: -0.000645405 | H7: 4.6138 | I7: 4.61444 | J7: 5.248 | K7: 5.248 | L7: -0.0055 | M7: -0.0171 | N7: -8.1137
A8: 3 | B8: -7.26824e-06 | C8: -0.000208996 | D8: 28.7545 | E8: 28.7547 | F8: -3.07177e-05 | G8: -0.000141745 | H8: 4.6143 | I8: 4.61444 | J8: 10.363 | K8: 10.363 | L8: -0.0067 | M8: 0.0004 | N8: -14.5738
A9: 4 | B9: -1.74537e-05 | C9: -0.000501877 | D9: 28.7542 | E9: 28.7547 | F9: -3.34075e-05 | G9: -0.000154157 | H9: 4.61429 | I9: 4.61444 | J9: 10.738 | K9: 10.738 | L9: -0.0045 | M9: -0.0167 | N9: -3.2686
A10: 5 | B10: -3.93444e-05 | C10: -0.00113134 | D10: 28.7536 | E10: 28.7547 | F10: -2.16201e-05 | G10: -9.97649e-05 | H10: 4.61434 | I10: 4.61444 | J10: 10.926 | K10: 10.926 | L10: -0.0032 | M10: -0.0196 | N10: 3.1915
A11: 6 | B11: 7.57746e-06 | C11: 0.000217888 | D11: 28.755 | E11: 28.7547 | F11: -6.42252e-05 | G11: -0.000296363 | H11: 4.61415 | I11: 4.61444 | J11: 11.486 | K11: 11.486 | L11: -0.0045 | M11: -0.0164 | N11: -3.2686
A12: 7 | B12: 1.59916e-05 | C12: 0.000459835 | D12: 28.7552 | E12: 28.7547 | F12: 3.53282e-05 | G12: 0.00016302 | H12: 4.61461 | I12: 4.61444 | J12: 11.8 | K12: 11.8 | L12: -0.0055 | M12: -0.0122 | N12: -8.1137
A13: 8 | B13: 4.27632e-05 | C13: 0.00122965 | D13: 28.756 | E13: 28.7547 | F13: -9.80342e-05 | G13: -0.000452373 | H13: 4.61399 | I13: 4.61444 | J13: 12.236 | K13: 12.236 | L13: 0.0126 | M13: -0.0093 | N13: 82.3279
A14: 9 | B14: 6.69049e-05 | C14: 0.00192383 | D14: 28.7567 | E14: 28.7547 | F14: -5.40551e-05 | G14: -0.000249434 | H14: 4.61419 | I14: 4.61444 | J14: 12.361 | K14: 12.361 | L14: 0.0258 | M14: -0.0013 | N14: 148.544
A15: 10 | B15: 7.96221e-05 | C15: 0.00228951 | D15: 28.757 | E15: 28.7547 | F15: 5.48903e-06 | G15: 2.53288e-05 | H15: 4.61447 | I15: 4.61444 | J15: 12.485 | K15: 12.485 | L15: 0.0316 | M15: 0.0084 | N15: 177.615
A16: 11 | B16: 0.000116336 | C16: 0.00334521 | D16: 28.7581 | E16: 28.7547 | F16: 4.07989e-05 | G16: 0.000188264 | H16: 4.61463 | I16: 4.61444 | J16: 12.611 | K16: 12.611 | L16: 0.0461 | M16: 0.0287 | N16: 250.291
... A243: 238 | B243: 0.0089995 | C243: 0.258778 | D243: 29.0135 | E243: 28.7547 | F243: 0.000995591 | G243: 0.0045941 | H243: 4.61904 | I243: 4.61444 | J243: 140.405 | K243: 140.405 | L243: 2.2518 | M243: 2.1964 | N243: 11303.6
A244: 239 | F244: 0.00103848 | G244: 0.00479201 | H244: 4.61924 | I244: 4.61444 | J244: 140.594 | K244: 140.594 | L244: 2.2618 | M244: 2.2254 | N244: 11353.6
A245: 240 | F245: 0.00106498 | G245: 0.00491429 | H245: 4.61936 | I245: 4.61444 | J245: 141.033 | K245: 141.033 | L245: 2.2696 | M245: 2.2286 | N245: 11392.4
A246: 241 | F246: 0.00110704 | G246: 0.00510836 | H246: 4.61955 | I246: 4.61444 | J246: 141.655 | K246: 141.655 | L246: 2.2828 | M246: 2.2248 | N246: 11458.6
A247: 242 | F247: 0.00106289 | G247: 0.00490465 | H247: 4.61935 | I247: 4.61444 | J247: 142.277 | K247: 142.277 | L247: 2.2941 | M247: 2.2357 | N247: 11515.1
A248: 243 | B248: 0.00922123 | C248: 0.265154 | D248: 29.0199 | E248: 28.7547 | F248: 0.000950685 | G248: 0.00438688 | H248: 4.61883 | I248: 4.61444 | J248: 142.901 | K248: 142.901 | L248: 2.2963 | M248: 2.2444 | N248: 11526.4
A249: 244 | F249: 0.00105218 | G249: 0.00485521 | H249: 4.6193 | I249: 4.61444 | J249: 143.215 | K249: 143.215 | L249: 2.3034 | M249: 2.256 | N249: 11562
A250: 245 | B250: 0.00936449 | C250: 0.269273 | D250: 29.024 | E250: 28.7547 | F250: 0.00119434 | G250: 0.00551122 | H250: 4.61996 | I250: 4.61444 | J250: 143.901 | K250: 143.901 | L250: 2.2995 | M250: 2.2586 | N250: 11542.6
A251: 246 | B251: 0.00935524 | C251: 0.269008 | D251: 29.0237 | E251: 28.7547 | F251: 0.00108162 | G251: 0.00499106 | H251: 4.61944 | I251: 4.61444 | J251: 144.402 | K251: 144.402 | L251: 2.3247 | M251: 2.2596 | N251: 11668.5
A252: 247 | F252: 0.00114697 | G252: 0.00529262 | H252: 4.61974 | I252: 4.61444 | J252: 144.523 | K252: 144.523 | L252: 2.3231 | M252: 2.2831 | N252: 11660.5
A253: 248 | F253: 0.00111978 | G253: 0.00516718 | H253: 4.61961 | I253: 4.61444 | J253: 145.149 | K253: 145.149 | L253: 2.3431 | M253: 2.2783 | N253: 11760.6
A254: 249 | F254: 0.00104415 | G254: 0.00481815 | H254: 4.61926 | I254: 4.61444 | J254: 145.711 | K254: 145.711 | L254: 2.3501 | M254: 2.2931 | N254: 11796.1
A255: 250 | F255: 0.00105779 | G255: 0.00488113 | H255: 4.61933 | I255: 4.61444 | J255: 146.395 | K255: 146.395 | L255: 2.3621 | M255: 2.3179 | N255: 11855.9
A256: 251 | F256: 0.000997934 | G256: 0.00460491 | H256: 4.61905 | I256: 4.61444 | J256: 147.084 | K256: 147.084 | L256: 2.3721 | M256: 2.3099 | N256: 11906
A257: 252 | F257: 0.00101496 | G257: 0.00468348 | H257: 4.61913 | I257: 4.61444 | J257: 147.771 | K257: 147.771 | L257: 2.385 | M257: 2.3318 | N257: 11970.6
A258: 253 | F258: 0.00116173 | G258: 0.00536072 | H258: 4.6198 | I258: 4.61444 | J258: 148.206 | K258: 148.206 | L258: 2.3898 | M258: 2.3157 | N258: 11994.8
A259: 254 | F259: 0.00100509 | G259: 0.00463793 | H259: 4.61908 | I259: 4.61444 | J259: 148.891 | K259: 148.891 | L259: 2.403 | M259: 2.3405 | N259: 12061
A260: 255 | F260: 0.00103258 | G260: 0.00476478 | H260: 4.61921 | I260: 4.61444 | J260: 149.33 | K260: 149.33 | L260: 2.4075 | M260: 2.3479 | N260: 12083.6
A261: 256 | F261: 0.00102659 | G261: 0.00473714 | H261: 4.61918 | I261: 4.61444 | J261: 149.957 | K261: 149.957 | L261: 2.421 | M261: 2.3853 | N261: 12151.4
A262: 257 | F262: 0.000987962 | G262: 0.0045589 | H262: 4.619 | I262: 4.61444 | J262: 150.265 | K262: 150.265 | L262: 2.4249 | M262: 2.3695 | N262: 12170.8
A263: 258 | F263: 0.00111323 | G263: 0.00513694 | H263: 4.61958 | I263: 4.61444 | J263: 151.013 | K263: 151.014 | L263: 2.4291 | M263: 2.3927 | N263: 12191.8
... A412: 407 | F412: -7.8431e-05 | G412: -0.000361916 | H412: 4.61408 | I412: 4.61444 | J412: 260.65 | K412: 260.65 | L412: -0.0003 | M412: -0.008 | N412: 17.7268
A413: 408 | J413: 260.908 | K413: 260.908 | L413: -0.0048 | M413: -0.0045 | N413: -4.8836
A414: 409 | J414: 261.101 | K414: 261.101 | L414: 0.0026 | M414: -0.0129 | N414: 32.262
A415: 410 | F415: -0.000171962 | G415: -0.000793511 | H415: 4.61365 | I415: 4.61444 | J415: 262.335 | K415: 262.335 | L415: -0.0055 | M415: -0.0277 | N415: -8.1137
...
