Workbook

Sheet OLS13
B2: ='OLS13-1'!$CS$2 -> Ult Stress, MPa | C2: ='OLS13-1'!$CZ$2 -> Failure Strains, % | D2: ='OLS13-1'!$DA$2 -> G13, MPa | E2: ='OLS13-1'!$DA$2 -> G13, MPa
A3: average | B3: =AVERAGE(B6:B9) -> 7.841201 | C3: =AVERAGE(C6:C9) -> 0.049180233 | D3: =AVERAGE(D6:D9) -> 349.97375 | E3: =AVERAGE(E6:E9) -> 321.68051
A4: sr. dev. | B4: =STDEV(B6:B9) -> 0.18150534 | C4: =STDEV(C6:C9) -> 0.0028237629 | D4: =STDEV(D6:D9) -> 27.580418 | E4: =STDEV(E6:E9) -> 19.060997
A5: CV | B5: =B4/B3 -> 0.023147645 | C5: =C4/C3 -> 0.057416623 | D5: =D4/D3 -> 0.078807106 | E5: =E4/E3 -> 0.059254436
A6: 1 | B6: ='OLS13-1'!$CS$3 -> 7.712497 | C6: ='OLS13-1'!$CZ$3 -> 0.052000886 | D6: ='OLS13-1'!CY3 -> 340.78605 | E6: ='OLS13-1'!$DA$3 -> 329.43389
A7: 2 | B7: ='OLS13-2'!CS3 -> 8.0488033 | C7: ='OLS13-2'!CZ3 -> 0.049186442 | D7: ='OLS13-2'!CY3 -> 380.97534 | E7: ='OLS13-2'!DA3 -> 335.64297
A8: 3 | B8: ='OLS13-3'!CS3 -> 7.7623027 | C8: ='OLS13-3'!CZ3 -> 0.046353371 | D8: ='OLS13-3'!CY3 -> 328.15985 | E8: ='OLS13-3'!DA3 -> 299.96466
S17: 45.5897 | T17: 22.795 | U17: 9.6 | V17: =(S17^2+U17^2)^0.5 -> 46.589492 | W17: =V17*T17 -> 1062.0075
S18: 48 | T18: 23 | U18: 9.6 | V18: =(S18^2+U18^2)^0.5 -> 48.950587 | W18: =V18*T18 -> 1125.8635
W19: =W18/W17 -> 1.0601277
S21: 4061

Sheet OLS13-1
A1: w | B1: t | C1: a | D1: L, mm | E1: tg(theta) | F1: ctg(theta) | G1: (2+tg^2+ctg^2)^0,5 | J1: cos | K1: sin | L1: acos | CZ1: =MATCH(CS3,CS5:CS1048576,0)-1 -> 752 | DB1: =MATCH(CS3,CS5:CS1048576,0)-1 -> 752
A2: =2*5 -> 10 | B2: 9.6 | C2: 40 | D2: =(B2^2+C2^2)^0.5 -> 41.135872 | E2: =B2/C2 -> 0.24 | F2: =1/E2 -> 4.1666667 | G2: =(2+E2^2+F2^2)^0.5 -> 4.4066667 | J2: =C2/D2 -> 0.9723873 | K2: =(1-J2^2)^0.5 -> 0.23337295 | L2: =ACOS(J2) -> 0.23554498 | CS2: Ult Stress, MPa | CZ2: Failure Strains, % | DA2: G13, MPa | DB2: Failure Strains, % | DC2: G13, MPa
A3: Average | Q3: P0 | AH3: P1 | AY3: P2 | BP3: P3 | CG3: Analog | CK3: E0 | CS3: =MAX(CS5:CS1048576) -> 7.712497 | CY3: =CS284/CZ284 -> 340.78605 | CZ3: =INDEX(CZ5:CZ1048576,MATCH(CS3,CS5:CS1048576,0)) -> 0.052000886 | DA3: =INDEX(LINEST(CS90:CS284,CZ90:CZ284),1) -> 329.43389 | DB3: =INDEX(DB5:DB1048576,MATCH(CS3,CS5:CS1048576,0)) -> 0.073407135 | DC3: =INDEX(LINEST(CS90:CS120,DB90:DB120),1) -> 280.77169 | DD3: before deformation | DI3: check | DJ3: after defor,mation
A4: Index [1] | B4: X [mm] | C4: Y [mm] | D4: Z [mm] | E4: U [mm] | F4: V [mm] | G4: W [mm] | H4: exx [1] - Lagrange | I4: eyy [1] - Lagrange | J4: exy [1] - Lagrange | K4: e1 [1] - Lagrange | L4: e2 [1] - Lagrange | M4: gamma [1] - Lagrange | N4: Sigma_X [mm] | O4: Sigma_Y [mm] | P4: Sigma_Z [mm] | Q4: X [mm] | R4: Y [mm] | S4: Z [mm] | T4: U [mm] | U4: V [mm] | V4: W [mm] | W4: X01 | X4: Y01 | Y4: exx [1] - Lagrange | Z4: eyy [1] - Lagrange | AA4: exy [1] - Lagrange | AB4: e1 [1] - Lagrange | AC4: e2 [1] - Lagrange | AD4: gamma [1] - Lagrange | AE4: Sigma_X [mm] | AF4: Sigma_Y [mm] | AG4: Sigma_Z [mm] | AH4: X [mm] | AI4: Y [mm] | AJ4: Z [mm] | AK4: U [mm] | AL4: V [mm] | AM4: W [mm] | AN4: X11 | AO4: Y11 | AP4: exx [1] - Lagrange | AQ4: eyy [1] - Lagrange | AR4: exy [1] - Lagrange | AS4: e1 [1] - Lagrange | AT4: e2 [1] - Lagrange | AU4: gamma [1] - Lagrange | AV4: Sigma_X [mm] | AW4: Sigma_Y [mm] | AX4: Sigma_Z [mm] | AY4: X [mm] | AZ4: Y [mm] | BA4: Z [mm] | BB4: U [mm] | BC4: V [mm] | BD4: W [mm] | BE4: X21 | BF4: Y21 | BG4: exx [1] - Lagrange | BH4: eyy [1] - Lagrange | BI4: exy [1] - Lagrange | BJ4: e1 [1] - Lagrange | BK4: e2 [1] - Lagrange | BL4: gamma [1] - Lagrange | BM4: Sigma_X [mm] | BN4: Sigma_Y [mm] | BO4: Sigma_Z [mm] | BP4: X [mm] | BQ4: Y [mm] | BR4: Z [mm] | BS4: U [mm] | BT4: V [mm] | BU4: W [mm] | BV4: X31 | BW4: Y31 | BX4: exx [1] - Lagrange | BY4: eyy [1] - Lagrange | BZ4: exy [1] - Lagrange | CA4: e1 [1] - Lagrange | CB4: e2 [1] - Lagrange | CC4: gamma [1] - Lagrange | CD4: Sigma_X [mm] | CE4: Sigma_Y [mm] | CF4: Sigma_Z [mm] | CG4: Time_1 | CH4: Time_0 | CI4: Dev1/ai0 | CJ4: Force_[N] | CK4: ?L/L0 [1] | CL4: L0, mm | CM4: L1 | CN4: (L1-L0)/L0 | CO4: cos(dth) | CP4: acos(dth) | CQ4: sin(dth) | CR4: Force' | CS4: Tau_13, Mpa | CT4: e_xx' | CU4: e_yy' | CV4: g_xy' | CW4: e_1 | CX4: e_3 | CY4: g_13' | CZ4: -g_13' | DA4: u, mm | DB4: g_13u | DC4: P0P3_x | DD4: P0P3_y | DE4: P0P3 | DF4: P2P1_x | DG4: P2P1_y | DH4: P2P1 | DI4: Cos0 | DJ4: P0P3_x1 | DK4: P0P3_y1 | DL4: P0P3_1 | DM4: P2P1_x1 | DN4: P2P1_y1 | DO4: P2P1_1 | DP4: Cos1 | DQ4: Cos03 | DR4: Cos21 | DS4: cos_P2P1 | DT4: sin_P2P1 | DU4: e1 | DV4: e3 | DW4: g13 | DX4: -g13 | DZ4: P2P0_x | EA4: P2P0_y | EB4: cos(021) | EC4: P2P0 | ED4: b | EE4: P2P0_x1 | EF4: P2P0_y1 | EG4: us_x | EH4: us_y | EI4: us | EJ4: gamma_13s
A5: 0 | B5: 0.00422635 | C5: 0.00853024 | D5: 8.51092e-05 | E5: 0 | F5: 0 | G5: 0 | H5: -1.4506e-17 | I5: -1.33785e-17 | J5: 2.09292e-20 | K5: -1.10475e-17 | L5: -1.68369e-17 | M5: -0.0016123 | N5: 0.000142282 | O5: 0.000162718 | P5: 0.001404 | Q5: -0.0426427 | R5: 17.8228 | S5: -0.0203832 | T5: 0 | U5: 0 | V5: 0 | W5: =Q5+T5 -> -0.0426427 | X5: =R5+U5 -> 17.8228 | Y5: -1.16997e-17 | Z5: -1.90803e-17 | AA5: 6.05227e-18 | AB5: -8.30007e-18 | AC5: -2.24799e-17 | AD5: 0.511939 | AE5: 7.94072e-05 | AF5: 9.67591e-05 | AG5: 0.000779351 | AH5: 0.16398 | AI5: -17.9784 | AJ5: 0.0178449 | AK5: 0 | AL5: 0 | AM5: 0 | AN5: =AH5+AK5 -> 0.16398 | AO5: =AI5+AL5 -> -17.9784 | AP5: -4.4207e-18 | AQ5: -3.96274e-18 | AR5: 5.66609e-18 | AS5: 1.49367e-18 | AT5: -9.87712e-18 | AU5: 0.806798 | AV5: 0.000117323 | AW5: 0.000116798 | AX5: 0.00115213 | AY5: 8.48689 | AZ5: 15.1324 | BA5: -0.107245 | BB5: 0 | BC5: 0 | BD5: 0 | BE5: =AY5+BB5 -> 8.48689 | BF5: =AZ5+BC5 -> 15.1324 | BG5: -3.79966e-17 | BH5: -2.36374e-17 | BI5: -5.54863e-18 | BJ5: -2.17287e-17 | BK5: -3.99054e-17 | BL5: -1.24177 | BM5: 0.000322327 | BN5: 0.000351077 | BO5: 0.00295653 | BP5: -8.52131 | BQ5: -14.4079 | BR5: -0.071984 | BS5: 0 | BT5: 0 | BU5: 0 | BV5: =BP5+BS5 -> -8.52131 | BW5: =BQ5+BT5 -> -14.4079 | BX5: -2.82959e-17 | BY5: -2.07333e-17 | BZ5: 1.98198e-18 | CA5: -2.0212e-17 | CB5: -2.88171e-17 | CC5: 1.32407 | CD5: 0.000108092 | CE5: 0.000126132 | CF5: 0.00114774 | CG5: -2095.45 | CH5: -2095.45 | CI5: -0.1795 | CJ5: -89.5404 | CK5: 0 | CL5: =R5-AI5 -> 35.8012 | CM5: =((W5-AN5)^2+(X5-AO5)^2)^0.5 -> 35.801796 | CN5: =(CM5-CL5)/CL5 -> 1.6654335e-05 | CO5: =(X5-AO5)/CM5 -> 0.99998335 | CP5: =ACOS(CO5) -> 0.0057713263 | CQ5: =(AN5-W5)/CM5 -> 0.0057712942 | CR5: =CJ5*CO5 -> -89.538909 | CS5: =-CR5/D$2/A$2 -> 0.21766624 | CT5: =H5*CO5^2+I5*CQ5^2+2*J5*CO5*CQ5 -> -1.4505721e-17 | CU5: =H5*CQ5^2+I5*CO5^2-2*J5*CO5*CQ5 -> -1.3378779e-17 | CV5: =2*((I5-H5)*CO5*CQ5+J5*(CO5^2-CQ5^2)) -> 5.4869663e-20 | CW5: =CT5*K$2^2+CU5*J$2^2+J$2*K$2*CV5 -> -1.3427704e-17 | CX5: =CT5*J$2^2+CU5*K$2^2-J$2*K$2*CV5 -> -1.4456796e-17 | CY5: =(2*(CU5-CT5)*J$2*K$2+CV5*(K$2^2-J$2^2)) -> 4.6257835e-19 | CZ5: =-CY5 -> -4.6257835e-19 | DA5: =-CK5*CL5 -> 0 | DB5: =G$2*DA5/CL5 -> 0 | DC5: =BP5-Q5 -> -8.4786673 | DD5: =BQ5-R5 -> -32.2307 | DE5: =(DC5^2+DD5^2)^0.5 -> 33.327253 | DF5: =AH5-AY5 -> -8.32291 | DG5: =AI5-AZ5 -> -33.1108 | DH5: =(DF5^2+DG5^2)^0.5 -> 34.140825 | DI5: =(DC5*DF5+DD5*DG5)/DE5/DH5 -> 0.99993982 | DJ5: =BV5-W5 -> -8.4786673 | DK5: =BW5-X5 -> -32.2307 | DL5: =(DJ5^2+DK5^2)^0.5 -> 33.327253 | DM5: =AN5-BE5 -> -8.32291 | DN5: =AO5-BF5 -> -33.1108 | DO5: =(DM5^2+DN5^2)^0.5 -> 34.140825 | DP5: =(DJ5*DM5+DK5*DN5)/DL5/DO5 -> 0.99993982 | DQ5: =(DJ5*DC5+DK5*DD5)/DE5/DL5 -> 1 | DR5: =(DM5*DF5+DN5*DG5)/DH5/DO5 -> 1 | DS5: =DJ5/DL5 -> -0.25440642 | DT5: =DK5/DL5 -> -0.9670974 | DU5: =DS5^2*H5+DT5^2*I5+2*DS5*DT5*J5 -> -1.3441176e-17 | DV5: =DT5^2*H5+DS5^2*I5-2*DS5*DT5*J5 -> -1.4443324e-17 | DW5: =2*((I5-H5)*DS5*DT5+(DS5^2-DT5^2)*J5) -> 5.1837067e-19 | DX5: =-DW5 -> -5.1837067e-19 | DZ5: =Q5-AY5 -> -8.5295327 | EA5: =R5-AZ5 -> 2.6904 | EB5: =(DZ5*DF5+EA5*DG5)/(DZ5^2+EA5^2)^0.5/(DF5^2+DG5^2)^0.5 -> -0.059246382 | EC5: =(DZ5^2+EA5^2)^0.5 -> 8.9437789 | ED5: =EC5*(1-EB5^2)^0.5 -> 8.9280681 | EE5: =W5-BE5 -> -8.5295327 | EF5: =X5-BF5 -> 2.6904 | EG5: =EE5-DZ5 -> 0 | EH5: =EF5-EA5 -> 0 | EI5: =(EG5^2+EH5^2)^0.5 -> 0 | EJ5: =EI5/ED5 -> 0
A6: 1 | B6: 0.00422635 | C6: 0.00853024 | D6: 8.51092e-05 | E6: -0.00172341 | F6: -0.000359031 | G6: 0.0117595 | H6: -2.05559e-05 | I6: -1.90194e-05 | J6: -2.52111e-05 | K6: 5.55421e-05 | L6: -9.51173e-05 | M6: -0.211617 | N6: 0.000100592 | O6: 0.000107273 | P6: 0.000946004 | Q6: -0.0426427 | R6: 17.8228 | S6: -0.0203832 | T6: -0.00376866 | U6: -0.00218908 | V6: 0.017635 | W6: =Q6+T6 -> -0.04641136 | X6: =R6+U6 -> 17.820611 | Y6: -0.000247777 | Z6: -0.000189405 | AA6: 9.22161e-05 | AB6: -0.000121789 | AC6: -0.000315393 | AD6: 0.938415 | AE6: 0.000102414 | AF6: 0.000120267 | AG6: 0.00095957 | AH6: 0.16398 | AI6: -17.9784 | AJ6: 0.0178449 | AK6: 0.000121972 | AL6: -0.00107493 | AM6: 0.00356335 | AN6: =AH6+AK6 -> 0.16410197 | AO6: =AI6+AL6 -> -17.979475 | AP6: 0.000122798 | AQ6: -0.000155863 | AR6: 0.00013018 | AS6: 0.000174468 | AT6: -0.000207533 | AU6: 0.37637 | AV6: 0.000111555 | AW6: 0.000107818 | AX6: 0.0010572 | AY6: 8.48689 | AZ6: 15.1324 | BA6: -0.107245 | BB6: -0.00449542 | BC6: -0.00159668 | BD6: 0.0215335 | BE6: =AY6+BB6 -> 8.4823946 | BF6: =AZ6+BC6 -> 15.130803 | BG6: -0.000238076 | BH6: -3.8812e-05 | BI6: -0.000205246 | BJ6: 8.9902e-05 | BK6: -0.00036679 | BL6: -1.0105 | BM6: 0.000108528 | BN6: 0.000124687 | BO6: 0.00102046 | BP6: -8.52131 | BQ6: -14.4079 | BR6: -0.071984 | BS6: -0.00058145 | BT6: -0.00185814 | BU6: 0.00650736 | BV6: =BP6+BS6 -> -8.5218915 | BW6: =BQ6+BT6 -> -14.409758 | BX6: -2.85875e-05 | BY6: 0.000213512 | BZ6: 6.61576e-06 | CA6: 0.00021371 | CB6: -2.8786e-05 | CC6: 1.54288 | CD6: 0.000104337 | CE6: 0.000109883 | CF6: 0.000984445 | CG6: -2091.71 | CH6: -2091.71 | CI6: -0.184 | CJ6: -91.8032 | CK6: -2.87585e-05 | CL6: =R6-AI6 -> 35.8012 | CM6: =((W6-AN6)^2+(X6-AO6)^2)^0.5 -> 35.800705 | CN6: =(CM6-CL6)/CL6 -> -1.3832503e-05 | CO6: =(X6-AO6)/CM6 -> 0.99998271 | CP6: =ACOS(CO6) -> 0.0058801788 | CQ6: =(AN6-W6)/CM6 -> 0.0058801449 | CR6: =CJ6*CO6 -> -91.801613 | CS6: =-CR6/D$2/A$2 -> 0.22316681 | CT6: =H6*CO6^2+I6*CQ6^2+2*J6*CO6*CQ6 -> -2.0852332e-05 | CU6: =H6*CQ6^2+I6*CO6^2-2*J6*CO6*CQ6 -> -1.8722968e-05 | CV6: =2*((I6-H6)*CO6*CQ6+J6*(CO6^2-CQ6^2)) -> -5.0400644e-05 | CW6: =CT6*K$2^2+CU6*J$2^2+J$2*K$2*CV6 -> -3.0276302e-05 | CX6: =CT6*J$2^2+CU6*K$2^2-J$2*K$2*CV6 -> -9.2989978e-06 | CY6: =(2*(CU6-CT6)*J$2*K$2+CV6*(K$2^2-J$2^2)) -> 4.5877138e-05 | CZ6: =-CY6 -> -4.5877138e-05 | DA6: =-CK6*CL6 -> 0.0010295888 | DB6: =G$2*DA6/CL6 -> 0.00012672912 | DC6: =BP6-Q6 -> -8.4786673 | DD6: =BQ6-R6 -> -32.2307 | DE6: =(DC6^2+DD6^2)^0.5 -> 33.327253 | DF6: =AH6-AY6 -> -8.32291 | DG6: =AI6-AZ6 -> -33.1108 | DH6: =(DF6^2+DG6^2)^0.5 -> 34.140825 | DI6: =(DC6*DF6+DD6*DG6)/DE6/DH6 -> 0.99993982 | DJ6: =BV6-W6 -> -8.4754801 | DK6: =BW6-X6 -> -32.230369 | DL6: =(DJ6^2+DK6^2)^0.5 -> 33.326123 | DM6: =AN6-BE6 -> -8.3182926 | DN6: =AO6-BF6 -> -33.110278 | DO6: =(DM6^2+DN6^2)^0.5 -> 34.139193 | DP6: =(DJ6*DM6+DK6*DN6)/DL6/DO6 -> 0.99993941 | DQ6: =(DJ6*DC6+DK6*DD6)/DE6/DL6 -> 1 | DR6: =(DM6*DF6+DN6*DG6)/DH6/DO6 -> 0.99999999 | DS6: =DJ6/DL6 -> -0.25431942 | DT6: =DK6/DL6 -> -0.96712028 | DU6: =DS6^2*H6+DT6^2*I6+2*DS6*DT6*J6 -> -3.1520495e-05 | DV6: =DT6^2*H6+DS6^2*I6-2*DS6*DT6*J6 -> -8.0548052e-06 | DW6: =2*((I6-H6)*DS6*DT6+(DS6^2-DT6^2)*J6) -> 4.4655576e-05 | DX6: =-DW6 -> -4.4655576e-05 | DZ6: =Q6-AY6 -> -8.5295327 | EA6: =R6-AZ6 -> 2.6904 | EB6: =(DZ6*DF6+EA6*DG6)/(DZ6^2+EA6^2)^0.5/(DF6^2+DG6^2)^0.5 -> -0.059246382 | EC6: =(DZ6^2+EA6^2)^0.5 -> 8.9437789 | ED6: =EC6*(1-EB6^2)^0.5 -> 8.9280681 | EE6: =W6-BE6 -> -8.5288059 | EF6: =X6-BF6 -> 2.6898076 | EG6: =EE6-DZ6 -> 0.00072676 | EH6: =EF6-EA6 -> -0.0005924 | EI6: =(EG6^2+EH6^2)^0.5 -> 0.00093761285 | EJ6: =EI6/ED6 -> 0.00010501856
A7: 2 | B7: 0.0030028 | C7: -0.00528478 | D7: 9.81668e-05 | E7: 0.00145144 | F7: -0.000929493 | G7: 0.0045131 | H7: -5.53285e-05 | I7: -1.47265e-05 | J7: 1.86591e-05 | K7: 4.14807e-05 | L7: -0.000111536 | M7: 0.218849 | N7: 0.000102495 | O7: 0.000109233 | P7: 0.000963288 | Q7: -0.0426427 | R7: 17.8228 | S7: -0.0203832 | T7: -0.000963696 | U7: -0.00159996 | V7: 0.00390228 | W7: =Q7+T7 -> -0.043606396 | X7: =R7+U7 -> 17.8212 | Y7: -0.000237203 | Z7: 6.81046e-05 | AA7: 7.76721e-05 | AB7: 8.68848e-05 | AC7: -0.000255984 | AD7: 1.33571 | AE7: 0.00010557 | AF7: 0.000123808 | AG7: 0.000988106 | AH7: 0.16398 | AI7: -17.9784 | AJ7: 0.0178449 | AK7: 0.00431278 | AL7: -0.00077484 | AM7: 0.00171976 | AN7: =AH7+AK7 -> 0.16829278 | AO7: =AI7+AL7 -> -17.979175 | AP7: -7.94496e-05 | AQ7: -0.00018141 | AR7: 0.000204764 | AS7: 8.06504e-05 | AT7: -0.00034151 | AU7: 0.663615 | AV7: 0.000115915 | AW7: 0.000111759 | AX7: 0.0010961 | AY7: 8.48689 | AZ7: 15.1324 | BA7: -0.107245 | BB7: -0.00242811 | BC7: -0.000167799 | BD7: 0.0233785 | BE7: =AY7+BB7 -> 8.4844619 | BF7: =AZ7+BC7 -> 15.132232 | BG7: -0.000495926 | BH7: 2.92376e-05 | BI7: -6.47581e-05 | BJ7: 3.71183e-05 | BK7: -0.000503806 | BL7: -1.44976 | BM7: 0.000114197 | BN7: 0.000131336 | BO7: 0.00107412 | BP7: -8.52131 | BQ7: -14.4079 | BR7: -0.071984 | BS7: 0.00316228 | BT7: -0.00246088 | BU7: -0.00207046 | BV7: =BP7+BS7 -> -8.5181477 | BW7: =BQ7+BT7 -> -14.410361 | BX7: 3.17528e-05 | BY7: 0.00025477 | BZ7: 2.48696e-05 | CA7: 0.000257775 | CB7: 2.87482e-05 | CC7: 1.46113 | CD7: 0.000106958 | CE7: 0.000112679 | CF7: 0.00100965 | CG7: -2091.08 | CH7: -2091.08 | CI7: -0.1991 | CJ7: -99.3996 | CK7: -2.16883e-05 | CL7: =R7-AI7 -> 35.8012 | CM7: =((W7-AN7)^2+(X7-AO7)^2)^0.5 -> 35.801002 | CN7: =(CM7-CL7)/CL7 -> -5.5310849e-06 | CO7: =(X7-AO7)/CM7 -> 0.99998248 | CP7: =ACOS(CO7) -> 0.0059188403 | CQ7: =(AN7-W7)/CM7 -> 0.0059188057 | CR7: =CJ7*CO7 -> -99.397859 | CS7: =-CR7/D$2/A$2 -> 0.24163304 | CT7: =H7*CO7^2+I7*CQ7^2+2*J7*CO7*CQ7 -> -5.5106202e-05 | CU7: =H7*CQ7^2+I7*CO7^2-2*J7*CO7*CQ7 -> -1.4948798e-05 | CV7: =2*((I7-H7)*CO7*CQ7+J7*(CO7^2-CQ7^2)) -> 3.7796208e-05 | CW7: =CT7*K$2^2+CU7*J$2^2+J$2*K$2*CV7 -> -8.5588362e-06 | CX7: =CT7*J$2^2+CU7*K$2^2-J$2*K$2*CV7 -> -6.1496164e-05 | CY7: =(2*(CU7-CT7)*J$2*K$2+CV7*(K$2^2-J$2^2)) -> -1.5453472e-05 | CZ7: =-CY7 -> 1.5453472e-05 | DA7: =-CK7*CL7 -> 0.00077646717 | DB7: =G$2*DA7/CL7 -> 9.5573109e-05 | DC7: =BP7-Q7 -> -8.4786673 | DD7: =BQ7-R7 -> -32.2307 | DE7: =(DC7^2+DD7^2)^0.5 -> 33.327253 | DF7: =AH7-AY7 -> -8.32291 | DG7: =AI7-AZ7 -> -33.1108 | DH7: =(DF7^2+DG7^2)^0.5 -> 34.140825 | DI7: =(DC7*DF7+DD7*DG7)/DE7/DH7 -> 0.99993982 | DJ7: =BV7-W7 -> -8.4745413 | DK7: =BW7-X7 -> -32.231561 | DL7: =(DJ7^2+DK7^2)^0.5 -> 33.327037 | DM7: =AN7-BE7 -> -8.3161691 | DN7: =AO7-BF7 -> -33.111407 | DO7: =(DM7^2+DN7^2)^0.5 -> 34.139771 | DP7: =(DJ7*DM7+DK7*DN7)/DL7/DO7 -> 0.99993906 | DQ7: =(DJ7*DC7+DK7*DD7)/DE7/DL7 -> 0.99999999 | DR7: =(DM7*DF7+DN7*DG7)/DH7/DO7 -> 0.99999998 | DS7: =DJ7/DL7 -> -0.25428427 | DT7: =DK7/DL7 -> -0.96712952 | DU7: =DS7^2*H7+DT7^2*I7+2*DS7*DT7*J7 -> -8.1743361e-06 | DV7: =DT7^2*H7+DS7^2*I7-2*DS7*DT7*J7 -> -6.1880664e-05 | DW7: =2*((I7-H7)*DS7*DT7+(DS7^2-DT7^2)*J7) -> -1.2522013e-05 | DX7: =-DW7 -> 1.2522013e-05 | DZ7: =Q7-AY7 -> -8.5295327 | EA7: =R7-AZ7 -> 2.6904 | EB7: =(DZ7*DF7+EA7*DG7)/(DZ7^2+EA7^2)^0.5/(DF7^2+DG7^2)^0.5 -> -0.059246382 | EC7: =(DZ7^2+EA7^2)^0.5 -> 8.9437789 | ED7: =EC7*(1-EB7^2)^0.5 -> 8.9280681 | EE7: =W7-BE7 -> -8.5280683 | EF7: =X7-BF7 -> 2.6889678 | EG7: =EE7-DZ7 -> 0.001464414 | EH7: =EF7-EA7 -> -0.001432161 | EI7: =(EG7^2+EH7^2)^0.5 -> 0.0020483148 | EJ7: =EI7/ED7 -> 0.00022942419
A8: 3 | B8: 0.00422635 | C8: 0.00853024 | D8: 8.51092e-05 | E8: 0.00604534 | F8: -0.00682197 | G8: -0.00355009 | H8: -0.00018315 | I8: -8.16554e-05 | J8: 3.2923e-05 | K8: -3.28914e-05 | L8: -0.000231914 | M8: 0.467935 | N8: 0.000104189 | O8: 0.000111056 | P8: 0.00097883 | Q8: -0.0426427 | R8: 17.8228 | S8: -0.0203832 | T8: 0.00271406 | U8: -0.0074638 | V8: 0.00192936 | W8: =Q8+T8 -> -0.03992864 | X8: =R8+U8 -> 17.815336 | Y8: -0.000271597 | Z8: 0.000234266 | AA8: 6.37193e-05 | AB8: 0.000242205 | AC8: -0.000279536 | AD8: 1.44714 | AE8: 0.000106747 | AF8: 0.000125178 | AG8: 0.000998993 | AH8: 0.16398 | AI8: -17.9784 | AJ8: 0.0178449 | AK8: 0.0100127 | AL8: -0.0046015 | AM8: -0.0068754 | AN8: =AH8+AK8 -> 0.1739927 | AO8: =AI8+AL8 -> -17.983002 | AP8: -0.000243134 | AQ8: -0.00017698 | AR8: 0.000117657 | AS8: -8.75107e-05 | AT8: -0.000332603 | AU8: 0.921537 | AV8: 0.000114475 | AW8: 0.000109928 | AX8: 0.0010785 | AY8: 8.48689 | AZ8: 15.1324 | BA8: -0.107245 | BB8: 0.00186836 | BC8: -0.00620668 | BD8: 0.00375484 | BE8: =AY8+BB8 -> 8.4887584 | BF8: =AZ8+BC8 -> 15.126193 | BG8: -0.000284346 | BH8: -4.46619e-05 | BI8: -0.00015936 | BJ8: 3.48936e-05 | BK8: -0.000363901 | BL8: -1.10764 | BM8: 0.000111104 | BN8: 0.000127835 | BO8: 0.00104527 | BP8: -8.52131 | BQ8: -14.4079 | BR8: -0.071984 | BS8: 0.0103603 | BT8: -0.00776595 | BU8: -0.0208214 | BV8: =BP8+BS8 -> -8.5109497 | BW8: =BQ8+BT8 -> -14.415666 | BX8: -7.03437e-07 | BY8: -0.000174497 | BZ8: -1.46199e-05 | CA8: 1.48679e-06 | CB8: -0.000176688 | CC8: -0.0803501 | CD8: 0.000104737 | CE8: 0.000109981 | CF8: 0.000985661 | CG8: -2090.58 | CH8: -2090.58 | CI8: -0.203 | CJ8: -101.339 | CK8: -7.89667e-05 | CL8: =R8-AI8 -> 35.8012 | CM8: =((W8-AN8)^2+(X8-AO8)^2)^0.5 -> 35.798977 | CN8: =(CM8-CL8)/CL8 -> -6.2096723e-05 | CO8: =(X8-AO8)/CM8 -> 0.99998215 | CP8: =ACOS(CO8) -> 0.0059756628 | CQ8: =(AN8-W8)/CM8 -> 0.0059756272 | CR8: =CJ8*CO8 -> -101.33719 | CS8: =-CR8/D$2/A$2 -> 0.24634749 | CT8: =H8*CO8^2+I8*CQ8^2+2*J8*CO8*CQ8 -> -0.00018275291 | CU8: =H8*CQ8^2+I8*CO8^2-2*J8*CO8*CQ8 -> -8.2052488e-05 | CV8: =2*((I8-H8)*CO8*CQ8+J8*(CO8^2-CQ8^2)) -> 6.7054264e-05 | CW8: =CT8*K$2^2+CU8*J$2^2+J$2*K$2*CV8 -> -7.2320379e-05 | CX8: =CT8*J$2^2+CU8*K$2^2-J$2*K$2*CV8 -> -0.00019248502 | CY8: =(2*(CU8-CT8)*J$2*K$2+CV8*(K$2^2-J$2^2)) -> -1.4046648e-05 | CZ8: =-CY8 -> 1.4046648e-05 | DA8: =-CK8*CL8 -> 0.0028271026 | DB8: =G$2*DA8/CL8 -> 0.00034797992 | DC8: =BP8-Q8 -> -8.4786673 | DD8: =BQ8-R8 -> -32.2307 | DE8: =(DC8^2+DD8^2)^0.5 -> 33.327253 | DF8: =AH8-AY8 -> -8.32291 | DG8: =AI8-AZ8 -> -33.1108 | DH8: =(DF8^2+DG8^2)^0.5 -> 34.140825 | DI8: =(DC8*DF8+DD8*DG8)/DE8/DH8 -> 0.99993982 | DJ8: =BV8-W8 -> -8.4710211 | DK8: =BW8-X8 -> -32.231002 | DL8: =(DJ8^2+DK8^2)^0.5 -> 33.325601 | DM8: =AN8-BE8 -> -8.3147657 | DN8: =AO8-BF8 -> -33.109195 | DO8: =(DM8^2+DN8^2)^0.5 -> 34.137283 | DP8: =(DJ8*DM8+DK8*DN8)/DL8/DO8 -> 0.99993987 | DQ8: =(DJ8*DC8+DK8*DD8)/DE8/DL8 -> 0.99999997 | DR8: =(DM8*DF8+DN8*DG8)/DH8/DO8 -> 0.99999998 | DS8: =DJ8/DL8 -> -0.25418959 | DT8: =DK8/DL8 -> -0.96715441 | DU8: =DS8^2*H8+DT8^2*I8+2*DS8*DT8*J8 -> -7.2025585e-05 | DV8: =DT8^2*H8+DS8^2*I8-2*DS8*DT8*J8 -> -0.00019277981 | DW8: =2*((I8-H8)*DS8*DT8+(DS8^2-DT8^2)*J8) -> -7.4340864e-06 | DX8: =-DW8 -> 7.4340864e-06 | DZ8: =Q8-AY8 -> -8.5295327 | EA8: =R8-AZ8 -> 2.6904 | EB8: =(DZ8*DF8+EA8*DG8)/(DZ8^2+EA8^2)^0.5/(DF8^2+DG8^2)^0.5 -> -0.059246382 | EC8: =(DZ8^2+EA8^2)^0.5 -> 8.9437789 | ED8: =EC8*(1-EB8^2)^0.5 -> 8.9280681 | EE8: =W8-BE8 -> -8.528687 | EF8: =X8-BF8 -> 2.6891429 | EG8: =EE8-DZ8 -> 0.0008457 | EH8: =EF8-EA8 -> -0.00125712 | EI8: =(EG8^2+EH8^2)^0.5 -> 0.0015151103 | EJ8: =EI8/ED8 -> 0.00016970192
A9: 4 | B9: 0.00422635 | C9: 0.00853024 | D9: 8.51092e-05 | E9: 0.00446163 | F9: -0.00596019 | G9: 0.00758031 | H9: -0.000151506 | I9: -0.000136954 | J9: 5.159e-05 | K9: -4.96442e-05 | L9: -0.000238816 | M9: 0.468373 | N9: 0.000103502 | O9: 0.000110213 | P9: 0.000971493 | Q9: -0.0426427 | R9: 17.8228 | S9: -0.0203832 | T9: 0.00062325 | U9: -0.0081627 | V9: 0.0126088 | W9: =Q9+T9 -> -0.04201945 | X9: =R9+U9 -> 17.814637 | Y9: -0.00028253 | Z9: -5.45562e-05 | AA9: 5.70023e-05 | AB9: -4.0903e-05 | AC9: -0.000296183 | AD9: 1.34075 | AE9: 0.000108204 | AF9: 0.000126625 | AG9: 0.0010105 | AH9: 0.16398 | AI9: -17.9784 | AJ9: 0.0178449 | AK9: 0.00739728 | AL9: -0.00286612 | AM9: -0.000778047 | AN9: =AH9+AK9 -> 0.17137728 | AO9: =AI9+AL9 -> -17.981266 | AP9: -0.000146077 | AQ9: -5.23171e-05 | AR9: 0.00023786 | AS9: 0.000143288 | AT9: -0.000341682 | AU9: 0.8827 | AV9: 0.000112181 | AW9: 0.000108107 | AX9: 0.00106034 | AY9: 8.48689 | AZ9: 15.1324 | BA9: -0.107245 | BB9: 4.2941e-05 | BC9: -0.00653347 | BD9: 0.0154435 | BE9: =AY9+BB9 -> 8.4869329 | BF9: =AZ9+BC9 -> 15.125867 | BG9: -0.000205002 | BH9: -0.000151158 | BI9: -4.92858e-05 | BJ9: -0.000121133 | BK9: -0.000235027 | BL9: -1.03602 | BM9: 0.000112022 | BN9: 0.00012886 | BO9: 0.00105374 | BP9: -8.52131 | BQ9: -14.4079 | BR9: -0.071984 | BS9: 0.00878857 | BT9: -0.006917 | BU9: -0.0101773 | BV9: =BP9+BS9 -> -8.5125214 | BW9: =BQ9+BT9 -> -14.414817 | BX9: -0.000310907 | BY9: -0.000144807 | BZ9: 7.60767e-05 | CA9: -0.000115043 | CB9: -0.000340671 | CC9: 1.20164 | CD9: 0.000109262 | CE9: 0.000114607 | CF9: 0.00102699 | CG9: -2090.46 | CH9: -2090.46 | CI9: -0.2095 | CJ9: -104.572 | CK9: -0.000146847 | CL9: =R9-AI9 -> 35.8012 | CM9: =((W9-AN9)^2+(X9-AO9)^2)^0.5 -> 35.796539 | CN9: =(CM9-CL9)/CL9 -> -0.00013017734 | CO9: =(X9-AO9)/CM9 -> 0.99998223 | CP9: =ACOS(CO9) -> 0.0059614141 | CQ9: =(AN9-W9)/CM9 -> 0.0059613788 | CR9: =CJ9*CO9 -> -104.57014 | CS9: =-CR9/D$2/A$2 -> 0.2542067 | CT9: =H9*CO9^2+I9*CQ9^2+2*J9*CO9*CQ9 -> -0.0001508904 | CU9: =H9*CQ9^2+I9*CO9^2-2*J9*CO9*CQ9 -> -0.0001375696 | CV9: =2*((I9-H9)*CO9*CQ9+J9*(CO9^2-CQ9^2)) -> 0.00010334616 | CW9: =CT9*K$2^2+CU9*J$2^2+J$2*K$2*CV9 -> -0.00011484286 | CX9: =CT9*J$2^2+CU9*K$2^2-J$2*K$2*CV9 -> -0.00017361714 | CY9: =(2*(CU9-CT9)*J$2*K$2+CV9*(K$2^2-J$2^2)) -> -8.6043345e-05 | CZ9: =-CY9 -> 8.6043345e-05 | DA9: =-CK9*CL9 -> 0.0052572988 | DB9: =G$2*DA9/CL9 -> 0.00064710578 | DC9: =BP9-Q9 -> -8.4786673 | DD9: =BQ9-R9 -> -32.2307 | DE9: =(DC9^2+DD9^2)^0.5 -> 33.327253 | DF9: =AH9-AY9 -> -8.32291 | DG9: =AI9-AZ9 -> -33.1108 | DH9: =(DF9^2+DG9^2)^0.5 -> 34.140825 | DI9: =(DC9*DF9+DD9*DG9)/DE9/DH9 -> 0.99993982 | DJ9: =BV9-W9 -> -8.470502 | DK9: =BW9-X9 -> -32.229454 | DL9: =(DJ9^2+DK9^2)^0.5 -> 33.323972 | DM9: =AN9-BE9 -> -8.3155557 | DN9: =AO9-BF9 -> -33.107133 | DO9: =(DM9^2+DN9^2)^0.5 -> 34.135476 | DP9: =(DJ9*DM9+DK9*DN9)/DL9/DO9 -> 0.99994031 | DQ9: =(DJ9*DC9+DK9*DD9)/DE9/DL9 -> 0.99999997 | DR9: =(DM9*DF9+DN9*DG9)/DH9/DO9 -> 0.99999998 | DS9: =DJ9/DL9 -> -0.25418644 | DT9: =DK9/DL9 -> -0.96715524 | DU9: =DS9^2*H9+DT9^2*I9+2*DS9*DT9*J9 -> -0.00011252868 | DV9: =DT9^2*H9+DS9^2*I9-2*DS9*DT9*J9 -> -0.00017593132 | DW9: =2*((I9-H9)*DS9*DT9+(DS9^2-DT9^2)*J9) -> -8.2692064e-05 | DX9: =-DW9 -> 8.2692064e-05 | DZ9: =Q9-AY9 -> -8.5295327 | EA9: =R9-AZ9 -> 2.6904 | EB9: =(DZ9*DF9+EA9*DG9)/(DZ9^2+EA9^2)^0.5/(DF9^2+DG9^2)^0.5 -> -0.059246382 | EC9: =(DZ9^2+EA9^2)^0.5 -> 8.9437789 | ED9: =EC9*(1-EB9^2)^0.5 -> 8.9280681 | EE9: =W9-BE9 -> -8.5289524 | EF9: =X9-BF9 -> 2.6887708 | EG9: =EE9-DZ9 -> 0.000580309 | EH9: =EF9-EA9 -> -0.00162923 | EI9: =(EG9^2+EH9^2)^0.5 -> 0.0017294938 | EJ9: =EI9/ED9 -> 0.00019371423
A10: 5 | B10: 0.00422635 | C10: 0.00853024 | D10: 8.51092e-05 | E10: 0.00502183 | F10: -0.00674605 | G10: -0.0182532 | H10: -1.95807e-05 | I10: -3.28198e-05 | J10: 2.93529e-05 | K10: 5.82508e-05 | L10: -0.000110651 | M10: 0.283082 | N10: 0.000103127 | O10: 0.000109854 | P10: 0.000968522 | Q10: -0.0426427 | R10: 17.8228 | S10: -0.0203832 | T10: 0.00131963 | U10: -0.00806513 | V10: -0.0229808 | W10: =Q10+T10 -> -0.04132307 | X10: =R10+U10 -> 17.814735 | Y10: -0.000180012 | Z10: 0.000355076 | AA10: 0.000189328 | AB10: 0.000415485 | AC10: -0.000240421 | AD10: 1.26258 | AE10: 0.00010207 | AF10: 0.000120137 | AG10: 0.000958732 | AH10: 0.16398 | AI10: -17.9784 | AJ10: 0.0178449 | AK10: 0.00872463 | AL10: -0.0060444 | AM10: -0.0138085 | AN10: =AH10+AK10 -> 0.17270463 | AO10: =AI10+AL10 -> -17.984444 | AP10: -0.000154116 | AQ10: -0.000158062 | AR10: 0.000120668 | AS10: -3.50928e-05 | AT10: -0.000277086 | AU10: 0.776137 | AV10: 0.000118142 | AW10: 0.000113412 | AX10: 0.00111276 | AY10: 8.48689 | AZ10: 15.1324 | BA10: -0.107245 | BB10: 0.00183867 | BC10: -0.00555405 | BD10: -0.0196013 | BE10: =AY10+BB10 -> 8.4887287 | BF10: =AZ10+BC10 -> 15.126846 | BG10: -2.41595e-05 | BH10: 9.16136e-05 | BI10: -0.00010146 | BJ10: 0.00015071 | BK10: -8.32558e-05 | BL10: -1.0432 | BM10: 0.000110734 | BN10: 0.000127385 | BO10: 0.00104169 | BP10: -8.52131 | BQ10: -14.4079 | BR10: -0.071984 | BS10: 0.00886278 | BT10: -0.00922082 | BU10: -0.022856 | BV10: =BP10+BS10 -> -8.5124472 | BW10: =BQ10+BT10 -> -14.417121 | BX10: -0.00012482 | BY10: 8.67948e-05 | BZ10: 2.59892e-05 | CA10: 8.99562e-05 | CB10: -0.000127981 | CC10: 1.45022 | CD10: 0.000105657 | CE10: 0.000109923 | CF10: 0.000985777 | CG10: -2090.15 | CH10: -2090.15 | CI10: -0.2111 | CJ10: -105.38 | CK10: -5.49272e-05 | CL10: =R10-AI10 -> 35.8012 | CM10: =((W10-AN10)^2+(X10-AO10)^2)^0.5 -> 35.799819 | CN10: =(CM10-CL10)/CL10 -> -3.8572632e-05 | CO10: =(X10-AO10)/CM10 -> 0.99998213 | CP10: =ACOS(CO10) -> 0.0059784932 | CQ10: =(AN10-W10)/CM10 -> 0.0059784576 | CR10: =CJ10*CO10 -> -105.37812 | CS10: =-CR10/D$2/A$2 -> 0.25617086 | CT10: =H10*CO10^2+I10*CQ10^2+2*J10*CO10*CQ10 -> -1.9230209e-05 | CU10: =H10*CQ10^2+I10*CO10^2-2*J10*CO10*CQ10 -> -3.3170291e-05 | CV10: =2*((I10-H10)*CO10*CQ10+J10*(CO10^2-CQ10^2)) -> 5.8543308e-05 | CW10: =CT10*K$2^2+CU10*J$2^2+J$2*K$2*CV10 -> -1.9125905e-05 | CX10: =CT10*J$2^2+CU10*K$2^2-J$2*K$2*CV10 -> -3.3274595e-05 | CY10: =(2*(CU10-CT10)*J$2*K$2+CV10*(K$2^2-J$2^2)) -> -5.8493241e-05 | CZ10: =-CY10 -> 5.8493241e-05 | DA10: =-CK10*CL10 -> 0.0019664597 | DB10: =G$2*DA10/CL10 -> 0.00024204586 | DC10: =BP10-Q10 -> -8.4786673 | DD10: =BQ10-R10 -> -32.2307 | DE10: =(DC10^2+DD10^2)^0.5 -> 33.327253 | DF10: =AH10-AY10 -> -8.32291 | DG10: =AI10-AZ10 -> -33.1108 | DH10: =(DF10^2+DG10^2)^0.5 -> 34.140825 | DI10: =(DC10*DF10+DD10*DG10)/DE10/DH10 -> 0.99993982 | DJ10: =BV10-W10 -> -8.4711241 | DK10: =BW10-X10 -> -32.231856 | DL10: =(DJ10^2+DK10^2)^0.5 -> 33.326453 | DM10: =AN10-BE10 -> -8.316024 | DN10: =AO10-BF10 -> -33.11129 | DO10: =(DM10^2+DN10^2)^0.5 -> 34.139622 | DP10: =(DJ10*DM10+DK10*DN10)/DL10/DO10 -> 0.99994014 | DQ10: =(DJ10*DC10+DK10*DD10)/DE10/DL10 -> 0.99999997 | DR10: =(DM10*DF10+DN10*DG10)/DH10/DO10 -> 0.99999998 | DS10: =DJ10/DL10 -> -0.25418619 | DT10: =DK10/DL10 -> -0.9671553 | DU10: =DS10^2*H10+DT10^2*I10+2*DS10*DT10*J10 -> -1.7532325e-05 | DV10: =DT10^2*H10+DS10^2*I10-2*DS10*DT10*J10 -> -3.4868175e-05 | DW10: =2*((I10-H10)*DS10*DT10+(DS10^2-DT10^2)*J10) -> -5.7629099e-05 | DX10: =-DW10 -> 5.7629099e-05 | DZ10: =Q10-AY10 -> -8.5295327 | EA10: =R10-AZ10 -> 2.6904 | EB10: =(DZ10*DF10+EA10*DG10)/(DZ10^2+EA10^2)^0.5/(DF10^2+DG10^2)^0.5 -> -0.059246382 | EC10: =(DZ10^2+EA10^2)^0.5 -> 8.9437789 | ED10: =EC10*(1-EB10^2)^0.5 -> 8.9280681 | EE10: =W10-BE10 -> -8.5300517 | EF10: =X10-BF10 -> 2.6878889 | EG10: =EE10-DZ10 -> -0.00051904 | EH10: =EF10-EA10 -> -0.00251108 | EI10: =(EG10^2+EH10^2)^0.5 -> 0.0025641617 | EJ10: =EI10/ED10 -> 0.0002872023
A11: 6 | B11: 0.00422635 | C11: 0.00853024 | D11: 8.51092e-05 | E11: 0.00601905 | F11: -0.00834383 | G11: 0.0115619 | H11: -9.46244e-05 | I11: -0.000114711 | J11: 6.02832e-05 | K11: -1.52069e-05 | L11: -0.000194128 | M11: 0.630422 | N11: 0.000105757 | O11: 0.000112543 | P11: 0.00099171 | Q11: -0.0426427 | R11: 17.8228 | S11: -0.0203832 | T11: 0.00160933 | U11: -0.0100077 | V11: 0.0124275 | W11: =Q11+T11 -> -0.04103337 | X11: =R11+U11 -> 17.812792 | Y11: -9.60365e-05 | Z11: 0.000100886 | AA11: 7.56648e-05 | AB11: 0.000126697 | AC11: -0.000121848 | AD11: 1.24349 | AE11: 0.000108123 | AF11: 0.000126539 | AG11: 0.00100984 | AH11: 0.16398 | AI11: -17.9784 | AJ11: 0.0178449 | AK11: 0.010203 | AL11: -0.00536926 | AM11: 0.0142575 | AN11: =AH11+AK11 -> 0.174183 | AO11: =AI11+AL11 -> -17.983769 | AP11: -0.000133706 | AQ11: -0.00030079 | AR11: 0.000162544 | AS11: -3.42571e-05 | AT11: -0.000400239 | AU11: 0.547557 | AV11: 0.000118429 | AW11: 0.0001139 | AX11: 0.00111728 | AY11: 8.48689 | AZ11: 15.1324 | BA11: -0.107245 | BB11: 0.000711442 | BC11: -0.0071623 | BD11: 0.0160916 | BE11: =AY11+BB11 -> 8.4876014 | BF11: =AZ11+BC11 -> 15.125238 | BG11: -0.000506914 | BH11: -0.000127587 | BI11: 7.09224e-05 | BJ11: -0.000114734 | BK11: -0.000519767 | BL11: 1.3911 | BM11: 0.000116216 | BN11: 0.000133642 | BO11: 0.00109311 | BP11: -8.52131 | BQ11: -14.4079 | BR11: -0.071984 | BS11: 0.0104511 | BT11: -0.00984055 | BU11: 0.00453579 | BV11: =BP11+BS11 -> -8.5108589 | BW11: =BQ11+BT11 -> -14.417741 | BX11: -0.000159388 | BY11: -0.000147057 | BZ11: 1.47619e-05 | CA11: -0.000136892 | CB11: -0.000169554 | CC11: 0.954893 | CD11: 0.000109247 | CE11: 0.000114524 | CF11: 0.00102631 | CG11: -2089.46 | CH11: -2089.46 | CI11: -0.2172 | CJ11: -108.451 | CK11: -0.000127421 | CL11: =R11-AI11 -> 35.8012 | CM11: =((W11-AN11)^2+(X11-AO11)^2)^0.5 -> 35.797209 | CN11: =(CM11-CL11)/CL11 -> -0.0001114902 | CO11: =(X11-AO11)/CM11 -> 0.99998193 | CP11: =ACOS(CO11) -> 0.0060121355 | CQ11: =(AN11-W11)/CM11 -> 0.0060120992 | CR11: =CJ11*CO11 -> -108.44904 | CS11: =-CR11/D$2/A$2 -> 0.26363617 | CT11: =H11*CO11^2+I11*CQ11^2+2*J11*CO11*CQ11 -> -9.3900282e-05 | CU11: =H11*CQ11^2+I11*CO11^2-2*J11*CO11*CQ11 -> -0.00011543512 | CV11: =2*((I11-H11)*CO11*CQ11+J11*(CO11^2-CQ11^2)) -> 0.00012031616 | CW11: =CT11*K$2^2+CU11*J$2^2+J$2*K$2*CV11 -> -8.6959054e-05 | CX11: =CT11*J$2^2+CU11*K$2^2-J$2*K$2*CV11 -> -0.00012237635 | CY11: =(2*(CU11-CT11)*J$2*K$2+CV11*(K$2^2-J$2^2)) -> -0.00011698437 | CZ11: =-CY11 -> 0.00011698437 | DA11: =-CK11*CL11 -> 0.0045618247 | DB11: =G$2*DA11/CL11 -> 0.00056150187 | DC11: =BP11-Q11 -> -8.4786673 | DD11: =BQ11-R11 -> -32.2307 | DE11: =(DC11^2+DD11^2)^0.5 -> 33.327253 | DF11: =AH11-AY11 -> -8.32291 | DG11: =AI11-AZ11 -> -33.1108 | DH11: =(DF11^2+DG11^2)^0.5 -> 34.140825 | DI11: =(DC11*DF11+DD11*DG11)/DE11/DH11 -> 0.99993982 | DJ11: =BV11-W11 -> -8.4698255 | DK11: =BW11-X11 -> -32.230533 | DL11: =(DJ11^2+DK11^2)^0.5 -> 33.324843 | DM11: =AN11-BE11 -> -8.3134184 | DN11: =AO11-BF11 -> -33.109007 | DO11: =(DM11^2+DN11^2)^0.5 -> 34.136773 | DP11: =(DJ11*DM11+DK11*DN11)/DL11/DO11 -> 0.99993981 | DQ11: =(DJ11*DC11+DK11*DD11)/DE11/DL11 -> 0.99999997 | DR11: =(DM11*DF11+DN11*DG11)/DH11/DO11 -> 0.99999997 | DS11: =DJ11/DL11 -> -0.2541595 | DT11: =DK11/DL11 -> -0.96716232 | DU11: =DS11^2*H11+DT11^2*I11+2*DS11*DT11*J11 -> -8.3776617e-05 | DV11: =DT11^2*H11+DS11^2*I11-2*DS11*DT11*J11 -> -0.00012555878 | DW11: =2*((I11-H11)*DS11*DT11+(DS11^2-DT11^2)*J11) -> -0.00011486505 | DX11: =-DW11 -> 0.00011486505 | DZ11: =Q11-AY11 -> -8.5295327 | EA11: =R11-AZ11 -> 2.6904 | EB11: =(DZ11*DF11+EA11*DG11)/(DZ11^2+EA11^2)^0.5/(DF11^2+DG11^2)^0.5 -> -0.059246382 | EC11: =(DZ11^2+EA11^2)^0.5 -> 8.9437789 | ED11: =EC11*(1-EB11^2)^0.5 -> 8.9280681 | EE11: =W11-BE11 -> -8.5286348 | EF11: =X11-BF11 -> 2.6875546 | EG11: =EE11-DZ11 -> 0.000897888 | EH11: =EF11-EA11 -> -0.0028454 | EI11: =(EG11^2+EH11^2)^0.5 -> 0.0029837064 | EJ11: =EI11/ED11 -> 0.00033419396
A12: 7 | B12: 0.00422635 | C12: 0.00853024 | D12: 8.51092e-05 | E12: 0.00330109 | F12: -0.00840234 | G12: 0.0228119 | H12: 4.32019e-05 | I12: -3.69059e-05 | J12: 3.5743e-05 | K12: 9.86555e-05 | L12: -9.23595e-05 | M12: 0.175728 | N12: 0.000104433 | O12: 0.00011115 | P12: 0.000979705 | Q12: -0.0426427 | R12: 17.8228 | S12: -0.0203832 | T12: -0.00277532 | U12: -0.00939524 | V12: 0.0221239 | W12: =Q12+T12 -> -0.04541802 | X12: =R12+U12 -> 17.813405 | Y12: -0.000125994 | Z12: 0.000395738 | AA12: -1.99215e-06 | AB12: 0.000395761 | AC12: -0.000126017 | AD12: -0.866121 | AE12: 0.000103657 | AF12: 0.000121846 | AG12: 0.000972381 | AH12: 0.16398 | AI12: -17.9784 | AJ12: 0.0178449 | AK12: 0.00884646 | AL12: -0.00746389 | AM12: 0.0204728 | AN12: =AH12+AK12 -> 0.17282646 | AO12: =AI12+AL12 -> -17.985864 | AP12: 4.5725e-05 | AQ12: -0.000159848 | AR12: 0.000222816 | AS12: 0.000188714 | AT12: -0.000302836 | AU12: 0.569001 | AV12: 0.000118904 | AW12: 0.000114212 | AX12: 0.00112041 | AY12: 8.48689 | AZ12: 15.1324 | BA12: -0.107245 | BB12: -0.00225988 | BC12: -0.00645975 | BD12: 0.0252374 | BE12: =AY12+BB12 -> 8.4846301 | BF12: =AZ12+BC12 -> 15.12594 | BG12: -0.000183631 | BH12: -6.35954e-06 | BI12: -0.000144591 | BJ12: 7.46169e-05 | BK12: -0.000264607 | BL12: -1.06052 | BM12: 0.000112181 | BN12: 0.00012886 | BO12: 0.00105471 | BP12: -8.52131 | BQ12: -14.4079 | BR12: -0.071984 | BS12: 0.00673243 | BT12: -0.0116907 | BU12: 0.0188905 | BV12: =BP12+BS12 -> -8.5145776 | BW12: =BQ12+BT12 -> -14.419591 | BX12: 0.000159108 | BY12: 5.89082e-05 | BZ12: 1.66271e-05 | CA12: 0.000162519 | CB12: 5.54976e-05 | CC12: 0.149996 | CD12: 0.000108902 | CE12: 0.000114611 | CF12: 0.00102678 | CG12: -2088.77 | CH12: -2088.77 | CI12: -0.2259 | CJ12: -112.815 | CK12: -5.34305e-05 | CL12: =R12-AI12 -> 35.8012 | CM12: =((W12-AN12)^2+(X12-AO12)^2)^0.5 -> 35.799934 | CN12: =(CM12-CL12)/CL12 -> -3.5365016e-05 | CO12: =(X12-AO12)/CM12 -> 0.99998142 | CP12: =ACOS(CO12) -> 0.0060962635 | CQ12: =(AN12-W12)/CM12 -> 0.0060962258 | CR12: =CJ12*CO12 -> -112.8129 | CS12: =-CR12/D$2/A$2 -> 0.27424459 | CT12: =H12*CO12^2+I12*CQ12^2+2*J12*CO12*CQ12 -> 4.363471e-05 | CU12: =H12*CQ12^2+I12*CO12^2-2*J12*CO12*CQ12 -> -3.733871e-05 | CV12: =2*((I12-H12)*CO12*CQ12+J12*(CO12^2-CQ12^2)) -> 7.0503994e-05 | CW12: =CT12*K$2^2+CU12*J$2^2+J$2*K$2*CV12 -> -1.6929266e-05 | CX12: =CT12*J$2^2+CU12*K$2^2-J$2*K$2*CV12 -> 2.3225266e-05 | CY12: =(2*(CU12-CT12)*J$2*K$2+CV12*(K$2^2-J$2^2)) -> -9.9574703e-05 | CZ12: =-CY12 -> 9.9574703e-05 | DA12: =-CK12*CL12 -> 0.001912876 | DB12: =G$2*DA12/CL12 -> 0.0002354504 | DC12: =BP12-Q12 -> -8.4786673 | DD12: =BQ12-R12 -> -32.2307 | DE12: =(DC12^2+DD12^2)^0.5 -> 33.327253 | DF12: =AH12-AY12 -> -8.32291 | DG12: =AI12-AZ12 -> -33.1108 | DH12: =(DF12^2+DG12^2)^0.5 -> 34.140825 | DI12: =(DC12*DF12+DD12*DG12)/DE12/DH12 -> 0.99993982 | DJ12: =BV12-W12 -> -8.4691596 | DK12: =BW12-X12 -> -32.232995 | DL12: =(DJ12^2+DK12^2)^0.5 -> 33.327056 | DM12: =AN12-BE12 -> -8.3118037 | DN12: =AO12-BF12 -> -33.111804 | DO12: =(DM12^2+DN12^2)^0.5 -> 34.139093 | DP12: =(DJ12*DM12+DK12*DN12)/DL12/DO12 -> 0.9999395 | DQ12: =(DJ12*DC12+DK12*DD12)/DE12/DL12 -> 0.99999996 | DR12: =(DM12*DF12+DN12*DG12)/DH12/DO12 -> 0.99999995 | DS12: =DJ12/DL12 -> -0.25412264 | DT12: =DK12/DL12 -> -0.967172 | DU12: =DS12^2*H12+DT12^2*I12+2*DS12*DT12*J12 -> -1.4162822e-05 | DV12: =DT12^2*H12+DS12^2*I12-2*DS12*DT12*J12 -> 2.0458822e-05 | DW12: =2*((I12-H12)*DS12*DT12+(DS12^2-DT12^2)*J12) -> -0.00010163095 | DX12: =-DW12 -> 0.00010163095 | DZ12: =Q12-AY12 -> -8.5295327 | EA12: =R12-AZ12 -> 2.6904 | EB12: =(DZ12*DF12+EA12*DG12)/(DZ12^2+EA12^2)^0.5/(DF12^2+DG12^2)^0.5 -> -0.059246382 | EC12: =(DZ12^2+EA12^2)^0.5 -> 8.9437789 | ED12: =EC12*(1-EB12^2)^0.5 -> 8.9280681 | EE12: =W12-BE12 -> -8.5300481 | EF12: =X12-BF12 -> 2.6874645 | EG12: =EE12-DZ12 -> -0.00051544 | EH12: =EF12-EA12 -> -0.00293549 | EI12: =(EG12^2+EH12^2)^0.5 -> 0.0029803993 | EJ12: =EI12/ED12 -> 0.00033382354
A13: 8 | B13: 0.00422635 | C13: 0.00853024 | D13: 8.51092e-05 | E13: 0.00610733 | F13: -0.0123885 | G13: -0.0181262 | H13: 8.67893e-05 | I13: -3.55209e-06 | J13: 5.40894e-05 | K13: 0.000147392 | L13: -6.41549e-05 | M13: 0.298408 | N13: 0.000105401 | O13: 0.000112316 | P13: 0.000990116 | Q13: -0.0426427 | R13: 17.8228 | S13: -0.0203832 | T13: 0.000189998 | U13: -0.0128922 | V13: -0.024303 | W13: =Q13+T13 -> -0.042452702 | X13: =R13+U13 -> 17.809908 | Y13: 8.12075e-05 | Z13: 4.34995e-05 | AA13: 5.79418e-05 | AB13: 0.000124685 | AC13: 2.18967e-08 | AD13: 0.627698 | AE13: 0.000105199 | AF13: 0.000123438 | AG13: 0.000985202 | AH13: 0.16398 | AI13: -17.9784 | AJ13: 0.0178449 | AK13: 0.011281 | AL13: -0.0117647 | AM13: -0.00934143 | AN13: =AH13+AK13 -> 0.175261 | AO13: =AI13+AL13 -> -17.990165 | AP13: -8.32861e-05 | AQ13: -0.000111637 | AR13: 0.000201533 | AS13: 0.000104689 | AT13: -0.000299611 | AU13: 0.749588 | AV13: 0.000119688 | AW13: 0.000115158 | AX13: 0.00112952 | AY13: 8.48689 | AZ13: 15.1324 | BA13: -0.107245 | BB13: 0.00133492 | BC13: -0.00976337 | BD13: -0.0274058 | BE13: =AY13+BB13 -> 8.4882249 | BF13: =AZ13+BC13 -> 15.122637 | BG13: -0.000324237 | BH13: 0.00014867 | BI13: -0.000182993 | BJ13: 0.000211268 | BK13: -0.000386836 | BL13: -1.24082 | BM13: 0.000113218 | BN13: 0.000130291 | BO13: 0.00106519 | BP13: -8.52131 | BQ13: -14.4079 | BR13: -0.071984 | BS13: 0.0101381 | BT13: -0.0164732 | BU13: -0.0157951 | BV13: =BP13+BS13 -> -8.5111719 | BW13: =BQ13+BT13 -> -14.424373 | BX13: 1.29558e-05 | BY13: 9.11888e-05 | BZ13: 1.09627e-05 | CA13: 9.33106e-05 | CB13: 1.0834e-05 | CC13: 1.03476 | CD13: 0.000105376 | CE13: 0.000110387 | CF13: 0.000989481 | CG13: -2087.97 | CH13: -2087.97 | CI13: -0.2352 | CJ13: -117.502 | CK13: -2.86784e-05 | CL13: =R13-AI13 -> 35.8012 | CM13: =((W13-AN13)^2+(X13-AO13)^2)^0.5 -> 35.800734 | CN13: =(CM13-CL13)/CL13 -> -1.3002544e-05 | CO13: =(X13-AO13)/CM13 -> 0.99998151 | CP13: =ACOS(CO13) -> 0.006081301 | CQ13: =(AN13-W13)/CM13 -> 0.0060812636 | CR13: =CJ13*CO13 -> -117.49983 | CS13: =-CR13/D$2/A$2 -> 0.28563835 | CT13: =H13*CO13^2+I13*CQ13^2+2*J13*CO13*CQ13 -> 8.7443811e-05 | CU13: =H13*CQ13^2+I13*CO13^2-2*J13*CO13*CQ13 -> -4.2066006e-06 | CV13: =2*((I13-H13)*CO13*CQ13+J13*(CO13^2-CQ13^2)) -> 0.00010707204 | CW13: =CT13*K$2^2+CU13*J$2^2+J$2*K$2*CV13 -> 2.5082689e-05 | CX13: =CT13*J$2^2+CU13*K$2^2-J$2*K$2*CV13 -> 5.8154521e-05 | CY13: =(2*(CU13-CT13)*J$2*K$2+CV13*(K$2^2-J$2^2)) -> -0.00013700538 | CZ13: =-CY13 -> 0.00013700538 | DA13: =-CK13*CL13 -> 0.0010267211 | DB13: =G$2*DA13/CL13 -> 0.00012637615 | DC13: =BP13-Q13 -> -8.4786673 | DD13: =BQ13-R13 -> -32.2307 | DE13: =(DC13^2+DD13^2)^0.5 -> 33.327253 | DF13: =AH13-AY13 -> -8.32291 | DG13: =AI13-AZ13 -> -33.1108 | DH13: =(DF13^2+DG13^2)^0.5 -> 34.140825 | DI13: =(DC13*DF13+DD13*DG13)/DE13/DH13 -> 0.99993982 | DJ13: =BV13-W13 -> -8.4687192 | DK13: =BW13-X13 -> -32.234281 | DL13: =(DJ13^2+DK13^2)^0.5 -> 33.328187 | DM13: =AN13-BE13 -> -8.3129639 | DN13: =AO13-BF13 -> -33.112801 | DO13: =(DM13^2+DN13^2)^0.5 -> 34.140342 | DP13: =(DJ13*DM13+DK13*DN13)/DL13/DO13 -> 0.99994003 | DQ13: =(DJ13*DC13+DK13*DD13)/DE13/DL13 -> 0.99999995 | DR13: =(DM13*DF13+DN13*DG13)/DH13/DO13 -> 0.99999996 | DS13: =DJ13/DL13 -> -0.2541008 | DT13: =DK13/DL13 -> -0.96717774 | DU13: =DS13^2*H13+DT13^2*I13+2*DS13*DT13*J13 -> 2.8867093e-05 | DV13: =DT13^2*H13+DS13^2*I13-2*DS13*DT13*J13 -> 5.4370117e-05 | DW13: =2*((I13-H13)*DS13*DT13+(DS13^2-DT13^2)*J13) -> -0.00013861391 | DX13: =-DW13 -> 0.00013861391 | DZ13: =Q13-AY13 -> -8.5295327 | EA13: =R13-AZ13 -> 2.6904 | EB13: =(DZ13*DF13+EA13*DG13)/(DZ13^2+EA13^2)^0.5/(DF13^2+DG13^2)^0.5 -> -0.059246382 | EC13: =(DZ13^2+EA13^2)^0.5 -> 8.9437789 | ED13: =EC13*(1-EB13^2)^0.5 -> 8.9280681 | EE13: =W13-BE13 -> -8.5306776 | EF13: =X13-BF13 -> 2.6872712 | EG13: =EE13-DZ13 -> -0.001144922 | EH13: =EF13-EA13 -> -0.00312883 | EI13: =(EG13^2+EH13^2)^0.5 -> 0.0033317298 | EJ13: =EI13/ED13 -> 0.00037317477
A14: 9 | B14: 0.00422635 | C14: 0.00853024 | D14: 8.51092e-05 | E14: 0.0033534 | F14: -0.0130856 | G14: 0.0108568 | H14: -6.41582e-05 | I14: -7.12419e-05 | J14: 6.38185e-05 | K14: 2.9933e-05 | L14: -0.000165333 | M14: 0.552492 | N14: 0.000106414 | O14: 0.000113424 | P14: 0.000999911 | Q14: -0.0426427 | R14: 17.8228 | S14: -0.0203832 | T14: -0.00371324 | U14: -0.0146853 | V14: 0.0118939 | W14: =Q14+T14 -> -0.04635594 | X14: =R14+U14 -> 17.808115 | Y14: -2.67143e-05 | Z14: 0.000106995 | AA14: 4.85356e-05 | AB14: 0.000123391 | AC14: -4.31109e-05 | AD14: 1.25425 | AE14: 0.000105809 | AF14: 0.000124588 | AG14: 0.000994371 | AH14: 0.16398 | AI14: -17.9784 | AJ14: 0.0178449 | AK14: 0.0100148 | AL14: -0.0113706 | AM14: 0.00346319 | AN14: =AH14+AK14 -> 0.1739948 | AO14: =AI14+AL14 -> -17.989771 | AP14: -0.000379376 | AQ14: -0.000359269 | AR14: 0.00036576 | AS14: -3.39918e-06 | AT14: -0.000735246 | AU14: 0.799247 | AV14: 0.000123055 | AW14: 0.000118658 | AX14: 0.00116361 | AY14: 8.48689 | AZ14: 15.1324 | BA14: -0.107245 | BB14: -0.00419141 | BC14: -0.0103892 | BD14: 0.0214563 | BE14: =AY14+BB14 -> 8.4826986 | BF14: =AZ14+BC14 -> 15.122011 | BG14: -0.000424514 | BH14: 2.05062e-06 | BI14: -0.000169237 | BJ14: 6.12068e-05 | BK14: -0.00048367 | BL14: -1.23452 | BM14: 0.000115448 | BN14: 0.000132966 | BO14: 0.00108644 | BP14: -8.52131 | BQ14: -14.4079 | BR14: -0.071984 | BS14: 0.00938063 | BT14: -0.0167949 | BU14: -0.000948911 | BV14: =BP14+BS14 -> -8.5119294 | BW14: =BQ14+BT14 -> -14.424695 | BX14: -2.56385e-05 | BY14: 0.000110619 | BZ14: 8.10349e-06 | CA14: 0.000112255 | CB14: -2.72746e-05 | CC14: 1.10005 | CD14: 0.000107134 | CE14: 0.000111582 | CF14: 0.00100065 | CG14: -2087.34 | CH14: -2087.34 | CI14: -0.2443 | CJ14: -122.027 | CK14: -9.08015e-05 | CL14: =R14-AI14 -> 35.8012 | CM14: =((W14-AN14)^2+(X14-AO14)^2)^0.5 -> 35.798563 | CN14: =(CM14-CL14)/CL14 -> -7.3643666e-05 | CO14: =(X14-AO14)/CM14 -> 0.99998106 | CP14: =ACOS(CO14) -> 0.0061553345 | CQ14: =(AN14-W14)/CM14 -> 0.0061552956 | CR14: =CJ14*CO14 -> -122.02469 | CS14: =-CR14/D$2/A$2 -> 0.29663814 | CT14: =H14*CO14^2+I14*CQ14^2+2*J14*CO14*CQ14 -> -6.337284e-05 | CU14: =H14*CQ14^2+I14*CO14^2-2*J14*CO14*CQ14 -> -7.202726e-05 | CV14: =2*((I14-H14)*CO14*CQ14+J14*(CO14^2-CQ14^2)) -> 0.00012754013 | CW14: =CT14*K$2^2+CU14*J$2^2+J$2*K$2*CV14 -> -4.2613375e-05 | CX14: =CT14*J$2^2+CU14*K$2^2-J$2*K$2*CV14 -> -9.2786725e-05 | CY14: =(2*(CU14-CT14)*J$2*K$2+CV14*(K$2^2-J$2^2)) -> -0.00011757558 | CZ14: =-CY14 -> 0.00011757558 | DA14: =-CK14*CL14 -> 0.0032508027 | DB14: =G$2*DA14/CL14 -> 0.00040013194 | DC14: =BP14-Q14 -> -8.4786673 | DD14: =BQ14-R14 -> -32.2307 | DE14: =(DC14^2+DD14^2)^0.5 -> 33.327253 | DF14: =AH14-AY14 -> -8.32291 | DG14: =AI14-AZ14 -> -33.1108 | DH14: =(DF14^2+DG14^2)^0.5 -> 34.140825 | DI14: =(DC14*DF14+DD14*DG14)/DE14/DH14 -> 0.99993982 | DJ14: =BV14-W14 -> -8.4655734 | DK14: =BW14-X14 -> -32.23281 | DL14: =(DJ14^2+DK14^2)^0.5 -> 33.325965 | DM14: =AN14-BE14 -> -8.3087038 | DN14: =AO14-BF14 -> -33.111781 | DO14: =(DM14^2+DN14^2)^0.5 -> 34.138316 | DP14: =(DJ14*DM14+DK14*DN14)/DL14/DO14 -> 0.99993967 | DQ14: =(DJ14*DC14+DK14*DD14)/DE14/DL14 -> 0.99999992 | DR14: =(DM14*DF14+DN14*DG14)/DH14/DO14 -> 0.99999992 | DS14: =DJ14/DL14 -> -0.25402335 | DT14: =DK14/DL14 -> -0.96719808 | DU14: =DS14^2*H14+DT14^2*I14+2*DS14*DT14*J14 -> -3.9425554e-05 | DV14: =DT14^2*H14+DS14^2*I14-2*DS14*DT14*J14 -> -9.5974546e-05 | DW14: =2*((I14-H14)*DS14*DT14+(DS14^2-DT14^2)*J14) -> -0.00011464552 | DX14: =-DW14 -> 0.00011464552 | DZ14: =Q14-AY14 -> -8.5295327 | EA14: =R14-AZ14 -> 2.6904 | EB14: =(DZ14*DF14+EA14*DG14)/(DZ14^2+EA14^2)^0.5/(DF14^2+DG14^2)^0.5 -> -0.059246382 | EC14: =(DZ14^2+EA14^2)^0.5 -> 8.9437789 | ED14: =EC14*(1-EB14^2)^0.5 -> 8.9280681 | EE14: =W14-BE14 -> -8.5290545 | EF14: =X14-BF14 -> 2.6861039 | EG14: =EE14-DZ14 -> 0.00047817 | EH14: =EF14-EA14 -> -0.0042961 | EI14: =(EG14^2+EH14^2)^0.5 -> 0.004322629 | EJ14: =EI14/ED14 -> 0.00048416174
A15: 10 | B15: 0.00422635 | C15: 0.00853024 | D15: 8.51092e-05 | E15: 0.00385724 | F15: -0.0138684 | G15: 0.00883446 | H15: -2.69018e-06 | I15: -7.22729e-05 | J15: 1.70037e-05 | K15: 5.61148e-05 | L15: -0.000131078 | M15: 0.103074 | N15: 0.000105522 | O15: 0.000112366 | P15: 0.000990541 | Q15: -0.0426427 | R15: 17.8228 | S15: -0.0203832 | T15: -0.00469949 | U15: -0.0156974 | V15: 0.0124529 | W15: =Q15+T15 -> -0.04734219 | X15: =R15+U15 -> 17.807103 | Y15: -0.000101909 | Z15: -0.000129734 | AA15: 0.000108388 | AB15: -6.31567e-06 | AC15: -0.000225328 | AD15: 0.722905 | AE15: 0.000106146 | AF15: 0.000124748 | AG15: 0.000995419 | AH15: 0.16398 | AI15: -17.9784 | AJ15: 0.0178449 | AK15: 0.0117684 | AL15: -0.0120783 | AM15: 0.00219783 | AN15: =AH15+AK15 -> 0.1757484 | AO15: =AI15+AL15 -> -17.990478 | AP15: -0.00023694 | AQ15: 8.19155e-05 | AR15: 0.000303765 | AS15: 0.000265571 | AT15: -0.000420596 | AU15: 1.02699 | AV15: 0.000118195 | AW15: 0.000113821 | AX15: 0.0011164 | AY15: 8.48689 | AZ15: 15.1324 | BA15: -0.107245 | BB15: -0.0039836 | BC15: -0.0117838 | BD15: 0.013391 | BE15: =AY15+BB15 -> 8.4829064 | BF15: =AZ15+BC15 -> 15.120616 | BG15: -0.000130962 | BH15: -1.01977e-05 | BI15: -0.000224506 | BJ15: 0.000162405 | BK15: -0.000303565 | BL15: -0.915497 | BM15: 0.000114617 | BN15: 0.000131659 | BO15: 0.00107766 | BP15: -8.52131 | BQ15: -14.4079 | BR15: -0.071984 | BS15: 0.0102282 | BT15: -0.0175199 | BU15: -0.00439541 | BV15: =BP15+BS15 -> -8.5110818 | BW15: =BQ15+BT15 -> -14.42542 | BX15: 0.000178223 | BY15: 0.000126605 | BZ15: 0.000118451 | CA15: 0.000273731 | CB15: 3.10971e-05 | CC15: 0.678031 | CD15: 0.00011098 | CE15: 0.000115916 | CF15: 0.0010393 | CG15: -2086.9 | CH15: -2086.9 | CI15: -0.241 | CJ15: -120.411 | CK15: -9.91797e-05 | CL15: =R15-AI15 -> 35.8012 | CM15: =((W15-AN15)^2+(X15-AO15)^2)^0.5 -> 35.798276 | CN15: =(CM15-CL15)/CL15 -> -8.1672018e-05 | CO15: =(X15-AO15)/CM15 -> 0.99998058 | CP15: =ACOS(CO15) -> 0.0062319212 | CQ15: =(AN15-W15)/CM15 -> 0.0062318808 | CR15: =CJ15*CO15 -> -120.40866 | CS15: =-CR15/D$2/A$2 -> 0.29270963 | CT15: =H15*CO15^2+I15*CQ15^2+2*J15*CO15*CQ15 -> -2.4809564e-06 | CU15: =H15*CQ15^2+I15*CO15^2-2*J15*CO15*CQ15 -> -7.2482124e-05 | CV15: =2*((I15-H15)*CO15*CQ15+J15*(CO15^2-CQ15^2)) -> 3.3137513e-05 | CW15: =CT15*K$2^2+CU15*J$2^2+J$2*K$2*CV15 -> -6.1149795e-05 | CX15: =CT15*J$2^2+CU15*K$2^2-J$2*K$2*CV15 -> -1.3813285e-05 | CY15: =(2*(CU15-CT15)*J$2*K$2+CV15*(K$2^2-J$2^2)) -> -6.1298556e-05 | CZ15: =-CY15 -> 6.1298556e-05 | DA15: =-CK15*CL15 -> 0.0035507523 | DB15: =G$2*DA15/CL15 -> 0.00043705188 | DC15: =BP15-Q15 -> -8.4786673 | DD15: =BQ15-R15 -> -32.2307 | DE15: =(DC15^2+DD15^2)^0.5 -> 33.327253 | DF15: =AH15-AY15 -> -8.32291 | DG15: =AI15-AZ15 -> -33.1108 | DH15: =(DF15^2+DG15^2)^0.5 -> 34.140825 | DI15: =(DC15*DF15+DD15*DG15)/DE15/DH15 -> 0.99993982 | DJ15: =BV15-W15 -> -8.4637396 | DK15: =BW15-X15 -> -32.232523 | DL15: =(DJ15^2+DK15^2)^0.5 -> 33.325222 | DM15: =AN15-BE15 -> -8.307158 | DN15: =AO15-BF15 -> -33.111095 | DO15: =(DM15^2+DN15^2)^0.5 -> 34.137274 | DP15: =(DJ15*DM15+DK15*DN15)/DL15/DO15 -> 0.9999398 | DQ15: =(DJ15*DC15+DK15*DD15)/DE15/DL15 -> 0.9999999 | DR15: =(DM15*DF15+DN15*DG15)/DH15/DO15 -> 0.9999999 | DS15: =DJ15/DL15 -> -0.25397399 | DT15: =DK15/DL15 -> -0.96721105 | DU15: =DS15^2*H15+DT15^2*I15+2*DS15*DT15*J15 -> -5.9430823e-05 | DV15: =DT15^2*H15+DS15^2*I15-2*DS15*DT15*J15 -> -1.5532257e-05 | DW15: =2*((I15-H15)*DS15*DT15+(DS15^2-DT15^2)*J15) -> -6.3805752e-05 | DX15: =-DW15 -> 6.3805752e-05 | DZ15: =Q15-AY15 -> -8.5295327 | EA15: =R15-AZ15 -> 2.6904 | EB15: =(DZ15*DF15+EA15*DG15)/(DZ15^2+EA15^2)^0.5/(DF15^2+DG15^2)^0.5 -> -0.059246382 | EC15: =(DZ15^2+EA15^2)^0.5 -> 8.9437789 | ED15: =EC15*(1-EB15^2)^0.5 -> 8.9280681 | EE15: =W15-BE15 -> -8.5302486 | EF15: =X15-BF15 -> 2.6864864 | EG15: =EE15-DZ15 -> -0.00071589 | EH15: =EF15-EA15 -> -0.0039136 | EI15: =(EG15^2+EH15^2)^0.5 -> 0.0039785379 | EJ15: =EI15/ED15 -> 0.00044562136
A16: 11 | B16: 0.00422635 | C16: 0.00853024 | D16: 8.51092e-05 | E16: 0.00275402 | F16: -0.0190402 | G16: -9.69292e-05 | H16: -9.70012e-06 | I16: -3.55188e-05 | J16: 7.3066e-05 | K16: 7.23308e-05 | L16: -0.00011755 | M16: 0.472858 | N16: 0.000106412 | O16: 0.000113508 | P16: 0.00100086 | Q16: -0.0426427 | R16: 17.8228 | S16: -0.0203832 | T16: -0.00568033 | U16: -0.0200209 | V16: 0.0058375 | W16: =Q16+T16 -> -0.04832303 | X16: =R16+U16 -> 17.802779 | Y16: -0.000221553 | Z16: -9.93911e-05 | AA16: 0.0002187 | AB16: 6.67334e-05 | AC16: -0.000387677 | AD16: 0.921221 | AE16: 0.000109183 | AF16: 0.000128488 | AG16: 0.00102526 | AH16: 0.16398 | AI16: -17.9784 | AJ16: 0.0178449 | AK16: 0.010599 | AL16: -0.0179304 | AM16: -0.00588423 | AN16: =AH16+AK16 -> 0.174579 | AO16: =AI16+AL16 -> -17.99633 | AP16: -8.73953e-05 | AQ16: -0.000178713 | AR16: 0.000241494 | AS16: 0.000112764 | AT16: -0.000378873 | AU16: 0.692224 | AV16: 0.000120705 | AW16: 0.000116106 | AX16: 0.00113896 | AY16: 8.48689 | AZ16: 15.1324 | BA16: -0.107245 | BB16: -0.00485717 | BC16: -0.0149945 | BD16: 0.0101118 | BE16: =AY16+BB16 -> 8.4820328 | BF16: =AZ16+BC16 -> 15.117406 | BG16: -0.000211312 | BH16: 9.9272e-05 | BI16: -1.30064e-05 | BJ16: 9.98665e-05 | BK16: -0.000211907 | BL16: -1.52764 | BM16: 0.000111771 | BN16: 0.00012828 | BO16: 0.00105059 | BP16: -8.52131 | BQ16: -14.4079 | BR16: -0.071984 | BS16: 0.00911506 | BT16: -0.0240791 | BU16: -0.0114567 | BV16: =BP16+BS16 -> -8.5121949 | BW16: =BQ16+BT16 -> -14.431979 | BX16: -2.00571e-05 | BY16: -6.49446e-05 | BZ16: 2.40016e-05 | CA16: -7.74599e-06 | CB16: -7.72558e-05 | CC16: 0.389717 | CD16: 0.000106674 | CE16: 0.000112493 | CF16: 0.00100774 | CG16: -2085.97 | CH16: -2085.97 | CI16: -0.2559 | CJ16: -127.846 | CK16: -5.5986e-05 | CL16: =R16-AI16 -> 35.8012 | CM16: =((W16-AN16)^2+(X16-AO16)^2)^0.5 -> 35.799803 | CN16: =(CM16-CL16)/CL16 -> -3.9008762e-05 | CO16: =(X16-AO16)/CM16 -> 0.99998062 | CP16: =ACOS(CO16) -> 0.0062263881 | CQ16: =(AN16-W16)/CM16 -> 0.0062263479 | CR16: =CJ16*CO16 -> -127.84352 | CS16: =-CR16/D$2/A$2 -> 0.31078354 | CT16: =H16*CO16^2+I16*CQ16^2+2*J16*CO16*CQ16 -> -8.7912699e-06 | CU16: =H16*CQ16^2+I16*CO16^2-2*J16*CO16*CQ16 -> -3.642765e-05 | CV16: =2*((I16-H16)*CO16*CQ16+J16*(CO16^2-CQ16^2)) -> 0.00014579916 | CW16: =CT16*K$2^2+CU16*J$2^2+J$2*K$2*CV16 -> -1.8364485e-06 | CX16: =CT16*J$2^2+CU16*K$2^2-J$2*K$2*CV16 -> -4.3382471e-05 | CY16: =(2*(CU16-CT16)*J$2*K$2+CV16*(K$2^2-J$2^2)) -> -0.00014246085 | CZ16: =-CY16 -> 0.00014246085 | DA16: =-CK16*CL16 -> 0.002004366 | DB16: =G$2*DA16/CL16 -> 0.00024671164 | DC16: =BP16-Q16 -> -8.4786673 | DD16: =BQ16-R16 -> -32.2307 | DE16: =(DC16^2+DD16^2)^0.5 -> 33.327253 | DF16: =AH16-AY16 -> -8.32291 | DG16: =AI16-AZ16 -> -33.1108 | DH16: =(DF16^2+DG16^2)^0.5 -> 34.140825 | DI16: =(DC16*DF16+DD16*DG16)/DE16/DH16 -> 0.99993982 | DJ16: =BV16-W16 -> -8.4638719 | DK16: =BW16-X16 -> -32.234758 | DL16: =(DJ16^2+DK16^2)^0.5 -> 33.327418 | DM16: =AN16-BE16 -> -8.3074538 | DN16: =AO16-BF16 -> -33.113736 | DO16: =(DM16^2+DN16^2)^0.5 -> 34.139908 | DP16: =(DJ16*DM16+DK16*DN16)/DL16/DO16 -> 0.99993983 | DQ16: =(DJ16*DC16+DK16*DD16)/DE16/DL16 -> 0.99999989 | DR16: =(DM16*DF16+DN16*DG16)/DH16/DO16 -> 0.99999989 | DS16: =DJ16/DL16 -> -0.25396123 | DT16: =DK16/DL16 -> -0.9672144 | DU16: =DS16^2*H16+DT16^2*I16+2*DS16*DT16*J16 -> 2.041537e-06 | DV16: =DT16^2*H16+DS16^2*I16-2*DS16*DT16*J16 -> -4.7260457e-05 | DW16: =2*((I16-H16)*DS16*DT16+(DS16^2-DT16^2)*J16) -> -0.00013996599 | DX16: =-DW16 -> 0.00013996599 | DZ16: =Q16-AY16 -> -8.5295327 | EA16: =R16-AZ16 -> 2.6904 | EB16: =(DZ16*DF16+EA16*DG16)/(DZ16^2+EA16^2)^0.5/(DF16^2+DG16^2)^0.5 -> -0.059246382 | EC16: =(DZ16^2+EA16^2)^0.5 -> 8.9437789 | ED16: =EC16*(1-EB16^2)^0.5 -> 8.9280681 | EE16: =W16-BE16 -> -8.5303559 | EF16: =X16-BF16 -> 2.6853736 | EG16: =EE16-DZ16 -> -0.00082316 | EH16: =EF16-EA16 -> -0.0050264 | EI16: =(EG16^2+EH16^2)^0.5 -> 0.0050933574 | EJ16: =EI16/ED16 -> 0.00057048818
... A45: 40 | B45: 0.00422635 | C45: 0.00853024 | D45: 8.51092e-05 | E45: -0.036698 | F45: -0.126697 | G45: 0.0311551 | H45: 0.000279468 | I45: -0.000334135 | J45: 0.00057734 | K45: 0.000635327 | L45: -0.000689993 | M45: 0.543258 | N45: 0.000107946 | O45: 0.000115202 | P45: 0.00101432 | Q45: -0.0426427 | R45: 17.8228 | S45: -0.0203832 | T45: -0.0767722 | U45: -0.133992 | V45: 0.0415776 | W45: =Q45+T45 -> -0.1194149 | X45: =R45+U45 -> 17.688808 | Y45: 0.000285005 | Z45: -0.000361149 | AA45: 0.0010028 | AB45: 0.0010157 | AC45: -0.00109185 | AD45: 0.629952 | AE45: 0.000106348 | AF45: 0.000125102 | AG45: 0.000998418 | AH45: 0.16398 | AI45: -17.9784 | AJ45: 0.0178449 | AK45: 0.00433929 | AL45: -0.117465 | AM45: 0.0310928 | AN45: =AH45+AK45 -> 0.16831929 | AO45: =AI45+AL45 -> -18.095865 | AP45: -0.000448797 | AQ45: -0.000675675 | AR45: 0.000827626 | AS45: 0.000273449 | AT45: -0.00139792 | AU45: 0.717057 | AV45: 0.000118459 | AW45: 0.000114032 | AX45: 0.0011186 | AY45: 8.48689 | AZ45: 15.1324 | BA45: -0.107245 | BB45: -0.0701943 | BC45: -0.101631 | BD45: 0.0827149 | BE45: =AY45+BB45 -> 8.4166957 | BF45: =AZ45+BC45 -> 15.030769 | BG45: -0.000258882 | BH45: -0.00010768 | BI45: 0.000287204 | BJ45: 0.000114889 | BK45: -0.000481451 | BL45: 0.915981 | BM45: 0.000121251 | BN45: 0.000140449 | BO45: 0.00114333 | BP45: -8.52131 | BQ45: -14.4079 | BR45: -0.071984 | BS45: -0.00461673 | BT45: -0.15176 | BU45: -0.018061 | BV45: =BP45+BS45 -> -8.5259267 | BW45: =BQ45+BT45 -> -14.55966 | BX45: 2.84125e-06 | BY45: -3.64671e-05 | BZ45: 0.000278403 | CA45: 0.000262857 | CB45: -0.000296483 | CC45: 0.752249 | CD45: 0.000109035 | CE45: 0.000115315 | CF45: 0.00103268 | CG45: -2059.39 | CH45: -2059.39 | CI45: -0.5237 | CJ45: -262.158 | CK45: -0.000445374 | CL45: =R45-AI45 -> 35.8012 | CM45: =((W45-AN45)^2+(X45-AO45)^2)^0.5 -> 35.78583 | CN45: =(CM45-CL45)/CL45 -> -0.0004293215 | CO45: =(X45-AO45)/CM45 -> 0.99996768 | CP45: =ACOS(CO45) -> 0.0080405371 | CQ45: =(AN45-W45)/CM45 -> 0.0080404504 | CR45: =CJ45*CO45 -> -262.14953 | CS45: =-CR45/D$2/A$2 -> 0.63727718 | CT45: =H45*CO45^2+I45*CQ45^2+2*J45*CO45*CQ45 -> 0.00028871218 | CU45: =H45*CQ45^2+I45*CO45^2-2*J45*CO45*CQ45 -> -0.00034337918 | CV45: =2*((I45-H45)*CO45*CQ45+J45*(CO45^2-CQ45^2)) -> 0.0011446637 | CW45: =CT45*K$2^2+CU45*J$2^2+J$2*K$2*CV45 -> -4.9196351e-05 | CX45: =CT45*J$2^2+CU45*K$2^2-J$2*K$2*CV45 -> -5.4706487e-06 | CY45: =(2*(CU45-CT45)*J$2*K$2+CV45*(K$2^2-J$2^2)) -> -0.0013068598 | CZ45: =-CY45 -> 0.0013068598 | DA45: =-CK45*CL45 -> 0.015944924 | DB45: =G$2*DA45/CL45 -> 0.0019626148 | DC45: =BP45-Q45 -> -8.4786673 | DD45: =BQ45-R45 -> -32.2307 | DE45: =(DC45^2+DD45^2)^0.5 -> 33.327253 | DF45: =AH45-AY45 -> -8.32291 | DG45: =AI45-AZ45 -> -33.1108 | DH45: =(DF45^2+DG45^2)^0.5 -> 34.140825 | DI45: =(DC45*DF45+DD45*DG45)/DE45/DH45 -> 0.99993982 | DJ45: =BV45-W45 -> -8.4065118 | DK45: =BW45-X45 -> -32.248468 | DL45: =(DJ45^2+DK45^2)^0.5 -> 33.326163 | DM45: =AN45-BE45 -> -8.2483764 | DN45: =AO45-BF45 -> -33.126634 | DO45: =(DM45^2+DN45^2)^0.5 -> 34.138096 | DP45: =(DJ45*DM45+DK45*DN45)/DL45/DO45 -> 0.99993981 | DQ45: =(DJ45*DC45+DK45*DD45)/DE45/DL45 -> 0.99999751 | DR45: =(DM45*DF45+DN45*DG45)/DH45/DO45 -> 0.99999751 | DS45: =DJ45/DL45 -> -0.25224962 | DT45: =DK45/DL45 -> -0.9676622 | DU45: =DS45^2*H45+DT45^2*I45+2*DS45*DT45*J45 -> -1.3242886e-05 | DV45: =DT45^2*H45+DS45^2*I45-2*DS45*DT45*J45 -> -4.1424114e-05 | DW45: =2*((I45-H45)*DS45*DT45+(DS45^2-DT45^2)*J45) -> -0.0013072874 | DX45: =-DW45 -> 0.0013072874 | DZ45: =Q45-AY45 -> -8.5295327 | EA45: =R45-AZ45 -> 2.6904 | EB45: =(DZ45*DF45+EA45*DG45)/(DZ45^2+EA45^2)^0.5/(DF45^2+DG45^2)^0.5 -> -0.059246382 | EC45: =(DZ45^2+EA45^2)^0.5 -> 8.9437789 | ED45: =EC45*(1-EB45^2)^0.5 -> 8.9280681 | EE45: =W45-BE45 -> -8.5361106 | EF45: =X45-BF45 -> 2.658039 | EG45: =EE45-DZ45 -> -0.0065779 | EH45: =EF45-EA45 -> -0.032361 | EI45: =(EG45^2+EH45^2)^0.5 -> 0.033022766 | EJ45: =EI45/ED45 -> 0.0036987583
A46: 41 | B46: 0.00422635 | C46: 0.00853024 | D46: 8.51092e-05 | E46: -0.0344573 | F46: -0.131478 | G46: 0.0116084 | H46: 0.0001725 | I46: -0.000418885 | J46: 0.000607412 | K46: 0.000563133 | L46: -0.000809518 | M46: 0.553907 | N46: 0.000108272 | O46: 0.000115549 | P46: 0.00101724 | Q46: -0.0426427 | R46: 17.8228 | S46: -0.0203832 | T46: -0.0747652 | U46: -0.140256 | V46: 0.0177672 | W46: =Q46+T46 -> -0.1174079 | X46: =R46+U46 -> 17.682544 | Y46: 5.71573e-05 | Z46: -0.000633325 | AA46: 0.00111605 | AB46: 0.000880272 | AC46: -0.00145644 | AD46: 0.635618 | AE46: 0.000104579 | AF46: 0.000123245 | AG46: 0.000983755 | AH46: 0.16398 | AI46: -17.9784 | AJ46: 0.0178449 | AK46: 0.00785957 | AL46: -0.120434 | AM46: 0.00897588 | AN46: =AH46+AK46 -> 0.17183957 | AO46: =AI46+AL46 -> -18.098834 | AP46: -0.000660782 | AQ46: -0.000802097 | AR46: 0.00085189 | AS46: 0.000123611 | AT46: -0.00158649 | AU46: 0.743921 | AV46: 0.00011786 | AW46: 0.000113558 | AX46: 0.00111352 | AY46: 8.48689 | AZ46: 15.1324 | BA46: -0.107245 | BB46: -0.069023 | BC46: -0.10578 | BD46: 0.0596754 | BE46: =AY46+BB46 -> 8.417867 | BF46: =AZ46+BC46 -> 15.02662 | BG46: -0.000439414 | BH46: -0.000291509 | BI46: 0.000370382 | BJ46: 1.34937e-05 | BK46: -0.000744416 | BL46: 0.885938 | BM46: 0.000126939 | BN46: 0.00014716 | BO46: 0.00119723 | BP46: -8.52131 | BQ46: -14.4079 | BR46: -0.071984 | BS46: -0.00166662 | BT46: -0.155517 | BU46: -0.0258413 | BV46: =BP46+BS46 -> -8.5229766 | BW46: =BQ46+BT46 -> -14.563417 | BX46: 0.000127882 | BY46: -0.000264327 | BZ46: 0.000223231 | CA46: 0.000228939 | CB46: -0.000365384 | CC46: 0.425143 | CD46: 0.000109012 | CE46: 0.000114416 | CF46: 0.00102543 | CG46: -2058.7 | CH46: -2058.7 | CI46: -0.5334 | CJ46: -267.007 | CK46: -0.000537959 | CL46: =R46-AI46 -> 35.8012 | CM46: =((W46-AN46)^2+(X46-AO46)^2)^0.5 -> 35.782547 | CN46: =(CM46-CL46)/CL46 -> -0.00052101376 | CO46: =(X46-AO46)/CM46 -> 0.99996733 | CP46: =ACOS(CO46) -> 0.0080835671 | CQ46: =(AN46-W46)/CM46 -> 0.0080834791 | CR46: =CJ46*CO46 -> -266.99828 | CS46: =-CR46/D$2/A$2 -> 0.64906433 | CT46: =H46*CO46^2+I46*CQ46^2+2*J46*CO46*CQ46 -> 0.00018228104 | CU46: =H46*CQ46^2+I46*CO46^2-2*J46*CO46*CQ46 -> -0.00042866604 | CV46: =2*((I46-H46)*CO46*CQ46+J46*(CO46^2-CQ46^2)) -> 0.0012051047 | CW46: =CT46*K$2^2+CU46*J$2^2+J$2*K$2*CV46 -> -0.000121919 | CX46: =CT46*J$2^2+CU46*K$2^2-J$2*K$2*CV46 -> -0.000124466 | CY46: =(2*(CU46-CT46)*J$2*K$2+CV46*(K$2^2-J$2^2)) -> -0.0013511207 | CZ46: =-CY46 -> 0.0013511207 | DA46: =-CK46*CL46 -> 0.019259578 | DB46: =G$2*DA46/CL46 -> 0.002370606 | DC46: =BP46-Q46 -> -8.4786673 | DD46: =BQ46-R46 -> -32.2307 | DE46: =(DC46^2+DD46^2)^0.5 -> 33.327253 | DF46: =AH46-AY46 -> -8.32291 | DG46: =AI46-AZ46 -> -33.1108 | DH46: =(DF46^2+DG46^2)^0.5 -> 34.140825 | DI46: =(DC46*DF46+DD46*DG46)/DE46/DH46 -> 0.99993982 | DJ46: =BV46-W46 -> -8.4055687 | DK46: =BW46-X46 -> -32.245961 | DL46: =(DJ46^2+DK46^2)^0.5 -> 33.323499 | DM46: =AN46-BE46 -> -8.2460274 | DN46: =AO46-BF46 -> -33.125454 | DO46: =(DM46^2+DN46^2)^0.5 -> 34.136383 | DP46: =(DJ46*DM46+DK46*DN46)/DL46/DO46 -> 0.99993926 | DQ46: =(DJ46*DC46+DK46*DD46)/DE46/DL46 -> 0.9999975 | DR46: =(DM46*DF46+DN46*DG46)/DH46/DO46 -> 0.99999738 | DS46: =DJ46/DL46 -> -0.25224148 | DT46: =DK46/DL46 -> -0.96766432 | DU46: =DS46^2*H46+DT46^2*I46+2*DS46*DT46*J46 -> -8.4737264e-05 | DV46: =DT46^2*H46+DS46^2*I46-2*DS46*DT46*J46 -> -0.00016164774 | DW46: =2*((I46-H46)*DS46*DT46+(DS46^2-DT46^2)*J46) -> -0.0013489323 | DX46: =-DW46 -> 0.0013489323 | DZ46: =Q46-AY46 -> -8.5295327 | EA46: =R46-AZ46 -> 2.6904 | EB46: =(DZ46*DF46+EA46*DG46)/(DZ46^2+EA46^2)^0.5/(DF46^2+DG46^2)^0.5 -> -0.059246382 | EC46: =(DZ46^2+EA46^2)^0.5 -> 8.9437789 | ED46: =EC46*(1-EB46^2)^0.5 -> 8.9280681 | EE46: =W46-BE46 -> -8.5352749 | EF46: =X46-BF46 -> 2.655924 | EG46: =EE46-DZ46 -> -0.0057422 | EH46: =EF46-EA46 -> -0.034476 | EI46: =(EG46^2+EH46^2)^0.5 -> 0.034950929 | EJ46: =EI46/ED46 -> 0.0039147247 | EU46: =441/0.875 -> 504
