Workbook

Sheet L30TX
B2: ='L30TX-1'!$F$9 -> Ult Load, N | C2: ='L30TX-1'!$G$9 -> Ult Stress, MPa | D2: ='L30TX-1'!$E$9 -> Failure Strain, % | E2: ='L30TX-1'!$J$9 -> Ex, MPa | F2: ='L30TX-1'!$K$9 -> νyx | G2: ='L30TX-1_DIC'!P2 -> νzx
A3: average | B3: =AVERAGE(B6:B8) -> 17807.081 | C3: =AVERAGE(C6:C8) -> 103.80748 | D3: =AVERAGE(D6:D8) -> 0.01183 | E3: =AVERAGE(E6:E8) -> 14620.187 | F3: =AVERAGE(F6:F8) -> 0.62987709 | G3: =AVERAGE(G6:G8) -> 0.31285661
A4: sr. dev. | B4: =STDEV(B6:B8) -> 2333.9134 | C4: =STDEV(C6:C8) -> 7.5828067 | D4: =STDEV(D6:D8) -> 0.0011941105 | E4: =STDEV(E6:E8) -> 975.93951 | F4: =STDEV(F6:F8) -> 0.11883622 | G4: =STDEV(G6:G8) -> 0.10389745
A5: CV | B5: =B4/B3 -> 0.13106659 | C5: =C4/C3 -> 0.073046827 | D5: =D4/D3 -> 0.10093918 | E5: =E4/E3 -> 0.066752873 | F5: =F4/F3 -> 0.18866573 | G5: =G4/G3 -> 0.33209287
A6: 1 | B6: ='L30TX-1'!F10 -> 15113.982 | C6: ='L30TX-1'!G10 -> 95.29684 | D6: ='L30TX-1'!E10 -> 0.01085 | E6: ='L30TX-1'!J10 -> 13647.148 | F6: ='L30TX-1'!K10 -> 0.76228807 | H6: ='L30TX-1_DIC'!P3 -> 0.083982073
A7: 2 | B7: ='L30TX-2'!F10 -> 19066.637 | C7: ='L30TX-2'!G10 -> 106.28073 | D7: ='L30TX-2'!E10 -> 0.01316 | E7: ='L30TX-2'!J10 -> 15599.002 | F7: ='L30TX-2'!K10 -> 0.53248593 | G7: ='L30TX-2_DIC'!O3 -> 0.23939002
A8: 3 | B8: ='L30TX-3'!F10 -> 19240.623 | C8: ='L30TX-3'!G10 -> 109.84486 | D8: ='L30TX-3'!E10 -> 0.01148 | E8: ='L30TX-3'!J10 -> 14614.412 | F8: ='L30TX-3'!K10 -> 0.59485726 | G8: ='L30TX-3_DIC'!O3 -> 0.3863232
A12: 4 | C12: ='L30TX-4'!G10 -> 98.32121 | D12: ='L30TX-4'!E10 -> 0.01712 | E12: ='L30TX-4'!J10 -> 10779.017 | F12: ='L30TX-4'!K10 -> 0.54751818 | G12: ='L30TX-4_DIC'!O3 -> 0.506732

Sheet L30TX-1
A1: General : End date | B1: 45813
A2: General : Specimen number (included) | B2: 1
A3: Maximum Load : Maximum Load | B3: 15113.982 | C3: N
A4: Specimen choice input : Fiber direction | B4: <None>
A5: Specimen properties : Thickness | B5: 6.95 | C5: mm
A6: Specimen properties : Width | B6: 22.82 | C6: mm
A7: Specimen properties : Length | B7: 200 | C7: mm
A8: Modulus (Chord 0,05 % - 0,25 %) : Modulus (Chord 0,05 % - 0,25 %) | B8: 13822.551 | C8: MPa | E8: =MATCH(G10,G13:G1048576,0)-1 -> 1756
A9: Strain : Tensile strain (Extension) gauge length | B9: 25 | C9: mm | E9: Failure Strain, % | F9: Ult Load, N | G9: Ult Stress, MPa | J9: Ex, MPa | K9: νyx
E10: =INDEX(C13:C1048576,MATCH(G10,G13:G1048576,0)) -> 0.01085 | F10: =MAX(F13:F1048576) -> 15113.982 | G10: =MAX(G13:G1048576) -> 95.29684 | J10: =INDEX(LINEST(G13:G560,E13:E560),1) -> 13647.148 | K10: =INDEX(LINEST(I13:I560,E13:E560),1) -> 0.76228807
A11: Time | B11: Extension | C11: Strain 1 | D11: Tensile extension | E11: Tensile strain (Strain 1) | F11: Load | G11: Tensile stress | H11: Transverse deformation | I11: Transverse strain
A12: (s) | B12: (mm) | C12: (mm/mm) | D12: (mm) | E12: (mm/mm) | F12: (N) | G12: (MPa) | H12: (mm) | I12: (mm/mm)
A13: 0 | B13: 0 | C13: 0 | D13: 1e-05 | E13: 0 | F13: 78.9012 | G13: 0.49749 | H13: 0.00042 | I13: 2e-05
A14: 0.1 | B14: 0.00098 | C14: 1e-05 | D14: 0.00013 | E14: 1e-05 | F14: 91.60429 | G14: 0.57758 | H14: 0.00048 | I14: 2e-05
A15: 0.2 | B15: 0.00307 | C15: 2e-05 | D15: 0.00041 | E15: 2e-05 | F15: 121.38594 | G15: 0.76536 | H15: 0.00064 | I15: 3e-05
A16: 0.3 | B16: 0.0075 | C16: 4e-05 | D16: 0.00105 | E16: 4e-05 | F16: 185.67003 | G16: 1.17069 | H16: 0.00096 | I16: 4e-05
A17: 0.4 | B17: 0.01105 | C17: 6e-05 | D17: 0.00159 | E17: 6e-05 | F17: 235.6368 | G17: 1.48574 | H17: 0.00124 | I17: 5e-05
A18: 0.5 | B18: 0.0144 | C18: 8e-05 | D18: 0.0021 | E18: 8e-05 | F18: 282.34467 | G18: 1.78024 | H18: 0.00149 | I18: 7e-05
A19: 0.6 | B19: 0.0177 | C19: 0.0001 | D19: 0.00256 | E19: 0.0001 | F19: 328.33752 | G19: 2.07024 | H19: 0.00174 | I19: 8e-05
A20: 0.7 | B20: 0.02096 | C20: 0.00012 | D20: 0.00302 | E20: 0.00012 | F20: 373.2944 | G20: 2.3537 | H20: 0.00199 | I20: 9e-05
A21: 0.8 | B21: 0.02483 | C21: 0.00014 | D21: 0.00357 | E21: 0.00014 | F21: 426.6026 | G21: 2.68982 | H21: 0.00227 | I21: 0.0001
A22: 0.9 | B22: 0.02752 | C22: 0.00016 | D22: 0.00395 | E22: 0.00016 | F22: 462.60272 | G22: 2.91681 | H22: 0.00248 | I22: 0.00011
A23: 1 | B23: 0.03118 | C23: 0.00018 | D23: 0.00449 | E23: 0.00018 | F23: 512.36658 | G23: 3.23058 | H23: 0.00276 | I23: 0.00012
A24: 1.1 | B24: 0.03447 | C24: 0.0002 | D24: 0.00497 | E24: 0.0002 | F24: 556.62201 | G24: 3.50962 | H24: 0.00301 | I24: 0.00013
A25: 1.2 | B25: 0.03759 | C25: 0.00022 | D25: 0.0054 | E25: 0.00022 | F25: 597.58441 | G25: 3.7679 | H25: 0.00326 | I25: 0.00014 | W25: 7.91
A26: 1.3 | B26: 0.0412 | C26: 0.00024 | D26: 0.00588 | E26: 0.00024 | F26: 645.79968 | G26: 4.0719 | H26: 0.00354 | I26: 0.00016 | W26: 7.73
A27: 1.4 | B27: 0.04416 | C27: 0.00025 | D27: 0.00629 | E27: 0.00025 | F27: 684.09113 | G27: 4.31334 | H27: 0.00377 | I27: 0.00017 | W27: =AVERAGE(W25:W26) -> 7.82
A28: 1.5 | B28: 0.04814 | C28: 0.00027 | D28: 0.00684 | E28: 0.00027 | F28: 736.40717 | G28: 4.6432 | H28: 0.00406 | I28: 0.00018
A29: 1.6 | B29: 0.05087 | C29: 0.00029 | D29: 0.00721 | E29: 0.00029 | F29: 770.46326 | G29: 4.85793 | H29: 0.00428 | I29: 0.00019
A30: 1.7 | B30: 0.05444 | C30: 0.00031 | D30: 0.00771 | E30: 0.00031 | F30: 815.69611 | G30: 5.14314 | H30: 0.00453 | I30: 0.0002
A31: 1.8 | B31: 0.05794 | C31: 0.00033 | D31: 0.00818 | E31: 0.00033 | F31: 859.93188 | G31: 5.42205 | H31: 0.00478 | I31: 0.00021
A32: 1.9 | B32: 0.0609 | C32: 0.00034 | D32: 0.00855 | E32: 0.00034 | F32: 895.56976 | G32: 5.64676 | H32: 0.00501 | I32: 0.00022
A33: 2 | B33: 0.06462 | C33: 0.00036 | D33: 0.00904 | E33: 0.00036 | F33: 942.3894 | G33: 5.94196 | H33: 0.00527 | I33: 0.00023
A34: 2.1 | B34: 0.06754 | C34: 0.00038 | D34: 0.00941 | E34: 0.00038 | F34: 977.20624 | G34: 6.16149 | H34: 0.0055 | I34: 0.00024
A35: 2.2 | B35: 0.0713 | C35: 0.0004 | D35: 0.00992 | E35: 0.0004 | F35: 1023.5155 | G35: 6.45348 | H35: 0.00576 | I35: 0.00025
A36: 2.3 | B36: 0.07429 | C36: 0.00041 | D36: 0.0103 | E36: 0.00041 | F36: 1058.6512 | G36: 6.67502 | H36: 0.00599 | I36: 0.00026
A37: 2.4 | B37: 0.07767 | C37: 0.00043 | D37: 0.01073 | E37: 0.00043 | F37: 1099.033 | G37: 6.92963 | H37: 0.00624 | I37: 0.00027
A38: 2.5 | B38: 0.08139 | C38: 0.00045 | D38: 0.01119 | E38: 0.00045 | F38: 1143.8094 | G38: 7.21196 | H38: 0.00649 | I38: 0.00028
A39: 2.6 | B39: 0.08417 | C39: 0.00046 | D39: 0.01153 | E39: 0.00046 | F39: 1174.8597 | G39: 7.40774 | H39: 0.00671 | I39: 0.00029
... A1788: 175.117 | B1788: 5.83505 | C1788: 0.01661 | D1788: 0.41523 | E1788: 0.01661 | F1788: 8872.4307 | G1788: 55.94254 | H1788: -0.18176 | I1788: -0.00797

Sheet L30TX-1_DIC
P2: νzx
A3: E0 | F3: E1 | J3: Analog | P3: =-INDEX(LINEST(F5:F125,B5:B125),1) -> 0.083982073
A4: Index [1] | B4: ?L/L0 [1] | C4: ?L [mm] | D4: L1 [mm] | E4: L0 [mm] | F4: ?L/L0 [1] | G4: ?L [mm] | H4: L1 [mm] | I4: L0 [mm] | J4: Time_1 | K4: Time_0 | L4: Dev1/ai0 | M4: Dev1/ai1 | N4: Force_[N] | O4: stress
A5: 0 | B5: 0 | C5: 0 | D5: 37.2804 | E5: 37.2804 | F5: 0 | G5: 0 | H5: 3.44518 | I5: 3.44518 | J5: -173.566 | K5: -173.563 | L5: 0.0132 | M5: -0.0009 | N5: 87.2089 | O5: =N5/22.82/6.95 -> 0.54987043
A6: 1 | B6: -1.04796e-05 | C6: -0.000390684 | D6: 37.28 | E6: 37.2804 | F6: -2.5923e-05 | G6: -8.93093e-05 | H6: 3.44509 | I6: 3.44518 | J6: -170.025 | K6: -170.025 | L6: 0.0132 | M6: -9.9768 | N6: 87.2089 | O6: =N6/22.82/6.95 -> 0.54987043
A7: 2 | B7: -1.26185e-05 | C7: -0.000470424 | D7: 37.2799 | E7: 37.2804 | F7: -4.02859e-05 | G7: -0.000138792 | H7: 3.44504 | I7: 3.44518 | J7: -164.907 | K7: -164.907 | L7: 0.0103 | M7: -0.0029 | N7: 72.6741 | O7: =N7/22.82/6.95 -> 0.45822546
A8: 3 | B8: 5.03775e-05 | C8: 0.00187809 | D8: 37.2823 | E8: 37.2804 | F8: -9.88364e-06 | G8: -3.40509e-05 | H8: 3.44515 | I8: 3.44518 | J8: -160.664 | K8: -160.664 | L8: 0.0326 | M8: 0.0013 | N8: 184.108 | O8: =N8/22.82/6.95 -> 1.1608396
A9: 4 | B9: 7.14789e-05 | C9: 0.00266476 | D9: 37.283 | E9: 37.2804 | F9: -4.82917e-05 | G9: -0.000166374 | H9: 3.44501 | I9: 3.44518 | J9: -160.415 | K9: -160.415 | L9: 0.0558 | M9: 0.0062 | N9: 300.386 | O9: =N9/22.82/6.95 -> 1.8939968
A10: 5 | B10: 9.13653e-05 | C10: 0.00340613 | D10: 37.2838 | E10: 37.2804 | F10: -4.98738e-05 | G10: -0.000171824 | H10: 3.44501 | I10: 3.44518 | J10: -160.228 | K10: -160.228 | L10: 0.0667 | M10: 0.0132 | N10: 355.296 | O10: =N10/22.82/6.95 -> 2.2402159
A11: 6 | B11: 0.000100385 | C11: 0.00374241 | D11: 37.2841 | E11: 37.2804 | F11: -6.77706e-05 | G11: -0.000233482 | H11: 3.44495 | I11: 3.44518 | J11: -160.042 | K11: -160.042 | L11: 0.0809 | M11: 0.0149 | N11: 426.355 | O11: =N11/22.82/6.95 -> 2.6882578
A12: 7 | B12: 0.000119128 | C12: 0.00444115 | D12: 37.2848 | E12: 37.2804 | F12: -0.000166166 | G12: -0.000572473 | H12: 3.44461 | I12: 3.44518 | J12: -159.917 | K12: -159.917 | L12: 0.097 | M12: 0.0136 | N12: 507.104 | O12: =N12/22.82/6.95 -> 3.1973972
A13: 8 | B13: 0.000180681 | C13: 0.00673586 | D13: 37.2871 | E13: 37.2804 | F13: -0.000127248 | G13: -0.000438394 | H13: 3.44474 | I13: 3.44518 | J13: -159.792 | K13: -159.792 | L13: 0.1099 | M13: 0.0181 | N13: 571.703 | O13: =N13/22.82/6.95 -> 3.6047075
A14: 9 | B14: 0.000167868 | C14: 0.00625819 | D14: 37.2866 | E14: 37.2804 | F14: -0.000143574 | G14: -0.000494638 | H14: 3.44469 | I14: 3.44518 | J14: -159.661 | K14: -159.661 | L14: 0.1154 | M14: 0.0216 | N14: 599.158 | O14: =N14/22.82/6.95 -> 3.777817
A15: 10 | B15: 0.000213493 | C15: 0.00795909 | D15: 37.2883 | E15: 37.2804 | F15: -8.13024e-05 | G15: -0.000280102 | H15: 3.4449 | I15: 3.44518 | J15: -159.479 | K15: -159.479 | L15: 0.1415 | M15: 0.0239 | N15: 729.971 | O15: =N15/22.82/6.95 -> 4.6026204
A16: 11 | B16: 0.000269346 | C16: 0.0100413 | D16: 37.2904 | E16: 37.2804 | F16: -7.9654e-05 | G16: -0.000274423 | H16: 3.44491 | I16: 3.44518 | J16: -159.23 | K16: -159.23 | L16: 0.1579 | M16: 0.0277 | N16: 812.335 | O16: =N16/22.82/6.95 -> 5.1219428
... A138: 133 | B138: 0.00333102 | C138: 0.124182 | D138: 37.4046 | E138: 37.2804 | F138: -0.000243235 | G138: -0.000837989 | H138: 3.44434 | I138: 3.44518 | J138: -88.904 | K138: -88.904 | L138: 1.5477 | M138: 0.3536 | N138: 7776.13 | O138: =N138/22.82/6.95 -> 49.030133
A139: 134 | B139: 0.00332414 | C139: 0.123925 | D139: 37.4043 | E139: 37.2804 | G139: -0.000807756 | H139: 3.44437 | I139: 3.44518 | J139: -88.218 | K139: -88.218 | L139: 1.5547 | M139: 0.3533 | N139: 7811.66 | O139: =N139/22.82/6.95 -> 49.254157
A140: 135 | B140: 0.00335415 | C140: 0.125044 | D140: 37.4054 | E140: 37.2804 | G140: -0.000829211 | H140: 3.44435 | I140: 3.44518 | J140: -87.466 | K140: -87.466 | L140: 1.5654 | M140: 0.3578 | N140: 7864.96 | O140: =N140/22.82/6.95 -> 49.590224
A141: 136 | B141: 0.00336667 | C141: 0.125511 | D141: 37.4059 | E141: 37.2804 | G141: -0.000779593 | H141: 3.4444 | I141: 3.44518 | J141: -86.721 | K141: -86.721 | L141: 1.577 | M141: 0.3597 | N141: 7923.09 | O141: =N141/22.82/6.95 -> 49.956746
A142: 137 | B142: 0.00342346 | C142: 0.127628 | D142: 37.408 | E142: 37.2804 | G142: -0.00083779 | H142: 3.44434 | I142: 3.44518 | J142: -85.973 | K142: -85.973 | L142: 1.5857 | M142: 0.3678 | N142: 7966.7 | O142: =N142/22.82/6.95 -> 50.231716
A143: 138 | B143: 0.00340401 | C143: 0.126903 | D143: 37.4073 | E143: 37.2804 | G143: -0.000803846 | H143: 3.44438 | I143: 3.44518 | J143: -85.724 | K143: -85.723 | L143: 1.5889 | M143: 0.3629 | N143: 7982.85 | O143: =N143/22.82/6.95 -> 50.333546
A144: 139 | B144: 0.00344192 | C144: 0.128316 | D144: 37.4087 | E144: 37.2804 | G144: -0.000760183 | H144: 3.44442 | I144: 3.44518 | J144: -84.412 | K144: -84.412 | L144: 1.6002 | M144: 0.369 | N144: 8039.37 | O144: =N144/22.82/6.95 -> 50.689916
A145: 140 | B145: 0.00345793 | C145: 0.128913 | D145: 37.4093 | E145: 37.2804 | G145: -0.0010571 | H145: 3.44412 | I145: 3.44518 | J145: -83.538 | K145: -83.538 | L145: 1.624 | M145: 0.3678 | N145: 8158.88 | O145: =N145/22.82/6.95 -> 51.443452
A146: 141 | B146: 0.00349119 | C146: 0.130153 | D146: 37.4105 | E146: 37.2804 | G146: -0.000704074 | H146: 3.44448 | I146: 3.44518 | J146: -83.165 | K146: -83.165 | L146: 1.6282 | M146: 0.3716 | N146: 8179.88 | O146: =N146/22.82/6.95 -> 51.575861
A147: 142 | B147: 0.00348493 | C147: 0.12992 | D147: 37.4103 | E147: 37.2804 | G147: -0.000750714 | H147: 3.44443 | I147: 3.44518 | J147: -82.353 | K147: -82.352 | L147: 1.6356 | M147: 0.3765 | N147: 8217.02 | O147: =N147/22.82/6.95 -> 51.810037
A148: 143 | B148: 0.00352604 | C148: 0.131452 | D148: 37.4118 | E148: 37.2804 | G148: -0.000785785 | H148: 3.44439 | I148: 3.44518 | J148: -81.605 | K148: -81.605 | L148: 1.6401 | M148: 0.3829 | N148: 8239.63 | O148: =N148/22.82/6.95 -> 51.952597
A149: 144 | B149: 0.00356164 | C149: 0.132779 | D149: 37.4132 | E149: 37.2804 | G149: -0.000998484 | H149: 3.44418 | I149: 3.44518 | J149: -81.106 | K149: -81.106 | L149: 1.6543 | M149: 0.379 | N149: 8310.69 | O149: =N149/22.82/6.95 -> 52.400646
A150: 145 | B150: 0.00359493 | C150: 0.13402 | D150: 37.4144 | E150: 37.2804 | G150: -0.000630682 | H150: 3.44455 | I150: 3.44518 | J150: -79.918 | K150: -79.918 | L150: 1.6679 | M150: 0.3823 | N150: 8378.52 | O150: =N150/22.82/6.95 -> 52.828328
... A302: 297 | B302: 0.00642281 | C302: 0.239445 | D302: 37.5198 | E302: 37.2804 | G302: 0.00188796 | H302: 3.44707 | I302: 3.44518 | J302: 13.554 | K302: 13.555 | L302: 3.0044 | M302: 1.0755 | N302: 15075.9 | O302: =N302/22.82/6.95 -> 95.056715
A303: 298 | C303: 0.0323531 | D303: 37.3127 | E303: 37.2804 | G303: 0.0025814 | H303: 3.44776 | I303: 3.44518 | J303: 14.117 | K303: 14.117 | L303: 1.5418 | M303: 0.7796 | N303: 7747.06
A304: 299 | C304: 0.0283425 | D304: 37.3087 | E304: 37.2804 | G304: 0.00227697 | H304: 3.44746 | I304: 3.44518 | J304: 14.241 | K304: 14.242 | L304: 0.6971 | M304: 0.5118 | N304: 3514.2
A305: 300 | C305: 0.0274076 | D305: 37.3078 | E305: 37.2804 | G305: 0.00235756 | H305: 3.44754 | I305: 3.44518 | J305: 14.368 | K305: 14.368 | L305: 0.331 | M305: 0.3984 | N305: 1679.58
A306: 301 | C306: 0.0266971 | D306: 37.3071 | E306: 37.2804 | G306: 0.00176987 | H306: 3.44695 | I306: 3.44518 | J306: 14.494 | K306: 14.494 | L306: 0.1502 | M306: 0.3623 | N306: 773.576
A307: 302 | C307: 0.0240554 | D307: 37.3044 | E307: 37.2804 | G307: 0.0019171 | H307: 3.4471 | I307: 3.44518 | J307: 14.616 | K307: 14.616 | L307: 0.0729 | M307: 0.351 | N307: 385.98
A308: 303 | C308: 0.0230366 | D308: 37.3034 | E308: 37.2804 | G308: 0.00229116 | H308: 3.44747 | I308: 3.44518 | J308: 14.744 | K308: 14.744 | L308: 0.0355 | M308: 0.3426 | N308: 198.643
A309: 304 | C309: 0.0219655 | D309: 37.3023 | E309: 37.2804 | G309: 0.00241942 | H309: 3.4476 | I309: 3.44518 | J309: 14.865 | K309: 14.866 | L309: 0.0181 | M309: 0.3462 | N309: 111.434
A310: 305 | C310: 0.0221812 | D310: 37.3026 | E310: 37.2804 | G310: 0.00197066 | H310: 3.44715 | I310: 3.44518 | J310: 15.178 | K310: 15.178 | L310: 0.0107 | M310: 0.3555 | N310: 74.2891

Sheet L30TX-2
A1: General : End date | B1: 45813
A2: General : Specimen number (included) | B2: 2
A3: Maximum Load : Maximum Load | B3: 19066.637 | C3: N
A4: Specimen choice input : Fiber direction | B4: <None>
A5: Specimen properties : Thickness | B5: 7.91 | C5: mm
A6: Specimen properties : Width | B6: 22.68 | C6: mm
A7: Specimen properties : Length | B7: 200 | C7: mm
A8: Modulus (Chord 0,05 % - 0,25 %) : Modulus (Chord 0,05 % - 0,25 %) | B8: 15713.011 | C8: MPa | E8: =MATCH(G10,G13:G1048576,0)-1 -> 1757
A9: Strain : Tensile strain (Extension) gauge length | B9: 25 | C9: mm | E9: Failure Strain, % | F9: Ult Load, N | G9: Ult Stress, MPa | J9: Ex, MPa | K9: νyx
E10: =INDEX(C13:C1048576,MATCH(G10,G13:G1048576,0)) -> 0.01316 | F10: =MAX(F13:F1048576) -> 19066.637 | G10: =MAX(G13:G1048576) -> 106.28073 | J10: =INDEX(LINEST(G13:G560,E13:E560),1) -> 15599.002 | K10: =INDEX(LINEST(I13:I560,E13:E560),1) -> 0.53248593
A11: Time | B11: Extension | C11: Strain 1 | D11: Tensile extension | E11: Tensile strain (Strain 1) | F11: Load | G11: Tensile stress | H11: Transverse deformation | I11: Transverse strain
A12: (s) | B12: (mm) | C12: (mm/mm) | D12: (mm) | E12: (mm/mm) | F12: (N) | G12: (MPa) | H12: (mm) | I12: (mm/mm)
A13: 0 | B13: -0.00053 | C13: 0 | D13: -2e-05 | E13: 0 | F13: 192.87527 | G13: 1.07512 | H13: 0.00016 | I13: 1e-05
A14: 0.1 | B14: 0.00029 | C14: 0 | D14: 6e-05 | E14: 0 | F14: 202.72766 | G14: 1.13004 | H14: 0.0002 | I14: 1e-05
A15: 0.2 | B15: 0.00209 | C15: 1e-05 | D15: 0.00029 | E15: 1e-05 | F15: 230.12759 | G15: 1.28277 | H15: 0.00029 | I15: 1e-05
A16: 0.3 | B16: 0.00626 | C16: 3e-05 | D16: 0.00081 | E16: 3e-05 | F16: 295.40109 | G16: 1.64662 | H16: 0.0005 | I16: 2e-05
A17: 0.4 | B17: 0.00996 | C17: 5e-05 | D17: 0.00128 | E17: 5e-05 | F17: 352.8334 | G17: 1.96675 | H17: 0.00069 | I17: 3e-05
A18: 0.5 | B18: 0.0139 | C18: 7e-05 | D18: 0.00178 | E18: 7e-05 | F18: 412.86633 | G18: 2.30139 | H18: 0.00089 | I18: 4e-05
A19: 0.6 | B19: 0.01662 | C19: 8e-05 | D19: 0.0021 | E19: 8e-05 | F19: 453.01096 | G19: 2.52516 | H19: 0.00101 | I19: 4e-05
A20: 0.7 | B20: 0.02026 | C20: 0.0001 | D20: 0.00253 | E20: 0.0001 | F20: 506.41904 | G20: 2.82287 | H20: 0.00119 | I20: 5e-05
A21: 0.8 | B21: 0.02377 | C21: 0.00012 | D21: 0.00294 | E21: 0.00012 | F21: 557.5459 | G21: 3.10786 | H21: 0.00134 | I21: 6e-05
A22: 0.9 | B22: 0.02663 | C22: 0.00013 | D22: 0.00327 | E22: 0.00013 | F22: 598.04608 | G22: 3.33361 | H22: 0.00148 | I22: 7e-05
A23: 1 | B23: 0.03036 | C23: 0.00015 | D23: 0.00372 | E23: 0.00015 | F23: 652.93109 | G23: 3.63955 | H23: 0.00165 | I23: 7e-05
A24: 1.1 | B24: 0.03336 | C24: 0.00016 | D24: 0.00408 | E24: 0.00016 | F24: 695.94543 | G24: 3.87932 | H24: 0.00178 | I24: 8e-05
... A1788: 175.133 | B1788: 5.83491 | C1788: 0.02668 | D1788: 0.66697 | E1788: 0.02668 | F1788: 11183.572 | G1788: 62.33917 | H1788: -0.31718 | I1788: -0.01398

Sheet L30TX-2_DIC
O2: νzx
A3: E0 | F3: E1 | J3: Analog | O3: =-INDEX(LINEST(F5:F293,B5:B293),1) -> 0.23939002
A4: Index [1] | B4: ?L/L0 [1] | C4: ?L [mm] | D4: L1 [mm] | E4: L0 [mm] | F4: ?L/L0 [1] | G4: ?L [mm] | H4: L1 [mm] | I4: L0 [mm] | J4: Time_1 | K4: Time_0 | L4: Dev1/ai0 | M4: Dev1/ai1 | N4: Force_[N]
A5: 0 | B5: 0 | C5: 0 | D5: 37.296 | E5: 37.296 | F5: 0 | G5: 0 | H5: 4.8268 | I5: 4.8268 | J5: -1456 | K5: -1455.99 | L5: 0.0361 | M5: -0.0009 | N5: 201.872
A6: 1 | B6: 5.50276e-06 | C6: 0.000205231 | D6: 37.2962 | E6: 37.296 | F6: 2.92718e-05 | G6: 0.000141289 | H6: 4.82694 | I6: 4.8268 | J6: -1451.22 | K6: -1451.22 | L6: 0.0345 | M6: -0.0009 | N6: 193.798
A7: 2 | B7: -8.32761e-07 | C7: -3.10587e-05 | D7: 37.296 | E7: 37.296 | F7: -2.01544e-05 | G7: -9.72814e-05 | H7: 4.8267 | I7: 4.8268 | J7: -1446.17 | K7: -1446.17 | L7: 0.0348 | M7: -9.9807 | N7: 195.413
A8: 3 | B8: 6.48407e-05 | C8: 0.0024183 | D8: 37.2985 | E8: 37.296 | F8: -7.74203e-05 | G8: -0.000373692 | H8: 4.82643 | I8: 4.8268 | J8: -1441.55 | K8: -1441.55 | L8: 0.059 | M8: -0.0016 | N8: 316.536
A9: 4 | B9: 0.000100667 | C9: 0.00375449 | D9: 37.2998 | E9: 37.296 | F9: -3.75446e-05 | G9: -0.00018122 | H9: 4.82662 | I9: 4.8268 | J9: -1441.36 | K9: -1441.36 | L9: 0.0767 | M9: 0.001 | N9: 405.36
A10: 5 | B10: 0.000116011 | C10: 0.00432676 | D10: 37.3004 | E10: 37.296 | F10: -7.32485e-05 | G10: -0.000353556 | H10: 4.82645 | I10: 4.8268 | J10: -1441.17 | K10: -1441.17 | L10: 0.0922 | M10: 0.0071 | N10: 482.879
A11: 6 | B11: 0.000123729 | C11: 0.0046146 | D11: 37.3007 | E11: 37.296 | F11: -7.60834e-05 | G11: -0.000367239 | H11: 4.82643 | I11: 4.8268 | J11: -1441.05 | K11: -1441.05 | L11: 0.1019 | M11: 0.01 | N11: 531.328
A12: 7 | B12: 0.000158996 | C12: 0.00592992 | D12: 37.302 | E12: 37.296 | F12: -6.57194e-05 | G12: -0.000317215 | H12: 4.82648 | I12: 4.8268 | J12: -1440.86 | K12: -1440.86 | L12: 0.1209 | M12: 0.0123 | N12: 626.612
A13: 8 | B13: 0.000186388 | C13: 0.00695154 | D13: 37.303 | E13: 37.296 | F13: -9.64408e-05 | G13: -0.000465501 | H13: 4.82634 | I13: 4.8268 | J13: -1440.74 | K13: -1440.73 | L13: 0.1399 | M13: 0.0136 | N13: 721.896
A14: 9 | B14: 0.000217282 | C14: 0.00810375 | D14: 37.3041 | E14: 37.296 | F14: -0.000109955 | G14: -0.000530733 | H14: 4.82627 | I14: 4.8268 | J14: -1440.49 | K14: -1440.49 | L14: 0.1541 | M14: 0.0187 | N14: 792.955
A15: 10 | B15: 0.000213793 | C15: 0.00797363 | D15: 37.304 | E15: 37.296 | F15: -9.92532e-05 | G15: -0.000479076 | H15: 4.82632 | I15: 4.8268 | J15: -1440.36 | K15: -1440.36 | L15: 0.1667 | M15: 0.0252 | N15: 855.94
A16: 11 | B16: 0.000226636 | C16: 0.00845262 | D16: 37.3045 | E16: 37.296 | F16: -6.11253e-05 | G16: -0.00029504 | H16: 4.82651 | I16: 4.8268 | J16: -1440.24 | K16: -1440.24 | L16: 0.1837 | M16: 0.0277 | N16: 941.534
... A297: 292 | B297: 0.00507203 | C297: 0.189166 | D297: 37.4852 | E297: 37.296 | F297: -0.00114788 | G297: -0.00554059 | H297: 4.82126 | I297: 4.8268 | J297: -1306.01 | K297: -1306.01 | L297: 3.0827 | M297: 0.6839 | N297: 15468.3
A298: 293 | B298: 0.00409978 | C298: 0.152906 | D298: 37.4489 | E298: 37.296 | G298: -0.00326683 | H298: 4.82353 | I298: 4.8268 | J298: -1304.95 | K298: -1304.95 | L298: 2.9876 | M298: 0.7851 | N298: 14991.9
A299: 294 | B299: 0.00409872 | C299: 0.152866 | D299: 37.4489 | E299: 37.296 | G299: -0.00311072 | H299: 4.82369 | I299: 4.8268 | J299: -1304.83 | K299: -1304.83 | L299: 2.9451 | M299: 0.8219 | N299: 14778.7
A300: 295 | B300: 0.00409403 | C300: 0.152691 | D300: 37.4487 | E300: 37.296 | G300: -0.00314031 | H300: 4.82366 | I300: 4.8268 | J300: -1304.7 | K300: -1304.7 | L300: 2.9348 | M300: 0.8351 | N300: 14727
A301: 296 | B301: 0.00410034 | C301: 0.152927 | D301: 37.449 | E301: 37.296 | G301: -0.00325566 | H301: 4.82355 | I301: 4.8268 | J301: -1304.58 | K301: -1304.58 | L301: 2.9309 | M301: 0.8554 | N301: 14707.6
A302: 297 | B302: 0.00411967 | C302: 0.153647 | D302: 37.4497 | E302: 37.296 | G302: -0.00321888 | H302: 4.82358 | I302: 4.8268 | J302: -1304.27 | K302: -1304.27 | L302: 2.9444 | M302: 0.8731 | N302: 14775.5
A303: 298 | B303: 0.00413596 | C303: 0.154255 | D303: 37.4503 | E303: 37.296 | G303: -0.00339425 | H303: 4.82341 | I303: 4.8268 | J303: -1304.14 | K303: -1304.14 | L303: 2.9499 | M303: 0.8825 | N303: 14802.9
A304: 299 | B304: 0.00416721 | C304: 0.15542 | D304: 37.4515 | E304: 37.296 | G304: -0.00351868 | H304: 4.82328 | I304: 4.8268 | J304: -1303.96 | K304: -1303.95 | L304: 2.9628 | M304: 0.8879 | N304: 14867.5
A305: 300 | B305: 0.00418593 | C305: 0.156119 | D305: 37.4522 | E305: 37.296 | G305: -0.00336322 | H305: 4.82344 | I305: 4.8268 | J305: -1303.83 | K305: -1303.83 | L305: 2.9741 | M305: 0.8953 | N305: 14924
A306: 301 | B306: 0.00419031 | C306: 0.156282 | D306: 37.4523 | E306: 37.296 | G306: -0.0033276 | H306: 4.82347 | I306: 4.8268 | J306: -1303.71 | K306: -1303.7 | L306: 2.9831 | M306: 0.9031 | N306: 14969.3
A307: 302 | B307: 0.00419699 | C307: 0.156531 | D307: 37.4526 | E307: 37.296 | G307: -0.00351751 | H307: 4.82328 | I307: 4.8268 | J307: -1303.58 | K307: -1303.58 | L307: 2.9979 | M307: 0.906 | N307: 15043.6
A308: 303 | B308: 0.00420683 | C308: 0.156898 | D308: 37.4529 | E308: 37.296 | G308: -0.0031937 | H308: 4.82361 | I308: 4.8268 | J308: -1303.39 | K308: -1303.39 | L308: 3.0073 | M308: 0.9121 | N308: 15090.4
A309: 304 | B309: 0.00424144 | C309: 0.158189 | D309: 37.4542 | E309: 37.296 | G309: -0.00324587 | H309: 4.82356 | I309: 4.8268 | J309: -1303.21 | K309: -1303.21 | L309: 3.0173 | M309: 0.915 | N309: 15140.5
... A387: 382 | B387: 0.00572722 | C387: 0.213603 | D387: 37.5096 | E387: 37.296 | G387: -0.0043254 | H387: 4.82248 | I387: 4.8268 | J387: -1267.45 | K387: -1267.45 | L387: 3.7895 | M387: 1.3017 | N387: 19010
A388: 383 | G388: 0.000808228 | H388: 4.82761 | I388: 4.8268 | J388: -1266.76 | K388: -1266.76 | L388: 1.7491 | M388: 2.4588 | N388: 8785.49
A389: 384 | G389: 0.000641027 | H389: 4.82744 | I389: 4.8268 | J389: -1266.64 | K389: -1266.64 | L389: 0.8096 | M389: 3.0244 | N389: 4077.83
A390: 385 | G390: 0.000749437 | H390: 4.82755 | I390: 4.8268 | J390: -1266.52 | K390: -1266.52 | L390: 0.3678 | M390: 3.3135 | N390: 1863.69
A391: 386 | G391: 0.000563428 | H391: 4.82736 | I391: 4.8268 | J391: -1266.39 | K391: -1266.39 | L391: 0.1715 | M391: 3.4559 | N391: 880.164
A392: 387 | G392: 0.00034748 | H392: 4.82715 | I392: 4.8268 | J392: -1266.27 | K392: -1266.27 | L392: 0.0812 | M392: 3.5317 | N392: 427.97
A393: 388 | G393: 0.000474221 | H393: 4.82728 | I393: 4.8268 | J393: -1266.14 | K393: -1266.14 | L393: 0.0426 | M393: 3.5723 | N393: 234.172
A394: 389 | G394: 0.000560984 | H394: 4.82736 | I394: 4.8268 | J394: -1266.01 | K394: -1266.01 | L394: 0.02 | M394: 3.5974 | N394: 121.123
A395: 390 | G395: 0.000442286 | H395: 4.82724 | I395: 4.8268 | J395: -1265.89 | K395: -1265.89 | L395: 0.0161 | M395: 3.608 | N395: 101.744
A396: 391 | G396: 0.000805504 | H396: 4.82761 | I396: 4.8268 | J396: -1265.27 | K396: -1265.27 | L396: 0.0081 | M396: 3.6454 | N396: 61.3692
A397: 392 | G397: 0.000136444 | H397: 4.82694 | I397: 4.8268 | J397: -1261.84 | K397: -1261.84 | L397: 0.0129 | M397: 3.7002 | N397: 85.5939
A398: 393 | G398: 0.000398177 | H398: 4.8272 | I398: 4.8268 | J398: -1261.21 | K398: -1261.21 | L398: 0.0142 | M398: 3.6992 | N398: 92.0538

Sheet L30TX-3
A1: General : End date | B1: 45813
A2: General : Specimen number (included) | B2: 3
A3: Maximum Load : Maximum Load | B3: 19240.623 | C3: N
A4: Specimen choice input : Fiber direction | B4: <None>
A5: Specimen properties : Thickness | B5: 7.73 | C5: mm
A6: Specimen properties : Width | B6: 22.66 | C6: mm
A7: Specimen properties : Length | B7: 200 | C7: mm
A8: Modulus (Chord 0,05 % - 0,25 %) : Modulus (Chord 0,05 % - 0,25 %) | B8: 14774.99 | C8: MPa | E8: =MATCH(G10,G13:G1048576,0)-1 -> 2076
A9: Strain : Tensile strain (Extension) gauge length | B9: 25 | C9: mm | E9: Failure Strain, % | F9: Ult Load, N | G9: Ult Stress, MPa | J9: Ex, MPa | K9: νyx
E10: =INDEX(C13:C1048576,MATCH(G10,G13:G1048576,0)) -> 0.01148 | F10: =MAX(F13:F1048576) -> 19240.623 | G10: =MAX(G13:G1048576) -> 109.84486 | J10: =INDEX(LINEST(G13:G734,E13:E734),1) -> 14614.412 | K10: =INDEX(LINEST(I13:I734,E13:E734),1) -> 0.59485726
A11: Time | B11: Extension | C11: Strain 1 | D11: Tensile extension | E11: Tensile strain (Strain 1) | F11: Load | G11: Tensile stress | H11: Transverse deformation | I11: Transverse strain
A12: (s) | B12: (mm) | C12: (mm/mm) | D12: (mm) | E12: (mm/mm) | F12: (N) | G12: (MPa) | H12: (mm) | I12: (mm/mm)
A13: 0 | B13: 0 | C13: 0 | D13: 3e-05 | E13: 0 | F13: 24.73321 | G13: 0.1412 | H13: 5e-05 | I13: 0
A14: 0.1 | B14: 0.00084 | C14: 1e-05 | D14: 0.00015 | E14: 1e-05 | F14: 37.26379 | G14: 0.21274 | H14: 9e-05 | I14: 0
A15: 0.2 | B15: 0.00341 | C15: 2e-05 | D15: 0.00051 | E15: 2e-05 | F15: 79.48277 | G15: 0.45377 | H15: 0.00025 | I15: 1e-05
A16: 0.3 | B16: 0.00736 | C16: 4e-05 | D16: 0.00106 | E16: 4e-05 | F16: 144.4538 | G16: 0.82469 | H16: 0.00051 | I16: 2e-05
A17: 0.4 | B17: 0.01088 | C17: 6e-05 | D17: 0.00154 | E17: 6e-05 | F17: 200.96283 | G17: 1.1473 | H17: 0.00074 | I17: 3e-05
A18: 0.5 | B18: 0.01474 | C18: 8e-05 | D18: 0.0021 | E18: 8e-05 | F18: 262.68991 | G18: 1.4997 | H18: 0.00098 | I18: 4e-05
A19: 0.6 | B19: 0.01749 | C19: 0.0001 | D19: 0.00247 | E19: 0.0001 | F19: 304.53546 | G19: 1.7386 | H19: 0.00115 | I19: 5e-05
A20: 0.7 | B20: 0.02107 | C20: 0.00012 | D20: 0.00295 | E20: 0.00012 | F20: 358.58051 | G20: 2.04714 | H20: 0.00138 | I20: 6e-05
A21: 0.8 | B21: 0.02441 | C21: 0.00013 | D21: 0.00336 | E21: 0.00013 | F21: 407.40695 | G21: 2.32589 | H21: 0.00158 | I21: 7e-05
A22: 0.9 | B22: 0.02751 | C22: 0.00015 | D22: 0.00376 | E22: 0.00015 | F22: 451.09723 | G22: 2.57532 | H22: 0.00178 | I22: 8e-05
A23: 1 | B23: 0.03121 | C23: 0.00017 | D23: 0.00424 | E23: 0.00017 | F23: 504.34998 | G23: 2.87934 | H23: 0.00197 | I23: 9e-05
A24: 1.1 | B24: 0.03421 | C24: 0.00018 | D24: 0.0046 | E24: 0.00018 | F24: 545.1311 | G24: 3.11216 | H24: 0.00215 | I24: 9e-05
... A2108: 207.578 | B2108: 6.91702 | C2108: 0.03643 | D2108: 0.91076 | E2108: 0.03643 | F2108: 11378.834 | G2108: 64.96185 | H2108: 0.08099 | I2108: 0.00357

Sheet L30TX-3_DIC
O2: νzx
A3: E0 | F3: E1 | J3: Analog | O3: =-INDEX(LINEST(F5:F129,B5:B129),1) -> 0.3863232
A4: Index [1] | B4: ?L/L0 [1] | C4: ?L [mm] | D4: L1 [mm] | E4: L0 [mm] | F4: ?L/L0 [1] | G4: ?L [mm] | H4: L1 [mm] | I4: L0 [mm] | J4: Time_1 | K4: Time_0 | L4: Dev1/ai0 | M4: Dev1/ai1 | N4: Force_[N]
A5: 0 | B5: 0 | C5: 0 | D5: 42.7665 | E5: 42.7665 | F5: 0 | G5: 0 | H5: 4.95596 | I5: 4.95596 | J5: 0 | K5: 0.004 | L5: 0.001 | M5: -0.0003 | N5: 25.8396
A6: 1 | B6: -2.56665e-05 | C6: -0.00109767 | D6: 42.7654 | E6: 42.7665 | F6: -2.49274e-05 | G6: -0.000123539 | H6: 4.95583 | I6: 4.95596 | J6: 4.665 | K6: 4.665 | L6: 0.0023 | M6: -9.9788 | N6: 32.2996
A7: 2 | B7: 1.81723e-05 | C7: 0.000777163 | D7: 42.7673 | E7: 42.7665 | F7: -1.18253e-07 | G7: -5.86057e-07 | H7: 4.95596 | I7: 4.95596 | J7: 8.848 | K7: 8.848 | L7: 0.0207 | M7: 0.0007 | N7: 124.353
A8: 3 | B8: 4.15714e-05 | C8: 0.00177786 | D8: 42.7683 | E8: 42.7665 | F8: -1.22468e-05 | G8: -6.06946e-05 | H8: 4.9559 | I8: 4.95596 | J8: 9.036 | K8: 9.036 | L8: 0.0426 | M8: 0.0052 | N8: 234.172
A9: 4 | B9: 5.52622e-05 | C9: 0.00236337 | D9: 42.7688 | E9: 42.7665 | F9: -3.64383e-05 | G9: -0.000180586 | H9: 4.95578 | I9: 4.95596 | J9: 9.227 | K9: 9.227 | L9: 0.0526 | M9: 0.0052 | N9: 284.237
A10: 5 | B10: 0.000119744 | C10: 0.00512103 | D10: 42.7716 | E10: 42.7665 | F10: -3.01819e-05 | G10: -0.00014958 | H10: 4.95581 | I10: 4.95596 | J10: 9.347 | K10: 9.348 | L10: 0.0732 | M10: 0.0045 | N10: 387.595
A11: 6 | B11: 0.000131109 | C11: 0.00560707 | D11: 42.7721 | E11: 42.7665 | F11: -4.41885e-05 | G11: -0.000218997 | H11: 4.95574 | I11: 4.95596 | J11: 9.534 | K11: 9.534 | L11: 0.0858 | M11: 0.0126 | N11: 450.579
A12: 7 | B12: 0.000160793 | C12: 0.00687656 | D12: 42.7733 | E12: 42.7665 | F12: -3.67065e-05 | G12: -0.000181916 | H12: 4.95578 | I12: 4.95596 | J12: 9.657 | K12: 9.657 | L12: 0.0999 | M12: 0.0161 | N12: 521.639
A13: 8 | B13: 0.000182546 | C13: 0.00780685 | D13: 42.7743 | E13: 42.7665 | F13: -5.23087e-05 | G13: -0.00025924 | H13: 4.9557 | I13: 4.95596 | J13: 9.847 | K13: 9.848 | L13: 0.1151 | M13: 0.0174 | N13: 597.543
A14: 9 | B14: 0.000204404 | C14: 0.00874164 | D14: 42.7752 | E14: 42.7665 | F14: -7.93899e-05 | G14: -0.000393453 | H14: 4.95556 | I14: 4.95596 | J14: 9.971 | K14: 9.972 | L14: 0.1299 | M14: 0.0203 | N14: 671.832
A15: 10 | B15: 0.000220192 | C15: 0.00941685 | D15: 42.7759 | E15: 42.7665 | F15: -0.000121293 | G15: -0.000601123 | H15: 4.95536 | I15: 4.95596 | J15: 10.219 | K15: 10.219 | L15: 0.1509 | M15: 0.0252 | N15: 776.805
A16: 11 | B16: 0.000241069 | C16: 0.0103097 | D16: 42.7768 | E16: 42.7665 | F16: -0.000115633 | G16: -0.000573072 | H16: 4.95538 | I16: 4.95596 | J16: 10.407 | K16: 10.407 | L16: 0.1702 | M16: 0.0268 | N16: 873.704
... A357: 352 | B357: 0.0056056 | C357: 0.239732 | D357: 43.0062 | E357: 42.7665 | F357: -0.00110627 | G357: -0.00548261 | H357: 4.95047 | I357: 4.95596 | J357: 197.172 | K357: 197.172 | L357: 3.4765 | M357: 0.886 | N357: 17441.8
A358: 353 | B358: 0.00511115 | C358: 0.218586 | D358: 42.9851 | E358: 42.7665 | G358: -0.00444399 | H358: 4.95151 | I358: 4.95596 | J358: 197.295 | K358: 197.295 | L358: 3.4324 | M358: 0.9563 | N358: 17220.6
A359: 354 | B359: 0.00507791 | C359: 0.217164 | D359: 42.9836 | E359: 42.7665 | G359: -0.00429262 | H359: 4.95166 | I359: 4.95596 | J359: 197.424 | K359: 197.424 | L359: 3.4221 | M359: 0.983 | N359: 17168.9
A360: 355 | B360: 0.005099 | C360: 0.218066 | D360: 42.9845 | E360: 42.7665 | G360: -0.00431263 | H360: 4.95164 | I360: 4.95596 | J360: 197.544 | K360: 197.544 | L360: 3.4192 | M360: 1.012 | N360: 17154.3
A361: 356 | B361: 0.00511893 | C361: 0.218919 | D361: 42.9854 | E361: 42.7665 | G361: -0.00506404 | H361: 4.95089 | I361: 4.95596 | J361: 198.045 | K361: 198.045 | L361: 3.4346 | M361: 1.0542 | N361: 17231.9
A362: 357 | B362: 0.0051497 | C362: 0.220235 | D362: 42.9867 | E362: 42.7665 | G362: -0.0045406 | H362: 4.95142 | I362: 4.95596 | J362: 198.294 | K362: 198.294 | L362: 3.4453 | M362: 1.0633 | N362: 17285.2
A363: 358 | B363: 0.00517653 | C363: 0.221382 | D363: 42.9879 | E363: 42.7665 | G363: -0.00461877 | H363: 4.95134 | I363: 4.95596 | J363: 198.418 | K363: 198.418 | L363: 3.4514 | M363: 1.0662 | N363: 17315.8
A364: 359 | B364: 0.00520402 | C364: 0.222558 | D364: 42.989 | E364: 42.7665 | G364: -0.0045169 | H364: 4.95144 | I364: 4.95596 | J364: 198.667 | K364: 198.667 | L364: 3.4662 | M364: 1.0765 | N364: 17390.1
A365: 360 | B365: 0.00522615 | C365: 0.223504 | D365: 42.99 | E365: 42.7665 | G365: -0.00435064 | H365: 4.95161 | I365: 4.95596 | J365: 198.854 | K365: 198.854 | L365: 3.473 | M365: 1.079 | N365: 17424
A366: 361 | B366: 0.00522658 | C366: 0.223522 | D366: 42.99 | E366: 42.7665 | G366: -0.00459582 | H366: 4.95136 | I366: 4.95596 | J366: 199.106 | K366: 199.106 | L366: 3.4891 | M366: 1.09 | N366: 17504.8
A367: 362 | B367: 0.00523731 | C367: 0.223981 | D367: 42.9905 | E367: 42.7665 | G367: -0.00470691 | H367: 4.95125 | I367: 4.95596 | J367: 199.23 | K367: 199.23 | L367: 3.4891 | M367: 1.0845 | N367: 17504.8
A368: 363 | B368: 0.00528067 | C368: 0.225836 | D368: 42.9923 | E368: 42.7665 | G368: -0.00492686 | H368: 4.95103 | I368: 4.95596 | J368: 199.666 | K368: 199.666 | L368: 3.5049 | M368: 1.0961 | N368: 17583.9
A369: 364 | B369: 0.00529698 | C369: 0.226533 | D369: 42.993 | E369: 42.7665 | G369: -0.00502383 | H369: 4.95093 | I369: 4.95596 | J369: 199.917 | K369: 199.917 | L369: 3.5075 | M369: 1.0987 | N369: 17596.8
... A380: 375 | B380: 0.00566032 | C380: 0.242072 | D380: 43.0085 | E380: 42.7665 | G380: -0.0050181 | H380: 4.95094 | I380: 4.95596 | J380: 205.72 | K380: 205.72 | L380: 3.6274 | M380: 1.1164 | N380: 18197.6
A381: 376 | G381: -0.00521006 | H381: 4.95075 | I381: 4.95596 | J381: 206.093 | K381: 206.093 | L381: 3.639 | M381: 1.1216 | N381: 18255.8
A382: 377 | B382: 0.00571098 | C382: 0.244239 | D382: 43.0107 | E382: 42.7665 | G382: -0.00536773 | H382: 4.95059 | I382: 4.95596 | J382: 206.592 | K382: 206.592 | L382: 3.6457 | M382: 1.1264 | N382: 18289.7
A383: 378 | B383: 0.00575912 | C383: 0.246297 | D383: 43.0128 | E383: 42.7665 | G383: -0.00535961 | H383: 4.9506 | I383: 4.95596 | J383: 207.156 | K383: 207.157 | L383: 3.6654 | M383: 1.1258 | N383: 18388.2
A384: 379 | G384: -0.00523863 | H384: 4.95072 | I384: 4.95596 | J384: 207.528 | K384: 207.528 | L384: 3.6686 | M384: 1.1277 | N384: 18404.3
A385: 380 | B385: 0.00577191 | C385: 0.246844 | D385: 43.0133 | E385: 42.7665 | G385: -0.00524767 | H385: 4.95071 | I385: 4.95596 | J385: 208.089 | K385: 208.09 | L385: 3.6847 | M385: 1.1309 | N385: 18485.1
A386: 381 | B386: 0.00578708 | C386: 0.247493 | D386: 43.014 | E386: 42.7665 | G386: -0.00518645 | H386: 4.95077 | I386: 4.95596 | J386: 208.402 | K386: 208.403 | L386: 3.6912 | M386: 1.1338 | N386: 18517.4
A387: 382 | B387: 0.0058109 | C387: 0.248512 | D387: 43.015 | E387: 42.7665 | G387: -0.00530532 | H387: 4.95065 | I387: 4.95596 | J387: 208.963 | K387: 208.963 | L387: 3.7018 | M387: 1.1409 | N387: 18570.7
A388: 383 | G388: -0.00534896 | H388: 4.95061 | I388: 4.95596 | J388: 209.337 | K388: 209.338 | L388: 3.7112 | M388: 1.1364 | N388: 18617.5
A389: 384 | B389: 0.00582917 | C389: 0.249293 | D389: 43.0158 | E389: 42.7665 | G389: -0.00549794 | H389: 4.95046 | I389: 4.95596 | J389: 210.024 | K389: 210.024 | L389: 3.7218 | M389: 1.1429 | N389: 18670.8
A390: 385 | G390: -0.00565765 | H390: 4.9503 | I390: 4.95596 | J390: 210.151 | K390: 210.151 | L390: 3.7266 | M390: 1.1458 | N390: 18695
A391: 386 | B391: 0.00586732 | C391: 0.250925 | D391: 43.0174 | E391: 42.7665 | G391: -0.00550244 | H391: 4.95045 | I391: 4.95596 | J391: 210.774 | K391: 210.774 | L391: 3.7411 | M391: 1.1438 | N391: 18767.7
...

Sheet L30TX-4
A1: General : End date | B1: 45813
A2: General : Specimen number (included) | B2: 4
A3: Maximum Load : Maximum Load | B3: 12766.498 | C3: N
A4: Specimen choice input : Fiber direction | B4: <None>
A5: Specimen properties : Thickness | B5: 5.68 | C5: mm
A6: Specimen properties : Width | B6: 22.86 | C6: mm
A7: Specimen properties : Length | B7: 200 | C7: mm
A8: Modulus (Chord 0,05 % - 0,25 %) : Modulus (Chord 0,05 % - 0,25 %) | B8: 10885.883 | C8: MPa | E8: =MATCH(G10,G13:G1048576,0)-1 -> 1605
A9: Strain : Tensile strain (Extension) gauge length | B9: 25 | C9: mm | E9: Failure Strain, % | F9: Ult Load, N | G9: Ult Stress, MPa | J9: Ex, MPa | K9: νyx
E10: =INDEX(C13:C1048576,MATCH(G10,G13:G1048576,0)) -> 0.01712 | F10: =MAX(F13:F1048576) -> 12766.498 | G10: =MAX(G13:G1048576) -> 98.32121 | J10: =INDEX(LINEST(G13:G281,E13:E281),1) -> 10779.017 | K10: =INDEX(LINEST(I13:I281,E13:E281),1) -> 0.54751818
A11: Time | B11: Extension | C11: Strain 1 | D11: Tensile extension | E11: Tensile strain (Strain 1) | F11: Load | G11: Tensile stress | H11: Transverse deformation | I11: Transverse strain
A12: (s) | B12: (mm) | C12: (mm/mm) | D12: (mm) | E12: (mm/mm) | F12: (N) | G12: (MPa) | H12: (mm) | I12: (mm/mm)
A13: 0 | B13: -0.0003 | C13: 0 | D13: 5e-05 | E13: 0 | F13: -151.53397 | G13: -1.16704 | H13: 8e-05 | I13: 0
A14: 0.1 | B14: 0.00034 | C14: 1e-05 | D14: 0.00013 | E14: 1e-05 | F14: -144.71823 | G14: -1.11455 | H14: 0.00013 | I14: 1e-05
A15: 0.2 | B15: 0.00191 | C15: 2e-05 | D15: 0.00045 | E15: 2e-05 | F15: -123.79255 | G15: -0.95339 | H15: 0.00029 | I15: 1e-05
A16: 0.3 | B16: 0.00644 | C16: 6e-05 | D16: 0.00141 | E16: 6e-05 | F16: -62.34749 | G16: -0.48017 | H16: 0.00078 | I16: 3e-05
A17: 0.4 | B17: 0.01011 | C17: 9e-05 | D17: 0.00214 | E17: 9e-05 | F17: -14.07758 | G17: -0.10842 | H17: 0.00117 | I17: 5e-05
A18: 0.5 | B18: 0.01383 | C18: 0.00012 | D18: 0.00288 | E18: 0.00012 | F18: 34.44233 | G18: 0.26526 | H18: 0.00158 | I18: 7e-05
A19: 0.6 | B19: 0.01661 | C19: 0.00014 | D19: 0.00347 | E19: 0.00014 | F19: 69.49558 | G19: 0.53522 | H19: 0.0019 | I19: 8e-05
A20: 0.7 | B20: 0.02041 | C20: 0.00017 | D20: 0.00421 | E20: 0.00017 | F20: 117.65745 | G20: 0.90614 | H20: 0.00231 | I20: 0.0001
A21: 0.8 | B21: 0.0234 | C21: 0.00019 | D21: 0.00479 | E21: 0.00019 | F21: 154.0797 | G21: 1.18665 | H21: 0.00262 | I21: 0.00011
A22: 0.9 | B22: 0.02694 | C22: 0.00022 | D22: 0.0055 | E22: 0.00022 | F22: 197.42709 | G22: 1.52049 | H22: 0.003 | I22: 0.00013
A23: 1 | B23: 0.0302 | C23: 0.00024 | D23: 0.00611 | E23: 0.00024 | F23: 236.47595 | G23: 1.82122 | H23: 0.00332 | I23: 0.00015
A24: 1.1 | B24: 0.03341 | C24: 0.00027 | D24: 0.00671 | E24: 0.00027 | F24: 274.2323 | G24: 2.112 | H24: 0.00365 | I24: 0.00016
... A1636: 159.611 | B1636: 5.31784 | C1636: 0.01537 | D1636: 0.3842 | E1636: 0.01537 | F1636: 7301.9766 | G1636: 56.23619 | H1636: 0.04287 | I1636: 0.00188

Sheet L30TX-4_DIC
O2: νzx
A3: E0 | F3: E1 | J3: Analog | O3: =-INDEX(LINEST(F5:F198,B5:B198),1) -> 0.506732
A4: Index [1] | B4: ?L/L0 [1] | C4: ?L [mm] | D4: L1 [mm] | E4: L0 [mm] | F4: ?L/L0 [1] | G4: ?L [mm] | H4: L1 [mm] | I4: L0 [mm] | J4: Time_1 | K4: Time_0 | L4: Dev1/ai0 | M4: Dev1/ai1 | N4: Force_[N]
A5: 0 | B5: 0 | C5: 0 | D5: 22.609 | E5: 22.609 | F5: 0 | G5: 0 | H5: 3.34598 | I5: 3.34598 | J5: 0 | K5: 0.004 | L5: -0.0345 | M5: 0.0023 | N5: -151.808
A6: 1 | B6: -3.76426e-05 | C6: -0.000851062 | D6: 22.6082 | E6: 22.609 | F6: 7.45161e-05 | G6: 0.000249329 | H6: 3.34623 | I6: 3.34598 | J6: 4.612 | K6: 4.612 | L6: -0.0345 | M6: -9.9814 | N6: -151.808
A7: 2 | B7: -5.08376e-05 | C7: -0.00114939 | D7: 22.6079 | E7: 22.609 | F7: -4.88292e-05 | G7: -0.000163381 | H7: 3.34582 | I7: 3.34598 | J7: 4.917 | K7: 4.917 | L7: -0.0332 | M7: -9.9778 | N7: -145.348
A8: 3 | B8: -3.37168e-05 | C8: -0.000762306 | D8: 22.6083 | E8: 22.609 | F8: 0.000223084 | G8: 0.000746434 | H8: 3.34673 | I8: 3.34598 | J8: 10.034 | K8: 10.034 | L8: -0.0357 | M8: -0.0045 | N8: -158.268
A9: 4 | B9: -6.55679e-05 | C9: -0.00148243 | D9: 22.6076 | E9: 22.609 | F9: 1.43386e-05 | G9: 4.79766e-05 | H9: 3.34603 | I9: 3.34598 | J9: 12.342 | K9: 12.342 | L9: -0.0309 | M9: -0.0029 | N9: -134.043
A10: 5 | B10: -6.34148e-05 | C10: -0.00143375 | D10: 22.6076 | E10: 22.609 | F10: 2.49342e-05 | G10: 8.34292e-05 | H10: 3.34606 | I10: 3.34598 | J10: 16.713 | K10: 16.713 | L10: -0.0335 | M10: -0.0016 | N10: -146.963
A11: 6 | B11: -1.16334e-05 | C11: -0.00026302 | D11: 22.6088 | E11: 22.609 | F11: 9.15274e-05 | G11: 0.000306249 | H11: 3.34629 | I11: 3.34598 | J11: 18.272 | K11: 18.272 | L11: -0.0357 | M11: -0.0026 | N11: -158.268
A12: 7 | B12: -5.65473e-05 | C12: -0.00127848 | D12: 22.6078 | E12: 22.609 | F12: 8.14087e-05 | G12: 0.000272392 | H12: 3.34625 | I12: 3.34598 | J12: 18.459 | K12: 18.459 | L12: -0.0341 | M12: -0.0048 | N12: -150.193
A13: 8 | B13: -1.46503e-05 | C13: -0.000331229 | D13: 22.6087 | E13: 22.609 | F13: -4.4535e-05 | G13: -0.000149013 | H13: 3.34583 | I13: 3.34598 | J13: 23.512 | K13: 23.512 | L13: -0.0319 | M13: -0.0038 | N13: -138.888
A14: 9 | B14: 3.48446e-06 | C14: 7.87804e-05 | D14: 22.6091 | E14: 22.609 | F14: -8.06454e-05 | G14: -0.000269838 | H14: 3.34571 | I14: 3.34598 | J14: 25.072 | K14: 25.072 | L14: -0.0267 | M14: -0.0029 | N14: -113.049
A15: 10 | B15: 4.86518e-05 | C15: 0.00109997 | D15: 22.6101 | E15: 22.609 | F15: -0.000216706 | G15: -0.000725093 | H15: 3.34525 | I15: 3.34598 | J15: 25.261 | K15: 25.261 | L15: -0.0048 | M15: 0.0074 | N15: -3.23
A16: 11 | B16: 6.89674e-05 | C16: 0.00155929 | D16: 22.6106 | E16: 22.609 | F16: -7.84771e-05 | G16: -0.000262583 | H16: 3.34572 | I16: 3.34598 | J16: 25.51 | K16: 25.51 | L16: 0.0033 | M16: 0.0116 | N16: 37.1445
... A220: 215 | B220: 0.00313272 | C220: 0.0708279 | D220: 22.6799 | E220: 22.609 | F220: -0.0015463 | G220: -0.0051739 | H220: 3.3408 | I220: 3.34598 | J220: 138.953 | K220: 138.953 | L220: 1.9873 | M220: 0.7951 | N220: 9978.97
A221: 216 | B221: 0.00251411 | C221: 0.0568416 | D221: 22.6659 | E221: 22.609 | G221: -0.0046952 | H221: 3.34128 | I221: 3.34598 | J221: 140.45 | K221: 140.45 | L221: 1.9756 | M221: 0.9656 | N221: 9920.83
A222: 217 | B222: 0.00166606 | C222: 0.0376679 | D222: 22.6467 | E222: 22.609 | G222: -0.00391399 | H222: 3.34206 | I222: 3.34598 | J222: 141.387 | K222: 141.387 | L222: 1.9515 | M222: 1.1148 | N222: 9799.7
A223: 218 | B223: 0.00168985 | C223: 0.0382059 | D223: 22.6472 | E223: 22.609 | G223: -0.00405473 | H223: 3.34192 | I223: 3.34598 | J223: 141.513 | K223: 141.513 | L223: 1.9315 | M223: 1.1638 | N223: 9699.57
A224: 219 | B224: 0.00168362 | C224: 0.0380651 | D224: 22.6471 | E224: 22.609 | G224: -0.00424511 | H224: 3.34173 | I224: 3.34598 | J224: 142.072 | K224: 142.072 | L224: 1.9415 | M224: 1.2125 | N224: 9749.64
A225: 220 | B225: 0.00167261 | C225: 0.037816 | D225: 22.6469 | E225: 22.609 | G225: -0.00409331 | H225: 3.34189 | I225: 3.34598 | J225: 142.324 | K225: 142.324 | L225: 1.957 | M225: 1.2199 | N225: 9827.16
A226: 221 | B226: 0.00174437 | C226: 0.0394384 | D226: 22.6485 | E226: 22.609 | G226: -0.00420072 | H226: 3.34178 | I226: 3.34598 | J226: 142.512 | K226: 142.513 | L226: 1.9631 | M226: 1.2299 | N226: 9857.84
A227: 222 | B227: 0.0017172 | C227: 0.0388243 | D227: 22.6479 | E227: 22.609 | G227: -0.00425272 | H227: 3.34173 | I227: 3.34598 | J227: 142.946 | K227: 142.946 | L227: 1.9727 | M227: 1.2502 | N227: 9906.29
A228: 223 | B228: 0.00172616 | C228: 0.0390269 | D228: 22.6481 | E228: 22.609 | G228: -0.00436986 | H228: 3.34161 | I228: 3.34598 | J228: 143.135 | K228: 143.135 | L228: 1.9824 | M228: 1.2531 | N228: 9954.74
A229: 224 | B229: 0.00174274 | C229: 0.0394017 | D229: 22.6484 | E229: 22.609 | G229: -0.00439935 | H229: 3.34158 | I229: 3.34598 | J229: 143.571 | K229: 143.571 | L229: 1.994 | M229: 1.266 | N229: 10012.9
A230: 225 | B230: 0.00172994 | C230: 0.0391123 | D230: 22.6482 | E230: 22.609 | G230: -0.00447442 | H230: 3.3415 | I230: 3.34598 | J230: 143.946 | K230: 143.946 | L230: 1.9969 | M230: 1.2805 | N230: 10027.4
A231: 226 | B231: 0.00176104 | C231: 0.0398155 | D231: 22.6489 | E231: 22.609 | G231: -0.00430697 | H231: 3.34167 | I231: 3.34598 | J231: 144.444 | K231: 144.444 | L231: 2.0082 | M231: 1.2895 | N231: 10083.9
A232: 227 | B232: 0.00176257 | C232: 0.03985 | D232: 22.6489 | E232: 22.609 | G232: -0.004431 | H232: 3.34155 | I232: 3.34598 | J232: 144.82 | K232: 144.82 | L232: 2.0204 | M232: 1.2982 | N232: 10145.3
... A321: 316 | B321: -0.00117997 | C321: -0.026678 | D321: 22.5824 | E321: 22.609 | G321: -0.00149392 | H321: 3.34448 | I321: 3.34598 | J321: 186.563 | K321: 186.563 | L321: 0.0065 | M321: 0.5702 | N321: 53.2943
