Workbook

Sheet OLT
B2: ='OLT-1'!BF2 -> Ult Stress, MPa | C2: ='OLT-1'!BG2 -> Failure Strains, % | D2: ='OLT-2'!BR2 -> E1, MPa | E2: ='OLT-1'!BK2 -> ν31
A3: average | B3: =AVERAGE(B6:B9) -> 394.78013 | C3: =AVERAGE(C6:C9) -> 0.0117636 | D3: =AVERAGE(D6:D9) -> 31551.184 | E3: =AVERAGE(E6:E9) -> 0.43181253
A4: sr. dev. | B4: =STDEV(B6:B9) -> 27.420106 | C4: =STDEV(C6:C9) -> 0.00071976873 | D4: =STDEV(D6:D9) -> 761.95041 | E4: =STDEV(E6:E9) -> 0.059622045
A5: CV | B5: =B4/B3 -> 0.069456651 | C5: =C4/C3 -> 0.061186094 | D5: =D4/D3 -> 0.024149661 | E5: =E4/E3 -> 0.13807391
A6: 1 | B6: ='OLT-1'!$BF$3 -> 411.03571 | C6: ='OLT-1'!$BG$3 -> 0.0122702 | D6: ='OLT-1'!$BJ$3 -> 31912.687 | E6: ='OLT-1'!$BK$3 -> 0.4831438
A7: 2 | B7: ='OLT-2'!$BN$3 -> 410.18273 | C7: ='OLT-2'!$BO$3 -> 0.0120809 | D7: ='OLT-2'!$BR$3 -> 32065.095 | E7: ='OLT-2'!$BS$3 -> 0.36641512
A8: 3 | B8: ='OLT-3'!BR3 -> 363.12195 | C8: ='OLT-3'!BS3 -> 0.0109397 | D8: ='OLT-3'!BV3 -> 30675.771 | E8: ='OLT-3'!BW3 -> 0.44587867

Sheet OLT-1
A1: w | B1: t | BG1: =MATCH(BF3,BF5:BF1048576,0)-1 -> 599
A2: 6 | B2: 8.4 | BF2: Ult Stress, MPa | BG2: Failure Strains, % | BJ2: E1, MPa | BK2: ν31
A3: Average | B3: E0 | F3: E1 | J3: E2 | N3: E3 | R3: E4 | V3: E5 | Z3: E6 | AD3: E7 | AH3: E8 | AL3: E9 | AP3: E10 | AT3: E11 | AX3: E12 | BB3: Analog | BF3: =MAX(BF5:BF1048576) -> 411.03571 | BG3: =INDEX(BG5:BG1048576,MATCH(BF3,BF5:BF1048576,0)) -> 0.0122702 | BH3: =INDEX(BH5:BH1048576,MATCH(BF3,BF5:BF1048576,0)) -> -0.0066100367 | BI3: =INDEX(BI5:BI1048576,MATCH(BF3,BF5:BF1048576,0)) -> 0.0054925233 | BJ3: =INDEX(LINEST(BF5:BF435,BG5:BG435),1) -> 31912.687 | BK3: =INDEX(LINEST(BI5:BI435,BG5:BG435),1) -> 0.4831438
A4: Index [1] | B4: ?L/L0 [1] | C4: ?L [mm] | D4: L1 [mm] | E4: L0 [mm] | F4: ?L/L0 [1] | G4: ?L [mm] | H4: L1 [mm] | I4: L0 [mm] | J4: ?L/L0 [1] | K4: ?L [mm] | L4: L1 [mm] | M4: L0 [mm] | N4: ?L/L0 [1] | O4: ?L [mm] | P4: L1 [mm] | Q4: L0 [mm] | R4: ?L/L0 [1] | S4: ?L [mm] | T4: L1 [mm] | U4: L0 [mm] | V4: ?L/L0 [1] | W4: ?L [mm] | X4: L1 [mm] | Y4: L0 [mm] | Z4: ?L/L0 [1] | AA4: ?L [mm] | AB4: L1 [mm] | AC4: L0 [mm] | AD4: ?L/L0 [1] | AE4: ?L [mm] | AF4: L1 [mm] | AG4: L0 [mm] | AH4: ?L/L0 [1] | AI4: ?L [mm] | AJ4: L1 [mm] | AK4: L0 [mm] | AL4: ?L/L0 [1] | AM4: ?L [mm] | AN4: L1 [mm] | AO4: L0 [mm] | AP4: ?L/L0 [1] | AQ4: ?L [mm] | AR4: L1 [mm] | AS4: L0 [mm] | AT4: ?L/L0 [1] | AU4: ?L [mm] | AV4: L1 [mm] | AW4: L0 [mm] | AX4: ?L/L0 [1] | AY4: ?L [mm] | AZ4: L1 [mm] | BA4: L0 [mm] | BB4: Time_1 | BC4: Time_0 | BD4: Dev1/ai0 | BE4: Force_[N] | BF4: σ1, MPa | BG4: ε1 | BH4: ε3 | BI4: ε3_v1
A5: 0 | B5: 0 | C5: 0 | D5: 33.6519 | E5: 33.6519 | F5: 0 | G5: 0 | H5: 5.00679 | I5: 5.00679 | J5: 0 | K5: 0 | L5: 5.10485 | M5: 5.10485 | N5: 0 | O5: 0 | P5: 5.30412 | Q5: 5.30412 | R5: 0 | S5: 0 | T5: 4.58276 | U5: 4.58276 | V5: 0 | W5: 0 | X5: 4.81253 | Y5: 4.81253 | Z5: 0 | AA5: 0 | AB5: 4.50528 | AC5: 4.50528 | AD5: 0 | AE5: 0 | AF5: 4.68559 | AG5: 4.68559 | AH5: 0 | AI5: 0 | AJ5: 4.25815 | AK5: 4.25815 | AL5: 0 | AM5: 0 | AN5: 4.51905 | AO5: 4.51905 | AP5: 0 | AQ5: 0 | AR5: 4.633 | AS5: 4.633 | AT5: 0 | AU5: 0 | AV5: 4.7131 | AW5: 4.7131 | AX5: 0 | AY5: 0 | AZ5: 3.3622 | BA5: 3.3622 | BB5: -127.279 | BC5: -127.275 | BD5: 0.0168 | BE5: 93.6725 | BF5: =BE5/$A$2/$B$2 -> 1.8585813 | BG5: =B5 -> 0 | BH5: =AVERAGE(F5,J5,N5,R5,V5,Z5) -> 0 | BI5: =-AVERAGE(F5,J5,N5,R5,V5,Z5,AD5,AH5,AL5,AP5,AT5,AX5) -> 0
A6: 1 | B6: -1.61742e-05 | C6: -0.000544292 | D6: 33.6514 | E6: 33.6519 | F6: 1.51688e-05 | G6: 7.59472e-05 | H6: 5.00687 | I6: 5.00679 | J6: 9.8278e-05 | K6: 0.000501695 | L6: 5.10535 | M6: 5.10485 | N6: 5.14485e-05 | O6: 0.000272889 | P6: 5.3044 | Q6: 5.30412 | R6: -7.16449e-06 | S6: -3.28332e-05 | T6: 4.58273 | U6: 4.58276 | V6: -3.89455e-05 | W6: -0.000187426 | X6: 4.81234 | Y6: 4.81253 | Z6: 4.22699e-05 | AA6: 0.000190438 | AB6: 4.50547 | AC6: 4.50528 | AD6: -6.96257e-06 | AE6: -3.26238e-05 | AF6: 4.68556 | AG6: 4.68559 | AH6: -1.54651e-05 | AI6: -6.58528e-05 | AJ6: 4.25809 | AK6: 4.25815 | AL6: 3.13805e-05 | AM6: 0.00014181 | AN6: 4.51919 | AO6: 4.51905 | AP6: -3.91707e-06 | AQ6: -1.81478e-05 | AR6: 4.63299 | AS6: 4.633 | AT6: -1.98289e-05 | AU6: -9.34556e-05 | AV6: 4.71301 | AW6: 4.7131 | AX6: 5.04753e-05 | AY6: 0.000169708 | AZ6: 3.36237 | BA6: 3.3622 | BB6: -126.486 | BC6: -126.485 | BD6: 0.0165 | BE6: 92.0575 | BF6: =BE6/$A$2/$B$2 -> 1.8265377 | BG6: =B6 -> -1.61742e-05 | BH6: =AVERAGE(F6,J6,N6,R6,V6,Z6) -> 2.6842535e-05 | BI6: =-AVERAGE(F6,J6,N6,R6,V6,Z6,AD6,AH6,AL6,AP6,AT6,AX6) -> -1.6394781e-05
A7: 2 | B7: -3.66353e-05 | C7: -0.00123285 | D7: 33.6507 | E7: 33.6519 | F7: 9.66081e-05 | G7: 0.000483697 | H7: 5.00728 | I7: 5.00679 | J7: 0.000136516 | K7: 0.000696893 | L7: 5.10555 | M7: 5.10485 | N7: 0.000103264 | O7: 0.000547726 | P7: 5.30467 | Q7: 5.30412 | R7: 4.84985e-05 | S7: 0.000222257 | T7: 4.58299 | U7: 4.58276 | V7: 0.000145831 | W7: 0.000701816 | X7: 4.81323 | Y7: 4.81253 | Z7: 0.000145528 | AA7: 0.000655644 | AB7: 4.50594 | AC7: 4.50528 | AD7: 8.63069e-05 | AE7: 0.000404399 | AF7: 4.686 | AG7: 4.68559 | AH7: 9.11654e-05 | AI7: 0.000388196 | AJ7: 4.25854 | AK7: 4.25815 | AL7: 0.0001423 | AM7: 0.000643062 | AN7: 4.51969 | AO7: 4.51905 | AP7: 4.0468e-05 | AQ7: 0.000187489 | AR7: 4.63319 | AS7: 4.633 | AT7: 6.53435e-05 | AU7: 0.00030797 | AV7: 4.71341 | AW7: 4.7131 | AX7: 0.000133719 | AY7: 0.000449589 | AZ7: 3.36265 | BA7: 3.3622 | BB7: -125.417 | BC7: -125.417 | BD7: 0.0139 | BE7: 79.1371 | BF7: =BE7/$A$2/$B$2 -> 1.5701806 | BG7: =B7 -> -3.66353e-05 | BH7: =AVERAGE(F7,J7,N7,R7,V7,Z7) -> 0.0001127076 | BI7: =-AVERAGE(F7,J7,N7,R7,V7,Z7,AD7,AH7,AL7,AP7,AT7,AX7) -> -0.00010296237
A8: 3 | B8: -2.4102e-05 | C8: -0.000811081 | D8: 33.6511 | E8: 33.6519 | F8: 1.55488e-05 | G8: 7.78495e-05 | H8: 5.00687 | I8: 5.00679 | J8: 6.59e-05 | K8: 0.000336409 | L8: 5.10519 | M8: 5.10485 | N8: -2.32089e-05 | O8: -0.000123103 | P8: 5.304 | Q8: 5.30412 | R8: -5.40236e-05 | S8: -0.000247577 | T8: 4.58252 | U8: 4.58276 | V8: 2.04504e-05 | W8: 9.84183e-05 | X8: 4.81263 | Y8: 4.81253 | Z8: 4.16083e-05 | AA8: 0.000187457 | AB8: 4.50547 | AC8: 4.50528 | AD8: 3.86288e-05 | AE8: 0.000180999 | AF8: 4.68577 | AG8: 4.68559 | AH8: -3.93588e-05 | AI8: -0.000167596 | AJ8: 4.25799 | AK8: 4.25815 | AL8: 0.000124738 | AM8: 0.000563698 | AN8: 4.51961 | AO8: 4.51905 | AP8: 7.58894e-05 | AQ8: 0.000351596 | AR8: 4.63336 | AS8: 4.633 | AT8: 0.000102434 | AU8: 0.00048278 | AV8: 4.71358 | AW8: 4.7131 | AX8: 0.00011685 | AY8: 0.000392874 | AZ8: 3.3626 | BA8: 3.3622 | BB8: -125.301 | BC8: -125.3 | BD8: 0.0155 | BE8: 87.2123 | BF8: =BE8/$A$2/$B$2 -> 1.7304028 | BG8: =B8 -> -2.4102e-05 | BH8: =AVERAGE(F8,J8,N8,R8,V8,Z8) -> 1.1045833e-05 | BI8: =-AVERAGE(F8,J8,N8,R8,V8,Z8,AD8,AH8,AL8,AP8,AT8,AX8) -> -4.04547e-05
A9: 4 | B9: -8.14996e-05 | C9: -0.00274262 | D9: 33.6492 | E9: 33.6519 | F9: -7.98645e-05 | G9: -0.000399865 | H9: 5.0064 | I9: 5.00679 | J9: -6.30742e-05 | K9: -0.000321985 | L9: 5.10453 | M9: 5.10485 | N9: -0.000118112 | O9: -0.000626479 | P9: 5.3035 | Q9: 5.30412 | R9: -0.000201871 | S9: -0.000925129 | T9: 4.58184 | U9: 4.58276 | V9: -0.000102894 | W9: -0.00049518 | X9: 4.81203 | Y9: 4.81253 | Z9: -7.30653e-05 | AA9: -0.00032918 | AB9: 4.50495 | AC9: 4.50528 | AD9: -9.04773e-05 | AE9: -0.00042394 | AF9: 4.68517 | AG9: 4.68559 | AH9: -8.77536e-05 | AI9: -0.000373668 | AJ9: 4.25778 | AK9: 4.25815 | AL9: -1.33495e-05 | AM9: -6.03271e-05 | AN9: 4.51899 | AO9: 4.51905 | AP9: -2.3745e-05 | AQ9: -0.000110011 | AR9: 4.63289 | AS9: 4.633 | AT9: -2.05799e-05 | AU9: -9.69949e-05 | AV9: 4.713 | AW9: 4.7131 | AX9: 3.06697e-05 | AY9: 0.000103118 | AZ9: 3.36231 | BA9: 3.3622 | BB9: -125.176 | BC9: -124.176 | BD9: 0.0161 | BE9: 90.4424 | BF9: =BE9/$A$2/$B$2 -> 1.7944921 | BG9: =B9 -> -8.14996e-05 | BH9: =AVERAGE(F9,J9,N9,R9,V9,Z9) -> -0.00010648017 | BI9: =-AVERAGE(F9,J9,N9,R9,V9,Z9,AD9,AH9,AL9,AP9,AT9,AX9) -> 7.034305e-05
A10: 5 | B10: -5.83235e-05 | C10: -0.0019627 | D10: 33.65 | E10: 33.6519 | F10: 2.65752e-05 | G10: 0.000133056 | H10: 5.00693 | I10: 5.00679 | J10: 7.27218e-05 | K10: 0.000371234 | L10: 5.10522 | M10: 5.10485 | N10: 2.07138e-05 | O10: 0.000109868 | P10: 5.30423 | Q10: 5.30412 | R10: -6.70258e-05 | S10: -0.000307163 | T10: 4.58246 | U10: 4.58276 | V10: 1.1635e-05 | W10: 5.59936e-05 | X10: 4.81258 | Y10: 4.81253 | Z10: -8.88118e-06 | AA10: -4.00122e-05 | AB10: 4.50524 | AC10: 4.50528 | AD10: -7.79499e-05 | AE10: -0.000365241 | AF10: 4.68523 | AG10: 4.68559 | AH10: -7.28208e-05 | AI10: -0.000310082 | AJ10: 4.25784 | AK10: 4.25815 | AL10: 6.98212e-06 | AM10: 3.15525e-05 | AN10: 4.51908 | AO10: 4.51905 | AP10: -4.97013e-05 | AQ10: -0.000230266 | AR10: 4.63277 | AS10: 4.633 | AT10: 1.36988e-06 | AU10: 6.4564e-06 | AV10: 4.71311 | AW10: 4.7131 | AX10: 4.3275e-05 | AY10: 0.000145499 | AZ10: 3.36235 | BA10: 3.3622 | BB10: -123.786 | BC10: -123.781 | BD10: 0.0155 | BE10: 87.2123 | BF10: =BE10/$A$2/$B$2 -> 1.7304028 | BG10: =B10 -> -5.83235e-05 | BH10: =AVERAGE(F10,J10,N10,R10,V10,Z10) -> 9.2898033e-06 | BI10: =-AVERAGE(F10,J10,N10,R10,V10,Z10,AD10,AH10,AL10,AP10,AT10,AX10) -> 7.7588483e-06
A11: 6 | B11: -7.37056e-05 | C11: -0.00248034 | D11: 33.6495 | E11: 33.6519 | F11: 1.65023e-05 | G11: 8.26237e-05 | H11: 5.00688 | I11: 5.00679 | J11: 1.99222e-05 | K11: 0.0001017 | L11: 5.10495 | M11: 5.10485 | N11: -2.56012e-05 | O11: -0.000135792 | P11: 5.30399 | Q11: 5.30412 | R11: -6.90142e-05 | S11: -0.000316276 | T11: 4.58245 | U11: 4.58276 | V11: 4.342e-05 | W11: 0.00020896 | X11: 4.81274 | Y11: 4.81253 | Z11: 5.63066e-05 | AA11: 0.000253677 | AB11: 4.50554 | AC11: 4.50528 | AD11: 3.05514e-05 | AE11: 0.000143152 | AF11: 4.68574 | AG11: 4.68559 | AH11: -1.80287e-05 | AI11: -7.6769e-05 | AJ11: 4.25808 | AK11: 4.25815 | AL11: 9.35039e-05 | AM11: 0.000422548 | AN11: 4.51947 | AO11: 4.51905 | AP11: -2.67314e-05 | AQ11: -0.000123847 | AR11: 4.63288 | AS11: 4.633 | AT11: 8.97009e-06 | AU11: 4.22769e-05 | AV11: 4.71314 | AW11: 4.7131 | AX11: 0.00010334 | AY11: 0.00034745 | AZ11: 3.36255 | BA11: 3.3622 | BB11: -122.741 | BC11: -122.741 | BD11: 0.0203 | BE11: 111.438 | BF11: =BE11/$A$2/$B$2 -> 2.2110714 | BG11: =B11 -> -7.37056e-05 | BH11: =AVERAGE(F11,J11,N11,R11,V11,Z11) -> 6.9226167e-06 | BI11: =-AVERAGE(F11,J11,N11,R11,V11,Z11,AD11,AH11,AL11,AP11,AT11,AX11) -> -1.9428416e-05
A12: 7 | B12: -3.50011e-05 | C12: -0.00117786 | D12: 33.6508 | E12: 33.6519 | F12: -8.03867e-05 | G12: -0.00040248 | H12: 5.00639 | I12: 5.00679 | J12: -6.91435e-05 | K12: -0.000352967 | L12: 5.1045 | M12: 5.10485 | N12: -4.42012e-05 | O12: -0.000234449 | P12: 5.30389 | Q12: 5.30412 | R12: -0.000138788 | S12: -0.000636031 | T12: 4.58213 | U12: 4.58276 | V12: -2.35819e-05 | W12: -0.000113489 | X12: 4.81241 | Y12: 4.81253 | Z12: 3.99454e-05 | AA12: 0.000179965 | AB12: 4.50546 | AC12: 4.50528 | AD12: -4.71442e-05 | AE12: -0.000220898 | AF12: 4.68537 | AG12: 4.68559 | AH12: -9.48371e-05 | AI12: -0.000403831 | AJ12: 4.25775 | AK12: 4.25815 | AL12: -1.03234e-05 | AM12: -4.66518e-05 | AN12: 4.519 | AO12: 4.51905 | AP12: -8.95828e-05 | AQ12: -0.000415037 | AR12: 4.63259 | AS12: 4.633 | AT12: -1.51008e-05 | AU12: -7.11716e-05 | AV12: 4.71303 | AW12: 4.7131 | AX12: 9.81635e-05 | AY12: 0.000330046 | AZ12: 3.36253 | BA12: 3.3622 | BB12: -121.681 | BC12: -121.68 | BD12: 0.019 | BE12: 104.978 | BF12: =BE12/$A$2/$B$2 -> 2.0828968 | BG12: =B12 -> -3.50011e-05 | BH12: =AVERAGE(F12,J12,N12,R12,V12,Z12) -> -5.269265e-05 | BI12: =-AVERAGE(F12,J12,N12,R12,V12,Z12,AD12,AH12,AL12,AP12,AT12,AX12) -> 3.9581725e-05
A13: 8 | B13: -2.85386e-05 | C13: -0.00096038 | D13: 33.651 | E13: 33.6519 | F13: -2.03231e-05 | G13: -0.000101754 | H13: 5.00669 | I13: 5.00679 | J13: 0.000111127 | K13: 0.000567287 | L13: 5.10542 | M13: 5.10485 | N13: 7.50287e-05 | O13: 0.000397961 | P13: 5.30452 | Q13: 5.30412 | R13: 2.9613e-05 | S13: 0.00013571 | T13: 4.5829 | U13: 4.58276 | V13: 3.9355e-05 | W13: 0.000189397 | X13: 4.81272 | Y13: 4.81253 | Z13: 9.64068e-05 | AA13: 0.00043434 | AB13: 4.50572 | AC13: 4.50528 | AD13: 1.83311e-05 | AE13: 8.58922e-05 | AF13: 4.68568 | AG13: 4.68559 | AH13: -1.05082e-05 | AI13: -4.47455e-05 | AJ13: 4.25811 | AK13: 4.25815 | AL13: 1.35225e-07 | AM13: 6.11087e-07 | AN13: 4.51905 | AO13: 4.51905 | AP13: -8.63155e-05 | AQ13: -0.0003999 | AR13: 4.6326 | AS13: 4.633 | AT13: -5.48587e-05 | AU13: -0.000258555 | AV13: 4.71284 | AW13: 4.7131 | AX13: 3.61261e-06 | AY13: 1.21463e-05 | AZ13: 3.36222 | BA13: 3.3622 | BB13: -120.995 | BC13: -120.995 | BD13: 0.0155 | BE13: 87.2123 | BF13: =BE13/$A$2/$B$2 -> 1.7304028 | BG13: =B13 -> -2.85386e-05 | BH13: =AVERAGE(F13,J13,N13,R13,V13,Z13) -> 5.5201233e-05 | BI13: =-AVERAGE(F13,J13,N13,R13,V13,Z13,AD13,AH13,AL13,AP13,AT13,AX13) -> -1.6800328e-05
A14: 9 | B14: -5.81829e-05 | C14: -0.00195797 | D14: 33.65 | E14: 33.6519 | F14: 0.000151715 | G14: 0.000759605 | H14: 5.00755 | I14: 5.00679 | J14: 0.00021358 | K14: 0.0010903 | L14: 5.10594 | M14: 5.10485 | N14: 0.000107515 | O14: 0.000570274 | P14: 5.30469 | Q14: 5.30412 | R14: 7.61775e-05 | S14: 0.000349103 | T14: 4.58311 | U14: 4.58276 | V14: 0.000151375 | W14: 0.000728497 | X14: 4.81326 | Y14: 4.81253 | Z14: 8.99419e-05 | AA14: 0.000405214 | AB14: 4.50569 | AC14: 4.50528 | AD14: 0.000103228 | AE14: 0.000483684 | AF14: 4.68608 | AG14: 4.68559 | AH14: 2.98741e-05 | AI14: 0.000127209 | AJ14: 4.25828 | AK14: 4.25815 | AL14: 0.000133586 | AM14: 0.000603682 | AN14: 4.51965 | AO14: 4.51905 | AP14: -9.05066e-06 | AQ14: -4.19317e-05 | AR14: 4.63296 | AS14: 4.633 | AT14: 6.17464e-05 | AU14: 0.000291017 | AV14: 4.71339 | AW14: 4.7131 | AX14: 0.000114115 | AY14: 0.000383676 | AZ14: 3.36259 | BA14: 3.3622 | BB14: -120.371 | BC14: -120.371 | BD14: 0.0203 | BE14: 111.438 | BF14: =BE14/$A$2/$B$2 -> 2.2110714 | BG14: =B14 -> -5.81829e-05 | BH14: =AVERAGE(F14,J14,N14,R14,V14,Z14) -> 0.0001317174 | BI14: =-AVERAGE(F14,J14,N14,R14,V14,Z14,AD14,AH14,AL14,AP14,AT14,AX14) -> -0.0001019836
A15: 10 | B15: -4.64306e-05 | C15: -0.00156248 | D15: 33.6504 | E15: 33.6519 | F15: 8.77368e-05 | G15: 0.00043928 | H15: 5.00723 | I15: 5.00679 | J15: 0.000132699 | K15: 0.000677411 | L15: 5.10553 | M15: 5.10485 | N15: 0.00012571 | O15: 0.000666779 | P15: 5.30479 | Q15: 5.30412 | R15: 6.65566e-05 | S15: 0.000305013 | T15: 4.58307 | U15: 4.58276 | V15: 0.000188753 | W15: 0.000908381 | X15: 4.81344 | Y15: 4.81253 | Z15: 0.000219376 | AA15: 0.000988349 | AB15: 4.50627 | AC15: 4.50528 | AD15: 0.000131105 | AE15: 0.000614304 | AF15: 4.68621 | AG15: 4.68559 | AH15: 4.82608e-05 | AI15: 0.000205502 | AJ15: 4.25836 | AK15: 4.25815 | AL15: 8.22063e-05 | AM15: 0.000371494 | AN15: 4.51942 | AO15: 4.51905 | AP15: 5.22349e-05 | AQ15: 0.000242005 | AR15: 4.63325 | AS15: 4.633 | AT15: 6.96895e-06 | AU15: 3.28454e-05 | AV15: 4.71313 | AW15: 4.7131 | AX15: 9.51741e-05 | AY15: 0.000319994 | AZ15: 3.36252 | BA15: 3.3622 | BB15: -119.996 | BC15: -119.996 | BD15: 0.0145 | BE15: 82.3672 | BF15: =BE15/$A$2/$B$2 -> 1.6342698 | BG15: =B15 -> -4.64306e-05 | BH15: =AVERAGE(F15,J15,N15,R15,V15,Z15) -> 0.00013680523 | BI15: =-AVERAGE(F15,J15,N15,R15,V15,Z15,AD15,AH15,AL15,AP15,AT15,AX15) -> -0.00010306512
A16: 11 | B16: 4.12998e-05 | C16: 0.00138982 | D16: 33.6533 | E16: 33.6519 | F16: -3.80494e-05 | G16: -0.000190506 | H16: 5.0066 | I16: 5.00679 | J16: 8.55686e-06 | K16: 4.36815e-05 | L16: 5.10489 | M16: 5.10485 | N16: -3.9954e-05 | O16: -0.000211921 | P16: 5.30391 | Q16: 5.30412 | R16: -6.96935e-05 | S16: -0.000319389 | T16: 4.58245 | U16: 4.58276 | V16: -4.6506e-05 | W16: -0.000223811 | X16: 4.8123 | Y16: 4.81253 | Z16: -6.30982e-05 | AA16: -0.000284275 | AB16: 4.505 | AC16: 4.50528 | AD16: -1.87157e-05 | AE16: -8.7694e-05 | AF16: 4.6855 | AG16: 4.68559 | AH16: -7.69411e-05 | AI16: -0.000327627 | AJ16: 4.25783 | AK16: 4.25815 | AL16: 2.41046e-06 | AM16: 1.0893e-05 | AN16: 4.51906 | AO16: 4.51905 | AP16: -8.11741e-05 | AQ16: -0.00037608 | AR16: 4.63263 | AS16: 4.633 | AT16: 5.26817e-05 | AU16: 0.000248294 | AV16: 4.71335 | AW16: 4.7131 | AX16: 0.000147103 | AY16: 0.00049459 | AZ16: 3.3627 | BA16: 3.3622 | BB16: -119.558 | BC16: -119.558 | BD16: 0.0332 | BE16: 176.04 | BF16: =BE16/$A$2/$B$2 -> 3.4928571 | BG16: =B16 -> 4.12998e-05 | BH16: =AVERAGE(F16,J16,N16,R16,V16,Z16) -> -4.1457373e-05 | BI16: =-AVERAGE(F16,J16,N16,R16,V16,Z16,AD16,AH16,AL16,AP16,AT16,AX16) -> 1.8614998e-05
... A604: 599 | B604: 0.0122702 | C604: 0.412916 | D604: 34.0649 | E604: 33.6519 | F604: -0.00644521 | G604: -0.0322698 | H604: 4.97452 | I604: 5.00679 | J604: -0.00723389 | K604: -0.0369279 | L604: 5.06792 | M604: 5.10485 | N604: -0.00535525 | O604: -0.0284049 | P604: 5.27572 | Q604: 5.30412 | R604: -0.00692427 | S604: -0.0317323 | T604: 4.55103 | U604: 4.58276 | V604: -0.00665485 | W604: -0.0320267 | X604: 4.7805 | Y604: 4.81253 | Z604: -0.00704675 | AA604: -0.0317476 | AB604: 4.47353 | AC604: 4.50528 | AD604: -0.00251003 | AE604: -0.011761 | AF604: 4.67383 | AG604: 4.68559 | AH604: -0.00517935 | AI604: -0.0220545 | AJ604: 4.2361 | AK604: 4.25815 | AL604: -0.00420336 | AM604: -0.0189952 | AN604: 4.50005 | AO604: 4.51905 | AP604: -0.00633808 | AQ604: -0.0293643 | AR604: 4.60364 | AS604: 4.633 | AT604: -0.00162973 | AU604: -0.00768107 | AV604: 4.70542 | AW604: 4.7131 | AX604: -0.00638951 | AY604: -0.0214828 | AZ604: 3.34072 | BA604: 3.3622 | BB604: 54.848 | BC604: 54.848 | BD604: 4.1321 | BE604: 20716.2 | BF604: =BE604/$A$2/$B$2 -> 411.03571 | BG604: =B604 -> 0.0122702 | BH604: =AVERAGE(F604,J604,N604,R604,V604,Z604) -> -0.0066100367 | BI604: =-AVERAGE(F604,J604,N604,R604,V604,Z604,AD604,AH604,AL604,AP604,AT604,AX604) -> 0.0054925233
A606: 600 | B606: 0.00165962 | C606: 0.0558494 | D606: 33.7078 | E606: 33.6519 | F606: 0.00288096 | G606: 0.0144244 | H606: 5.02122 | I606: 5.00679 | J606: 0.00322473 | K606: 0.0164618 | L606: 5.12131 | M606: 5.10485 | N606: 0.00341021 | O606: 0.0180882 | P606: 5.32221 | Q606: 5.30412 | R606: 0.00407055 | S606: 0.0186544 | T606: 4.60142 | U606: 4.58276 | V606: 0.00502378 | W606: 0.0241771 | X606: 4.8367 | Y606: 4.81253 | Z606: 0.00523935 | AA606: 0.0236048 | AB606: 4.52889 | AC606: 4.50528 | AD606: 0.00715626 | AE606: 0.0335313 | AF606: 4.71912 | AG606: 4.68559 | AH606: 0.00830781 | AI606: 0.0353759 | AJ606: 4.29353 | AK606: 4.25815 | AL606: 0.00957883 | AM606: 0.0432872 | AN606: 4.56233 | AO606: 4.51905 | AP606: 0.0100911 | AQ606: 0.0467523 | AR606: 4.67976 | AS606: 4.633 | AT606: 0.0132526 | AU606: 0.0624608 | AV606: 4.77556 | AW606: 4.7131 | AX606: 0.0193529 | AY606: 0.0650683 | AZ606: 3.42727 | BA606: 3.3622 | BB606: 55.098 | BC606: 55.098 | BD606: 2.4665 | BE606: 12369.6 | BF606: =BE606/$A$2/$B$2 -> 245.42857
A607: 601 | B607: 0.00125521 | C607: 0.0422403 | D607: 33.6942 | E607: 33.6519 | F607: 0.00317159 | G607: 0.0158795 | H607: 5.02267 | I607: 5.00679 | J607: 0.00351223 | K607: 0.0179294 | L607: 5.12278 | M607: 5.10485 | N607: 0.00333269 | O607: 0.017677 | P607: 5.3218 | Q607: 5.30412 | R607: 0.00451441 | S607: 0.0206885 | T607: 4.60345 | U607: 4.58276 | V607: 0.00529015 | W607: 0.025459 | X607: 4.83799 | Y607: 4.81253 | Z607: 0.00575935 | AA607: 0.0259475 | AB607: 4.53123 | AC607: 4.50528 | AD607: 0.00718988 | AE607: 0.0336889 | AF607: 4.71928 | AG607: 4.68559 | AH607: 0.00881568 | AI607: 0.0375385 | AJ607: 4.29569 | AK607: 4.25815 | AL607: 0.00984649 | AM607: 0.0444967 | AN607: 4.56354 | AO607: 4.51905 | AP607: 0.0105127 | AQ607: 0.0487053 | AR607: 4.68171 | AS607: 4.633 | AT607: 0.0128598 | AU607: 0.0606093 | AV607: 4.77371 | AW607: 4.7131 | AX607: 0.0200159 | AY607: 0.0672974 | AZ607: 3.4295 | BA607: 3.3622 | BB607: 55.224 | BC607: 55.224 | BD607: 1.1177 | BE607: 5610.67 | BF607: =BE607/$A$2/$B$2 -> 111.32282
A608: 602 | B608: 0.00114948 | C608: 0.0386822 | D608: 33.6906 | E608: 33.6519 | F608: 0.00319358 | G608: 0.0159896 | H608: 5.02278 | I608: 5.00679 | J608: 0.0035304 | K608: 0.0180222 | L608: 5.12287 | M608: 5.10485 | N608: 0.00335881 | O608: 0.0178155 | P608: 5.32194 | Q608: 5.30412 | R608: 0.00453265 | S608: 0.020772 | T608: 4.60354 | U608: 4.58276 | V608: 0.0052256 | W608: 0.0251484 | X608: 4.83768 | Y608: 4.81253 | Z608: 0.00569002 | AA608: 0.0256352 | AB608: 4.53092 | AC608: 4.50528 | AD608: 0.00693025 | AE608: 0.0324723 | AF608: 4.71806 | AG608: 4.68559 | AH608: 0.00884163 | AI608: 0.037649 | AJ608: 4.2958 | AK608: 4.25815 | AL608: 0.00976544 | AM608: 0.0441305 | AN608: 4.56318 | AO608: 4.51905 | AP608: 0.0105998 | AQ608: 0.0491091 | AR608: 4.68211 | AS608: 4.633 | AT608: 0.0128251 | AU608: 0.0604458 | AV608: 4.77355 | AW608: 4.7131 | AX608: 0.0203998 | AY608: 0.0685882 | AZ608: 3.43079 | BA608: 3.3622 | BB608: 55.349 | BC608: 55.35 | BD608: 0.5102 | BE608: 2566.31 | BF608: =BE608/$A$2/$B$2 -> 50.918849
A609: 603 | B609: 0.00105596 | C609: 0.0355351 | D609: 33.6875 | E609: 33.6519 | F609: 0.00334268 | G609: 0.0167361 | H609: 5.02353 | I609: 5.00679 | J609: 0.00376903 | K609: 0.0192404 | L609: 5.12409 | M609: 5.10485 | N609: 0.00348507 | O609: 0.0184852 | P609: 5.32261 | Q609: 5.30412 | R609: 0.00473346 | S609: 0.0216923 | T609: 4.60446 | U609: 4.58276 | V609: 0.00530247 | W609: 0.0255183 | X609: 4.83805 | Y609: 4.81253 | Z609: 0.00584468 | AA609: 0.0263319 | AB609: 4.53161 | AC609: 4.50528 | AD609: 0.00702469 | AE609: 0.0329148 | AF609: 4.71851 | AG609: 4.68559 | AH609: 0.00890843 | AI609: 0.0379335 | AJ609: 4.29609 | AK609: 4.25815 | AL609: 0.00968704 | AM609: 0.0437762 | AN609: 4.56282 | AO609: 4.51905 | AP609: 0.0106457 | AQ609: 0.0493217 | AR609: 4.68233 | AS609: 4.633 | AT609: 0.0126872 | AU609: 0.0597961 | AV609: 4.7729 | AW609: 4.7131 | AX609: 0.020495 | AY609: 0.0689082 | AZ609: 3.43111 | BA609: 3.3622 | BB609: 55.475 | BC609: 55.475 | BD609: 0.2263 | BE609: 1143.45 | BF609: =BE609/$A$2/$B$2 -> 22.6875
A610: 604 | B610: 0.00100439 | C610: 0.0337998 | D610: 33.6857 | E610: 33.6519 | F610: 0.003271 | G610: 0.0163772 | H610: 5.02317 | I610: 5.00679 | J610: 0.00366328 | K610: 0.0187005 | L610: 5.12355 | M610: 5.10485 | N610: 0.0033124 | O610: 0.0175694 | P610: 5.32169 | Q610: 5.30412 | R610: 0.00468782 | S610: 0.0214832 | T610: 4.60425 | U610: 4.58276 | V610: 0.00522382 | W610: 0.0251398 | X610: 4.83767 | Y610: 4.81253 | Z610: 0.00582807 | AA610: 0.0262571 | AB610: 4.53154 | AC610: 4.50528 | AD610: 0.00691402 | AE610: 0.0323963 | AF610: 4.71799 | AG610: 4.68559 | AH610: 0.00889503 | AI610: 0.0378764 | AJ610: 4.29603 | AK610: 4.25815 | AL610: 0.00963023 | AM610: 0.0435195 | AN610: 4.56257 | AO610: 4.51905 | AP610: 0.0105999 | AQ610: 0.0491095 | AR610: 4.68211 | AS610: 4.633 | AT610: 0.0126833 | AU610: 0.0597778 | AV610: 4.77288 | AW610: 4.7131 | AX610: 0.0205354 | AY610: 0.0690443 | AZ610: 3.43125 | BA610: 3.3622 | BB610: 55.597 | BC610: 55.597 | BD610: 0.0945 | BE610: 482.898 | BF610: =BE610/$A$2/$B$2 -> 9.5813095
A611: 605 | B611: 0.000955693 | C611: 0.0321609 | D611: 33.6841 | E611: 33.6519 | F611: 0.00335941 | G611: 0.0168199 | H611: 5.02361 | I611: 5.00679 | J611: 0.00389921 | K611: 0.0199049 | L611: 5.12475 | M611: 5.10485 | N611: 0.00354465 | O611: 0.0188012 | P611: 5.32292 | Q611: 5.30412 | R611: 0.00494217 | S611: 0.0226488 | T611: 4.60541 | U611: 4.58276 | V611: 0.00544661 | W611: 0.026212 | X611: 4.83874 | Y611: 4.81253 | Z611: 0.00599354 | AA611: 0.0270026 | AB611: 4.53228 | AC611: 4.50528 | AD611: 0.00702209 | AE611: 0.0329026 | AF611: 4.7185 | AG611: 4.68559 | AH611: 0.00898648 | AI611: 0.0382658 | AJ611: 4.29642 | AK611: 4.25815 | AL611: 0.00973356 | AM611: 0.0439864 | AN611: 4.56303 | AO611: 4.51905 | AP611: 0.0107184 | AQ611: 0.0496586 | AR611: 4.68266 | AS611: 4.633 | AT611: 0.0127251 | AU611: 0.0599748 | AV611: 4.77308 | AW611: 4.7131 | AX611: 0.0206503 | AY611: 0.0694305 | AZ611: 3.43163 | BA611: 3.3622 | BB611: 55.724 | BC611: 55.724 | BD611: 0.0374 | BE611: 197.035 | BF611: =BE611/$A$2/$B$2 -> 3.9094246
A612: 606 | B612: 0.000965929 | C612: 0.0325054 | D612: 33.6844 | E612: 33.6519 | F612: 0.00344186 | G612: 0.0172327 | H612: 5.02403 | I612: 5.00679 | J612: 0.00392415 | K612: 0.0200322 | L612: 5.12488 | M612: 5.10485 | N612: 0.00348753 | O612: 0.0184983 | P612: 5.32262 | Q612: 5.30412 | R612: 0.00492826 | S612: 0.0225851 | T612: 4.60535 | U612: 4.58276 | V612: 0.00541478 | W612: 0.0260588 | X612: 4.83859 | Y612: 4.81253 | Z612: 0.00594415 | AA612: 0.0267801 | AB612: 4.53206 | AC612: 4.50528 | AD612: 0.0069644 | AE612: 0.0326323 | AF612: 4.71823 | AG612: 4.68559 | AH612: 0.00899176 | AI612: 0.0382883 | AJ612: 4.29644 | AK612: 4.25815 | AL612: 0.00973407 | AM612: 0.0439887 | AN612: 4.56304 | AO612: 4.51905 | AP612: 0.0107159 | AQ612: 0.0496469 | AR612: 4.68265 | AS612: 4.633 | AT612: 0.0126854 | AU612: 0.0597874 | AV612: 4.77289 | AW612: 4.7131 | AX612: 0.0207167 | AY612: 0.0696537 | AZ612: 3.43186 | BA612: 3.3622 | BB612: 55.848 | BC612: 55.848 | BD612: 0.0078 | BE612: 48.4513 | BF612: =BE612/$A$2/$B$2 -> 0.96133532
A613: 607 | B613: 0.000899076 | C613: 0.0302557 | D613: 33.6822 | E613: 33.6519 | F613: 0.0035211 | G613: 0.0176294 | H613: 5.02442 | I613: 5.00679 | J613: 0.00393546 | K613: 0.02009 | L613: 5.12494 | M613: 5.10485 | N613: 0.00353284 | O613: 0.0187386 | P613: 5.32286 | Q613: 5.30412 | R613: 0.00491495 | S613: 0.022524 | T613: 4.60529 | U613: 4.58276 | V613: 0.00539754 | W613: 0.0259758 | X613: 4.8385 | Y613: 4.81253 | Z613: 0.00598985 | AA613: 0.0269859 | AB613: 4.53227 | AC613: 4.50528 | AD613: 0.00692049 | AE613: 0.0324266 | AF613: 4.71802 | AG613: 4.68559 | AH613: 0.0090009 | AI613: 0.0383272 | AJ613: 4.29648 | AK613: 4.25815 | AL613: 0.00969258 | AM613: 0.0438012 | AN613: 4.56285 | AO613: 4.51905 | AP613: 0.0106537 | AQ613: 0.0493587 | AR613: 4.68236 | AS613: 4.633 | AT613: 0.0127097 | AU613: 0.0599021 | AV613: 4.773 | AW613: 4.7131 | AX613: 0.0208094 | AY613: 0.0699656 | AZ613: 3.43217 | BA613: 3.3622 | BB613: 55.973 | BC613: 55.974 | BD613: -0.0045 | BE613: -12.9205 | BF613: =BE613/$A$2/$B$2 -> -0.25635913
A614: 608 | B614: 0.000831217 | C614: 0.0279721 | D614: 33.6799 | E614: 33.6519 | F614: 0.00350665 | G614: 0.0175571 | H614: 5.02435 | I614: 5.00679 | J614: 0.00397171 | K614: 0.020275 | L614: 5.12512 | M614: 5.10485 | N614: 0.00351791 | O614: 0.0186594 | P614: 5.32278 | Q614: 5.30412 | R614: 0.00504134 | S614: 0.0231033 | T614: 4.60587 | U614: 4.58276 | V614: 0.00542043 | W614: 0.026086 | X614: 4.83861 | Y614: 4.81253 | Z614: 0.00599468 | AA614: 0.0270077 | AB614: 4.53229 | AC614: 4.50528 | AD614: 0.00695448 | AE614: 0.0325859 | AF614: 4.71818 | AG614: 4.68559 | AH614: 0.00903235 | AI614: 0.0384611 | AJ614: 4.29662 | AK614: 4.25815 | AL614: 0.00974278 | AM614: 0.0440281 | AN614: 4.56307 | AO614: 4.51905 | AP614: 0.0106964 | AQ614: 0.0495565 | AR614: 4.68256 | AS614: 4.633 | AT614: 0.0126196 | AU614: 0.0594777 | AV614: 4.77258 | AW614: 4.7131 | AX614: 0.0206985 | AY614: 0.0695925 | AZ614: 3.4318 | BA614: 3.3622 | BB614: 56.288 | BC614: 56.289 | BD614: -0.0093 | BE614: -37.1461 | BF614: =BE614/$A$2/$B$2 -> -0.73702579
A615: 609 | B615: 0.000750198 | C615: 0.0252456 | D615: 33.6772 | E615: 33.6519 | F615: 0.00354924 | G615: 0.0177703 | H615: 5.02457 | I615: 5.00679 | J615: 0.00406271 | K615: 0.0207395 | L615: 5.12559 | M615: 5.10485 | N615: 0.00346072 | O615: 0.0183561 | P615: 5.32248 | Q615: 5.30412 | R615: 0.00500528 | S615: 0.022938 | T615: 4.6057 | U615: 4.58276 | V615: 0.00539749 | W615: 0.0259756 | X615: 4.8385 | Y615: 4.81253 | Z615: 0.00605137 | AA615: 0.0272631 | AB615: 4.53254 | AC615: 4.50528 | AD615: 0.00687549 | AE615: 0.0322157 | AF615: 4.71781 | AG615: 4.68559 | AH615: 0.00912381 | AI615: 0.0388506 | AJ615: 4.29701 | AK615: 4.25815 | AL615: 0.00967518 | AM615: 0.0437226 | AN615: 4.56277 | AO615: 4.51905 | AP615: 0.0108006 | AQ615: 0.0500391 | AR615: 4.68304 | AS615: 4.633 | AT615: 0.0126501 | AU615: 0.0596211 | AV615: 4.77272 | AW615: 4.7131 | AX615: 0.0209849 | AY615: 0.0705554 | AZ615: 3.43276 | BA615: 3.3622 | BB615: 57.346 | BC615: 57.346 | BD615: -0.0151 | BE615: -66.2169 | BF615: =BE615/$A$2/$B$2 -> -1.3138274
A616: 610 | B616: 0.000753087 | C616: 0.0253428 | D616: 33.6773 | E616: 33.6519 | F616: 0.00359969 | G616: 0.0180229 | H616: 5.02482 | I616: 5.00679 | J616: 0.00415474 | K616: 0.0212093 | L616: 5.12606 | M616: 5.10485 | N616: 0.00354824 | O616: 0.0188203 | P616: 5.32294 | Q616: 5.30412 | R616: 0.00520349 | S616: 0.0238464 | T616: 4.60661 | U616: 4.58276 | V616: 0.00550079 | W616: 0.0264727 | X616: 4.839 | Y616: 4.81253 | Z616: 0.00613718 | AA616: 0.0276497 | AB616: 4.53293 | AC616: 4.50528 | AD616: 0.00689854 | AE616: 0.0323237 | AF616: 4.71792 | AG616: 4.68559 | AH616: 0.00913382 | AI616: 0.0388932 | AJ616: 4.29705 | AK616: 4.25815 | AL616: 0.00968764 | AM616: 0.0437789 | AN616: 4.56283 | AO616: 4.51905 | AP616: 0.0107695 | AQ616: 0.0498953 | AR616: 4.6829 | AS616: 4.633 | AT616: 0.0126206 | AU616: 0.0594821 | AV616: 4.77258 | AW616: 4.7131 | AX616: 0.0210406 | AY616: 0.0707429 | AZ616: 3.43295 | BA616: 3.3622 | BB616: 57.909 | BC616: 57.909 | BD616: -0.0148 | BE616: -64.6019 | BF616: =BE616/$A$2/$B$2 -> -1.2817837
A617: 611 | B617: 0.00066566 | C617: 0.0224008 | D617: 33.6743 | E617: 33.6519 | F617: 0.00372185 | G617: 0.0186345 | H617: 5.02543 | I617: 5.00679 | J617: 0.00425132 | K617: 0.0217023 | L617: 5.12655 | M617: 5.10485 | N617: 0.00367385 | O617: 0.0194865 | P617: 5.32361 | Q617: 5.30412 | R617: 0.00519846 | S617: 0.0238233 | T617: 4.60659 | U617: 4.58276 | V617: 0.005521 | W617: 0.02657 | X617: 4.8391 | Y617: 4.81253 | Z617: 0.00617247 | AA617: 0.0278087 | AB617: 4.53309 | AC617: 4.50528 | AD617: 0.00688719 | AE617: 0.0322706 | AF617: 4.71786 | AG617: 4.68559 | AH617: 0.00915258 | AI617: 0.0389731 | AJ617: 4.29713 | AK617: 4.25815 | AL617: 0.0096572 | AM617: 0.0436413 | AN617: 4.56269 | AO617: 4.51905 | AP617: 0.0108395 | AQ617: 0.0502195 | AR617: 4.68322 | AS617: 4.633 | AT617: 0.012659 | AU617: 0.0596632 | AV617: 4.77276 | AW617: 4.7131 | AX617: 0.0210599 | AY617: 0.0708076 | AZ617: 3.43301 | BA617: 3.3622 | BB617: 58.593 | BC617: 58.593 | BD617: -0.0132 | BE617: -56.5267 | BF617: =BE617/$A$2/$B$2 -> -1.1215615

Sheet OLT-2
A1: w | B1: t | BO1: =MATCH(BN3,BN5:BN1048576,0)-1 -> 597
A2: 6 | B2: 8.3 | BN2: Ult Stress, MPa | BO2: Failure Strains, % | BR2: E1, MPa | BS2: ν31
A3: Average | B3: E0 | F3: E1 | J3: E2 | N3: E3 | R3: E4 | V3: E5 | Z3: E6 | AD3: E7 | AH3: E8 | AL3: E9 | AP3: E10 | AT3: E11 | AX3: E12 | BB3: E13 | BF3: E14 | BJ3: Analog | BN3: =MAX(BN5:BN1048576) -> 410.18273 | BO3: =INDEX(BO5:BO1048576,MATCH(BN3,BN5:BN1048576,0)) -> 0.0120809 | BP3: =INDEX(BP5:BP1048576,MATCH(BN3,BN5:BN1048576,0)) -> 0.00368776 | BQ3: =INDEX(BQ5:BQ1048576,MATCH(BN3,BN5:BN1048576,0)) -> -0.0025390362 | BR3: =INDEX(LINEST(BN14:BN352,BO14:BO352),1) -> 32065.095 | BS3: =INDEX(LINEST(BP14:BP352,BO14:BO352),1) -> 0.36641512
A4: Index [1] | B4: ?L/L0 [1] | C4: ?L [mm] | D4: L1 [mm] | E4: L0 [mm] | F4: ?L/L0 [1] | G4: ?L [mm] | H4: L1 [mm] | I4: L0 [mm] | J4: ?L/L0 [1] | K4: ?L [mm] | L4: L1 [mm] | M4: L0 [mm] | N4: ?L/L0 [1] | O4: ?L [mm] | P4: L1 [mm] | Q4: L0 [mm] | R4: ?L/L0 [1] | S4: ?L [mm] | T4: L1 [mm] | U4: L0 [mm] | V4: ?L/L0 [1] | W4: ?L [mm] | X4: L1 [mm] | Y4: L0 [mm] | Z4: ?L/L0 [1] | AA4: ?L [mm] | AB4: L1 [mm] | AC4: L0 [mm] | AD4: ?L/L0 [1] | AE4: ?L [mm] | AF4: L1 [mm] | AG4: L0 [mm] | AH4: ?L/L0 [1] | AI4: ?L [mm] | AJ4: L1 [mm] | AK4: L0 [mm] | AL4: ?L/L0 [1] | AM4: ?L [mm] | AN4: L1 [mm] | AO4: L0 [mm] | AP4: ?L/L0 [1] | AQ4: ?L [mm] | AR4: L1 [mm] | AS4: L0 [mm] | AT4: ?L/L0 [1] | AU4: ?L [mm] | AV4: L1 [mm] | AW4: L0 [mm] | AX4: ?L/L0 [1] | AY4: ?L [mm] | AZ4: L1 [mm] | BA4: L0 [mm] | BB4: ?L/L0 [1] | BC4: ?L [mm] | BD4: L1 [mm] | BE4: L0 [mm] | BF4: ?L/L0 [1] | BG4: ?L [mm] | BH4: L1 [mm] | BI4: L0 [mm] | BJ4: Time_1 | BK4: Time_0 | BL4: Dev1/ai0 | BM4: Force_[N] | BN4: σ1, MPa | BO4: ε1 | BP4: ε3 | BQ4: ε3_v1
A5: 0 | B5: 0 | C5: 0 | D5: 33.6492 | E5: 33.6492 | F5: 0 | G5: 0 | H5: 4.44226 | I5: 4.44226 | J5: 0 | K5: 0 | L5: 4.51466 | M5: 4.51466 | N5: 0 | O5: 0 | P5: 4.53363 | Q5: 4.53363 | R5: 0 | S5: 0 | T5: 5.06822 | U5: 5.06822 | V5: 0 | W5: 0 | X5: 4.65748 | Y5: 4.65748 | Z5: 0 | AA5: 0 | AB5: 4.20099 | AC5: 4.20099 | AD5: 0 | AE5: 0 | AF5: 4.35175 | AG5: 4.35175 | AH5: 0 | AI5: 0 | AJ5: 4.3448 | AK5: 4.3448 | AL5: 0 | AM5: 0 | AN5: 3.99554 | AO5: 3.99554 | AP5: 0 | AQ5: 0 | AR5: 4.2886 | AS5: 4.2886 | AT5: 0 | AU5: 0 | AV5: 3.69256 | AW5: 3.69256 | AX5: 0 | AY5: 0 | AZ5: 3.98075 | BA5: 3.98075 | BB5: 0 | BC5: 0 | BD5: 3.55967 | BE5: 3.55967 | BF5: 0 | BG5: 0 | BH5: 4.85271 | BI5: 4.85271 | BJ5: 0 | BK5: 0.004 | BL5: 0.0071 | BM5: 45.2212 | BN5: =BM5/$A$2/$B$2 -> 0.90805622 | BO5: =B5 -> 0 | BP5: =-AVERAGE(J5,V5,AD5,AP5,AX5) -> 0 | BQ5: =-AVERAGE(F5,J5,N5,R5,V5,Z5,AD5,AH5,AP5,AT5,AX5,BB5,BF5) -> 0
A6: 1 | B6: -2.101e-05 | C6: -0.000706971 | D6: 33.6485 | E6: 33.6492 | F6: 7.50363e-06 | G6: 3.33331e-05 | H6: 4.44229 | I6: 4.44226 | J6: 2.14996e-05 | K6: 9.70633e-05 | L6: 4.51475 | M6: 4.51466 | N6: 4.21534e-05 | O6: 0.000191108 | P6: 4.53382 | Q6: 4.53363 | R6: -1.94572e-06 | S6: -9.86135e-06 | T6: 5.06821 | U6: 5.06822 | V6: -3.48825e-05 | W6: -0.000162464 | X6: 4.65731 | Y6: 4.65748 | Z6: -0.000100586 | AA6: -0.000422563 | AB6: 4.20057 | AC6: 4.20099 | AD6: -3.67164e-06 | AE6: -1.5978e-05 | AF6: 4.35173 | AG6: 4.35175 | AH6: 3.10286e-06 | AI6: 1.34813e-05 | AJ6: 4.34481 | AK6: 4.3448 | AL6: -3.40246e-07 | AM6: -1.35946e-06 | AN6: 3.99554 | AO6: 3.99554 | AP6: 8.63981e-06 | AQ6: 3.70527e-05 | AR6: 4.28864 | AS6: 4.2886 | AT6: -2.42903e-05 | AU6: -8.96933e-05 | AV6: 3.69247 | AW6: 3.69256 | AX6: 1.61147e-05 | AY6: 6.41485e-05 | AZ6: 3.98081 | BA6: 3.98075 | BB6: -8.36854e-06 | BC6: -2.97892e-05 | BD6: 3.55964 | BE6: 3.55967 | BF6: 3.88707e-05 | BG6: 0.000188628 | BH6: 4.85289 | BI6: 4.85271 | BJ6: 0.746 | BK6: 0.746 | BL6: 0.0058 | BM6: 38.761 | BN6: =BM6/$A$2/$B$2 -> 0.77833333 | BO6: =B6 -> -2.101e-05 | BP6: =-AVERAGE(J6,V6,AD6,AP6,AX6) -> -1.539994e-06 | BQ6: =AVERAGE(F6,J6,N6,R6,V6,Z6,AD6,AH6,AP6,AT6,AX6,BB6,BF6) -> -2.7584615e-06
A7: 2 | B7: -7.34135e-06 | C7: -0.00024703 | D7: 33.6489 | E7: 33.6492 | F7: -2.50209e-05 | G7: -0.000111149 | H7: 4.44214 | I7: 4.44226 | J7: 7.12477e-06 | K7: 3.21659e-05 | L7: 4.51469 | M7: 4.51466 | N7: -2.75528e-05 | O7: -0.000124914 | P7: 4.53351 | Q7: 4.53363 | R7: -5.62042e-06 | S7: -2.84855e-05 | T7: 5.06819 | U7: 5.06822 | V7: -4.63606e-05 | W7: -0.000215923 | X7: 4.65726 | Y7: 4.65748 | Z7: -5.68705e-05 | AA7: -0.000238913 | AB7: 4.20076 | AC7: 4.20099 | AD7: 2.25372e-05 | AE7: 9.80763e-05 | AF7: 4.35184 | AG7: 4.35175 | AH7: 3.99205e-06 | AI7: 1.73447e-05 | AJ7: 4.34482 | AK7: 4.3448 | AL7: -9.66554e-05 | AM7: -0.00038619 | AN7: 3.99515 | AO7: 3.99554 | AP7: -1.60409e-05 | AQ7: -6.87929e-05 | AR7: 4.28853 | AS7: 4.2886 | AT7: -7.85859e-05 | AU7: -0.000290183 | AV7: 3.69227 | AW7: 3.69256 | AX7: -2.23913e-05 | AY7: -8.91339e-05 | AZ7: 3.98066 | BA7: 3.98075 | BB7: -9.01812e-06 | BC7: -3.21015e-05 | BD7: 3.55963 | BE7: 3.55967 | BF7: -9.72013e-06 | BG7: -4.71689e-05 | BH7: 4.85266 | BI7: 4.85271 | BJ7: 1.807 | BK7: 1.807 | BL7: 0.0058 | BM7: 38.761 | BN7: =BM7/$A$2/$B$2 -> 0.77833333 | BO7: =B7 -> -7.34135e-06 | BP7: =-AVERAGE(J7,V7,AD7,AP7,AX7) -> 1.1026166e-05 | BQ7: =AVERAGE(F7,J7,N7,R7,V7,Z7,AD7,AH7,AP7,AT7,AX7,BB7,BF7) -> -2.027135e-05
A8: 3 | B8: -2.22326e-05 | C8: -0.000748109 | D8: 33.6484 | E8: 33.6492 | F8: 7.53003e-05 | G8: 0.000334503 | H8: 4.44259 | I8: 4.44226 | J8: 2.39008e-05 | K8: 0.000107904 | L8: 4.51476 | M8: 4.51466 | N8: 1.296e-05 | O8: 5.87561e-05 | P8: 4.53369 | Q8: 4.53363 | R8: 2.85671e-06 | S8: 1.44784e-05 | T8: 5.06824 | U8: 5.06822 | V8: -3.3266e-05 | W8: -0.000154935 | X8: 4.65732 | Y8: 4.65748 | Z8: -7.4236e-05 | AA8: -0.000311865 | AB8: 4.20068 | AC8: 4.20099 | AD8: -2.697e-05 | AE8: -0.000117367 | AF8: 4.35163 | AG8: 4.35175 | AH8: -2.8276e-05 | AI8: -0.000122854 | AJ8: 4.34468 | AK8: 4.3448 | AL8: -3.89994e-05 | AM8: -0.000155824 | AN8: 3.99538 | AO8: 3.99554 | AP8: -6.3918e-05 | AQ8: -0.000274119 | AR8: 4.28833 | AS8: 4.2886 | AT8: -0.000187548 | AU8: -0.000692533 | AV8: 3.69187 | AW8: 3.69256 | AX8: -0.000120124 | AY8: -0.000478183 | AZ8: 3.98027 | BA8: 3.98075 | BB8: -0.000125639 | BC8: -0.000447233 | BD8: 3.55922 | BE8: 3.55967 | BF8: -9.11164e-05 | BG8: -0.000442161 | BH8: 4.85226 | BI8: 4.85271 | BJ8: 2.928 | BK8: 2.928 | BL8: 0.0078 | BM8: 48.4513 | BN8: =BM8/$A$2/$B$2 -> 0.97291767 | BO8: =B8 -> -2.22326e-05 | BP8: =-AVERAGE(J8,V8,AD8,AP8,AX8) -> 4.407544e-05 | BQ8: =AVERAGE(F8,J8,N8,R8,V8,Z8,AD8,AH8,AP8,AT8,AX8,BB8,BF8) -> -4.8928892e-05
A9: 4 | B9: -4.04073e-05 | C9: -0.00135967 | D9: 33.6478 | E9: 33.6492 | F9: -4.47049e-05 | G9: -0.00019859 | H9: 4.44206 | I9: 4.44226 | J9: -5.78014e-05 | K9: -0.000260954 | L9: 4.5144 | M9: 4.51466 | N9: -6.39375e-05 | O9: -0.000289869 | P9: 4.53334 | Q9: 4.53363 | R9: -7.96732e-05 | S9: -0.000403802 | T9: 5.06782 | U9: 5.06822 | V9: -0.000137595 | W9: -0.000640847 | X9: 4.65684 | Y9: 4.65748 | Z9: -0.000106205 | AA9: -0.000446167 | AB9: 4.20055 | AC9: 4.20099 | AD9: -7.97828e-06 | AE9: -3.47195e-05 | AF9: 4.35171 | AG9: 4.35175 | AH9: -8.43467e-05 | AI9: -0.00036647 | AJ9: 4.34443 | AK9: 4.3448 | AL9: -8.76932e-05 | AM9: -0.000350382 | AN9: 3.99519 | AO9: 3.99554 | AP9: -0.000106364 | AQ9: -0.000456153 | AR9: 4.28814 | AS9: 4.2886 | AT9: -0.000125789 | AU9: -0.000464483 | AV9: 3.6921 | AW9: 3.69256 | AX9: -0.000121193 | AY9: -0.000482439 | AZ9: 3.98026 | BA9: 3.98075 | BB9: -0.000156217 | BC9: -0.000556081 | BD9: 3.55911 | BE9: 3.55967 | BF9: -7.98012e-05 | BG9: -0.000387252 | BH9: 4.85232 | BI9: 4.85271 | BJ9: 3.367 | BK9: 3.367 | BL9: 0.0058 | BM9: 38.761 | BN9: =BM9/$A$2/$B$2 -> 0.77833333 | BO9: =B9 -> -4.04073e-05 | BP9: =-AVERAGE(J9,V9,AD9,AP9,AX9) -> 8.6186336e-05 | BQ9: =AVERAGE(F9,J9,N9,R9,V9,Z9,AD9,AH9,AP9,AT9,AX9,BB9,BF9) -> -9.0123552e-05
A10: 5 | B10: 2.63365e-06 | C10: 8.862e-05 | D10: 33.6493 | E10: 33.6492 | F10: 3.04063e-05 | G10: 0.000135073 | H10: 4.44239 | I10: 4.44226 | J10: 8.64476e-06 | K10: 3.90281e-05 | L10: 4.5147 | M10: 4.51466 | N10: 1.02983e-05 | O10: 4.66885e-05 | P10: 4.53368 | Q10: 4.53363 | R10: 4.48147e-05 | S10: 0.000227131 | T10: 5.06845 | U10: 5.06822 | V10: -1.82543e-05 | W10: -8.50189e-05 | X10: 4.65739 | Y10: 4.65748 | Z10: -4.56345e-05 | AA10: -0.00019171 | AB10: 4.2008 | AC10: 4.20099 | AD10: 2.40471e-05 | AE10: 0.000104647 | AF10: 4.35185 | AG10: 4.35175 | AH10: 5.21802e-05 | AI10: 0.000226713 | AJ10: 4.34503 | AK10: 4.3448 | AL10: -3.98357e-05 | AM10: -0.000159165 | AN10: 3.99538 | AO10: 3.99554 | AP10: -1.699e-05 | AQ10: -7.28632e-05 | AR10: 4.28853 | AS10: 4.2886 | AT10: -8.1584e-05 | AU10: -0.000301254 | AV10: 3.69226 | AW10: 3.69256 | AX10: 3.48069e-06 | AY10: 1.38557e-05 | AZ10: 3.98076 | BA10: 3.98075 | BB10: -2.70235e-05 | BC10: -9.61945e-05 | BD10: 3.55957 | BE10: 3.55967 | BF10: 2.32989e-06 | BG10: 1.13063e-05 | BH10: 4.85272 | BI10: 4.85271 | BJ10: 4.489 | BK10: 4.489 | BL10: 0.0062 | BM10: 40.376 | BN10: =BM10/$A$2/$B$2 -> 0.81076305 | BO10: =B10 -> 2.63365e-06 | BP10: =-AVERAGE(J10,V10,AD10,AP10,AX10) -> -1.8565e-07 | BQ10: =AVERAGE(F10,J10,N10,R10,V10,Z10,AD10,AH10,AP10,AT10,AX10,BB10,BF10) -> -1.0218738e-06
A11: 6 | B11: -4.57107e-06 | C11: -0.000153813 | D11: 33.649 | E11: 33.6492 | F11: 5.51612e-05 | G11: 0.00024504 | H11: 4.4425 | I11: 4.44226 | J11: 5.54997e-05 | K11: 0.000250562 | L11: 4.51491 | M11: 4.51466 | N11: 4.7073e-05 | O11: 0.000213412 | P11: 4.53384 | Q11: 4.53363 | R11: 4.54548e-05 | S11: 0.000230375 | T11: 5.06845 | U11: 5.06822 | V11: 3.87369e-06 | W11: 1.80416e-05 | X11: 4.6575 | Y11: 4.65748 | Z11: -3.01297e-05 | AA11: -0.000126575 | AB11: 4.20087 | AC11: 4.20099 | AD11: 6.69832e-05 | AE11: 0.000291494 | AF11: 4.35204 | AG11: 4.35175 | AH11: 2.64398e-05 | AI11: 0.000114876 | AJ11: 4.34492 | AK11: 4.3448 | AL11: -7.66965e-06 | AM11: -3.06444e-05 | AN11: 3.99551 | AO11: 3.99554 | AP11: 1.68221e-06 | AQ11: 7.21432e-06 | AR11: 4.28861 | AS11: 4.2886 | AT11: -8.83286e-05 | AU11: -0.000326159 | AV11: 3.69223 | AW11: 3.69256 | AX11: -0.000123349 | AY11: -0.000491021 | AZ11: 3.98025 | BA11: 3.98075 | BB11: -9.57827e-05 | BC11: -0.000340954 | BD11: 3.55933 | BE11: 3.55967 | BF11: -5.72619e-05 | BG11: -0.000277875 | BH11: 4.85243 | BI11: 4.85271 | BJ11: 5.551 | BK11: 5.551 | BL11: 0.0065 | BM11: 41.9911 | BN11: =BM11/$A$2/$B$2 -> 0.84319478 | BO11: =B11 -> -4.57107e-06 | BP11: =-AVERAGE(J11,V11,AD11,AP11,AX11) -> -9.3796e-07 | BQ11: =AVERAGE(F11,J11,N11,R11,V11,Z11,AD11,AH11,AP11,AT11,AX11,BB11,BF11) -> -7.1295615e-06
A12: 7 | B12: 4.49597e-05 | C12: 0.00151286 | D12: 33.6507 | E12: 33.6492 | F12: 2.39239e-05 | G12: 0.000106276 | H12: 4.44236 | I12: 4.44226 | J12: 3.45314e-05 | K12: 0.000155897 | L12: 4.51481 | M12: 4.51466 | N12: 3.33755e-05 | O12: 0.000151312 | P12: 4.53378 | Q12: 4.53363 | R12: 6.6475e-05 | S12: 0.00033691 | T12: 5.06856 | U12: 5.06822 | V12: -9.36683e-06 | W12: -4.36258e-05 | X12: 4.65743 | Y12: 4.65748 | Z12: 1.97292e-05 | AA12: 8.28822e-05 | AB12: 4.20108 | AC12: 4.20099 | AD12: 5.5904e-05 | AE12: 0.00024328 | AF12: 4.35199 | AG12: 4.35175 | AH12: 5.83444e-05 | AI12: 0.000253495 | AJ12: 4.34505 | AK12: 4.3448 | AL12: -8.1268e-06 | AM12: -3.24709e-05 | AN12: 3.9955 | AO12: 3.99554 | AP12: -2.32777e-05 | AQ12: -9.98287e-05 | AR12: 4.2885 | AS12: 4.2886 | AT12: -4.43205e-05 | AU12: -0.000163656 | AV12: 3.6924 | AW12: 3.69256 | AX12: -7.81705e-05 | AY12: -0.000311177 | AZ12: 3.98043 | BA12: 3.98075 | BB12: -3.37014e-05 | BC12: -0.000119966 | BD12: 3.55955 | BE12: 3.55967 | BF12: 2.59216e-07 | BG12: 1.2579e-06 | BH12: 4.85271 | BI12: 4.85271 | BJ12: 6.297 | BK12: 6.298 | BL12: 0.0078 | BM12: 48.4513 | BN12: =BM12/$A$2/$B$2 -> 0.97291767 | BO12: =B12 -> 4.49597e-05 | BP12: =-AVERAGE(J12,V12,AD12,AP12,AX12) -> 4.075926e-06 | BQ12: =AVERAGE(F12,J12,N12,R12,V12,Z12,AD12,AH12,AP12,AT12,AX12,BB12,BF12) -> 7.9773605e-06
A13: 8 | B13: -3.6018e-06 | C13: -0.000121198 | D13: 33.649 | E13: 33.6492 | F13: 7.6631e-05 | G13: 0.000340415 | H13: 4.4426 | I13: 4.44226 | J13: 2.80986e-05 | K13: 0.000126855 | L13: 4.51478 | M13: 4.51466 | N13: 1.4647e-05 | O13: 6.6404e-05 | P13: 4.5337 | Q13: 4.53363 | R13: 1.82026e-05 | S13: 9.22548e-05 | T13: 5.06832 | U13: 5.06822 | V13: -5.41316e-06 | W13: -2.52116e-05 | X13: 4.65745 | Y13: 4.65748 | Z13: -8.21251e-05 | AA13: -0.000345007 | AB13: 4.20065 | AC13: 4.20099 | AD13: 1.51025e-06 | AE13: 6.57221e-06 | AF13: 4.35175 | AG13: 4.35175 | AH13: -2.50423e-05 | AI13: -0.000108804 | AJ13: 4.34469 | AK13: 4.3448 | AL13: -7.63255e-05 | AM13: -0.000304961 | AN13: 3.99523 | AO13: 3.99554 | AP13: 3.30907e-06 | AQ13: 1.41913e-05 | AR13: 4.28861 | AS13: 4.2886 | AT13: -8.79311e-05 | AU13: -0.000324691 | AV13: 3.69224 | AW13: 3.69256 | AX13: -8.40079e-05 | AY13: -0.000334414 | AZ13: 3.98041 | BA13: 3.98075 | BB13: -5.8298e-05 | BC13: -0.000207521 | BD13: 3.55946 | BE13: 3.55967 | BF13: -8.36922e-05 | BG13: -0.000406134 | BH13: 4.8523 | BI13: 4.85271 | BJ13: 6.424 | BK13: 6.424 | BL13: 0.0084 | BM13: 51.6813 | BN13: =BM13/$A$2/$B$2 -> 1.0377771 | BO13: =B13 -> -3.6018e-06 | BP13: =-AVERAGE(J13,V13,AD13,AP13,AX13) -> 1.1300628e-05 | BQ13: =AVERAGE(F13,J13,N13,R13,V13,Z13,AD13,AH13,AP13,AT13,AX13,BB13,BF13) -> -2.1854711e-05
A14: 9 | B14: 9.75534e-06 | C14: 0.000328259 | D14: 33.6495 | E14: 33.6492 | F14: -3.18817e-05 | G14: -0.000141627 | H14: 4.44211 | I14: 4.44226 | J14: -1.62102e-05 | K14: -7.31833e-05 | L14: 4.51458 | M14: 4.51466 | N14: -1.35316e-05 | O14: -6.13474e-05 | P14: 4.53357 | Q14: 4.53363 | R14: -4.61458e-05 | S14: -0.000233877 | T14: 5.06799 | U14: 5.06822 | V14: -3.78257e-05 | W14: -0.000176172 | X14: 4.6573 | Y14: 4.65748 | Z14: -5.61587e-05 | AA14: -0.000235922 | AB14: 4.20076 | AC14: 4.20099 | AD14: -5.1384e-05 | AE14: -0.00022361 | AF14: 4.35152 | AG14: 4.35175 | AH14: -8.76961e-06 | AI14: -3.81022e-05 | AJ14: 4.34476 | AK14: 4.3448 | AL14: -3.71444e-05 | AM14: -0.000148412 | AN14: 3.99539 | AO14: 3.99554 | AP14: -2.78265e-05 | AQ14: -0.000119337 | AR14: 4.28848 | AS14: 4.2886 | AT14: -3.71175e-05 | AU14: -0.000137058 | AV14: 3.69242 | AW14: 3.69256 | AX14: -3.90205e-05 | AY14: -0.000155331 | AZ14: 3.98059 | BA14: 3.98075 | BB14: -6.44388e-05 | BC14: -0.000229381 | BD14: 3.55944 | BE14: 3.55967 | BF14: -1.92006e-05 | BG14: -9.3175e-05 | BH14: 4.85261 | BI14: 4.85271 | BJ14: 7.483 | BK14: 7.483 | BL14: 0.0168 | BM14: 93.6725 | BN14: =BM14/$A$2/$B$2 -> 1.8809739 | BO14: =B14 -> 9.75534e-06 | BP14: =-AVERAGE(J14,V14,AD14,AP14,AX14) -> 3.445338e-05 | BQ14: =AVERAGE(F14,J14,N14,R14,V14,Z14,AD14,AH14,AP14,AT14,AX14,BB14,BF14) -> -3.4577785e-05
A15: 10 | B15: 4.39118e-05 | C15: 0.00147759 | D15: 33.6506 | E15: 33.6492 | F15: -5.9701e-05 | G15: -0.000265207 | H15: 4.44199 | I15: 4.44226 | J15: -5.93798e-05 | K15: -0.000268079 | L15: 4.51439 | M15: 4.51466 | N15: -2.5837e-05 | O15: -0.000117136 | P15: 4.53351 | Q15: 4.53363 | R15: -5.78422e-05 | S15: -0.000293157 | T15: 5.06793 | U15: 5.06822 | V15: -0.000146742 | W15: -0.000683448 | X15: 4.65679 | Y15: 4.65748 | Z15: -9.75904e-05 | AA15: -0.000409977 | AB15: 4.20058 | AC15: 4.20099 | AD15: -7.99708e-05 | AE15: -0.000348013 | AF15: 4.3514 | AG15: 4.35175 | AH15: -9.0781e-05 | AI15: -0.000394425 | AJ15: 4.34441 | AK15: 4.3448 | AL15: -0.000111212 | AM15: -0.00044435 | AN15: 3.99509 | AO15: 3.99554 | AP15: -7.52363e-05 | AQ15: -0.000322658 | AR15: 4.28828 | AS15: 4.2886 | AT15: -0.000178976 | AU15: -0.000660881 | AV15: 3.6919 | AW15: 3.69256 | AX15: -0.000119695 | AY15: -0.000476476 | AZ15: 3.98027 | BA15: 3.98075 | BB15: -7.12298e-05 | BC15: -0.000253554 | BD15: 3.55941 | BE15: 3.55967 | BF15: -6.33694e-05 | BG15: -0.000307513 | BH15: 4.8524 | BI15: 4.85271 | BJ15: 7.608 | BK15: 7.609 | BL15: 0.0181 | BM15: 100.133 | BN15: =BM15/$A$2/$B$2 -> 2.0107028 | BO15: =B15 -> 4.39118e-05 | BP15: =-AVERAGE(J15,V15,AD15,AP15,AX15) -> 9.620478e-05 | BQ15: =AVERAGE(F15,J15,N15,R15,V15,Z15,AD15,AH15,AP15,AT15,AX15,BB15,BF15) -> -8.6642362e-05
A16: 11 | B16: 9.78681e-05 | C16: 0.00329318 | D16: 33.6525 | E16: 33.6492 | F16: -7.89851e-05 | G16: -0.000350872 | H16: 4.44191 | I16: 4.44226 | J16: -4.10366e-05 | K16: -0.000185266 | L16: 4.51447 | M16: 4.51466 | N16: -1.88587e-05 | O16: -8.54982e-05 | P16: 4.53355 | Q16: 4.53363 | R16: -7.13022e-06 | S16: -3.61376e-05 | T16: 5.06819 | U16: 5.06822 | V16: -3.30943e-05 | W16: -0.000154136 | X16: 4.65732 | Y16: 4.65748 | Z16: -1.97555e-05 | AA16: -8.29926e-05 | AB16: 4.20091 | AC16: 4.20099 | AD16: -3.16883e-05 | AE16: -0.000137899 | AF16: 4.35161 | AG16: 4.35175 | AH16: 7.45181e-06 | AI16: 3.23766e-05 | AJ16: 4.34483 | AK16: 4.3448 | AL16: -3.99436e-05 | AM16: -0.000159596 | AN16: 3.99538 | AO16: 3.99554 | AP16: 6.46611e-06 | AQ16: 2.77305e-05 | AR16: 4.28863 | AS16: 4.2886 | AT16: -0.000144326 | AU16: -0.000532933 | AV16: 3.69203 | AW16: 3.69256 | AX16: -0.000141243 | AY16: -0.000562251 | AZ16: 3.98018 | BA16: 3.98075 | BB16: -0.000147455 | BC16: -0.00052489 | BD16: 3.55914 | BE16: 3.55967 | BF16: -6.26924e-05 | BG16: -0.000304228 | BH16: 4.8524 | BI16: 4.85271 | BJ16: 7.859 | BK16: 7.859 | BL16: 0.0361 | BM16: 190.575 | BN16: =BM16/$A$2/$B$2 -> 3.8268072 | BO16: =B16 -> 9.78681e-05 | BP16: =-AVERAGE(J16,V16,AD16,AP16,AX16) -> 4.8119218e-05 | BQ16: =AVERAGE(F16,J16,N16,R16,V16,Z16,AD16,AH16,AP16,AT16,AX16,BB16,BF16) -> -5.4795938e-05
A17: 12 | B17: 0.000161872 | C17: 0.00544684 | D17: 33.6546 | E17: 33.6492 | F17: -7.20975e-05 | G17: -0.000320275 | H17: 4.44194 | I17: 4.44226 | J17: -7.30142e-05 | K17: -0.000329634 | L17: 4.51433 | M17: 4.51466 | N17: -5.57726e-05 | O17: -0.000252853 | P17: 4.53338 | Q17: 4.53363 | R17: -5.34141e-05 | S17: -0.000270715 | T17: 5.06795 | U17: 5.06822 | V17: -8.68784e-05 | W17: -0.000404634 | X17: 4.65707 | Y17: 4.65748 | Z17: -5.31532e-05 | AA17: -0.000223296 | AB17: 4.20077 | AC17: 4.20099 | AD17: -3.5581e-05 | AE17: -0.000154839 | AF17: 4.35159 | AG17: 4.35175 | AH17: -6.67927e-06 | AI17: -2.90201e-05 | AJ17: 4.34477 | AK17: 4.3448 | AL17: -3.66414e-05 | AM17: -0.000146402 | AN17: 3.99539 | AO17: 3.99554 | AP17: 1.11101e-05 | AQ17: 4.76468e-05 | AR17: 4.28865 | AS17: 4.2886 | AT17: -6.38252e-05 | AU17: -0.000235679 | AV17: 3.69233 | AW17: 3.69256 | AX17: -9.78987e-05 | AY17: -0.00038971 | AZ17: 3.98036 | BA17: 3.98075 | BB17: -6.62804e-05 | BC17: -0.000235936 | BD17: 3.55943 | BE17: 3.55967 | BF17: -7.8368e-05 | BG17: -0.000380297 | BH17: 4.85233 | BI17: 4.85271 | BJ17: 8.109 | BK17: 8.109 | BL17: 0.0516 | BM17: 268.097 | BN17: =BM17/$A$2/$B$2 -> 5.3834739 | BO17: =B17 -> 0.000161872 | BP17: =-AVERAGE(J17,V17,AD17,AP17,AX17) -> 5.645244e-05 | BQ17: =AVERAGE(F17,J17,N17,R17,V17,Z17,AD17,AH17,AP17,AT17,AX17,BB17,BF17) -> -5.6296344e-05
... A602: 597 | B602: 0.0120809 | C602: 0.406511 | D602: 34.0557 | E602: 33.6492 | F602: -0.0025928 | G602: -0.0115179 | H602: 4.43074 | I602: 4.44226 | J602: -0.00359736 | K602: -0.0162409 | L602: 4.49841 | M602: 4.51466 | N602: -0.000857682 | O602: -0.00388841 | P602: 4.52974 | Q602: 4.53363 | R602: -0.000613508 | S602: -0.0031094 | T602: 5.06511 | U602: 5.06822 | V602: -0.00412151 | W602: -0.0191959 | X602: 4.63828 | Y602: 4.65748 | Z602: -0.00110802 | AA602: -0.00465478 | AB602: 4.19634 | AC602: 4.20099 | AD602: -0.00435447 | AE602: -0.0189496 | AF602: 4.3328 | AG602: 4.35175 | AH602: -0.00173566 | AI602: -0.00754109 | AJ602: 4.33726 | AK602: 4.3448 | AL602: 0.000363211 | AM602: 0.00145122 | AN602: 3.99699 | AO602: 3.99554 | AP602: -0.00225928 | AQ602: -0.00968913 | AR602: 4.27891 | AS602: 4.2886 | AT602: -0.00272546 | AU602: -0.0100639 | AV602: 3.6825 | AW602: 3.69256 | AX602: -0.00410618 | AY602: -0.0163457 | AZ602: 3.9644 | BA602: 3.98075 | BB602: -0.00284804 | BC602: -0.0101381 | BD602: 3.54953 | BE602: 3.55967 | BF602: -0.0020875 | BG602: -0.01013 | BH602: 4.84258 | BI602: 4.85271 | BJ602: 213.656 | BK602: 213.656 | BL602: 4.0744 | BM602: 20427.1 | BN602: =BM602/$A$2/$B$2 -> 410.18273 | BO602: =B602 -> 0.0120809 | BP602: =-AVERAGE(J602,V602,AD602,AP602,AX602) -> 0.00368776 | BQ602: =AVERAGE(F602,J602,N602,R602,V602,Z602,AD602,AH602,AP602,AT602,AX602,BB602,BF602) -> -0.0025390362
A604: 598 | F604: 0.0300233 | G604: 0.133371 | H604: 4.57563 | I604: 4.44226 | BJ604: 213.84 | BK604: 213.84 | BL604: 2.6686 | BM604: 13382.3 | BN604: =BM604/$A$2/$B$2 -> 268.72088 | BO604: =J604 -> 0 | BP604: =AVERAGE(N604,R604,V604,Z604,AD604,AH604) -> #DIV/0! | BQ604: =AVERAGE(N604,R604,V604,Z604,AD604,AH604,AL604,AP604,AT604,AX604,BB604,BF604) -> #DIV/0!
A605: 599 | F605: 0.0258897 | G605: 0.115009 | H605: 4.55726 | I605: 4.44226 | BJ605: 213.966 | BK605: 213.966 | BL605: 1.2167 | BM605: 6106.48 | BN605: =BM605/$A$2/$B$2 -> 122.62008 | BO605: =J605 -> 0 | BP605: =AVERAGE(N605,R605,V605,Z605,AD605,AH605) -> #DIV/0! | BQ605: =AVERAGE(N605,R605,V605,Z605,AD605,AH605,AL605,AP605,AT605,AX605,BB605,BF605) -> #DIV/0!
A606: 600 | F606: 0.0257458 | G606: 0.114369 | H606: 4.55662 | I606: 4.44226 | BJ606: 214.091 | BK606: 214.091 | BL606: 0.5473 | BM606: 2752.04
A607: 601 | F607: 0.0257716 | G607: 0.114484 | H607: 4.55674 | I607: 4.44226 | BJ607: 214.22 | BK607: 214.22 | BL607: 0.2427 | BM607: 1225.82
A608: 602 | F608: 0.0256284 | G608: 0.113848 | H608: 4.5561 | I608: 4.44226 | BJ608: 214.34 | BK608: 214.341 | BL608: 0.1099 | BM608: 560.42
A609: 603 | F609: 0.0256429 | G609: 0.113912 | H609: 4.55617 | I609: 4.44226 | BJ609: 214.464 | BK609: 214.465 | BL609: 0.0406 | BM609: 213.186
A610: 604 | F610: 0.0256126 | G610: 0.113778 | H610: 4.55603 | I610: 4.44226 | BJ610: 214.59 | BK610: 214.59 | BL610: 0.0136 | BM610: 77.5221
A611: 605 | F611: 0.0255411 | G611: 0.11346 | H611: 4.55572 | I611: 4.44226 | BJ611: 214.778 | BK611: 214.779 | BL611: -0.0026 | BM611: -3.2302
A612: 606 | F612: 0.0255428 | G612: 0.113468 | H612: 4.55572 | I612: 4.44226 | BJ612: 214.963 | BK612: 214.964 | BL612: -0.009 | BM612: -35.5311
A613: 607 | F613: 0.0253862 | G613: 0.112772 | H613: 4.55503 | I613: 4.44226 | BJ613: 215.276 | BK613: 215.277 | BL613: -0.009 | BM613: -35.5311
A614: 608 | F614: 0.0253792 | G614: 0.112741 | H614: 4.555 | I614: 4.44226 | BJ614: 215.465 | BK614: 215.466 | BL614: -0.0135 | BM614: -58.1417
A615: 609 | F615: 0.0251977 | G615: 0.111935 | H615: 4.55419 | I615: 4.44226 | BJ615: 216.523 | BK615: 216.524 | BL615: -0.0135 | BM615: -58.1417
A616: 610 | F616: 0.0251835 | G616: 0.111872 | H616: 4.55413 | I616: 4.44226 | BJ616: 217.148 | BK616: 217.148 | BL616: -0.0103 | BM616: -41.9913
A617: 611 | F617: 0.0252029 | G617: 0.111958 | H617: 4.55421 | I617: 4.44226 | BJ617: 217.338 | BK617: 217.338 | BL617: -0.0103 | BM617: -41.9913
... A619: 613 | F619: 0.0251743 | G619: 0.11183 | H619: 4.55409 | I619: 4.44226 | BJ619: 219.52 | BK619: 219.521 | BL619: -0.009 | BM619: -35.5311

Sheet OLT-3
A1: w | B1: t | BS1: =MATCH(BR3,BR5:BR1048576,0)-1 -> 578
A2: 6 | B2: 8.2 | BR2: Ult Stress, MPa | BS2: Failure Strains, % | BV2: E1, MPa | BW2: ν31
A3: Average | B3: E0 | F3: E1 | J3: E2 | N3: E3 | R3: E4 | V3: E5 | Z3: E6 | AD3: E7 | AH3: E8 | AL3: E9 | AP3: E10 | AT3: E11 | AX3: E12 | BB3: E13 | BF3: E14 | BJ3: E15 | BN3: Analog | BR3: =MAX(BR5:BR1048576) -> 363.12195 | BS3: =INDEX(BS5:BS1048576,MATCH(BR3,BR5:BR1048576,0)) -> 0.0109397 | BT3: =INDEX(BT5:BT1048576,MATCH(BR3,BR5:BR1048576,0)) -> 0.00442676 | BU3: =INDEX(BU5:BU1048576,MATCH(BR3,BR5:BR1048576,0)) -> -0.0018965807 | BV3: =INDEX(LINEST(BR14:BR352,BS14:BS352),1) -> 30675.771 | BW3: =INDEX(LINEST(BT14:BT352,BS14:BS352),1) -> 0.44587867
A4: Index [1] | B4: ?L/L0 [1] | C4: ?L [mm] | D4: L1 [mm] | E4: L0 [mm] | F4: ?L/L0 [1] | G4: ?L [mm] | H4: L1 [mm] | I4: L0 [mm] | J4: ?L/L0 [1] | K4: ?L [mm] | L4: L1 [mm] | M4: L0 [mm] | N4: ?L/L0 [1] | O4: ?L [mm] | P4: L1 [mm] | Q4: L0 [mm] | R4: ?L/L0 [1] | S4: ?L [mm] | T4: L1 [mm] | U4: L0 [mm] | V4: ?L/L0 [1] | W4: ?L [mm] | X4: L1 [mm] | Y4: L0 [mm] | Z4: ?L/L0 [1] | AA4: ?L [mm] | AB4: L1 [mm] | AC4: L0 [mm] | AD4: ?L/L0 [1] | AE4: ?L [mm] | AF4: L1 [mm] | AG4: L0 [mm] | AH4: ?L/L0 [1] | AI4: ?L [mm] | AJ4: L1 [mm] | AK4: L0 [mm] | AL4: ?L/L0 [1] | AM4: ?L [mm] | AN4: L1 [mm] | AO4: L0 [mm] | AP4: ?L/L0 [1] | AQ4: ?L [mm] | AR4: L1 [mm] | AS4: L0 [mm] | AT4: ?L/L0 [1] | AU4: ?L [mm] | AV4: L1 [mm] | AW4: L0 [mm] | AX4: ?L/L0 [1] | AY4: ?L [mm] | AZ4: L1 [mm] | BA4: L0 [mm] | BB4: ?L/L0 [1] | BC4: ?L [mm] | BD4: L1 [mm] | BE4: L0 [mm] | BF4: ?L/L0 [1] | BG4: ?L [mm] | BH4: L1 [mm] | BI4: L0 [mm] | BJ4: ?L/L0 [1] | BK4: ?L [mm] | BL4: L1 [mm] | BM4: L0 [mm] | BN4: Time_1 | BO4: Time_0 | BP4: Dev1/ai0 | BQ4: Force_[N] | BR4: σ1, MPa | BS4: ε1 | BT4: ε3 | BU4: ε3_v1
A5: 0 | B5: 0 | C5: 0 | D5: 32.281 | E5: 32.281 | F5: 0 | G5: 0 | H5: 4.48717 | I5: 4.48717 | J5: 0 | K5: 0 | L5: 4.70999 | M5: 4.70999 | N5: 0 | O5: 0 | P5: 4.88404 | Q5: 4.88404 | R5: 0 | S5: 0 | T5: 4.54215 | U5: 4.54215 | V5: 0 | W5: 0 | X5: 4.9833 | Y5: 4.9833 | Z5: 0 | AA5: 0 | AB5: 5.04561 | AC5: 5.04561 | AD5: 0 | AE5: 0 | AF5: 4.49774 | AG5: 4.49774 | AH5: 0 | AI5: 0 | AJ5: 4.65996 | AK5: 4.65996 | AL5: 0 | AM5: 0 | AN5: 4.6326 | AO5: 4.6326 | AP5: 0 | AQ5: 0 | AR5: 4.07603 | AS5: 4.07603 | AT5: 0 | AU5: 0 | AV5: 4.13229 | AW5: 4.13229 | AX5: 0 | AY5: 0 | AZ5: 3.47875 | BA5: 3.47875 | BB5: 0 | BC5: 0 | BD5: 3.81681 | BE5: 3.81681 | BF5: 0 | BG5: 0 | BH5: 3.22495 | BI5: 3.22495 | BJ5: 0 | BK5: 0 | BL5: 3.07671 | BM5: 3.07671 | BN5: 0 | BO5: 0.004 | BP5: 0 | BQ5: 9.6902 | BR5: =BQ5/$A$2/$B$2 -> 0.19695528 | BS5: =B5 -> 0 | BT5: =-AVERAGE(N5,AX5,R5,AL5,BF5) -> 0 | BU5: =AVERAGE(J5,N5,R5,V5,Z5,AD5,AH5,AL5,AT5,AX5,BB5,BF5,BJ5,AP5,F5) -> 0
A6: 1 | B6: 8.42705e-05 | C6: 0.00272034 | D6: 32.2837 | E6: 32.281 | F6: -6.47062e-06 | G6: -2.90348e-05 | H6: 4.48714 | I6: 4.48717 | J6: -4.47105e-05 | K6: -0.000210586 | L6: 4.70978 | M6: 4.70999 | N6: -7.99973e-05 | O6: -0.00039071 | P6: 4.88365 | Q6: 4.88404 | R6: -6.61492e-05 | S6: -0.000300459 | T6: 4.54185 | U6: 4.54215 | V6: -1.5414e-05 | W6: -7.68127e-05 | X6: 4.98323 | Y6: 4.9833 | Z6: 4.02627e-05 | AA6: 0.00020315 | AB6: 5.04581 | AC6: 5.04561 | AD6: 1.33807e-05 | AE6: 6.01828e-05 | AF6: 4.4978 | AG6: 4.49774 | AH6: 6.08966e-05 | AI6: 0.000283776 | AJ6: 4.66024 | AK6: 4.65996 | AL6: 0.00011636 | AM6: 0.000539051 | AN6: 4.63314 | AO6: 4.6326 | AP6: 0.000154234 | AQ6: 0.000628664 | AR6: 4.07666 | AS6: 4.07603 | AT6: 9.36851e-05 | AU6: 0.000387134 | AV6: 4.13267 | AW6: 4.13229 | AX6: 2.95745e-05 | AY6: 0.000102882 | AZ6: 3.47885 | BA6: 3.47875 | BB6: 6.02766e-05 | BC6: 0.000230065 | BD6: 3.81704 | BE6: 3.81681 | BF6: 4.70374e-05 | BG6: 0.000151693 | BH6: 3.2251 | BI6: 3.22495 | BJ6: 8.10983e-05 | BK6: 0.000249516 | BL6: 3.07696 | BM6: 3.07671 | BN6: 0.45 | BO6: 0.45 | BP6: 0.0136 | BQ6: 77.5221 | BR6: =BQ6/$A$2/$B$2 -> 1.5756524 | BS6: =B6 -> 8.42705e-05 | BT6: =-AVERAGE(N6,AX6,R6,AL6,BF6) -> -9.36508e-06 | BU6: =AVERAGE(J6,N6,R6,V6,Z6,AD6,AH6,AL6,AT6,AX6,BB6,BF6,BJ6,AP6,F6) -> 3.2270952e-05
A7: 2 | B7: 3.48416e-05 | C7: 0.00112472 | D7: 32.2821 | E7: 32.281 | F7: -7.08271e-05 | G7: -0.000317814 | H7: 4.48685 | I7: 4.48717 | J7: -8.53474e-05 | K7: -0.000401986 | L7: 4.70959 | M7: 4.70999 | N7: -3.36338e-05 | O7: -0.000164269 | P7: 4.88387 | Q7: 4.88404 | R7: -6.15139e-05 | S7: -0.000279405 | T7: 4.54187 | U7: 4.54215 | V7: -3.89185e-05 | W7: -0.000193943 | X7: 4.98311 | Y7: 4.9833 | Z7: 2.38142e-05 | AA7: 0.000120157 | AB7: 5.04573 | AC7: 5.04561 | AD7: -1.50357e-05 | AE7: -6.76267e-05 | AF7: 4.49768 | AG7: 4.49774 | AH7: -2.88021e-06 | AI7: -1.34216e-05 | AJ7: 4.65995 | AK7: 4.65996 | AL7: 9.36857e-06 | AM7: 4.34008e-05 | AN7: 4.63264 | AO7: 4.6326 | AP7: 1.47144e-05 | AQ7: 5.99761e-05 | AR7: 4.07609 | AS7: 4.07603 | AT7: 8.83992e-05 | AU7: 0.000365291 | AV7: 4.13265 | AW7: 4.13229 | AX7: 5.99059e-05 | AY7: 0.000208398 | AZ7: 3.47896 | BA7: 3.47875 | BB7: 9.90107e-05 | BC7: 0.000377905 | BD7: 3.81719 | BE7: 3.81681 | BF7: 6.12174e-05 | BG7: 0.000197423 | BH7: 3.22515 | BI7: 3.22495 | BJ7: 7.69174e-05 | BK7: 0.000236653 | BL7: 3.07695 | BM7: 3.07671 | BN7: 0.574 | BO7: 0.574 | BP7: 0.0029 | BQ7: 24.2256 | BR7: =BQ7/$A$2/$B$2 -> 0.49239024 | BS7: =B7 -> 3.48416e-05 | BT7: =-AVERAGE(N7,AX7,R7,AL7,BF7) -> -7.068834e-06 | BU7: =AVERAGE(J7,N7,R7,V7,Z7,AD7,AH7,AL7,AT7,AX7,BB7,BF7,BJ7,AP7,F7) -> 8.3460773e-06
A8: 3 | B8: 7.54415e-05 | C8: 0.00243533 | D8: 32.2834 | E8: 32.281 | F8: -6.04038e-05 | G8: -0.000271042 | H8: 4.4869 | I8: 4.48717 | J8: -7.93161e-05 | K8: -0.000373578 | L8: 4.70962 | M8: 4.70999 | N8: -8.16094e-05 | O8: -0.000398583 | P8: 4.88364 | Q8: 4.88404 | R8: -4.17215e-05 | S8: -0.000189505 | T8: 4.54196 | U8: 4.54215 | V8: -0.00010889 | W8: -0.000542634 | X8: 4.98276 | Y8: 4.9833 | Z8: -9.07256e-05 | AA8: -0.000457766 | AB8: 5.04515 | AC8: 5.04561 | AD8: -1.42271e-05 | AE8: -6.39898e-05 | AF8: 4.49768 | AG8: 4.49774 | AH8: -6.73139e-05 | AI8: -0.00031368 | AJ8: 4.65965 | AK8: 4.65996 | AL8: 4.45291e-05 | AM8: 0.000206286 | AN8: 4.63281 | AO8: 4.6326 | AP8: 3.31402e-05 | AQ8: 0.000135081 | AR8: 4.07616 | AS8: 4.07603 | AT8: 0.000101911 | AU8: 0.000421125 | AV8: 4.13271 | AW8: 4.13229 | AX8: 2.83919e-06 | AY8: 9.87682e-06 | AZ8: 3.47876 | BA8: 3.47875 | BB8: 9.75979e-05 | BC8: 0.000372513 | BD8: 3.81718 | BE8: 3.81681 | BF8: -7.31098e-05 | BG8: -0.000235775 | BH8: 3.22471 | BI8: 3.22495 | BJ8: -6.26707e-05 | BK8: -0.00019282 | BL8: 3.07652 | BM8: 3.07671 | BN8: 1.645 | BO8: 1.646 | BP8: -0.0029 | BQ8: -4.8452 | BR8: =BQ8/$A$2/$B$2 -> -0.098479675 | BS8: =B8 -> 7.54415e-05 | BT8: =-AVERAGE(N8,AX8,R8,AL8,BF8) -> 2.9814482e-05 | BU8: =AVERAGE(J8,N8,R8,V8,Z8,AD8,AH8,AL8,AT8,AX8,BB8,BF8,BJ8,AP8,F8) -> -2.6664701e-05
