Workbook

Sheet OLC3
B2: ='OLT3-1'!V2 -> Ult Stress, MPa | C2: ='OLT3-1'!W2 -> Failure Strains, % | D2: ='OLT3-1'!Y2 -> Ez, MPa | E2: E3, Mpa | F2: vf | G2: Lx, мм | H2: Ly, мм | I2: t, мм | J2: a, мм | K2: m | L2: n | M2: Psi0 | N2: Psi90 | O2: Psi_i | P2: v | Q2: kz | R2: E3_eff | S2: k_E
A3: average | B3: =AVERAGE(B6:B9) -> 0.89068659 | C3: =AVERAGE(C6:C9) -> 0.00985977 | D3: =AVERAGE(D6:D9) -> 179.15396 | E3: =D3/Q3 -> 215.36647 | F3: 0.1776 | G3: 27 | H3: 7 | I3: 2 | J3: 5 | K3: =ROUNDDOWN(G3/J3,0) -> 5 | L3: =ROUNDDOWN(H3/J3,0) -> 1 | M3: =I3*(L3+1)/H3 -> 0.57142857 | N3: =I3*(K3+1)/G3 -> 0.44444444 | O3: =2*M3*N3 -> 0.50793651 | P3: =M3+N3 -> 1.015873 | Q3: =(P3-(1-3*F3)*O3/2/(1-2*F3)) -> 0.83185632 | R3: =D3/P3 -> 176.35468 | S3: =R3/E3 -> 0.81885856 | T3: =(1-S3) -> 0.18114144 | V3: =B3/P$3 -> 0.87676962
A4: sr. dev. | B4: =STDEV(B6:B9) -> 0.11222735 | C4: =STDEV(C6:C9) -> 0.0019418018 | D4: =STDEV(D6:D9) -> 3.843361 | R4: =D4/P$3 -> 3.7833085 | V4: =B4/P$3 -> 0.1104738
A5: CV | B5: =B4/B3 -> 0.12600094 | C5: =C4/C3 -> 0.1969419 | D5: =D4/D3 -> 0.021452838
A6: 1 | B6: ='OLT3-1'!V3 -> 0.79121447 | C6: ='OLT3-1'!W3 -> 0.00928675 | D6: ='OLT3-1'!Y3 -> 180.36076
A7: 2 | B7: ='OLT3-2'!$V$3 -> 0.86849248 | C7: ='OLT3-2'!$X$3 -> 0.00826896 | D7: ='OLT3-2'!$Y$3 -> 182.24909
A8: 3 | B8: ='OLT3-3'!V3 -> 1.0123528 | C8: ='OLT3-3'!W3 -> 0.0120236 | D8: ='OLT3-3'!Y3 -> 174.85203

Sheet OLT3-1
A1: w | B1: t | W1: =MATCH(V3,V5:V1048576,0)-1 -> 66
A2: 25.8 | B2: 7.05 | V2: Ult Stress, MPa | W2: Failure Strains, % | Y2: Ez, MPa
A3: Average | B3: E0 | F3: E1 | J3: E2 | N3: E3 | R3: Analog | V3: =MAX(V5:V1048576) -> 0.79121447 | W3: =INDEX(W5:W1048576,MATCH(V3,V5:V1048576,0)) -> 0.00928675 | X3: =INDEX(X5:X1048576,MATCH(V3,V5:V1048576,0)) -> 0.00956101 | Y3: =INDEX(LINEST(V11:V45,AA11:AA45),1) -> 180.36076
A4: Index [1] | B4: ?L/L0 [1] | C4: ?L [mm] | D4: L1 [mm] | E4: L0 [mm] | F4: ?L/L0 [1] | G4: ?L [mm] | H4: L1 [mm] | I4: L0 [mm] | J4: ?L/L0 [1] | K4: ?L [mm] | L4: L1 [mm] | M4: L0 [mm] | N4: ?L/L0 [1] | O4: ?L [mm] | P4: L1 [mm] | Q4: L0 [mm] | R4: Time_1 | S4: Time_0 | T4: Dev1/ai0 | U4: Force_[N] | V4: σ3, MPa | W4: ε30 | X4: ε31 | Y4: ε32 | Z4: ε33 | AA4: ε3
A5: 0 | B5: 0 | C5: 0 | D5: 23.901 | E5: 23.901 | F5: 0 | G5: 0 | H5: 24.5946 | I5: 24.5946 | J5: 0 | K5: 0 | L5: 23.9664 | M5: 23.9664 | N5: 0 | O5: 0 | P5: 24.179 | Q5: 24.179 | R5: 3779.18 | S5: 3779.18 | T5: -0.0325 | U5: -8.6251 | V5: =U5/$A$2/$B$2 -> -0.047419319 | W5: =B5 -> 0 | X5: =F5 -> 0 | Y5: =J5 -> 0 | Z5: =N5 -> 0 | AA5: =AVERAGE(W5:Z5) -> 0
A6: 1 | B6: -2.71433e-05 | C6: -0.00064875 | D6: 23.9003 | E6: 23.901 | F6: -3.35187e-05 | G6: -0.00082438 | H6: 24.5938 | I6: 24.5946 | J6: -2.24309e-05 | K6: -0.000537586 | L6: 23.9658 | M6: 23.9664 | N6: -3.15011e-05 | O6: -0.000761663 | P6: 24.1782 | Q6: 24.179 | R6: 3779.74 | S6: 3779.74 | T6: -0.0357 | U6: -9.5943 | V6: =U6/$A$2/$B$2 -> -0.052747815 | W6: =B6 -> -2.71433e-05 | X6: =F6 -> -3.35187e-05 | Y6: =J6 -> -2.24309e-05 | Z6: =N6 -> -3.15011e-05 | AA6: =AVERAGE(W6:Z6) -> -2.86485e-05
A7: 2 | B7: -1.60874e-07 | C7: -3.84505e-06 | D7: 23.9009 | E7: 23.901 | F7: -2.69893e-06 | G7: -6.63792e-05 | H7: 24.5946 | I7: 24.5946 | J7: 1.21931e-05 | K7: 0.000292224 | L7: 23.9666 | M7: 23.9664 | N7: -1.31056e-05 | O7: -0.000316879 | P7: 24.1787 | Q7: 24.179 | R7: 3781.8 | S7: 3781.8 | T7: -0.0319 | U7: -8.4313 | V7: =U7/$A$2/$B$2 -> -0.04635384 | W7: =B7 -> -1.60874e-07 | X7: =F7 -> -2.69893e-06 | Y7: =J7 -> 1.21931e-05 | Z7: =N7 -> -1.31056e-05 | AA7: =AVERAGE(W7:Z7) -> -9.43076e-07
A8: 3 | B8: 0.000114272 | C8: 0.0027312 | D8: 23.9037 | E8: 23.901 | F8: 0.000109941 | G8: 0.00270395 | H8: 24.5974 | I8: 24.5946 | J8: 0.000110882 | K8: 0.00265744 | L8: 23.969 | M8: 23.9664 | N8: 0.000115587 | O8: 0.00279477 | P8: 24.1818 | Q8: 24.179 | R8: 3782.04 | S8: 3782.04 | T8: -0.0225 | U8: -5.6209 | V8: =U8/$A$2/$B$2 -> -0.030902743 | W8: =B8 -> 0.000114272 | X8: =F8 -> 0.000109941 | Y8: =J8 -> 0.000110882 | Z8: =N8 -> 0.000115587 | AA8: =AVERAGE(W8:Z8) -> 0.0001126705
A9: 4 | B9: 0.000109284 | C9: 0.002612 | D9: 23.9036 | E9: 23.901 | F9: 9.17084e-05 | G9: 0.00225554 | H9: 24.5969 | I9: 24.5946 | J9: 8.7452e-05 | K9: 0.00209591 | L9: 23.9685 | M9: 23.9664 | N9: 9.7573e-05 | O9: 0.00235922 | P9: 24.1813 | Q9: 24.179 | R9: 3782.29 | S9: 3782.29 | T9: -0.0142 | U9: -3.1012 | V9: =U9/$A$2/$B$2 -> -0.017049865 | W9: =B9 -> 0.000109284 | X9: =F9 -> 9.17084e-05 | Y9: =J9 -> 8.7452e-05 | Z9: =N9 -> 9.7573e-05 | AA9: =AVERAGE(W9:Z9) -> 9.650435e-05
A10: 5 | B10: 0.000171908 | C10: 0.00410876 | D10: 23.9051 | E10: 23.901 | F10: 0.000175528 | G10: 0.00431705 | H10: 24.599 | I10: 24.5946 | J10: 0.000185861 | K10: 0.00445442 | L10: 23.9708 | M10: 23.9664 | N10: 0.000161685 | O10: 0.00390939 | P10: 24.1829 | Q10: 24.179 | R10: 3782.54 | S10: 3782.54 | T10: -0.0051 | U10: -0.3876 | V10: =U10/$A$2/$B$2 -> -0.0021309583 | W10: =B10 -> 0.000171908 | X10: =F10 -> 0.000175528 | Y10: =J10 -> 0.000185861 | Z10: =N10 -> 0.000161685 | AA10: =AVERAGE(W10:Z10) -> 0.0001737455
A11: 6 | B11: 0.000248376 | C11: 0.00593643 | D11: 23.9069 | E11: 23.901 | F11: 0.000251335 | G11: 0.0061815 | H11: 24.6008 | I11: 24.5946 | J11: 0.000266656 | K11: 0.00639077 | L11: 23.9727 | M11: 23.9664 | N11: 0.000228997 | O11: 0.00553691 | P11: 24.1845 | Q11: 24.179 | R11: 3782.92 | S11: 3782.92 | T11: 0.0091 | U11: 3.8765 | V11: =U11/$A$2/$B$2 -> 0.021312332 | W11: =B11 -> 0.000248376 | X11: =F11 -> 0.000251335 | Y11: =J11 -> 0.000266656 | Z11: =N11 -> 0.000228997 | AA11: =AVERAGE(W11:Z11) -> 0.000248841
A12: 7 | B12: 0.00028468 | C12: 0.00680413 | D12: 23.9078 | E12: 23.901 | F12: 0.000292341 | G12: 0.00719003 | H12: 24.6018 | I12: 24.5946 | J12: 0.000305363 | K12: 0.00731844 | L12: 23.9737 | M12: 23.9664 | N12: 0.000257687 | O12: 0.0062306 | P12: 24.1852 | Q12: 24.179 | R12: 3783.17 | S12: 3783.17 | T12: 0.0139 | U12: 5.3301 | V12: =U12/$A$2/$B$2 -> 0.029303975 | W12: =B12 -> 0.00028468 | X12: =F12 -> 0.000292341 | Y12: =J12 -> 0.000305363 | Z12: =N12 -> 0.000257687 | AA12: =AVERAGE(W12:Z12) -> 0.00028501775
A13: 8 | B13: 0.000366435 | C13: 0.00875815 | D13: 23.9097 | E13: 23.901 | F13: 0.000369852 | G13: 0.00909637 | H13: 24.6037 | I13: 24.5946 | J13: 0.000386965 | K13: 0.00927414 | L13: 23.9756 | M13: 23.9664 | N13: 0.000342573 | O13: 0.00828306 | P13: 24.1873 | Q13: 24.179 | R13: 3783.54 | S13: 3783.54 | T13: 0.0297 | U13: 10.0788 | V13: =U13/$A$2/$B$2 -> 0.055411512 | W13: =B13 -> 0.000366435 | X13: =F13 -> 0.000369852 | Y13: =J13 -> 0.000386965 | Z13: =N13 -> 0.000342573 | AA13: =AVERAGE(W13:Z13) -> 0.00036645625
A14: 9 | B14: 0.000392392 | C14: 0.00937853 | D14: 23.9103 | E14: 23.901 | F14: 0.000427878 | G14: 0.0105235 | H14: 24.6052 | I14: 24.5946 | J14: 0.000459914 | K14: 0.0110225 | L14: 23.9774 | M14: 23.9664 | N14: 0.000364041 | O14: 0.00880214 | P14: 24.1878 | Q14: 24.179 | R14: 3783.79 | S14: 3783.79 | T14: 0.0352 | U14: 11.7263 | V14: =U14/$A$2/$B$2 -> 0.064469185 | W14: =B14 -> 0.000392392 | X14: =F14 -> 0.000427878 | Y14: =J14 -> 0.000459914 | Z14: =N14 -> 0.000364041 | AA14: =AVERAGE(W14:Z14) -> 0.00041105625
A15: 10 | B15: 0.000431748 | C15: 0.0103192 | D15: 23.9113 | E15: 23.901 | F15: 0.000448068 | G15: 0.0110201 | H15: 24.6057 | I15: 24.5946 | J15: 0.000468476 | K15: 0.0112277 | L15: 23.9776 | M15: 23.9664 | N15: 0.000408789 | O15: 0.00988411 | P15: 24.1889 | Q15: 24.179 | R15: 3784.04 | S15: 3784.04 | T15: 0.041 | U15: 13.4707 | V15: =U15/$A$2/$B$2 -> 0.074059596 | W15: =B15 -> 0.000431748 | X15: =F15 -> 0.000448068 | Y15: =J15 -> 0.000468476 | Z15: =N15 -> 0.000408789 | AA15: =AVERAGE(W15:Z15) -> 0.00043927025
A16: 11 | B16: 0.000545882 | C16: 0.0130471 | D16: 23.914 | E16: 23.901 | F16: 0.000572177 | G16: 0.0140725 | H16: 24.6087 | I16: 24.5946 | J16: 0.000590942 | K16: 0.0141627 | L16: 23.9805 | M16: 23.9664 | N16: 0.000527383 | O16: 0.0127516 | P16: 24.1917 | Q16: 24.179 | R16: 3784.54 | S16: 3784.54 | T16: 0.0561 | U16: 18.0256 | V16: =U16/$A$2/$B$2 -> 0.099101655 | W16: =B16 -> 0.000545882 | X16: =F16 -> 0.000572177 | Y16: =J16 -> 0.000590942 | Z16: =N16 -> 0.000527383 | AA16: =AVERAGE(W16:Z16) -> 0.000559096
... A71: 66 | B71: 0.00928675 | C71: 0.221962 | D71: 24.1229 | E71: 23.901 | F71: 0.00956101 | G71: 0.23515 | H71: 24.8298 | I71: 24.5946 | J71: 0.00786896 | K71: 0.18859 | L71: 24.1549 | M71: 23.9664 | N71: 0.00893583 | O71: 0.216059 | P71: 24.395 | Q71: 24.179 | R71: 3825.85 | S71: 3825.85 | T71: 0.4748 | U71: 143.914 | V71: =U71/$A$2/$B$2 -> 0.79121447 | W71: =B71 -> 0.00928675 | X71: =F71 -> 0.00956101 | Y71: =J71 -> 0.00786896 | Z71: =N71 -> 0.00893583 | AA71: =AVERAGE(W71:Z71) -> 0.0089131375
A72: 67 | B72: 0.0097774 | C72: 0.233689 | D72: 24.1346 | E72: 23.901 | F72: 0.0102741 | G72: 0.252687 | H72: 24.8473 | I72: 24.5946 | N72: 0.00923217 | O72: 0.223224 | P72: 24.4022 | Q72: 24.179 | R72: 3829.78 | S72: 3829.78 | T72: 0.4538 | U72: 137.615 | V72: =U72/$A$2/$B$2 -> 0.75658365 | W72: =B72 -> 0.0097774 | X72: =F72 -> 0.0102741 | Y72: =J72 -> 0 | Z72: =N72 -> 0.00923217 | AA72: =AVERAGE(W72:Z72) -> 0.0073209175
A73: 68 | B73: 0.0096669 | C73: 0.231048 | D73: 24.132 | E73: 23.901 | F73: 0.0102032 | G73: 0.250944 | H73: 24.8456 | I73: 24.5946 | N73: 0.00906836 | O73: 0.219264 | P73: 24.3982 | Q73: 24.179 | R73: 3829.97 | S73: 3829.97 | T73: 0.4458 | U73: 135.192 | V73: =U73/$A$2/$B$2 -> 0.74326241 | W73: =B73 -> 0.0096669 | X73: =F73 -> 0.0102032 | Y73: =J73 -> 0 | Z73: =N73 -> 0.00906836 | AA73: =AVERAGE(W73:Z73) -> 0.007234615
A74: 69 | B74: 0.00953021 | C74: 0.227781 | D74: 24.1287 | E74: 23.901 | F74: 0.010134 | G74: 0.249243 | H74: 24.8439 | I74: 24.5946 | N74: 0.00888514 | O74: 0.214834 | P74: 24.3938 | Q74: 24.179 | R74: 3830.15 | S74: 3830.15 | T74: 0.4338 | U74: 131.606 | V74: =U74/$A$2/$B$2 -> 0.7235472 | W74: =B74 -> 0.00953021 | X74: =F74 -> 0.010134 | Y74: =J74 -> 0 | Z74: =N74 -> 0.00888514 | AA74: =AVERAGE(W74:Z74) -> 0.0071373375
A75: 70 | B75: 0.00946002 | C75: 0.226103 | D75: 24.1271 | E75: 23.901 | F75: 0.0100968 | G75: 0.248326 | H75: 24.843 | I75: 24.5946 | N75: 0.0087795 | O75: 0.212279 | P75: 24.3913 | Q75: 24.179 | R75: 3830.4 | S75: 3830.4 | T75: 0.4196 | U75: 127.342 | V75: =U75/$A$2/$B$2 -> 0.70010446 | W75: =B75 -> 0.00946002 | X75: =F75 -> 0.0100968 | Y75: =J75 -> 0 | Z75: =N75 -> 0.0087795 | AA75: =AVERAGE(W75:Z75) -> 0.00708408
A76: 71 | B76: 0.00942043 | C76: 0.225157 | D76: 24.1261 | E76: 23.901 | F76: 0.0100886 | G76: 0.248125 | H76: 24.8428 | I76: 24.5946 | N76: 0.00871505 | O76: 0.210721 | P76: 24.3897 | Q76: 24.179 | R76: 3830.53 | S76: 3830.53 | T76: 0.4164 | U76: 126.373 | V76: =U76/$A$2/$B$2 -> 0.69477706 | W76: =B76 -> 0.00942043 | X76: =F76 -> 0.0100886 | Y76: =J76 -> 0 | Z76: =N76 -> 0.00871505 | AA76: =AVERAGE(W76:Z76) -> 0.00705602
A77: 72 | B77: 0.00932883 | C77: 0.222968 | D77: 24.1239 | E77: 23.901 | F77: 0.010095 | G77: 0.248284 | H77: 24.8429 | I77: 24.5946 | N77: 0.00855914 | O77: 0.206951 | P77: 24.3859 | Q77: 24.179 | R77: 3831.03 | S77: 3831.03 | T77: 0.4074 | U77: 123.659 | V77: =U77/$A$2/$B$2 -> 0.67985596 | W77: =B77 -> 0.00932883 | X77: =F77 -> 0.010095 | Y77: =J77 -> 0 | Z77: =N77 -> 0.00855914 | AA77: =AVERAGE(W77:Z77) -> 0.0069957425
A78: 73 | B78: 0.00919432 | C78: 0.219753 | D78: 24.1207 | E78: 23.901 | F78: 0.0100411 | G78: 0.246958 | H78: 24.8416 | I78: 24.5946 | N78: 0.00837142 | O78: 0.202412 | P78: 24.3814 | Q78: 24.179 | R78: 3831.47 | S78: 3831.47 | T78: 0.3923 | U78: 119.104 | V78: =U78/$A$2/$B$2 -> 0.65481335 | W78: =B78 -> 0.00919432 | X78: =F78 -> 0.0100411 | Y78: =J78 -> 0 | Z78: =N78 -> 0.00837142 | AA78: =AVERAGE(W78:Z78) -> 0.00690171
A79: 74 | B79: 0.00911676 | C79: 0.217899 | D79: 24.1189 | E79: 23.901 | F79: 0.0100101 | G79: 0.246195 | H79: 24.8408 | I79: 24.5946 | N79: 0.0082387 | O79: 0.199203 | P79: 24.3782 | Q79: 24.179 | R79: 3831.71 | S79: 3831.72 | T79: 0.3865 | U79: 117.36 | V79: =U79/$A$2/$B$2 -> 0.64522514 | W79: =B79 -> 0.00911676 | X79: =F79 -> 0.0100101 | Y79: =J79 -> 0 | Z79: =N79 -> 0.0082387 | AA79: =AVERAGE(W79:Z79) -> 0.00684139
A80: 75 | B80: 0.00906455 | C80: 0.216651 | D80: 24.1176 | E80: 23.901 | F80: 0.0100224 | G80: 0.246498 | H80: 24.8411 | I80: 24.5946 | N80: 0.00814952 | O80: 0.197047 | P80: 24.376 | Q80: 24.179 | R80: 3832.53 | S80: 3832.53 | T80: 0.3806 | U80: 115.616 | V80: =U80/$A$2/$B$2 -> 0.63563692 | W80: =B80 -> 0.00906455 | X80: =F80 -> 0.0100224 | Y80: =J80 -> 0 | Z80: =N80 -> 0.00814952 | AA80: =AVERAGE(W80:Z80) -> 0.0068091175
A81: 76 | B81: 0.0091274 | C81: 0.218154 | D81: 24.1191 | E81: 23.901 | F81: 0.0103352 | G81: 0.254191 | H81: 24.8488 | I81: 24.5946 | J81: 0.0157535 | K81: 0.377553 | L81: 24.3439 | M81: 23.9664 | N81: 0.00802592 | O81: 0.194059 | P81: 24.373 | Q81: 24.179 | R81: 3836.02 | S81: 3836.02 | T81: 0.3707 | U81: 112.611 | V81: =U81/$A$2/$B$2 -> 0.61911595 | W81: =B81 -> 0.0091274 | X81: =F81 -> 0.0103352 | Y81: =J81 -> 0.0157535 | Z81: =N81 -> 0.00802592 | AA81: =AVERAGE(W81:Z81) -> 0.010810505
A82: 77 | B82: 0.00917583 | C82: 0.219311 | D82: 24.1203 | E82: 23.901 | F82: 0.0105251 | G82: 0.258861 | H82: 24.8535 | I82: 24.5946 | J82: 0.01619 | K82: 0.388015 | L82: 24.3544 | M82: 23.9664 | N82: 0.00803701 | O82: 0.194327 | P82: 24.3733 | Q82: 24.179 | R82: 3837.58 | S82: 3837.58 | T82: 0.3723 | U82: 113.096 | V82: =U82/$A$2/$B$2 -> 0.6217824 | W82: =B82 -> 0.00917583 | X82: =F82 -> 0.0105251 | Y82: =J82 -> 0.01619 | Z82: =N82 -> 0.00803701 | AA82: =AVERAGE(W82:Z82) -> 0.010981985
A83: 78 | B83: 0.00923034 | C83: 0.220614 | D83: 24.1216 | E83: 23.901 | F83: 0.0106383 | G83: 0.261646 | H83: 24.8563 | I83: 24.5946 | J83: 0.0160201 | K83: 0.383944 | L83: 24.3503 | M83: 23.9664 | N83: 0.00806649 | O83: 0.195039 | P83: 24.374 | Q83: 24.179 | R83: 3837.96 | S83: 3837.96 | T83: 0.3758 | U83: 114.162 | V83: =U83/$A$2/$B$2 -> 0.62764308 | W83: =B83 -> 0.00923034 | X83: =F83 -> 0.0106383 | Y83: =J83 -> 0.0160201 | Z83: =N83 -> 0.00806649 | AA83: =AVERAGE(W83:Z83) -> 0.010988808
A84: 79 | B84: 0.00925639 | C84: 0.221237 | D84: 24.1222 | E84: 23.901 | F84: 0.0108259 | G84: 0.266259 | H84: 24.8609 | I84: 24.5946 | J84: 0.0163914 | K84: 0.392843 | L84: 24.3592 | M84: 23.9664 | N84: 0.00805202 | O84: 0.19469 | P84: 24.3737 | Q84: 24.179 | R84: 3838.95 | S84: 3838.95 | T84: 0.3684 | U84: 111.933 | V84: =U84/$A$2/$B$2 -> 0.61538842 | W84: =B84 -> 0.00925639 | X84: =F84 -> 0.0108259 | Y84: =J84 -> 0.0163914 | Z84: =N84 -> 0.00805202 | AA84: =AVERAGE(W84:Z84) -> 0.011131428
A85: 80 | B85: 0.0092586 | C85: 0.221289 | D85: 24.1222 | E85: 23.901 | F85: 0.0108166 | G85: 0.266031 | H85: 24.8607 | I85: 24.5946 | J85: 0.0163105 | K85: 0.390903 | L85: 24.3573 | M85: 23.9664 | N85: 0.00811316 | O85: 0.196168 | P85: 24.3751 | Q85: 24.179 | R85: 3839.33 | S85: 3839.33 | T85: 0.3678 | U85: 111.739 | V85: =U85/$A$2/$B$2 -> 0.61432184 | W85: =B85 -> 0.0092586 | X85: =F85 -> 0.0108166 | Y85: =J85 -> 0.0163105 | Z85: =N85 -> 0.00811316 | AA85: =AVERAGE(W85:Z85) -> 0.011124715
A86: 81 | B86: 0.00927452 | C86: 0.22167 | D86: 24.1226 | E86: 23.901 | J86: 0.0163665 | K86: 0.392245 | L86: 24.3586 | M86: 23.9664 | N86: 0.008027 | O86: 0.194085 | P86: 24.3731 | Q86: 24.179 | R86: 3839.95 | S86: 3839.95 | T86: 0.37 | U86: 112.418 | V86: =U86/$A$2/$B$2 -> 0.61805487 | W86: =B86 -> 0.00927452 | X86: =F86 -> 0 | Y86: =J86 -> 0.0163665 | Z86: =N86 -> 0.008027 | AA86: =AVERAGE(W86:Z86) -> 0.008417005
A87: 82 | B87: 0.0092962 | C87: 0.222188 | D87: 24.1231 | E87: 23.901 | J87: 0.0166421 | K87: 0.398851 | L87: 24.3652 | M87: 23.9664 | N87: 0.00801214 | O87: 0.193725 | P87: 24.3727 | Q87: 24.179 | R87: 3841.32 | S87: 3841.32 | T87: 0.3655 | U87: 111.061 | V87: =U87/$A$2/$B$2 -> 0.61059432 | W87: =B87 -> 0.0092962 | X87: =F87 -> 0 | Y87: =J87 -> 0.0166421 | Z87: =N87 -> 0.00801214 | AA87: =AVERAGE(W87:Z87) -> 0.00848761
A88: 83 | B88: 0.00935255 | C88: 0.223535 | D88: 24.1245 | E88: 23.901 | J88: 0.016782 | K88: 0.402203 | L88: 24.3686 | M88: 23.9664 | N88: 0.00803748 | O88: 0.194338 | P88: 24.3733 | Q88: 24.179 | R88: 3841.89 | S88: 3841.89 | T88: 0.3581 | U88: 108.832 | V88: =U88/$A$2/$B$2 -> 0.59833966 | W88: =B88 -> 0.00935255 | X88: =F88 -> 0 | Y88: =J88 -> 0.016782 | Z88: =N88 -> 0.00803748 | AA88: =AVERAGE(W88:Z88) -> 0.0085430075
A89: 84 | B89: 0.00926669 | C89: 0.221483 | D89: 24.1224 | E89: 23.901 | J89: 0.0168383 | K89: 0.403552 | L89: 24.3699 | M89: 23.9664 | N89: 0.00791634 | O89: 0.191409 | P89: 24.3704 | Q89: 24.179 | R89: 3842.38 | S89: 3842.38 | T89: 0.3523 | U89: 107.087 | V89: =U89/$A$2/$B$2 -> 0.58874595 | W89: =B89 -> 0.00926669 | X89: =F89 -> 0 | Y89: =J89 -> 0.0168383 | Z89: =N89 -> 0.00791634 | AA89: =AVERAGE(W89:Z89) -> 0.0085053325
A90: 85 | B90: 0.00919069 | C90: 0.219666 | D90: 24.1206 | E90: 23.901 | N90: 0.00775471 | O90: 0.187501 | P90: 24.3665 | Q90: 24.179 | R90: 3843.13 | S90: 3843.13 | T90: 0.3381 | U90: 102.823 | V90: =U90/$A$2/$B$2 -> 0.56530321 | W90: =B90 -> 0.00919069 | X90: =F90 -> 0 | Y90: =J90 -> 0 | Z90: =N90 -> 0.00775471 | AA90: =AVERAGE(W90:Z90) -> 0.00423635
A91: 86 | B91: 0.00924316 | C91: 0.22092 | D91: 24.1219 | E91: 23.901 | N91: 0.00777144 | O91: 0.187905 | P91: 24.3669 | Q91: 24.179 | R91: 3843.95 | S91: 3843.95 | T91: 0.3259 | U91: 99.1407 | V91: =U91/$A$2/$B$2 -> 0.54505855 | W91: =B91 -> 0.00924316 | X91: =F91 -> 0 | Y91: =J91 -> 0 | Z91: =N91 -> 0.00777144 | AA91: =AVERAGE(W91:Z91) -> 0.00425365
A92: 87 | B92: 0.00929319 | C92: 0.222116 | D92: 24.1231 | E92: 23.901 | F92: 0.0134727 | G92: 0.331357 | H92: 24.926 | I92: 24.5946 | N92: 0.00777649 | O92: 0.188028 | P92: 24.367 | Q92: 24.179 | R92: 3845.32 | S92: 3845.32 | T92: 0.3378 | U92: 102.726 | V92: =U92/$A$2/$B$2 -> 0.56476992 | W92: =B92 -> 0.00929319 | X92: =F92 -> 0.0134727 | Y92: =J92 -> 0 | Z92: =N92 -> 0.00777649 | AA92: =AVERAGE(W92:Z92) -> 0.007635595
A93: 88 | B93: 0.00944436 | C93: 0.225729 | D93: 24.1267 | E93: 23.901 | F93: 0.0140156 | G93: 0.344709 | H93: 24.9394 | I93: 24.5946 | N93: 0.00789072 | O93: 0.190789 | P93: 24.3698 | Q93: 24.179 | R93: 3847.81 | S93: 3847.81 | T93: 0.3242 | U93: 98.6561 | V93: =U93/$A$2/$B$2 -> 0.5423943 | W93: =B93 -> 0.00944436 | X93: =F93 -> 0.0140156 | Y93: =J93 -> 0 | Z93: =N93 -> 0.00789072 | AA93: =AVERAGE(W93:Z93) -> 0.00783767
A94: 89 | B94: 0.00941285 | C94: 0.224976 | D94: 24.1259 | E94: 23.901 | F94: 0.013974 | G94: 0.343685 | H94: 24.9383 | I94: 24.5946 | N94: 0.00784416 | O94: 0.189664 | P94: 24.3686 | Q94: 24.179 | R94: 3848 | S94: 3848 | T94: 0.3139 | U94: 95.5549 | V94: =U94/$A$2/$B$2 -> 0.52534444 | W94: =B94 -> 0.00941285 | X94: =F94 -> 0.013974 | Y94: =J94 -> 0 | Z94: =N94 -> 0.00784416 | AA94: =AVERAGE(W94:Z94) -> 0.0078077525
...

Sheet OLT3-2
A1: w | B1: t | W1: =MATCH(V3,V5:V1048576,0)-1 -> 181
A2: 26.4 | B2: 6.95 | V2: Ult Stress, MPa | W2: Failure Strains, % | Y2: Ez, MPa
A3: Average | B3: E3 | F3: E0 | J3: E1 | N3: E2 | R3: Analog | V3: =MAX(V5:V1048576) -> 0.86849248 | W3: =INDEX(W5:W1048576,MATCH(V3,V5:V1048576,0)) -> 0.00841113 | X3: =INDEX(X5:X1048576,MATCH(V3,V5:V1048576,0)) -> 0.00826896 | Y3: =INDEX(LINEST(V25:V130,AA25:AA130),1) -> 182.24909
A4: Index [1] | B4: ?L/L0 [1] | C4: ?L [mm] | D4: L1 [mm] | E4: L0 [mm] | F4: ?L/L0 [1] | G4: ?L [mm] | H4: L1 [mm] | I4: L0 [mm] | J4: ?L/L0 [1] | K4: ?L [mm] | L4: L1 [mm] | M4: L0 [mm] | N4: ?L/L0 [1] | O4: ?L [mm] | P4: L1 [mm] | Q4: L0 [mm] | R4: Time_1 | S4: Time_0 | T4: Dev1/ai0 | U4: Force_[N] | V4: σ3, MPa | W4: ε30 | X4: ε31 | Y4: ε32 | Z4: ε33 | AA4: ε3
A5: 0 | B5: 0 | C5: 0 | D5: 57.298 | E5: 57.298 | F5: 0 | G5: 0 | H5: 57.2653 | I5: 57.2653 | J5: 0 | K5: 0 | L5: 57.0318 | M5: 57.0318 | N5: 0 | O5: 0 | P5: 56.2104 | Q5: 56.2104 | R5: 0 | S5: 0.003 | T5: -0.2046 | U5: -20.1594 | V5: =U5/$A$2/$B$2 -> -0.10987247 | W5: =B5 -> 0 | X5: =F5 -> 0 | Y5: =J5 -> 0 | Z5: =N5 -> 0 | AA5: =AVERAGE(W5:Z5) -> 0
A6: 1 | B6: -9.77778e-06 | C6: -0.000560247 | D6: 57.2975 | E6: 57.298 | F6: 4.05203e-06 | G6: 0.000232041 | H6: 57.2655 | I6: 57.2653 | J6: 1.55369e-05 | K6: 0.000886098 | L6: 57.0327 | M6: 57.0318 | N6: 2.59153e-05 | O6: 0.00145671 | P6: 56.2119 | Q6: 56.2104 | R6: 4.695 | S6: 4.695 | T6: -0.203 | U6: -19.9979 | V6: =U6/$A$2/$B$2 -> -0.10899226 | W6: =B6 -> -9.77778e-06 | X6: =F6 -> 4.05203e-06 | Y6: =J6 -> 1.55369e-05 | Z6: =N6 -> 2.59153e-05 | AA6: =AVERAGE(W6:Z6) -> 8.9316125e-06
A7: 2 | B7: -3.5838e-05 | C7: -0.00205344 | D7: 57.296 | E7: 57.298 | F7: -2.22864e-05 | G7: -0.00127624 | H7: 57.264 | I7: 57.2653 | J7: -9.77969e-06 | K7: -0.000557753 | L7: 57.0312 | M7: 57.0318 | N7: -5.26653e-06 | O7: -0.000296034 | P7: 56.2101 | Q7: 56.2104 | R7: 16.068 | S7: 16.072 | T7: -0.2072 | U7: -20.4179 | V7: =U7/$A$2/$B$2 -> -0.11128134 | W7: =B7 -> -3.5838e-05 | X7: =F7 -> -2.22864e-05 | Y7: =J7 -> -9.77969e-06 | Z7: =N7 -> -5.26653e-06 | AA7: =AVERAGE(W7:Z7) -> -1.8292655e-05
A8: 3 | B8: -3.99729e-05 | C8: -0.00229037 | D8: 57.2957 | E8: 57.298 | F8: -2.87343e-05 | G8: -0.00164548 | H8: 57.2637 | I8: 57.2653 | J8: -2.24518e-05 | K8: -0.00128047 | L8: 57.0305 | M8: 57.0318 | N8: -1.63814e-05 | O8: -0.000920805 | P8: 56.2095 | Q8: 56.2104 | R8: 18.483 | S8: 18.483 | T8: -0.2017 | U8: -19.8686 | V8: =U8/$A$2/$B$2 -> -0.10828755 | W8: =B8 -> -3.99729e-05 | X8: =F8 -> -2.87343e-05 | Y8: =J8 -> -2.24518e-05 | Z8: =N8 -> -1.63814e-05 | AA8: =AVERAGE(W8:Z8) -> -2.68851e-05
A9: 4 | B9: -8.17069e-07 | C9: -4.68164e-05 | D9: 57.298 | E9: 57.298 | F9: 1.52588e-05 | G9: 0.000873798 | H9: 57.2662 | I9: 57.2653 | J9: 2.24454e-05 | K9: 0.0012801 | L9: 57.0331 | M9: 57.0318 | N9: 2.66798e-05 | O9: 0.00149968 | P9: 56.2119 | Q9: 56.2104 | R9: 18.796 | S9: 18.796 | T9: -0.1995 | U9: -19.6425 | V9: =U9/$A$2/$B$2 -> -0.10705526 | W9: =B9 -> -8.17069e-07 | X9: =F9 -> 1.52588e-05 | Y9: =J9 -> 2.24454e-05 | Z9: =N9 -> 2.66798e-05 | AA9: =AVERAGE(W9:Z9) -> 1.5891733e-05
A10: 5 | B10: -5.86298e-05 | C10: -0.00335937 | D10: 57.2947 | E10: 57.298 | F10: -5.4456e-05 | G10: -0.00311844 | H10: 57.2622 | I10: 57.2653 | J10: -4.24232e-05 | K10: -0.00241947 | L10: 57.0294 | M10: 57.0318 | N10: -3.37157e-05 | O10: -0.00189517 | P10: 56.2085 | Q10: 56.2104 | R10: 19.483 | S10: 19.483 | T10: -0.2001 | U10: -19.7071 | V10: =U10/$A$2/$B$2 -> -0.10740735 | W10: =B10 -> -5.86298e-05 | X10: =F10 -> -5.4456e-05 | Y10: =J10 -> -4.24232e-05 | Z10: =N10 -> -3.37157e-05 | AA10: =AVERAGE(W10:Z10) -> -4.7306175e-05
A11: 6 | B11: -3.5213e-05 | C11: -0.00201764 | D11: 57.296 | E11: 57.298 | F11: -1.83242e-05 | G11: -0.00104934 | H11: 57.2643 | I11: 57.2653 | J11: -1.53168e-05 | K11: -0.000873542 | L11: 57.0309 | M11: 57.0318 | N11: -9.17203e-06 | O11: -0.000515563 | P11: 56.2099 | Q11: 56.2104 | R11: 21.043 | S11: 21.043 | T11: -0.1895 | U11: -18.6409 | V11: =U11/$A$2/$B$2 -> -0.10159636 | W11: =B11 -> -3.5213e-05 | X11: =F11 -> -1.83242e-05 | Y11: =J11 -> -1.53168e-05 | Z11: =N11 -> -9.17203e-06 | AA11: =AVERAGE(W11:Z11) -> -1.9506508e-05
A12: 7 | B12: 1.44368e-06 | C12: 8.272e-05 | D12: 57.2981 | E12: 57.298 | F12: 1.07791e-05 | G12: 0.000617271 | H12: 57.2659 | I12: 57.2653 | J12: 1.37729e-05 | K12: 0.000785492 | L12: 57.0326 | M12: 57.0318 | N12: 1.71916e-05 | O12: 0.000966348 | P12: 56.2114 | Q12: 56.2104 | R12: 21.166 | S12: 21.167 | T12: -0.1753 | U12: -17.2193 | V12: =U12/$A$2/$B$2 -> -0.093848376 | W12: =B12 -> 1.44368e-06 | X12: =F12 -> 1.07791e-05 | Y12: =J12 -> 1.37729e-05 | Z12: =N12 -> 1.71916e-05 | AA12: =AVERAGE(W12:Z12) -> 1.079682e-05
A13: 8 | B13: 1.04486e-05 | C13: 0.000598683 | D13: 57.2986 | E13: 57.298 | F13: 2.21667e-05 | G13: 0.00126938 | H13: 57.2666 | I13: 57.2653 | J13: 2.70542e-05 | K13: 0.00154295 | L13: 57.0333 | M13: 57.0318 | N13: 3.75343e-05 | O13: 0.00210982 | P13: 56.2125 | Q13: 56.2104 | R13: 21.291 | S13: 21.291 | T13: -0.1705 | U13: -16.7346 | V13: =U13/$A$2/$B$2 -> -0.091206671 | W13: =B13 -> 1.04486e-05 | X13: =F13 -> 2.21667e-05 | Y13: =J13 -> 2.70542e-05 | Z13: =N13 -> 3.75343e-05 | AA13: =AVERAGE(W13:Z13) -> 2.430095e-05
A14: 9 | B14: 1.15131e-05 | C14: 0.000659676 | D14: 57.2987 | E14: 57.298 | F14: 3.25335e-05 | G14: 0.00186304 | H14: 57.2672 | I14: 57.2653 | J14: 3.53051e-05 | K14: 0.00201351 | L14: 57.0338 | M14: 57.0318 | N14: 3.97006e-05 | O14: 0.00223159 | P14: 56.2126 | Q14: 56.2104 | R14: 21.479 | S14: 21.479 | T14: -0.1547 | U14: -15.1515 | V14: =U14/$A$2/$B$2 -> -0.082578483 | W14: =B14 -> 1.15131e-05 | X14: =F14 -> 3.25335e-05 | Y14: =J14 -> 3.53051e-05 | Z14: =N14 -> 3.97006e-05 | AA14: =AVERAGE(W14:Z14) -> 2.9763075e-05
A15: 10 | B15: 1.08574e-05 | C15: 0.000622105 | D15: 57.2986 | E15: 57.298 | F15: 2.85474e-05 | G15: 0.00163477 | H15: 57.2669 | I15: 57.2653 | J15: 3.65023e-05 | K15: 0.00208179 | L15: 57.0339 | M15: 57.0318 | N15: 4.95182e-05 | O15: 0.00278344 | P15: 56.2132 | Q15: 56.2104 | R15: 21.604 | S15: 21.604 | T15: -0.1469 | U15: -14.376 | V15: =U15/$A$2/$B$2 -> -0.078351864 | W15: =B15 -> 1.08574e-05 | X15: =F15 -> 2.85474e-05 | Y15: =J15 -> 3.65023e-05 | Z15: =N15 -> 4.95182e-05 | AA15: =AVERAGE(W15:Z15) -> 3.1356325e-05
A16: 11 | B16: 4.19561e-05 | C16: 0.002404 | D16: 57.3004 | E16: 57.298 | F16: 5.66183e-05 | G16: 0.00324226 | H16: 57.2685 | I16: 57.2653 | J16: 6.59417e-05 | K16: 0.00376077 | L16: 57.0355 | M16: 57.0318 | N16: 7.86945e-05 | O16: 0.00442345 | P16: 56.2148 | Q16: 56.2104 | R16: 21.796 | S16: 21.796 | T16: -0.1315 | U16: -12.8252 | V16: =U16/$A$2/$B$2 -> -0.069899717 | W16: =B16 -> 4.19561e-05 | X16: =F16 -> 5.66183e-05 | Y16: =J16 -> 6.59417e-05 | Z16: =N16 -> 7.86945e-05 | AA16: =AVERAGE(W16:Z16) -> 6.080265e-05
... A232: 227 | B232: 0.0147905 | C232: 0.847464 | D232: 58.1455 | E232: 57.298 | F232: 0.0146745 | G232: 0.84034 | H232: 58.1056 | I232: 57.2653 | J232: 0.0146741 | K232: 0.836891 | L232: 57.8687 | M232: 57.0318 | N232: 0.0143871 | O232: 0.808704 | P232: 57.0191 | Q232: 56.2104 | R232: 144.407 | S232: 144.407 | T232: 1.2321 | U232: 123.875 | V232: =U232/$A$2/$B$2 -> 0.6751417 | W232: =B232 -> 0.0147905 | X232: =F232 -> 0.0146745 | Y232: =J232 -> 0.0146741 | Z232: =N232 -> 0.0143871 | AA232: =AVERAGE(W232:Z232) -> 0.01463155

Sheet OLT3-3
A1: w | B1: t | W1: =MATCH(V3,V5:V1048576,0)-1 -> 226
A2: 26.1 | B2: 7.14 | V2: Ult Stress, MPa | W2: Failure Strains, % | Y2: Ez, MPa
A3: Average | B3: E3 | F3: E0 | J3: E1 | N3: E2 | R3: Analog | V3: =MAX(V5:V1048576) -> 1.0123528 | W3: =INDEX(W5:W1048576,MATCH(V3,V5:V1048576,0)) -> 0.0120236 | X3: =INDEX(X5:X1048576,MATCH(V3,V5:V1048576,0)) -> 0.0120121 | Y3: =INDEX(LINEST(V32:V130,AA32:AA130),1) -> 174.85203
A4: Index [1] | B4: ?L/L0 [1] | C4: ?L [mm] | D4: L1 [mm] | E4: L0 [mm] | F4: ?L/L0 [1] | G4: ?L [mm] | H4: L1 [mm] | I4: L0 [mm] | J4: ?L/L0 [1] | K4: ?L [mm] | L4: L1 [mm] | M4: L0 [mm] | N4: ?L/L0 [1] | O4: ?L [mm] | P4: L1 [mm] | Q4: L0 [mm] | R4: Time_1 | S4: Time_0 | T4: Dev1/ai0 | U4: Force_[N] | V4: σ3, MPa | W4: ε30 | X4: ε31 | Y4: ε32 | Z4: ε33 | AA4: ε3
A5: 0 | B5: 0 | C5: 0 | D5: 55.1504 | E5: 55.1504 | F5: 0 | G5: 0 | H5: 54.9192 | I5: 54.9192 | J5: 0 | K5: 0 | L5: 54.492 | M5: 54.492 | N5: 0 | O5: 0 | P5: 54.3869 | Q5: 54.3869 | R5: 0 | S5: 0.004 | T5: -0.2833 | U5: -28.0429 | V5: =U5/$A$2/$B$2 -> -0.15048188 | W5: =B5 -> 0 | X5: =F5 -> 0 | Y5: =J5 -> 0 | Z5: =N5 -> 0 | AA5: =AVERAGE(W5:Z5) -> 0
A6: 1 | B6: -1.61968e-05 | C6: -0.000893262 | D6: 55.1495 | E6: 55.1504 | F6: -1.4199e-05 | G6: -0.000779796 | H6: 54.9184 | I6: 54.9192 | J6: -1.9318e-05 | K6: -0.00105267 | L6: 54.4909 | M6: 54.492 | N6: -1.30589e-05 | O6: -0.000710235 | P6: 54.3862 | Q6: 54.3869 | R6: 1.839 | S6: 1.839 | T6: -0.2846 | U6: -28.1721 | V6: =U6/$A$2/$B$2 -> -0.15117518 | W6: =B6 -> -1.61968e-05 | X6: =F6 -> -1.4199e-05 | Y6: =J6 -> -1.9318e-05 | Z6: =N6 -> -1.30589e-05 | AA6: =AVERAGE(W6:Z6) -> -1.5693175e-05
A7: 2 | B7: 1.11136e-06 | C7: 6.1292e-05 | D7: 55.1504 | E7: 55.1504 | F7: 8.29743e-06 | G7: 0.000455688 | H7: 54.9196 | I7: 54.9192 | J7: 4.93411e-06 | K7: 0.000268869 | L7: 54.4923 | M7: 54.492 | N7: 1.35861e-05 | O7: 0.000738904 | P7: 54.3876 | Q7: 54.3869 | R7: 2.839 | S7: 2.839 | T7: -0.2765 | U7: -27.3644 | V7: =U7/$A$2/$B$2 -> -0.14684096 | W7: =B7 -> 1.11136e-06 | X7: =F7 -> 8.29743e-06 | Y7: =J7 -> 4.93411e-06 | Z7: =N7 -> 1.35861e-05 | AA7: =AVERAGE(W7:Z7) -> 6.98225e-06
A8: 3 | B8: -2.77754e-06 | C8: -0.000153182 | D8: 55.1502 | E8: 55.1504 | F8: 6.22265e-06 | G8: 0.000341743 | H8: 54.9195 | I8: 54.9192 | J8: 3.84625e-06 | K8: 0.00020959 | L8: 54.4922 | M8: 54.492 | N8: 1.45651e-05 | O8: 0.000792149 | P8: 54.3877 | Q8: 54.3869 | R8: 2.964 | S8: 2.964 | T8: -0.2655 | U8: -26.2659 | V8: =U8/$A$2/$B$2 -> -0.14094626 | W8: =B8 -> -2.77754e-06 | X8: =F8 -> 6.22265e-06 | Y8: =J8 -> 3.84625e-06 | Z8: =N8 -> 1.45651e-05 | AA8: =AVERAGE(W8:Z8) -> 5.464115e-06
A9: 4 | B9: 1.50657e-05 | C9: 0.000830881 | D9: 55.1512 | E9: 55.1504 | F9: 1.53909e-05 | G9: 0.000845257 | H9: 54.92 | I9: 54.9192 | J9: 1.867e-05 | K9: 0.00101737 | L9: 54.493 | M9: 54.492 | N9: 2.41776e-05 | O9: 0.00131494 | P9: 54.3882 | Q9: 54.3869 | R9: 3.152 | S9: 3.152 | T9: -0.2501 | U9: -24.715 | V9: =U9/$A$2/$B$2 -> -0.13262393 | W9: =B9 -> 1.50657e-05 | X9: =F9 -> 1.53909e-05 | Y9: =J9 -> 1.867e-05 | Z9: =N9 -> 2.41776e-05 | AA9: =AVERAGE(W9:Z9) -> 1.832605e-05
A10: 5 | B10: 4.79714e-05 | C10: 0.00264564 | D10: 55.153 | E10: 55.1504 | F10: 5.1801e-05 | G10: 0.00284487 | H10: 54.922 | I10: 54.9192 | J10: 4.9465e-05 | K10: 0.00269544 | L10: 54.4947 | M10: 54.492 | N10: 5.70737e-05 | O10: 0.00310406 | P10: 54.39 | Q10: 54.3869 | R10: 3.279 | S10: 3.279 | T10: -0.243 | U10: -24.0042 | V10: =U10/$A$2/$B$2 -> -0.12880968 | W10: =B10 -> 4.79714e-05 | X10: =F10 -> 5.1801e-05 | Y10: =J10 -> 4.9465e-05 | Z10: =N10 -> 5.70737e-05 | AA10: =AVERAGE(W10:Z10) -> 5.1577775e-05
A11: 6 | B11: 6.99235e-05 | C11: 0.00385631 | D11: 55.1542 | E11: 55.1504 | F11: 8.14744e-05 | G11: 0.00447451 | H11: 54.9236 | I11: 54.9192 | J11: 8.03654e-05 | K11: 0.00437927 | L11: 54.4964 | M11: 54.492 | N11: 8.44287e-05 | O11: 0.00459181 | P11: 54.3915 | Q11: 54.3869 | R11: 3.401 | S11: 3.401 | T11: -0.2294 | U11: -22.6472 | V11: =U11/$A$2/$B$2 -> -0.12152784 | W11: =B11 -> 6.99235e-05 | X11: =F11 -> 8.14744e-05 | Y11: =J11 -> 8.03654e-05 | Z11: =N11 -> 8.44287e-05 | AA11: =AVERAGE(W11:Z11) -> 7.9048e-05
A12: 7 | B12: 8.58604e-05 | C12: 0.00473523 | D12: 55.1551 | E12: 55.1504 | F12: 9.33424e-05 | G12: 0.00512629 | H12: 54.9243 | I12: 54.9192 | J12: 9.42448e-05 | K12: 0.00513559 | L12: 54.4971 | M12: 54.492 | N12: 0.000105335 | O12: 0.00572883 | P12: 54.3926 | Q12: 54.3869 | R12: 3.711 | S12: 3.711 | T12: -0.2104 | U12: -20.741 | V12: =U12/$A$2/$B$2 -> -0.11129893 | W12: =B12 -> 8.58604e-05 | X12: =F12 -> 9.33424e-05 | Y12: =J12 -> 9.42448e-05 | Z12: =N12 -> 0.000105335 | AA12: =AVERAGE(W12:Z12) -> 9.469565e-05
A13: 8 | B13: 7.72919e-05 | C13: 0.00426268 | D13: 55.1546 | E13: 55.1504 | F13: 8.62183e-05 | G13: 0.00473504 | H13: 54.9239 | I13: 54.9192 | J13: 8.65583e-05 | K13: 0.00471673 | L13: 54.4967 | M13: 54.492 | N13: 9.1776e-05 | O13: 0.00499141 | P13: 54.3919 | Q13: 54.3869 | R13: 3.837 | S13: 3.837 | T13: -0.2043 | U13: -20.1271 | V13: =U13/$A$2/$B$2 -> -0.10800466 | W13: =B13 -> 7.72919e-05 | X13: =F13 -> 8.62183e-05 | Y13: =J13 -> 8.65583e-05 | Z13: =N13 -> 9.1776e-05 | AA13: =AVERAGE(W13:Z13) -> 8.5461125e-05
A14: 9 | B14: 0.000107563 | C14: 0.00593215 | D14: 55.1563 | E14: 55.1504 | F14: 0.000107751 | G14: 0.00591759 | H14: 54.9251 | I14: 54.9192 | J14: 0.00010636 | K14: 0.00579575 | L14: 54.4978 | M14: 54.492 | N14: 0.000110473 | O14: 0.00600827 | P14: 54.3929 | Q14: 54.3869 | R14: 3.963 | S14: 3.963 | T14: -0.1927 | U14: -18.964 | V14: =U14/$A$2/$B$2 -> -0.10176331 | W14: =B14 -> 0.000107563 | X14: =F14 -> 0.000107751 | Y14: =J14 -> 0.00010636 | Z14: =N14 -> 0.000110473 | AA14: =AVERAGE(W14:Z14) -> 0.00010803675
A15: 10 | B15: 0.00014034 | C15: 0.00773979 | D15: 55.1581 | E15: 55.1504 | F15: 0.000146752 | G15: 0.00805951 | H15: 54.9272 | I15: 54.9192 | J15: 0.000151232 | K15: 0.00824095 | L15: 54.5002 | M15: 54.492 | N15: 0.000159248 | O15: 0.00866099 | P15: 54.3956 | Q15: 54.3869 | R15: 4.212 | S15: 4.212 | T15: -0.1747 | U15: -17.1546 | V15: =U15/$A$2/$B$2 -> -0.092053833 | W15: =B15 -> 0.00014034 | X15: =F15 -> 0.000146752 | Y15: =J15 -> 0.000151232 | Z15: =N15 -> 0.000159248 | AA15: =AVERAGE(W15:Z15) -> 0.000149393
A16: 11 | B16: 0.000155168 | C16: 0.00855755 | D16: 55.1589 | E16: 55.1504 | F16: 0.000157086 | G16: 0.00862702 | H16: 54.9278 | I16: 54.9192 | J16: 0.000159036 | K16: 0.00866617 | L16: 54.5007 | M16: 54.492 | N16: 0.000162185 | O16: 0.00882072 | P16: 54.3957 | Q16: 54.3869 | R16: 4.46 | S16: 4.46 | T16: -0.1598 | U16: -15.6684 | V16: =U16/$A$2/$B$2 -> -0.084078689 | W16: =B16 -> 0.000155168 | X16: =F16 -> 0.000157086 | Y16: =J16 -> 0.000159036 | Z16: =N16 -> 0.000162185 | AA16: =AVERAGE(W16:Z16) -> 0.00015836875
... A254: 249 | B254: 0.0172075 | C254: 0.949002 | D254: 56.0994 | E254: 55.1504 | F254: 0.01723 | G254: 0.946258 | H254: 55.8654 | I254: 54.9192 | J254: 0.0172661 | K254: 0.940866 | L254: 55.4329 | M254: 54.492 | N254: 0.017256 | O254: 0.938503 | P254: 55.3254 | Q254: 54.3869 | R254: 127.391 | S254: 127.392 | T254: -0.0055 | U254: -0.1923 | V254: =U254/$A$2/$B$2 -> -0.001031907 | W254: =B254 -> 0.0172075 | X254: =F254 -> 0.01723 | Y254: =J254 -> 0.0172661 | Z254: =N254 -> 0.017256 | AA254: =AVERAGE(W254:Z254) -> 0.0172399
