Workbook

Sheet Лист1
A1: t= | B1: 1
A2: v= | B2: 0.2
A3: phi= | B3: 30
A5: a90= | B5: 15
A6: a_phi | B6: 15
A9: Основание треугольника | B9: 17.320508
A10: Сторона треугольника | B10: 17.320508
A14: Длина КЭМ Х | B14: 30 | C14: =B14/1000 -> 0.03
A15: Ширина КЭМ Y max | B15: 34.6 | C15: =B15/1000 -> 0.0346
A16: Ширина КЭМ Y min | B16: 34.6 | C16: =B16/1000 -> 0.0346
A17: Ширина КЭМ Y среднее | B17: =(B15+B16)/2 -> 34.6 | C17: =B17/1000 -> 0.0346
A18: Высота КЭМ | B18: 30 | C18: =B18/1000 -> 0.03
B19: мм | C19: м
A21: Эквивалентная площадь в направлении Х | B21: =B15*B18 -> 1038 | C21: =C15*C18 -> 0.001038 | G21: Эквивалентная площадь в направлении Y | H21: =B14*B18 -> 900 | I21: =C14*C18 -> 0.0009
B22: мм^2 | C22: м^2
A25: НАПРАВЛЕНИЕ Х | G25: НАПРАВЛЕНИЕ Y | N25: Направление XY
A26: Средние перемещения переднего торца Х | B26: 0.006606 | C26: =B26/1000 -> 6.606e-06 | G26: Средние перемещения переднего торца Y | H26: 0.005998 | I26: =H26/1000 -> 5.998e-06 | N26: TAU = | O26: 10
B27: мм | C27: м | H27: мм | I27: м
N28: T1= | O28: =O26*(B14*B18) -> 9000
A29: Сила | B29: 1000 | G29: Сила | H29: 1000 | N29: T2= | O29: =O26*(B15*B18) -> 10380
B30: Н | H30: Н
N32: катет по y | O32: 0.731
A33: Ех= | B33: =B29*C14/(C21*C26) -> 4.3750733e+09 | G33: Еy= | H33: =H29*C15/(I21*I26) -> 6.4095439e+09 | N33: катет по х | O33: 117.126
B34: Па | H34: Па
N35: Тангенс угла | O35: =O32/O33 -> 0.006241142
B36: =B33/10^6 -> 4375.0733 | H36: =H33/10^6 -> 6409.5439
B37: МПа | H37: МПа | N37: угол | O37: =ATAN(O35) -> 0.006241061
A39: Ех в расчете | B39: =4.2795051822133*1000 -> 4279.5052 | G39: Еy в расчете | H39: =4.2795051822133*1000 -> 4279.5052
N40: G | O40: =O26/(O37) -> 1602.2917
A42: Погрешность Ех | B42: =(B36-B39)/B36*100 -> 2.1843771 | C42: % | G42: Погрешность Еy | H42: =(H36-H39)/H39*100 -> 49.773015 | I42: %
N43: G расчетное | O43: 1607.2
A44: Пуассоны без RBE | G44: Пуассоны без RBE
A45: Деформация по Х при растяжении по Х | B45: =0.006621/$B$14 -> 0.0002207 | G45: Деформация по Y при растяжении по Y | H45: =0.006009/B15 -> 0.00017367052 | N45: =(O43-O40)/O43*100 -> 0.30539663
A47: перемещения по Y при растяжении по Х | B47: =-0.002122 -> -0.002122 | G47: перемещения по Х при растяжении по Y | H47: =-0.001741 -> -0.001741 | I47: =-2*0.0005289 -> -0.0010578
A49: Деформация по Y при растяжении по Х | B49: =B47/$B$15 -> -6.132948e-05 | G49: Деформация по X при растяжении по Y | H49: =I47/B14 -> -3.526e-05
A52: Пуассон yx | B52: =-B49/B45 -> 0.27788618 | G52: Пуассон yx | H52: =-H49/H45 -> 0.20302812
A54: Пуассон програм | B54: 0.3318 | G54: Пуассон програм | H54: 0.3318
A56: Погрешность | B56: =(B52-B54)/B52*100 -> -19.401404 | C56: % | G56: Погрешность | H56: =(H52-H54)/H52*100 -> -63.425634 | I56: %
A61: перемещения по Z при растяжении по Х | B61: =-0.0005694 -> -0.0005694 | G61: перемещения по Z при растяжении по Х | H61: =-2.964*10^(-5) -> -2.964e-05
A63: Деформация по Z при растяжении по Х | B63: =B61/$B$18 -> -1.898e-05 | G63: Деформация по Z при растяжении по Х | H63: =H61/$B$18 -> -9.88e-07
...

Sheet isogrid
A1: t_теоретическое= | B1: 1 | C1: 1 | D1: Сила | E1: 1000 | F1: t_факт | G1: 1.5
A2: v_теоретическое= | B2: 0.2 | C2: 0.2 | F2: v_факт | G2: =(G1/B4)+(2*G1/B5) -> 0.3
A3: phi= | B3: 30 | C3: =D3*3.1415/180 -> 0.52358333 | D3: 30
A4: a90= | B4: 15 | C4: =3.75 -> 3.75 | D4: =C1*(1+SIN(C3))/(C2*SIN(C3)) -> 15.000267
A5: a_phi | B5: 15 | C5: =3.75 -> 3.75 | D5: =2*C1*(1+SIN(C3))/C2 -> 14.999866
A6: Высота КЭМ | B6: 30 | C6: =3.75*2 -> 7.5
A7: Основание треугольника | B7: 17.32 | C7: 4.33 | D7: =2*TAN(C3)*C4 -> 4.3299726
A8: Сторона треугольника | B8: 17.32 | C8: =C7 -> 4.33 | D8: =C4/COS(C3) -> 4.3300884
A9: Длина ячейки Х | B9: =B4 -> 15 | C9: =D4 -> 15.000267
A10: Ширина ячейки Y | B10: =B7 -> 17.32 | C10: =D7 -> 4.3299726
A11: Количество ячеек по Х | B11: 1 | C11: 2 | D11: 4 | E11: 6 | F11: 8 | G11: 10 | H11: 14 | L11: 2
A12: Длина модели по Х | B12: =$B$9*B11 -> 15 | C12: =$B$9*C11 -> 30 | D12: =$B$9*D11 -> 60 | E12: =$B$9*E11 -> 90 | F12: =$B$9*F11 -> 120 | G12: =$B$9*G11 -> 150 | H12: =$B$9*H11 -> 210 | K12: =$B$9*K11 -> 0 | L12: =$B$9*L11 -> 30 | M12: =$B$9*M11 -> 0 | N12: =$B$9*N11 -> 0 | O12: =$B$9*O11 -> 0 | P12: =$B$9*P11 -> 0
A13: Количество ячеек по Y | B13: 2 | C13: 2 | D13: 2 | E13: 2 | F13: 2 | G13: 2 | H13: 2 | K13: 2 | L13: 8 | M13: 2 | N13: 2 | O13: 2 | P13: 2
A14: Длина модели по Y мм | B14: =$B$10*B13 -> 34.64 | C14: =$B$10*C13 -> 34.64 | D14: =$B$10*D13 -> 34.64 | E14: =$B$10*E13 -> 34.64 | F14: =$B$10*F13 -> 34.64 | G14: =$B$10*G13 -> 34.64 | H14: =$B$10*H13 -> 34.64 | K14: =$B$10*K13 -> 34.64 | L14: =$B$10*L13 -> 138.56 | M14: =$B$10*M13 -> 34.64 | N14: =$B$10*N13 -> 34.64 | O14: =$B$10*O13 -> 34.64 | P14: =$B$10*P13 -> 34.64
A15: Площадь в направлении X м^2 | B15: =B14/1000*$B$6/1000 -> 0.0010392 | C15: =C14/1000*$B$6/1000 -> 0.0010392 | D15: =D14/1000*$B$6/1000 -> 0.0010392 | E15: =E14/1000*$B$6/1000 -> 0.0010392 | F15: =F14/1000*$B$6/1000 -> 0.0010392 | G15: =G14/1000*$B$6/1000 -> 0.0010392 | H15: =H14/1000*$B$6/1000 -> 0.0010392 | K15: =K14/1000*$B$6/1000 -> 0.0010392 | L15: =L14/1000*$B$6/1000 -> 0.0041568 | M15: =M14/1000*$B$6/1000 -> 0.0010392 | N15: =N14/1000*$B$6/1000 -> 0.0010392 | O15: =O14/1000*$B$6/1000 -> 0.0010392 | P15: =P14/1000*$B$6/1000 -> 0.0010392
A16: Перемещения по Х мм | B16: 0 | C16: 0.005262 | D16: 0.01069 | E16: 0.0161 | F16: 0.0216 | G16: 0.027 | H16: 0.038 | L16: 0.001624
A17: Ex | C17: =($E$1*(C12/1000)/(C15*C16/1000))/(10^6) -> 5486.1954 | D17: =($E$1*(D12/1000)/(D15*D16/1000))/(10^6) -> 5401.0029 | E17: =($E$1*(E12/1000)/(E15*E16/1000))/(10^6) -> 5379.1976 | F17: =($E$1*(F12/1000)/(F15*F16/1000))/(10^6) -> 5345.9926 | G17: =($E$1*(G12/1000)/(G15*G16/1000))/(10^6) -> 5345.9926 | H17: =($E$1*(H12/1000)/(H15*H16/1000))/(10^6) -> 5317.8558 | K17: =($E$1*(K12/1000)/(K15*K16/1000))/(10^6) -> #DIV/0! | L17: =($E$1*(L12/1000)/(L15*L16/1000))/(10^6) -> 4444.021 | M17: =($E$1*(M12/1000)/(M15*M16/1000))/(10^6) -> #DIV/0! | N17: =($E$1*(N12/1000)/(N15*N16/1000))/(10^6) -> #DIV/0! | O17: =($E$1*(O12/1000)/(O15*O16/1000))/(10^6) -> #DIV/0! | P17: =($E$1*(P12/1000)/(P15*P16/1000))/(10^6) -> #DIV/0!
A18: Ех аналитическое | B18: =5275.7 -> 5275.7
A19: Погрешность % | C19: =ABS($B$18-C17)/C17*100 -> 3.8368195 | D19: =ABS($B$18-D17)/D17*100 -> 2.3199924 | E19: =ABS($B$18-E17)/E17*100 -> 1.9240336 | F19: =ABS($B$18-F17)/F17*100 -> 1.3148661 | G19: =ABS($B$18-G17)/G17*100 -> 1.3148661 | H19: =ABS($B$18-H17)/H17*100 -> 0.79272251 | K19: =ABS($B$18-K17)/$B$18*100 -> #DIV/0! | L19: =ABS($B$18-L17)/$B$18*100 -> 15.764335 | M19: =ABS($B$18-M17)/$B$18*100 -> #DIV/0! | N19: =ABS($B$18-N17)/$B$18*100 -> #DIV/0! | O19: =ABS($B$18-O17)/$B$18*100 -> #DIV/0! | P19: =ABS($B$18-P17)/$B$18*100 -> #DIV/0!
A20: Перемещения по Y мм | C20: 0.001396 | D20: 0.001676 | E20: 0.001796 | F20: 0.001863 | G20: 0.001905 | H20: 0.001956
A21: Деформация Х | C21: =C16/C12 -> 0.0001754 | D21: =D16/D12 -> 0.00017816667 | E21: =E16/E12 -> 0.00017888889 | F21: =F16/F12 -> 0.00018 | G21: =G16/G12 -> 0.00018 | H21: =H16/H12 -> 0.00018095238 | K21: =K16/K12 -> #DIV/0! | L21: =L16/L12 -> 5.4133333e-05 | M21: =M16/M12 -> #DIV/0! | N21: =N16/N12 -> #DIV/0! | O21: =O16/O12 -> #DIV/0! | P21: =P16/P12 -> #DIV/0!
A22: Деформация Y | C22: =C20/C14 -> 4.0300231e-05 | D22: =D20/D14 -> 4.8383372e-05 | E22: =E20/E14 -> 5.1847575e-05 | F22: =F20/F14 -> 5.3781755e-05 | G22: =G20/G14 -> 5.4994226e-05 | H22: =H20/H14 -> 5.6466513e-05 | K22: =K20/K14 -> 0 | L22: =L20/L14 -> 0 | M22: =M20/M14 -> 0 | N22: =N20/N14 -> 0 | O22: =O20/O14 -> 0 | P22: =P20/P14 -> 0
A23: Пуассон YX | C23: =C22/C21 -> 0.22976186 | D23: =D22/D21 -> 0.27156242 | E23: =E22/E21 -> 0.28983116 | F23: =F22/F21 -> 0.29878753 | G23: =G22/G21 -> 0.30552348 | H23: =H22/H21 -> 0.31205178 | K23: =K22/K21 -> #DIV/0! | L23: =L22/L21 -> 0 | M23: =M22/M21 -> #DIV/0! | N23: =N22/N21 -> #DIV/0! | O23: =O22/O21 -> #DIV/0! | P23: =P22/P21 -> #DIV/0!
A24: Пуассон YX аналитический | B24: 0.3322
A25: Погрешность yx % | B25: =B24 -> 0.3322 | C25: =(ABS(C23-$B$25)/C23)*100 -> 44.584482 | D25: =(ABS(D23-$B$25)/D23)*100 -> 22.329148 | E25: =(ABS(E23-$B$25)/E23)*100 -> 14.618454 | F25: =(ABS(F23-$B$25)/F23)*100 -> 11.182686 | G25: =(ABS(G23-$B$25)/G23)*100 -> 8.7314142 | H25: =(ABS(H23-$B$25)/H23)*100 -> 6.456691 | K25: =(ABS(K23-$B$25)/$B$25)*100 -> #DIV/0! | L25: =(ABS(L23-$B$25)/$B$25)*100 -> 100 | M25: =(ABS(M23-$B$25)/$B$25)*100 -> #DIV/0! | N25: =(ABS(N23-$B$25)/$B$25)*100 -> #DIV/0! | O25: =(ABS(O23-$B$25)/$B$25)*100 -> #DIV/0! | P25: =(ABS(P23-$B$25)/$B$25)*100 -> #DIV/0!
A27: Перемещения по Z | C27: =8.806*10^(-4) -> 0.0008806 | D27: =9.483*10^(-4) -> 0.0009483 | E27: =9.733*10^(-4) -> 0.0009733 | F27: =9.862*10^(-4) -> 0.0009862 | G27: =9.942*10^(-4) -> 0.0009942 | H27: =1.003*10^(-3) -> 0.001003
A28: Деформация по Z | C28: =C27/$B$6 -> 2.9353333e-05 | D28: =D27/$B$6 -> 3.161e-05 | E28: =E27/$B$6 -> 3.2443333e-05 | F28: =F27/$B$6 -> 3.2873333e-05 | G28: =G27/$B$6 -> 3.314e-05 | H28: =H27/$B$6 -> 3.3433333e-05
A29: Пуассон ZX | C29: =C28/C21 -> 0.16735082 | D29: =D28/D21 -> 0.17741815 | E29: =E28/E21 -> 0.18136025 | F29: =F28/F21 -> 0.18262963 | G29: =G28/G21 -> 0.18411111 | H29: =H28/H21 -> 0.18476316
A30: Пуассон ZX аналитический | B30: 0.188
A31: Погрешность ZX % | B31: =B30 -> 0.188 | C31: =ABS($B$31-C29)/C29*100 -> 12.33886 | D31: =ABS($B$31-D29)/D29*100 -> 5.9643573 | E31: =ABS($B$31-E29)/E29*100 -> 3.6610843 | F31: =ABS($B$31-F29)/F29*100 -> 2.94058 | G31: =ABS($B$31-G29)/G29*100 -> 2.1122511 | H31: =ABS($B$31-H29)/H29*100 -> 1.7518872
A33: Растяжение по Y | B33: При увеличении ячеек по Y
A34: Количество ячеек по Y | C34: 2 | D34: 4 | E34: 6 | F34: 8 | G34: 10 | H34: 14
A35: Длина модели по Y | C35: =$B$8*C34 -> 34.64 | D35: =$B$8*D34 -> 69.28 | E35: =$B$8*E34 -> 103.92 | F35: =$B$8*F34 -> 138.56 | G35: =$B$8*G34 -> 173.2 | H35: =$B$8*H34 -> 242.48
A36: Количество ячеек по Х | C36: 2 | D36: 2 | E36: 2 | F36: 2 | G36: 2 | H36: 2
A37: Длина модели по Х | C37: =$B$9*C36 -> 30 | D37: =$B$9*D36 -> 30 | E37: =$B$9*E36 -> 30 | F37: =$B$9*F36 -> 30 | G37: =$B$9*G36 -> 30 | H37: =$B$9*H36 -> 30
A38: Площадь в направлении Y м^2 | C38: =C37*$B$6/1000000 -> 0.0009 | D38: =D37*$B$6/1000000 -> 0.0009 | E38: =E37*$B$6/1000000 -> 0.0009 | F38: =F37*$B$6/1000000 -> 0.0009 | G38: =G37*$B$6/1000000 -> 0.0009 | H38: =H37*$B$6/1000000 -> 0.0009
A39: Перемезщения по Y | C39: 0.005998 | D39: 0.0121 | E39: 0.018 | F39: 0.024 | G39: 0.03 | H39: 0.042
A40: Ey | C40: =($E$1*(C35/1000)/(C38*C39/1000))/(10^6) -> 6416.9538 | D40: =($E$1*(D35/1000)/(D38*D39/1000))/(10^6) -> 6361.7998 | E40: =($E$1*(E35/1000)/(E38*E39/1000))/(10^6) -> 6414.8148 | F40: =($E$1*(F35/1000)/(F38*F39/1000))/(10^6) -> 6414.8148 | G40: =($E$1*(G35/1000)/(G38*G39/1000))/(10^6) -> 6414.8148 | H40: =($E$1*(H35/1000)/(H38*H39/1000))/(10^6) -> 6414.8148
A41: Ey аналитическое | B41: =4269.832769697 -> 4269.8328
A42: Погрешность | C42: =ABS($B$41-C40)/$B$41*100 -> 50.285834 | D42: =ABS($B$41-D40)/$B$41*100 -> 48.994121 | E42: =ABS($B$41-E40)/$B$41*100 -> 50.235739 | F42: =ABS($B$41-F40)/$B$41*100 -> 50.235739 | G42: =ABS($B$41-G40)/$B$41*100 -> 50.235739 | H42: =ABS($B$41-H40)/$B$41*100 -> 50.235739
...

Sheet anisogrid
A1: t= | B1: 1 | C1: 1 | D1: Сила | E1: 10000 | F1: t_факт | G1: 2
A2: v= | B2: 0.2 | C2: 0.2 | F2: v_факт | G2: =(G1/B4)+(2*G1/B5) -> 0.39994931
A3: phi= | B3: 15 | C3: =D3*3.1415/180 -> 0.26179167 | D3: 15
A4: a90= | B4: =C4 -> 24.32 | C4: 24.32 | D4: =C1*(1+SIN(C3))/(C2*SIN(C3)) -> 24.319073
A5: a_phi | B5: =C5 -> 12.59 | C5: 12.59 | D5: =2*C1*(1+SIN(C3))/C2 -> 12.588116
A6: Высота КЭМ | B6: =C4 -> 24.32 | C6: =3.75*2 -> 7.5
A7: Основание треугольника | B7: =C7 -> 13.03 | C7: 13.03 | D7: =2*TAN(C3)*C4 -> 13.032646
A8: Сторона треугольника | B8: =C8 -> 25.17 | C8: 25.17 | D8: =C4/COS(C3) -> 25.177865
A9: Длина ячейки Х | B9: =B4 -> 24.32 | C9: =D4 -> 24.319073
A10: Ширина ячейки Y | B10: =B7 -> 13.03 | C10: =D7 -> 13.032646
A11: Количество ячеек по Х | B11: 1 | C11: 2 | D11: 4 | E11: 6 | F11: 8 | G11: 10 | H11: 12 | L11: 2
A12: Длина модели по Х | B12: =$B$9*B11 -> 24.32 | C12: =$B$9*C11 -> 48.64 | D12: =$B$9*D11 -> 97.28 | E12: =$B$9*E11 -> 145.92 | F12: =$B$9*F11 -> 194.56 | G12: =$B$9*G11 -> 243.2 | H12: =$B$9*H11 -> 291.84 | K12: =$B$9*K11 -> 0 | L12: =$B$9*L11 -> 48.64 | M12: =$B$9*M11 -> 0 | N12: =$B$9*N11 -> 0 | O12: =$B$9*O11 -> 0 | P12: =$B$9*P11 -> 0
A13: Количество ячеек по Y | B13: 2 | C13: 2 | D13: 2 | E13: 2 | F13: 2 | G13: 2 | H13: 2 | K13: 2 | L13: 8 | M13: 2 | N13: 2 | O13: 2 | P13: 2
A14: Длина модели по Y мм | B14: =$B$10*B13 -> 26.06 | C14: =$B$10*C13 -> 26.06 | D14: =$B$10*D13 -> 26.06 | E14: =$B$10*E13 -> 26.06 | F14: =$B$10*F13 -> 26.06 | G14: =$B$10*G13 -> 26.06 | H14: =$B$10*H13 -> 26.06 | K14: =$B$10*K13 -> 26.06 | L14: =$B$10*L13 -> 104.24 | M14: =$B$10*M13 -> 26.06 | N14: =$B$10*N13 -> 26.06 | O14: =$B$10*O13 -> 26.06 | P14: =$B$10*P13 -> 26.06
A15: Площадь в направлении X м^2 | B15: =B14/1000*$B$6/1000 -> 0.0006337792 | C15: =C14/1000*$B$6/1000 -> 0.0006337792 | D15: =D14/1000*$B$6/1000 -> 0.0006337792 | E15: =E14/1000*$B$6/1000 -> 0.0006337792 | F15: =F14/1000*$B$6/1000 -> 0.0006337792 | G15: =G14/1000*$B$6/1000 -> 0.0006337792 | H15: =H14/1000*$B$6/1000 -> 0.0006337792 | K15: =K14/1000*$B$6/1000 -> 0.0006337792 | L15: =L14/1000*$B$6/1000 -> 0.0025351168 | M15: =M14/1000*$B$6/1000 -> 0.0006337792 | N15: =N14/1000*$B$6/1000 -> 0.0006337792 | O15: =O14/1000*$B$6/1000 -> 0.0006337792 | P15: =P14/1000*$B$6/1000 -> 0.0006337792
A16: Перемещения по Х мм | B16: 0 | C16: 0.071291 | D16: 0.142582 | E16: 0.213874 | F16: 0.285166 | G16: 0.356458 | H16: 0.427749 | L16: 0.001624
A17: Ex | C17: =($E$1*(C12/1000)/(C15*C16/1000))/(10^6) -> 10765.17 | D17: =($E$1*(D12/1000)/(D15*D16/1000))/(10^6) -> 10765.17 | E17: =($E$1*(E12/1000)/(E15*E16/1000))/(10^6) -> 10765.119 | F17: =($E$1*(F12/1000)/(F15*F16/1000))/(10^6) -> 10765.094 | G17: =($E$1*(G12/1000)/(G15*G16/1000))/(10^6) -> 10765.079 | H17: =($E$1*(H12/1000)/(H15*H16/1000))/(10^6) -> 10765.094 | K17: =($E$1*(K12/1000)/(K15*K16/1000))/(10^6) -> #DIV/0! | L17: =($E$1*(L12/1000)/(L15*L16/1000))/(10^6) -> 118143.43 | M17: =($E$1*(M12/1000)/(M15*M16/1000))/(10^6) -> #DIV/0! | N17: =($E$1*(N12/1000)/(N15*N16/1000))/(10^6) -> #DIV/0! | O17: =($E$1*(O12/1000)/(O15*O16/1000))/(10^6) -> #DIV/0! | P17: =($E$1*(P12/1000)/(P15*P16/1000))/(10^6) -> #DIV/0!
A18: Ех аналитическое | B18: 10751
A19: Погрешность % | C19: =ABS($B$18-C17)/C17*100 -> 0.13162481 | D19: =ABS($B$18-D17)/D17*100 -> 0.13162481 | E19: =ABS($B$18-E17)/E17*100 -> 0.13115786 | F19: =ABS($B$18-F17)/F17*100 -> 0.13092438 | G19: =ABS($B$18-G17)/G17*100 -> 0.13078429 | H19: =ABS($B$18-H17)/H17*100 -> 0.13092438 | K19: =ABS($B$18-K17)/$B$18*100 -> #DIV/0! | L19: =ABS($B$18-L17)/$B$18*100 -> 998.90641 | M19: =ABS($B$18-M17)/$B$18*100 -> #DIV/0! | N19: =ABS($B$18-N17)/$B$18*100 -> #DIV/0! | O19: =ABS($B$18-O17)/$B$18*100 -> #DIV/0! | P19: =ABS($B$18-P17)/$B$18*100 -> #DIV/0!
A20: Перемещения по Y мм | C20: 0.008982 | D20: 0.008982 | E20: 0.008982 | F20: 0.008982 | G20: 0.008982 | H20: 0.008982
A21: Деформация Х | C21: =C16/C12 -> 0.0014656867 | D21: =D16/D12 -> 0.0014656867 | E21: =E16/E12 -> 0.0014656935 | F21: =F16/F12 -> 0.001465697 | G21: =G16/G12 -> 0.001465699 | H21: =H16/H12 -> 0.001465697 | K21: =K16/K12 -> #DIV/0! | L21: =L16/L12 -> 3.3388158e-05 | M21: =M16/M12 -> #DIV/0! | N21: =N16/N12 -> #DIV/0! | O21: =O16/O12 -> #DIV/0! | P21: =P16/P12 -> #DIV/0!
A22: Деформация Y | C22: =C20/C14 -> 0.00034466616 | D22: =D20/D14 -> 0.00034466616 | E22: =E20/E14 -> 0.00034466616 | F22: =F20/F14 -> 0.00034466616 | G22: =G20/G14 -> 0.00034466616 | H22: =H20/H14 -> 0.00034466616 | K22: =K20/K14 -> 0 | L22: =L20/L14 -> 0 | M22: =M20/M14 -> 0 | N22: =N20/N14 -> 0 | O22: =O20/O14 -> 0 | P22: =P20/P14 -> 0
A23: Пуассон YX | C23: =C22/C21 -> 0.23515678 | D23: =D22/D21 -> 0.23515678 | E23: =E22/E21 -> 0.23515568 | F23: =F22/F21 -> 0.23515513 | G23: =G22/G21 -> 0.2351548 | H23: =H22/H21 -> 0.23515513 | K23: =K22/K21 -> #DIV/0! | L23: =L22/L21 -> 0 | M23: =M22/M21 -> #DIV/0! | N23: =N22/N21 -> #DIV/0! | O23: =O22/O21 -> #DIV/0! | P23: =P22/P21 -> #DIV/0!
A24: Пуассон YX аналитический | B24: 0.2352
A25: Погрешность yx % | B25: =B24 -> 0.2352 | C25: =(ABS(C23-$B$25)/$B$25)*100 -> 0.018377177 | D25: =(ABS(D23-$B$25)/$B$25)*100 -> 0.018377177 | E25: =(ABS(E23-$B$25)/$B$25)*100 -> 0.018844656 | F25: =(ABS(F23-$B$25)/$B$25)*100 -> 0.019078394 | G25: =(ABS(G23-$B$25)/$B$25)*100 -> 0.019218636 | H25: =(ABS(H23-$B$25)/$B$25)*100 -> 0.019078394 | K25: =(ABS(K23-$B$25)/$B$25)*100 -> #DIV/0! | L25: =(ABS(L23-$B$25)/$B$25)*100 -> 100 | M25: =(ABS(M23-$B$25)/$B$25)*100 -> #DIV/0! | N25: =(ABS(N23-$B$25)/$B$25)*100 -> #DIV/0! | O25: =(ABS(O23-$B$25)/$B$25)*100 -> #DIV/0! | P25: =(ABS(P23-$B$25)/$B$25)*100 -> #DIV/0!
A27: Перемещения по Z | C27: =0.0137 -> 0.0137 | D27: =0.0137 -> 0.0137 | E27: =0.0137 -> 0.0137 | F27: =0.0137 -> 0.0137 | G27: =0.0137 -> 0.0137 | H27: =0.0137 -> 0.0137
A28: Деформация по Z | C28: =C27/$B$6 -> 0.00056332237 | D28: =D27/$B$6 -> 0.00056332237 | E28: =E27/$B$6 -> 0.00056332237 | F28: =F27/$B$6 -> 0.00056332237 | G28: =G27/$B$6 -> 0.00056332237 | H28: =H27/$B$6 -> 0.00056332237
A29: Пуассон ZX | C29: =C28/C21 -> 0.38434024 | D29: =D28/D21 -> 0.38434024 | E29: =E28/E21 -> 0.38433844 | F29: =F28/F21 -> 0.38433754 | G29: =G28/G21 -> 0.384337 | H29: =H28/H21 -> 0.38433754
A30: Пуассон ZX аналитический | B30: 0.383
A31: Погрешность ZX % | B31: =B30 -> 0.383 | C31: =ABS($B$31-C29)/$B$31*100 -> 0.34993193 | D31: =ABS($B$31-D29)/$B$31*100 -> 0.34993193 | E31: =ABS($B$31-E29)/$B$31*100 -> 0.34946273 | F31: =ABS($B$31-F29)/$B$31*100 -> 0.34922813 | G31: =ABS($B$31-G29)/$B$31*100 -> 0.34908737 | H31: =ABS($B$31-H29)/$B$31*100 -> 0.34922813
A33: Растяжение по Y | B33: При увеличении ячеек по Y
A34: Количество ячеек по Y
A35: Длина модели по Y
A36: Количество ячеек по Х
A37: Длина модели по Х
A38: Площадь в направлении Y м^2
A39: Перемезщения по Y
A40: Ey
A41: Ey аналитическое
A42: Погрешность
...

Sheet anisogrid15
A1: t= | B1: 1 | C1: 1 | D1: Сила | E1: 10000 | F1: t_факт | G1: 2
A2: v= | B2: 0.2 | C2: 0.2 | F2: v_факт | G2: =(G1/B4)+(2*G1/B5) -> 0.39994931
A3: phi= | B3: 15 | C3: =D3*3.1415/180 -> 0.26179167 | D3: 15
A4: a90= | B4: =C4 -> 24.32 | C4: 24.32 | D4: =C1*(1+SIN(C3))/(C2*SIN(C3)) -> 24.319073
A5: a_phi | B5: =C5 -> 12.59 | C5: 12.59 | D5: =2*C1*(1+SIN(C3))/C2 -> 12.588116
A6: Высота КЭМ | B6: =C4 -> 24.32 | C6: =3.75*2 -> 7.5
A7: Основание треугольника | B7: =C7 -> 13.03 | C7: 13.03 | D7: =2*TAN(C3)*C4 -> 13.032646
A8: Сторона треугольника | B8: =C8 -> 25.17 | C8: 25.17 | D8: =C4/COS(C3) -> 25.177865
A9: Длина ячейки Х | B9: =B4 -> 24.32 | C9: =D4 -> 24.319073
A10: Ширина ячейки Y | B10: =B7 -> 13.03 | C10: =D7 -> 13.032646
A11: Количество ячеек по Х | B11: 1 | C11: 2 | D11: 4 | E11: 6 | F11: 8 | G11: 10 | H11: 12 | L11: 2
A12: Длина модели по Х | B12: =$B$9*B11 -> 24.32 | C12: =$B$9*C11 -> 48.64 | D12: =$B$9*D11 -> 97.28 | E12: =$B$9*E11 -> 145.92 | F12: =$B$9*F11 -> 194.56 | G12: =$B$9*G11 -> 243.2 | H12: =$B$9*H11 -> 291.84 | K12: =$B$9*K11 -> 0 | L12: =$B$9*L11 -> 48.64 | M12: =$B$9*M11 -> 0 | N12: =$B$9*N11 -> 0 | O12: =$B$9*O11 -> 0 | P12: =$B$9*P11 -> 0
A13: Количество ячеек по Y | B13: 2 | C13: 2 | D13: 2 | E13: 2 | F13: 2 | G13: 2 | H13: 2 | K13: 2 | L13: 8 | M13: 2 | N13: 2 | O13: 2 | P13: 2
A14: Длина модели по Y мм | B14: =$B$10*B13 -> 26.06 | C14: =$B$10*C13 -> 26.06 | D14: =$B$10*D13 -> 26.06 | E14: =$B$10*E13 -> 26.06 | F14: =$B$10*F13 -> 26.06 | G14: =$B$10*G13 -> 26.06 | H14: =$B$10*H13 -> 26.06 | K14: =$B$10*K13 -> 26.06 | L14: =$B$10*L13 -> 104.24 | M14: =$B$10*M13 -> 26.06 | N14: =$B$10*N13 -> 26.06 | O14: =$B$10*O13 -> 26.06 | P14: =$B$10*P13 -> 26.06
A15: Площадь в направлении X м^2 | B15: =B14/1000*$B$6/1000 -> 0.0006337792 | C15: =C14/1000*$B$6/1000 -> 0.0006337792 | D15: =D14/1000*$B$6/1000 -> 0.0006337792 | E15: =E14/1000*$B$6/1000 -> 0.0006337792 | F15: =F14/1000*$B$6/1000 -> 0.0006337792 | G15: =G14/1000*$B$6/1000 -> 0.0006337792 | H15: =H14/1000*$B$6/1000 -> 0.0006337792 | K15: =K14/1000*$B$6/1000 -> 0.0006337792 | L15: =L14/1000*$B$6/1000 -> 0.0025351168 | M15: =M14/1000*$B$6/1000 -> 0.0006337792 | N15: =N14/1000*$B$6/1000 -> 0.0006337792 | O15: =O14/1000*$B$6/1000 -> 0.0006337792 | P15: =P14/1000*$B$6/1000 -> 0.0006337792
A16: Перемещения по Х мм | B16: 0 | C16: 0.101 | D16: 0.202 | E16: 0.303 | F16: 0.405 | G16: 0.506 | H16: 0.607 | L16: 0.001624
A17: Ex | C17: =($E$1*(C12/1000)/(C15*C16/1000))/(10^6) -> 7598.611 | D17: =($E$1*(D12/1000)/(D15*D16/1000))/(10^6) -> 7598.611 | E17: =($E$1*(E12/1000)/(E15*E16/1000))/(10^6) -> 7598.611 | F17: =($E$1*(F12/1000)/(F15*F16/1000))/(10^6) -> 7579.849 | G17: =($E$1*(G12/1000)/(G15*G16/1000))/(10^6) -> 7583.594 | H17: =($E$1*(H12/1000)/(H15*H16/1000))/(10^6) -> 7586.0927 | K17: =($E$1*(K12/1000)/(K15*K16/1000))/(10^6) -> #DIV/0! | L17: =($E$1*(L12/1000)/(L15*L16/1000))/(10^6) -> 118143.43 | M17: =($E$1*(M12/1000)/(M15*M16/1000))/(10^6) -> #DIV/0! | N17: =($E$1*(N12/1000)/(N15*N16/1000))/(10^6) -> #DIV/0! | O17: =($E$1*(O12/1000)/(O15*O16/1000))/(10^6) -> #DIV/0! | P17: =($E$1*(P12/1000)/(P15*P16/1000))/(10^6) -> #DIV/0!
A18: Ех аналитическое | B18: 7570
A19: Погрешность % | C19: =ABS($B$18-C17)/C17*100 -> 0.376529 | D19: =ABS($B$18-D17)/D17*100 -> 0.376529 | E19: =ABS($B$18-E17)/E17*100 -> 0.376529 | F19: =ABS($B$18-F17)/F17*100 -> 0.12993625 | G19: =ABS($B$18-G17)/G17*100 -> 0.1792548 | H19: =ABS($B$18-H17)/H17*100 -> 0.21213383 | K19: =ABS($B$18-K17)/$B$18*100 -> #DIV/0! | L19: =ABS($B$18-L17)/$B$18*100 -> 1460.6794 | M19: =ABS($B$18-M17)/$B$18*100 -> #DIV/0! | N19: =ABS($B$18-N17)/$B$18*100 -> #DIV/0! | O19: =ABS($B$18-O17)/$B$18*100 -> #DIV/0! | P19: =ABS($B$18-P17)/$B$18*100 -> #DIV/0!
A20: sigma max | C20: 55.79
A21: sigma analit
A22: разница
A24: Перемещения по Y мм | C24: 0.0126 | D24: 0.0126 | E24: 0.0126 | F24: 0.0126 | G24: 0.0126 | H24: 0.0126
A25: Деформация Х | C25: =C16/C12 -> 0.0020764803 | D25: =D16/D12 -> 0.0020764803 | E25: =E16/E12 -> 0.0020764803 | F25: =F16/F12 -> 0.0020816201 | G25: =G16/G12 -> 0.0020805921 | H25: =H16/H12 -> 0.0020799068 | K25: =K16/K12 -> #DIV/0! | L25: =L16/L12 -> 3.3388158e-05 | M25: =M16/M12 -> #DIV/0! | N25: =N16/N12 -> #DIV/0! | O25: =O16/O12 -> #DIV/0! | P25: =P16/P12 -> #DIV/0!
A26: Деформация Y | C26: =C24/C14 -> 0.00048349962 | D26: =D24/D14 -> 0.00048349962 | E26: =E24/E14 -> 0.00048349962 | F26: =F24/F14 -> 0.00048349962 | G26: =G24/G14 -> 0.00048349962 | H26: =H24/H14 -> 0.00048349962 | K26: =K24/K14 -> 0 | L26: =L24/L14 -> 0 | M26: =M24/M14 -> 0 | N26: =N24/N14 -> 0 | O26: =O24/O14 -> 0 | P26: =P24/P14 -> 0
A27: Пуассон YX | C27: =C26/C25 -> 0.23284576 | D27: =D26/D25 -> 0.23284576 | E27: =E26/E25 -> 0.23284576 | F27: =F26/F25 -> 0.23227083 | G27: =G26/G25 -> 0.23238559 | H27: =H26/H25 -> 0.23246215 | K27: =K26/K25 -> #DIV/0! | L27: =L26/L25 -> 0 | M27: =M26/M25 -> #DIV/0! | N27: =N26/N25 -> #DIV/0! | O27: =O26/O25 -> #DIV/0! | P27: =P26/P25 -> #DIV/0!
A28: Пуассон YX аналитический | B28: 0.2345
A29: Погрешность yx % | B29: =B28 -> 0.2345 | C29: =(ABS(C27-$B$29)/$B$29)*100 -> 0.70543463 | D29: =(ABS(D27-$B$29)/$B$29)*100 -> 0.70543463 | E29: =(ABS(E27-$B$29)/$B$29)*100 -> 0.70543463 | F29: =(ABS(F27-$B$29)/$B$29)*100 -> 0.95060639 | G29: =(ABS(G27-$B$29)/$B$29)*100 -> 0.90166895 | H29: =(ABS(H27-$B$29)/$B$29)*100 -> 0.86901711 | K29: =(ABS(K27-$B$29)/$B$29)*100 -> #DIV/0! | L29: =(ABS(L27-$B$29)/$B$29)*100 -> 100 | M29: =(ABS(M27-$B$29)/$B$29)*100 -> #DIV/0! | N29: =(ABS(N27-$B$29)/$B$29)*100 -> #DIV/0! | O29: =(ABS(O27-$B$29)/$B$29)*100 -> #DIV/0! | P29: =(ABS(P27-$B$29)/$B$29)*100 -> #DIV/0!
A31: Перемещения по Z | C31: =0.0149 -> 0.0149 | D31: =0.0149 -> 0.0149 | E31: =0.0149 -> 0.0149 | F31: =0.0149 -> 0.0149 | G31: =0.0149 -> 0.0149 | H31: =0.0149 -> 0.0149
A32: Деформация по Z | C32: =C31/$B$6 -> 0.00061266447 | D32: =D31/$B$6 -> 0.00061266447 | E32: =E31/$B$6 -> 0.00061266447 | F32: =F31/$B$6 -> 0.00061266447 | G32: =G31/$B$6 -> 0.00061266447 | H32: =H31/$B$6 -> 0.00061266447
A33: Пуассон ZX | C33: =C32/C25 -> 0.2950495 | D33: =D32/D25 -> 0.2950495 | E33: =E32/E25 -> 0.2950495 | F33: =F32/F25 -> 0.29432099 | G33: =G32/G25 -> 0.2944664 | H33: =H32/H25 -> 0.29456343
A34: Пуассон ZX аналитический | B34: 0.294
A35: Погрешность ZX % | B35: =B34 -> 0.294 | C35: =ABS($B$35-C33)/$B$35*100 -> 0.35697447 | D35: =ABS($B$35-D33)/$B$35*100 -> 0.35697447 | E35: =ABS($B$35-E33)/$B$35*100 -> 0.35697447 | F35: =ABS($B$35-F33)/$B$35*100 -> 0.10917947 | G35: =ABS($B$35-G33)/$B$35*100 -> 0.15864053 | H35: =ABS($B$35-H33)/$B$35*100 -> 0.19164173
A49: Растяжение по Y | B49: При увеличении ячеек по X | J49: no rbe | K49: rbe
A50: Количество ячеек по Y | C50: 2 | D50: 2 | E50: 2 | F50: 2 | G50: 2 | H50: 2 | I50: 8 | J50: 13 | K50: 13
A51: Длина модели по Y | C51: =$B$10*C50 -> 26.06 | D51: =$B$10*D50 -> 26.06 | E51: =$B$10*E50 -> 26.06 | F51: =$B$10*F50 -> 26.06 | G51: =$B$10*G50 -> 26.06 | H51: =$B$10*H50 -> 26.06 | I51: =$B$8*I50 -> 201.36 | J51: =$B$8*J50 -> 327.21 | K51: =$B$8*K50 -> 327.21
A52: Количество ячеек по Х | C52: 2 | D52: 4 | E52: 6 | F52: 8 | G52: 10 | H52: 12 | I52: 8 | J52: 12 | K52: 12
A53: Длина модели по Х | C53: =$B$9*C52 -> 48.64 | D53: =$B$9*D52 -> 97.28 | E53: =$B$9*E52 -> 145.92 | F53: =$B$9*F52 -> 194.56 | G53: =$B$9*G52 -> 243.2 | H53: =$B$9*H52 -> 291.84 | I53: =$B$9*I52 -> 194.56 | J53: =$B$9*J52 -> 291.84 | K53: =$B$9*K52 -> 291.84
A54: Площадь в направлении Y м^2 | C54: =C53*$B$6/1000000 -> 0.0011829248 | D54: =D53*$B$6/1000000 -> 0.0023658496 | E54: =E53*$B$6/1000000 -> 0.0035487744 | F54: =F53*$B$6/1000000 -> 0.0047316992 | G54: =G53*$B$6/1000000 -> 0.005914624 | H54: =H53*$B$6/1000000 -> 0.0070975488 | I54: =I53*$B$6/1000000 -> 0.0047316992 | J54: =J53*7/1000000 -> 0.00204288 | K54: =K53*7/1000000 -> 0.00204288
A55: Перемезщения по Y | C55: 0.0958 | D55: 0.0479 | E55: 0.0319 | F55: 0.0239 | G55: 0.0192 | H55: 0.016 | I55: 0.007995 | J55: 0.0387 | K55: 0.0385
...

Sheet 15_stress
A1: t= | B1: 1 | C1: 1 | D1: Сила | E1: 10000 | F1: t_факт | G1: 2
A2: v= | B2: 0.2 | C2: 0.2 | F2: v_факт | G2: =(G1/B4)+(2*G1/B5) -> 0.39994931
A3: phi= | B3: 15 | C3: =D3*3.1415/180 -> 0.26179167 | D3: 15
A4: a90= | B4: =C4 -> 24.32 | C4: 24.32 | D4: =C1*(1+SIN(C3))/(C2*SIN(C3)) -> 24.319073
A5: a_phi | B5: =C5 -> 12.59 | C5: 12.59 | D5: =2*C1*(1+SIN(C3))/C2 -> 12.588116
A6: Высота КЭМ | B6: =C4 -> 24.32 | C6: =3.75*2 -> 7.5
A7: Основание треугольника | B7: =C7 -> 13.03 | C7: 13.03 | D7: =2*TAN(C3)*C4 -> 13.032646
A8: Сторона треугольника | B8: =C8 -> 25.17 | C8: 25.17 | D8: =C4/COS(C3) -> 25.177865
A9: Длина ячейки Х | B9: =B4 -> 24.32 | C9: =D4 -> 24.319073
A10: Ширина ячейки Y | B10: =B7 -> 13.03 | C10: =D7 -> 13.032646
A11: Количество ячеек по Х | B11: 1 | C11: 2 | E11: sigmaX | F11: =50 -> 50
A12: Длина модели по Х | B12: =$B$9*B11 -> 24.32 | C12: =$B$9*C11 -> 48.64 | E12: площадь | F12: =B14*B6 -> 633.7792
A13: Количество ячеек по Y | B13: 2 | C13: 2 | E13: сила X | F13: =F11*F12 -> 31688.96 | H13: ТУТ ПЕРЕМЕЩЕНИЯ И СИЛА ВООБЩЕ НЕ ИМЕЮТ ОТНОШЕНИЯ К НАПРЯЖЕННИЯМ
A14: Длина модели по Y мм | B14: =$B$10*B13 -> 26.06 | C14: =$B$10*C13 -> 26.06
A15: Площадь в направлении X м^2 | B15: =B14/1000*$B$6/1000 -> 0.0006337792 | C15: =C14/1000*$B$6/1000 -> 0.0006337792 | H15: ЭТОТ ЛИСТ ТОЛЬКО ДЛЯ НАПРЯЖЕНИЙ
A16: Перемещения по Х мм | B16: 0 | C16: 0.101 | E16: sigmaY | F16: =50 -> 50
A17: Ex | C17: =($E$1*(C12/1000)/(C15*C16/1000))/(10^6) -> 7598.611 | E17: площадь | F17: =B6*C12 -> 1182.9248
A18: Ех аналитическое | B18: 7570 | E18: сила Y | F18: =F16*F17 -> 59146.24
A19: Погрешность % | C19: =ABS($B$18-C17)/C17*100 -> 0.376529
A20: sigma max | C20: 84.27 | D20: 21.7
A21: sigma analit | C21: 84.32 | D21: 21.82
A22: разница
E24: sigmaZ | F24: 50
E25: площадь | F25: =C14*C12 -> 1267.5584
E26: сила Z | F26: =F24*F25 -> 63377.92 | I26: x | Y26: y | AN26: xy | BC26: z | BQ26: xz | CG26: yz
I27: 30 | M27: 60 | Q27: 120 | Y27: 30 | AC27: 60 | AG27: 120 | AN27: 30 | AR27: 60 | AV27: 120 | BC27: 30 | BG27: 60 | BK27: 120 | BQ27: 30 | BU27: 60 | BY27: 120 | CG27: 30 | CK27: 60 | CO27: 120
I28: diag fem | J28: diag continuum | K28: 90 fem | L28: 90 continuum | M28: diag fem | N28: diag continuum | O28: 90 fem | P28: 90 continuum | Q28: diag fem | R28: diag continuum | S28: 90 fem | T28: 90 continuum | Y28: diag fem | Z28: diag continuum | AA28: 90 fem | AB28: 90 continuum | AC28: diag fem | AD28: diag continuum | AE28: 90 fem | AF28: 90 continuum | AG28: diag fem | AH28: diag continuum | AI28: 90 fem | AJ28: 90 continuum | AN28: diag fem | AO28: diag continuum | AP28: 90 fem | AQ28: 90 continuum | AR28: diag fem | AS28: diag continuum | AT28: 90 fem | AU28: 90 continuum | AV28: diag fem | AW28: diag continuum | AX28: 90 fem | AY28: 90 continuum | BC28: diag fem | BD28: diag continuum | BE28: 90 fem | BF28: 90 continuum | BG28: diag fem | BH28: diag continuum | BI28: 90 fem | BJ28: 90 continuum | BK28: diag fem | BL28: diag continuum | BM28: 90 fem | BN28: 90 continuum | BQ28: diag fem | BR28: diag continuum | BS28: 90 fem | BT28: 90 continuum | BU28: diag fem | BV28: diag continuum | BW28: 90 fem | BX28: 90 continuum | BY28: diag fem | BZ28: diag continuum | CA28: 90 fem | CB28: 90 continuum | CG28: diag fem | CH28: diag continuum | CI28: 90 fem | CJ28: 90 continuum | CK28: diag fem | CL28: diag continuum | CM28: 90 fem | CN28: 90 continuum | CO28: diag fem | CP28: diag continuum | CQ28: 90 fem | CR28: 90 continuum
I29: =$C$20 -> 84.27 | J29: =$C$21 -> 84.32 | K29: =$D$20 -> 21.7 | L29: =$D$21 -> 21.82 | M29: =isogrid_stress!$C$20 -> 124.87 | N29: =isogrid_stress!$C$21 -> 125 | O29: =isogrid_stress!$D$20 -> 62.23 | P29: =isogrid_stress!$D$21 -> 62.5 | Q29: =anisogrid120!$C$20 -> 453.558 | R29: =anisogrid120!$C$21 -> 450.88 | S29: =anisogrid120!$D$20 -> 380 | T29: =anisogrid120!$D$21 -> 384.79 | Y29: =$C$59 -> 0 | Z29: =$C$60 -> 0 | AA29: =$D$59 -> 303.73 | AB29: =$D$60 -> 303.98 | AC29: =isogrid_stress!$C$59 -> 0 | AD29: =isogrid_stress!$C$60 -> 0 | AE29: =isogrid_stress!$D$59 -> 187.35 | AF29: =isogrid_stress!$D$60 -> 187.5 | AG29: =anisogrid120!$C$59 -> 2.5 | AH29: =anisogrid120!$C$60 -> 0 | AI29: =anisogrid120!$D$59 -> 131.7 | AJ29: =anisogrid120!$D$60 -> 134.67 | AN29: =$C$126 -> 155.61 | AO29: =$C$127 -> 157.35 | AP29: =$D$126 -> 0 | AQ29: =$D$127 -> 0 | AR29: =isogrid_stress!$C$126 -> 110.88 | AS29: =isogrid_stress!$C$127 -> 108.25 | AT29: =isogrid_stress!$D$126 -> 0 | AU29: =isogrid_stress!$D$127 -> 0 | AV29: =anisogrid120!$C$126 -> 136.67 | AW29: =anisogrid120!$C$127 -> 134.67 | AX29: =anisogrid120!$D$126 -> 0 | AY29: =anisogrid120!$D$127 -> 0 | BC29: =$C$88 -> 62.493 | BD29: =$C$89 -> 62.5 | BE29: =$D$88 -> 62.493 | BF29: =$D$89 -> 62.5 | BG29: =isogrid_stress!$C$88 -> 62.5 | BH29: =isogrid_stress!$C$89 -> 62.5 | BI29: =isogrid_stress!$D$88 -> 62.5 | BJ29: =isogrid_stress!$D$89 -> 62.5 | BK29: =anisogrid120!$C$88 -> 62.478 | BL29: =anisogrid120!$C$89 -> 62.5 | BM29: =anisogrid120!$D$88 -> 62.478 | BN29: =anisogrid120!$D$89 -> 62.5 | BQ29: =$C$145 -> 1.63 | BR29: =$C$146 -> 1.63 | BS29: =$D$145 -> 0 | BT29: =$D$146 -> 0 | BU29: =isogrid_stress!$C$145 -> 2.256 | BV29: =isogrid_stress!$C$146 -> 2.17 | BW29: =isogrid_stress!$D$145 -> 0 | BX29: =isogrid_stress!$D$146 -> 0 | BY29: =anisogrid120!$C$145 -> 4.76 | BZ29: =anisogrid120!$C$146 -> 4.67 | CA29: =anisogrid120!$D$145 -> 0 | CB29: =anisogrid120!$D$146 -> 0 | CG29: =$C$166 -> 1.26 | CH29: =$C$167 -> 1.25 | CI29: =$D$166 -> 4.818 | CJ29: =$D$167 -> 4.83 | CK29: =isogrid_stress!$C$166 -> 1.262 | CL29: =isogrid_stress!$C$167 -> 1.25 | CM29: =isogrid_stress!$D$166 -> 2.525 | CN29: =isogrid_stress!$D$167 -> 2.5 | CO29: =anisogrid120!$C$166 -> 1.39 | CP29: =anisogrid120!$C$167 -> 1.25 | CQ29: =anisogrid120!$D$166 -> 1.598 | CR29: =anisogrid120!$D$167 -> 1.44
A49: Растяжение по Y | B49: При увеличении ячеек по X
A50: Количество ячеек по Y | C50: 2
A51: Длина модели по Y | C51: =$B$10*C50 -> 26.06
A52: Количество ячеек по Х | C52: 2
A53: Длина модели по Х | C53: =$B$9*C52 -> 48.64
A54: Площадь в направлении Y м^2 | C54: =C53*$B$6/1000000 -> 0.0011829248
A55: Перемезщения по Y | C55: 0.0958
A56: Ey | C56: =($E$1*(C51/1000)/(C54*C55/1000))/(10^6) -> 2299.5972
A57: Ey аналитическое | B57: 2293.9
A58: Погрешность | C58: =ABS($B$57-C56)/C56*100 -> 0.24774642
A59: sigma max | C59: 0 | D59: 303.73
A60: sigma analit | C60: 0 | D60: 303.98
...

Sheet isorg_30
A1: t= | B1: 4 | C1: 4 | D1: Сила | E1: 1000 | F1: t_факт | G1: 4
A2: v= | B2: 0.8 | C2: 0.8 | F2: v_факт | G2: =(G1/B4)+(2*G1/B5) -> 0.8
A3: phi= | B3: 30 | C3: =D3*3.1415/180 -> 0.52358333 | D3: 30
A4: a90= | B4: 15 | C4: =3.75 -> 3.75 | D4: =C1*(1+SIN(C3))/(C2*SIN(C3)) -> 15.000267
A5: a_phi | B5: 15 | C5: =3.75 -> 3.75 | D5: =2*C1*(1+SIN(C3))/C2 -> 14.999866
A6: Высота КЭМ | B6: 30 | C6: =3.75*2 -> 7.5
A7: Основание треугольника | B7: 17.32 | C7: 4.33 | D7: =2*TAN(C3)*C4 -> 4.3299726
A8: Сторона треугольника | B8: 17.32 | C8: =C7 -> 4.33 | D8: =C4/COS(C3) -> 4.3300884
A9: Длина ячейки Х | B9: =B4 -> 15 | C9: =D4 -> 15.000267
A10: Ширина ячейки Y | B10: =B7 -> 17.32 | C10: =D7 -> 4.3299726
A11: Количество ячеек по Х | B11: 1 | C11: 2 | E11: sigmaX | F11: =50 -> 50
A12: Длина модели по Х | B12: =$B$9*B11 -> 15 | C12: =$B$9*C11 -> 30 | E12: площадь | F12: =B14*B6 -> 1039.2
A13: Количество ячеек по Y | B13: 2 | C13: 2 | E13: сила X | F13: =F11*F12 -> 51960
A14: Длина модели по Y мм | B14: =$B$10*B13 -> 34.64 | C14: =$B$10*C13 -> 34.64
A15: Площадь в направлении X м^2 | B15: =B14/1000*$B$6/1000 -> 0.0010392 | C15: =C14/1000*$B$6/1000 -> 0.0010392
A16: Перемещения по Х мм | B16: 0 | C16: 0.201 | E16: sigmaY | F16: =50 -> 50
A17: Ex | C17: =(F13*(C12/1000)/(C15*C16/1000))/(10^6) -> 7462.6866 | E17: площадь | F17: =B6*C12 -> 900
A18: Ех аналитическое | B18: 7432 | E18: сила Y | F18: =F16*F17 -> 45000
A19: Погрешность % | C19: =ABS($B$18-C17)/C17*100 -> 0.4112
A20: sigma max | C20: 124.87 | D20: 62.23
A21: sigma analit
A22: разница
A24: Перемещения по Y мм | C24: 0.0779 | E24: sigmaZ | F24: 25
A25: Деформация Х | C25: =C16/C12 -> 0.0067 | E25: площадь | F25: =C14*C12 -> 1039.2
A26: Деформация Y | C26: =C24/C14 -> 0.0022488453 | E26: сила Z | F26: =F24*F25 -> 25980
A27: Пуассон YX | C27: =C26/C25 -> 0.33564855
A28: Пуассон YX аналитический | B28: 0.3317
A29: Погрешность yx % | B29: =B28 -> 0.3317 | C29: =(ABS(C27-$B$29)/$B$29)*100 -> 1.1903971
A31: Перемещения по Z | C31: 0.0291
A32: Деформация по Z | C32: =C31/$B$6 -> 0.00097
A33: Пуассон ZX | C33: =C32/C25 -> 0.14477612
A34: Пуассон ZX аналитический | B34: 0.1444
A35: Погрешность ZX % | B35: =B34 -> 0.1444 | C35: =ABS($B$35-C33)/$B$35*100 -> 0.2604705
A49: Растяжение по Y | B49: При увеличении ячеек по X
A50: Количество ячеек по Y | C50: 2
A51: Длина модели по Y | C51: =$B$10*C50 -> 34.64
A52: Количество ячеек по Х | C52: 2
A53: Длина модели по Х | C53: =$B$9*C52 -> 30
A54: Площадь в направлении Y м^2 | C54: =C53*$B$6/1000000 -> 0.0009
A55: Перемезщения по Y | C55: 0.232
...

Sheet isogrid_stress
A1: t= | B1: 1 | C1: 1 | D1: Сила | E1: 1000 | F1: t_факт | G1: 4
A2: v= | B2: 0.2 | C2: 0.2 | F2: v_факт | G2: =(G1/B4)+(2*G1/B5) -> 0.8
A3: phi= | B3: 30 | C3: =D3*3.1415/180 -> 0.52358333 | D3: 30
A4: a90= | B4: 15 | C4: =3.75 -> 3.75 | D4: =C1*(1+SIN(C3))/(C2*SIN(C3)) -> 15.000267
A5: a_phi | B5: 15 | C5: =3.75 -> 3.75 | D5: =2*C1*(1+SIN(C3))/C2 -> 14.999866
A6: Высота КЭМ | B6: 30 | C6: =3.75*2 -> 7.5
A7: Основание треугольника | B7: 17.32 | C7: 4.33 | D7: =2*TAN(C3)*C4 -> 4.3299726
A8: Сторона треугольника | B8: 17.32 | C8: =C7 -> 4.33 | D8: =C4/COS(C3) -> 4.3300884
A9: Длина ячейки Х | B9: =B4 -> 15 | C9: =D4 -> 15.000267
A10: Ширина ячейки Y | B10: =B7 -> 17.32 | C10: =D7 -> 4.3299726
A11: Количество ячеек по Х | B11: 1 | C11: 2 | E11: sigmaX | F11: =50 -> 50
A12: Длина модели по Х | B12: =$B$9*B11 -> 15 | C12: =$B$9*C11 -> 30 | E12: площадь | F12: =B14*B6 -> 1039.2
A13: Количество ячеек по Y | B13: 2 | C13: 2 | E13: сила X | F13: =F11*F12 -> 51960 | J13: ТУТ ПЕРЕМЕЩЕНИЯ И СИЛА ВООБЩЕ НЕ ИМЕЮТ ОТНОШЕНИЯ К НАПРЯЖЕННИЯМ
A14: Длина модели по Y мм | B14: =$B$10*B13 -> 34.64 | C14: =$B$10*C13 -> 34.64
A15: Площадь в направлении X м^2 | B15: =B14/1000*$B$6/1000 -> 0.0010392 | C15: =C14/1000*$B$6/1000 -> 0.0010392 | J15: ЭТОТ ЛИСТ ТОЛЬКО ДЛЯ НАПРЯЖЕНИЙ
A16: Перемещения по Х мм | B16: 0 | C16: 0.101 | E16: sigmaY | F16: =50 -> 50
A17: Ex | C17: =($E$1*(C12/1000)/(C15*C16/1000))/(10^6) -> 285.82535 | E17: площадь | F17: =B6*C12 -> 900
A18: Ех аналитическое | B18: 7570 | E18: сила Y | F18: =F16*F17 -> 45000
A19: Погрешность % | C19: =ABS($B$18-C17)/C17*100 -> 2548.4705
A20: sigma max | C20: 124.87 | D20: 62.23
A21: sigma analit | C21: 125 | D21: 62.5
A22: разница
E24: sigmaZ | F24: 25
E25: площадь | F25: =C14*C12 -> 1039.2
E26: сила Z | F26: =F24*F25 -> 25980
A49: Растяжение по Y | B49: При увеличении ячеек по X
A50: Количество ячеек по Y | C50: 2
A51: Длина модели по Y | C51: =$B$10*C50 -> 34.64
A52: Количество ячеек по Х | C52: 2
A53: Длина модели по Х | C53: =$B$9*C52 -> 30
A54: Площадь в направлении Y м^2 | C54: =C53*$B$6/1000000 -> 0.0009
A55: Перемезщения по Y | C55: 0.0958
A56: Ey | C56: =($E$1*(C51/1000)/(C54*C55/1000))/(10^6) -> 401.76293
A57: Ey аналитическое | B57: 2293.9
A58: Погрешность | C58: =ABS($B$57-C56)/C56*100 -> 470.9586
A59: sigma max | C59: 0 | D59: 187.35
A60: sigma analit | C60: 0 | D60: 187.5
A61: разница
A78: Растяжение по Z | B78: При увеличении ячеек по X
A79: Количество ячеек по Y | C79: 2
...

Sheet anisogrid120
A1: t= | B1: 1 | C1: 1 | D1: Сила | E1: 10000 | F1: t_факт | G1: 4
A2: v= | B2: 0.2 | C2: 0.2 | F2: v_факт | G2: =(G1/B4)+(2*G1/B5) -> 0.80012659
A3: phi= | B3: 60 | C3: =D3*3.1415/180 -> 1.0471667 | D3: 60
A4: a90= | B4: =C4 -> 10.77 | C4: 10.77 | D4: =C1*(1+SIN(C3))/(C2*SIN(C3)) -> 10.773606
A5: a_phi | B5: =C5 -> 18.66 | C5: 18.66 | D5: =2*C1*(1+SIN(C3))/C2 -> 18.6601
A6: Высота КЭМ | B6: 40 | C6: =3.75*2 -> 7.5
A7: Основание треугольника | B7: =C7 -> 37.3 | C7: 37.3 | D7: =2*TAN(C3)*C4 -> 37.305714
A8: Сторона треугольника | B8: =C8 -> 21.54 | C8: 21.54 | D8: =C4/COS(C3) -> 21.538848
A9: Длина ячейки Х | B9: =B4 -> 10.77 | C9: =D4 -> 10.773606
A10: Ширина ячейки Y | B10: =B7 -> 37.3 | C10: =D7 -> 37.305714
A11: Количество ячеек по Х | B11: 1 | C11: 2 | E11: sigmaX | F11: =50 -> 50
A12: Длина модели по Х | B12: =$B$9*B11 -> 10.77 | C12: =$B$9*C11 -> 21.54 | E12: площадь | F12: =B14*B6 -> 2984
A13: Количество ячеек по Y | B13: 2 | C13: 2 | E13: сила X | F13: =F11*F12 -> 149200
A14: Длина модели по Y мм | B14: =$B$10*B13 -> 74.6 | C14: =$B$10*C13 -> 74.6
A15: Площадь в направлении X м^2 | B15: =B14/1000*$B$6/1000 -> 0.002984 | C15: =C14/1000*$B$6/1000 -> 0.002984
A16: Перемещения по Х мм | B16: 0 | C16: 2.271 | E16: sigmaY | F16: =50 -> 50
A17: Ex | C17: =(F13*(C12/1000)/(C15*C16/1000))/(10^6) -> 474.24042 | E17: площадь | F17: =B6*C12 -> 861.6
A18: Ех аналитическое | B18: 454.6221 | E18: сила Y | F18: =F16*F17 -> 43080
A19: Погрешность % | C19: =ABS($B$18-C17)/C17*100 -> 4.1367884
A20: sigma max | C20: 453.558 | D20: 380
A21: sigma analit | C21: 450.88 | D21: 384.79
A22: разница
A24: Перемещения по Y мм | C24: 1.024 | E24: sigmaZ | F24: 50
A25: Деформация Х | C25: =C16/C12 -> 0.10543175 | E25: площадь | F25: =C14*C12 -> 1606.884
A26: Деформация Y | C26: =C24/C14 -> 0.013726542 | E26: сила Z | F26: =F24*F25 -> 80344.2
A27: Пуассон YX | C27: =C26/C25 -> 0.13019362
A28: Пуассон YX аналитический | B28: 0.1312
A29: Погрешность yx % | B29: =B28 -> 0.1312 | C29: =(ABS(C27-$B$29)/$B$29)*100 -> 0.76705992
A31: Перемещения по Z | C31: 0.0388
A32: Деформация по Z | C32: =C31/$B$6 -> 0.00097
A33: Пуассон ZX | C33: =C32/C25 -> 0.0092002642
A34: Пуассон ZX аналитический | B34: 0.0088
A35: Погрешность ZX % | B35: =B34 -> 0.0088 | C35: =ABS($B$35-C33)/$B$35*100 -> 4.5484568
A49: Растяжение по Y | B49: При увеличении ячеек по X
A50: Количество ячеек по Y | C50: 2
A51: Длина модели по Y | C51: =$B$10*C50 -> 74.6
A52: Количество ячеек по Х | C52: 2
A53: Длина модели по Х | C53: =$B$9*C52 -> 21.54
A54: Площадь в направлении Y м^2 | C54: =C53*$B$6/1000000 -> 0.0008616
A55: Перемезщения по Y | C55: 0.352
...

Sheet Лист2
A1: t= | B1: 1.5 | C1: 1.5 | D1: Сила
A2: v= | B2: 0.6 | C2: 0.6
A3: phi= | B3: 15 | C3: =D3*3.1415/180 -> 0.26179167 | D3: 15
A4: a90= | B4: =C4 -> 12.16 | C4: =12.16 -> 12.16 | D4: =C1*(1+SIN(C3))/(C2*SIN(C3)) -> 12.159537
A5: a_phi | B5: =C5 -> 6.3 | C5: 6.3 | D5: =2*C1*(1+SIN(C3))/C2 -> 6.2940579
A6: Высота КЭМ | B6: =8.5 -> 8.5 | C6: =3.75*2 -> 7.5
A7: Основание треугольника | B7: =C7 -> 6.52 | C7: 6.52 | D7: =2*TAN(C3)*C4 -> 6.5163231
A8: Сторона треугольника | B8: =C8 -> 12.589 | C8: 12.589 | D8: =C4/COS(C3) -> 12.588932
A9: Длина ячейки Х | B9: =B4 -> 12.16 | C9: =D4 -> 12.159537
A10: Ширина ячейки Y | B10: =B7 -> 6.52 | C10: =D7 -> 6.5163231

Sheet Сравнение КПО
E1: Габариты по КЭМ | J1: Габариты с учетом толщины периметров
E2: КПО1 | F2: Длина рабочей части | G2: 97.28 | H2: мм | J2: КПО1 | K2: Длина рабочей части | L2: 97.28 | M2: мм
F3: Ширина | G3: =21.548 -> 21.548 | H3: мм | K3: Ширина | L3: =21.548+1.5 -> 23.048 | M3: мм
F4: Высота | G4: 7.68 | H4: мм | K4: Высота | L4: 8.4 | M4: мм
F5: Площалдь сечения | G5: =G3/1000*G4/1000 -> 0.00016548864 | H5: м^2 | K5: Площалдь сечения | L5: =L3/1000*L4/1000 -> 0.0001936032 | M5: м^2
F6: Перемещения модели | G6: 0.0024546 | K6: Перемещения модели | L6: 0.0024546
F7: Нагрузка | G7: 100 | H7: N | K7: Нагрузка | L7: 100 | M7: N
G9: =G7*(G2/1000)/(G5*G6/1000) -> 2.3948298e+10 | L9: =L7*(L2/1000)/(L5*L6/1000) -> 2.0470587e+10
G11: =G9/10^6 -> 23948.298 | L11: =L9/10^6 -> 20470.587
E16: Габариты модели только по КЭМ
E17: КПО2 | F17: Длина рабочей части | G17: 97.28 | H17: мм | K17: КПО_идеал RBE/размеры только по габаритам КЭМ | L17: Длина рабочей части | M17: 97.28 | N17: мм | Q17: Габариты с учетом толщины | W17: КПО_без периметров | X17: Длина рабочей части | Y17: 97.28 | Z17: мм
F18: Ширина | G18: =21.548 -> 21.548 | H18: мм | L18: Ширина | M18: =19.79 -> 19.79 | N18: мм | Q18: КПО2 | R18: Длина рабочей части | S18: 97.28 | T18: мм | X18: Ширина | Y18: =19.79 -> 19.79 | Z18: мм
F19: Высота | G19: 7.68 | H19: мм | L19: Высота | M19: 7.68 | N19: мм | R19: Ширина | S19: =23.048 -> 23.048 | T19: мм | X19: Высота | Y19: 7.68 | Z19: мм
F20: Площалдь сечения | G20: =G18*G19 -> 165.48864 | H20: мм^2 | L20: Площалдь сечения | M20: =M18*M19 -> 151.9872 | N20: мм^2 | R20: Высота | S20: 8.4 | T20: мм | X20: Площалдь сечения | Y20: =Y18*Y19 -> 151.9872 | Z20: мм^2
F21: Перемещения модели | G21: 0.003331 | H21: мм | L21: Перемещения модели | M21: 0.003331 | N21: мм | R21: Площалдь сечения | S21: =S19*S20 -> 193.6032 | T21: мм^2 | X21: Перемещения модели | Y21: 0.004977 | Z21: мм
F22: Нагрузка | G22: 100 | H22: N | L22: Нагрузка | M22: 100 | N22: N | R22: Перемещения модели | S22: 0.002503 | T22: мм | X22: Нагрузка | Y22: 100 | Z22: N
R23: Нагрузка | S23: 100 | T23: N
G24: =G22*(G17/1000)/(G20*G21/1000) -> 17647.401 | M24: =M22*(M17/1000)/(M20*M21/1000) -> 19215.068 | Y24: =Y22*(Y17/1000)/(Y20*Y21/1000) -> 12860.235
G25: 15997 | S25: =S23*(S18/1000)/(S21*S22/1000) -> 20074.752
G26: =(G24-G25)/G25*100 -> 10.316938
E30: Треугольники без пластика | F30: Длина рабочей части | G30: 97.28 | H30: мм
F31: Ширина | G31: =21.554+1.5 -> 23.054 | H31: мм | K31: rebro_old
F32: Высота | G32: 7.68 | H32: мм | K32: КПО2 | L32: Длина рабочей части | M32: 97.28 | N32: мм
F33: Площалдь сечения | G33: =G31*G32 -> 177.05472 | H33: мм^2 | L33: Ширина | M33: =21.548 -> 21.548 | N33: мм
F34: Перемещения модели | G34: 0.002702 | H34: мм | L34: Высота | M34: 7.68 | N34: мм
F35: Нагрузка | G35: 100 | H35: N | L35: Площалдь сечения | M35: =M33*M34 -> 165.48864 | N35: мм^2
L36: Перемещения модели | M36: 0.003682 | N36: мм
G37: =G35*(G30/1000)/(G33*G34/1000) -> 20334.369 | L37: Нагрузка | M37: 100 | N37: N
M39: =M37*(M32/1000)/(M35*M36/1000) -> 15965.098
M40: 15997
M41: =(M39-M40)/M40*100 -> -0.19942441
E44: КПО_Z | F44: Длина рабочей части | G44: 41.1 | H44: мм
F45: Ширина | G45: 38.98 | H45: мм
F46: Высота | G46: 20.08 | H46: мм
F47: Площалдь сечения | G47: =G45*G44 -> 1602.078 | H47: мм^2
F48: Перемещения модели | G48: 0.029 | H48: мм | K48: 0.02927
F49: Нагрузка | G49: 1000 | H49: N
F51: Ez= | G51: =G49*(G46/1000)/(G47*G48/1000) -> 432.1973
F52: Ez_experiment= | G52: 455
F53: % | G53: =(G51-G52)/G52*100 -> -5.0115814
...

Sheet Шестигранник
A1: t_теоретическое= | B1: 1.5 | C1: 1.5 | D1: Сила | E1: 10000 | F1: t_факт | G1: 2
A2: v_теоретическое= | B2: 0.6 | C2: 0.6 | F2: v_факт | G2: =(G1/B4)+(2*G1/B5) -> 0.79939432
A3: phi= | B3: 15 | C3: =D3*3.1415/180 -> 0.52358333 | D3: 30
A4: a90= | B4: =C4 -> 12.16 | C4: =12.16 -> 12.16 | D4: =C1*(1+SIN(C3))/(C2*SIN(C3)) -> 7.5001337
A5: a_phi | B5: =C5 -> 6.3 | C5: 6.3 | D5: =2*C1*(1+SIN(C3))/C2 -> 7.4999331
A6: Высота КЭМ | B6: 7.68 | C6: =3.75*2 -> 7.5
A7: Основание треугольника | B7: =C7 -> 6.516 | C7: 6.516 | D7: =2*TAN(C3)*C4 -> 14.040658
A8: Сторона треугольника | B8: =C8 -> 12.589 | C8: 12.589 | D8: =C4/COS(C3) -> 14.041033
A9: Длина ячейки Х | B9: =B4 -> 12.16 | C9: =D4 -> 7.5001337
A10: Ширина ячейки Y | B10: =B7 -> 6.516 | C10: =D7 -> 14.040658
A11: Количество ячеек по Х | B11: 3 | C11: 3 | D11: 3 | E11: 3
A12: Длина модели по Х | B12: 97.28 | C12: 97.28 | D12: 97.28 | E12: 97.28 | F12: 97.28 | G12: 97.28
A13: Количество ячеек по Y | B13: 3 | C13: 6 | D13: 9 | E13: 12 | F13: 15 | G13: 18
A14: Длина модели по Y мм | B14: =B13*$B$10 -> 19.548 | C14: =C13*$B$10 -> 39.096 | D14: =D13*$B$10 -> 58.644 | E14: =E13*$B$10 -> 78.192 | F14: =F13*$B$10 -> 97.74 | G14: =G13*$B$10 -> 117.288
A15: Площадь в направлении X м^2 | B15: =B14/1000*$B$6/1000 -> 0.00015012864 | C15: =C14/1000*$B$6/1000 -> 0.00030025728 | D15: =D14/1000*$B$6/1000 -> 0.00045038592 | E15: =E14/1000*$B$6/1000 -> 0.00060051456 | F15: =F14/1000*$B$6/1000 -> 0.0007506432 | G15: =G14/1000*$B$6/1000 -> 0.00090077184
A16: Перемещения по Х мм | B16: =1.449 -> 1.449 | C16: 0.343 | D16: 0.19 | E16: 0.131 | F16: 0.1 | G16: 0.081
A17: Ex | B17: =($E$1*(B12/1000)/(B15*B16/1000))/(10^6) -> 4471.8953 | C17: =($E$1*(C12/1000)/(C15*C16/1000))/(10^6) -> 9445.738 | D17: =($E$1*(D12/1000)/(D15*D16/1000))/(10^6) -> 11368.029 | E17: =($E$1*(E12/1000)/(E15*E16/1000))/(10^6) -> 12365.985 | F17: =($E$1*(F12/1000)/(F15*F16/1000))/(10^6) -> 12959.553 | G17: =($E$1*(G12/1000)/(G15*G16/1000))/(10^6) -> 13332.873
A18: Ех аналитическое | B18: 15141 | C18: 15141 | D18: 15141 | E18: 15141 | F18: 15141 | G18: 15141
A19: Погрешность % | B19: =ABS($B$18-B17)/B17*100 -> 238.58127 | C19: =ABS($B$18-C17)/C17*100 -> 60.294516 | D19: =ABS($B$18-D17)/D17*100 -> 33.189321 | E19: =ABS($B$18-E17)/E17*100 -> 22.440709 | F19: =ABS($B$18-F17)/F17*100 -> 16.832737 | G19: =ABS($B$18-G17)/G17*100 -> 13.561421
A25: Без ГУ на БОКОВЫХ
A26: Количество ячеек по Х | B26: 3 | C26: 3 | D26: 3 | E26: 3
A27: Длина модели по Х | B27: =$B$9*B26 -> 36.48 | C27: =$B$9*C26 -> 36.48 | D27: =$B$9*D26 -> 36.48 | E27: =$B$9*E26 -> 36.48
A28: Количество ячеек по Y | B28: 2 | C28: 6 | D28: 9 | E28: 12
A29: Длина модели по Y мм | B29: =$B$10*B28 -> 13.032 | C29: =$B$10*C28 -> 39.096 | D29: =$B$10*D28 -> 58.644 | E29: =$B$10*E28 -> 78.192
A30: Площадь в направлении X м^2 | B30: =B29/1000*$B$6/1000 -> 0.00010008576 | C30: =C29/1000*$B$6/1000 -> 0.00030025728 | D30: =D29/1000*$B$6/1000 -> 0.00045038592 | E30: =E29/1000*$B$6/1000 -> 0.00060051456
A31: Перемещения по Х мм | B31: 0.004303 | C31: 0.0007015 | D31: 0.0004313 | E31: 0.0003113
A32: Ex | B32: =($E$1*(B27/1000)/(B30*B31/1000))/(10^6) -> 847054.18 | C32: =($E$1*(C27/1000)/(C30*C31/1000))/(10^6) -> 1731943.1 | D32: =($E$1*(D27/1000)/(D30*D31/1000))/(10^6) -> 1877978.3 | E32: =($E$1*(E27/1000)/(E30*E31/1000))/(10^6) -> 1951426.4
A33: Ех аналитическое | B33: 21502
A34: Погрешность % | B34: =ABS($B$18-B32)/B32*100 -> 98.212511 | C34: =ABS($B$18-C32)/C32*100 -> 99.12578 | D34: =ABS($B$18-D32)/D32*100 -> 99.193761 | E34: =ABS($B$18-E32)/E32*100 -> 99.224106

Sheet треуг с смещ
A1: t_теоретическое= | B1: 1.5 | C1: 1.5 | D1: Сила | E1: 10000 | F1: t_факт | G1: 2
A2: v_теоретическое= | B2: 0.6 | C2: 0.6 | F2: v_факт | G2: =(G1/B4)+(2*G1/B5) -> 0.79939432
A3: phi= | B3: 15 | C3: =D3*3.1415/180 -> 0.52358333 | D3: 30
A4: a90= | B4: =C4 -> 12.16 | C4: =12.16 -> 12.16 | D4: =C1*(1+SIN(C3))/(C2*SIN(C3)) -> 7.5001337
A5: a_phi | B5: =C5 -> 6.3 | C5: 6.3 | D5: =2*C1*(1+SIN(C3))/C2 -> 7.4999331
A6: Высота КЭМ | B6: 7.68 | C6: =3.75*2 -> 7.5
A7: Основание треугольника | B7: =C7 -> 6.516 | C7: 6.516 | D7: =2*TAN(C3)*C4 -> 14.040658
A8: Сторона треугольника | B8: =C8 -> 12.589 | C8: 12.589 | D8: =C4/COS(C3) -> 14.041033
A9: Длина ячейки Х | B9: =B4 -> 12.16 | C9: =D4 -> 7.5001337
A10: Ширина ячейки Y | B10: =B7 -> 6.516 | C10: =D7 -> 14.040658
A11: Количество ячеек по Х | B11: 3 | C11: 3 | D11: 3 | E11: 3
A12: Длина модели по Х | B12: 95.2467 | C12: 95.2467 | D12: 95.2467 | E12: 95.2467 | F12: 95.2467 | G12: 95.2467
A13: Количество ячеек по Y | B13: 3 | C13: 6 | D13: 9 | E13: 12 | F13: 15 | G13: 18
A14: Длина модели по Y мм | B14: =B13*$B$10 -> 19.548 | C14: =C13*$B$10 -> 39.096 | D14: =D13*$B$10 -> 58.644 | E14: =E13*$B$10 -> 78.192 | F14: =F13*$B$10 -> 97.74 | G14: =G13*$B$10 -> 117.288
A15: Площадь в направлении X м^2 | B15: =B14/1000*$B$6/1000 -> 0.00015012864 | C15: =C14/1000*$B$6/1000 -> 0.00030025728 | D15: =D14/1000*$B$6/1000 -> 0.00045038592 | E15: =E14/1000*$B$6/1000 -> 0.00060051456 | F15: =F14/1000*$B$6/1000 -> 0.0007506432 | G15: =G14/1000*$B$6/1000 -> 0.00090077184
A16: Перемещения по Х мм | B16: 0.418 | C16: 0.343 | D16: 0.19 | E16: 0.131 | F16: 0.1 | G16: 0.081
A17: Ex | B17: =($E$1*(B12/1000)/(B15*B16/1000))/(10^6) -> 15177.845 | C17: =($E$1*(C12/1000)/(C15*C16/1000))/(10^6) -> 9248.3077 | D17: =($E$1*(D12/1000)/(D15*D16/1000))/(10^6) -> 11130.419 | E17: =($E$1*(E12/1000)/(E15*E16/1000))/(10^6) -> 12107.517 | F17: =($E$1*(F12/1000)/(F15*F16/1000))/(10^6) -> 12688.678 | G17: =($E$1*(G12/1000)/(G15*G16/1000))/(10^6) -> 13054.196
A18: Ех аналитическое | B18: 15141 | C18: 15141 | D18: 15141 | E18: 15141 | F18: 15141 | G18: 15141
A19: Погрешность % | B19: =ABS($B$18-B17)/B17*100 -> 0.24275334 | C19: =ABS($B$18-C17)/C17*100 -> 63.716438 | D19: =ABS($B$18-D17)/D17*100 -> 36.032609 | E19: =ABS($B$18-E17)/E17*100 -> 25.054539 | F19: =ABS($B$18-F17)/F17*100 -> 19.32685 | G19: =ABS($B$18-G17)/G17*100 -> 15.985698
A25: Без ГУ на БОКОВЫХ
A26: Количество ячеек по Х | B26: 3 | C26: 3 | D26: 3 | E26: 3
A27: Длина модели по Х | B27: =$B$9*B26 -> 36.48 | C27: =$B$9*C26 -> 36.48 | D27: =$B$9*D26 -> 36.48 | E27: =$B$9*E26 -> 36.48
A28: Количество ячеек по Y | B28: 2 | C28: 6 | D28: 9 | E28: 12
A29: Длина модели по Y мм | B29: =$B$10*B28 -> 13.032 | C29: =$B$10*C28 -> 39.096 | D29: =$B$10*D28 -> 58.644 | E29: =$B$10*E28 -> 78.192
A30: Площадь в направлении X м^2 | B30: =B29/1000*$B$6/1000 -> 0.00010008576 | C30: =C29/1000*$B$6/1000 -> 0.00030025728 | D30: =D29/1000*$B$6/1000 -> 0.00045038592 | E30: =E29/1000*$B$6/1000 -> 0.00060051456
A31: Перемещения по Х мм | B31: 0.004303 | C31: 0.0007015 | D31: 0.0004313 | E31: 0.0003113
A32: Ex | B32: =($E$1*(B27/1000)/(B30*B31/1000))/(10^6) -> 847054.18 | C32: =($E$1*(C27/1000)/(C30*C31/1000))/(10^6) -> 1731943.1 | D32: =($E$1*(D27/1000)/(D30*D31/1000))/(10^6) -> 1877978.3 | E32: =($E$1*(E27/1000)/(E30*E31/1000))/(10^6) -> 1951426.4
A33: Ех аналитическое | B33: 21502
A34: Погрешность % | B34: =ABS($B$18-B32)/B32*100 -> 98.212511 | C34: =ABS($B$18-C32)/C32*100 -> 99.12578 | D34: =ABS($B$18-D32)/D32*100 -> 99.193761 | E34: =ABS($B$18-E32)/E32*100 -> 99.224106

Sheet Лист3
A1: t= | B1: 1 | C1: 1 | D1: Сила | E1: 10000 | F1: t_факт | G1: 2
A2: v= | B2: 0.2 | C2: 0.2 | F2: v_факт | G2: =(G1/B4)+(2*G1/B5) -> 0.81500755
A3: phi= | B3: 15 | C3: =D3*3.1415/180 -> 0.26179167 | D3: 15
A4: a90= | B4: 11.1432 | C4: 10.77 | D4: =C1*(1+SIN(C3))/(C2*SIN(C3)) -> 24.319073
A5: a_phi | B5: 6.294 | C5: 18.66 | D5: =2*C1*(1+SIN(C3))/C2 -> 12.588116
A6: Высота КЭМ | B6: 40 | C6: =3.75*2 -> 7.5
A7: Основание треугольника | B7: =C7 -> 37.3 | C7: 37.3 | D7: =2*TAN(C3)*C4 -> 5.7714474
A8: Сторона треугольника | B8: =C8 -> 21.54 | C8: 21.54 | D8: =C4/COS(C3) -> 11.149901
A9: Длина ячейки Х | B9: =B4 -> 11.1432 | C9: =D4 -> 24.319073
A10: Ширина ячейки Y | B10: =B7 -> 37.3 | C10: =D7 -> 5.7714474
A19: E3r | B19: 599
A20: sin phi = | B20: =SIN(C3) -> 0.25881159
A21: vfr | B21: =17.76/100 -> 0.1776
A24: = | B24: =(1-3*B21)/(1-2*B21) -> 0.72456576
A28: = | B28: =(1+4*B20)/(4*(1+B20)^2) -> 0.32109647
A32: дробь= | B32: =B24*B28*0.71 -> 0.16518541
A34: итого: | B34: =(1-B32)*B19 -> 500.05394

Sheet сводная табл напряжения
B1: x | C1: y | D1: z | E1: xy | F1: xz | G1: yz
A2: 15 | B2: ='15_stress'!C20 -> 84.27 | C2: ='15_stress'!D59 -> 303.73 | D2: ='15_stress'!C88 -> 62.493 | E2: ='15_stress'!C126 -> 155.61 | F2: ='15_stress'!C145 -> 1.63 | G2: ='15_stress'!C166 -> 1.26
A3: 30 | B3: =isorg_30!C20 -> 124.87 | C3: =isorg_30!D59 -> 187.5 | D3: =isogrid_stress!C88 -> 62.5 | E3: =isogrid_stress!C126 -> 110.88 | F3: =isogrid_stress!C145 -> 2.256 | G3: =isogrid_stress!C166 -> 1.262
A4: 60 | B4: =anisogrid120!C20 -> 453.558 | C4: =anisogrid120!D59 -> 131.7 | D4: =anisogrid120!C88 -> 62.478 | E4: =anisogrid120!C126 -> 136.67 | F4: =anisogrid120!C145 -> 4.76 | G4: =anisogrid120!C166 -> 1.39
B9: 15_stress
B10: isogrid_stress
B11: anisogrid120
B42: Ex | C42: Ey | D42: Ez | E42: Gxy | F42: Gxz | G42: Gyz
A43: 15
A44: 30
A45: 60
